Workbook
Name \0: #REF!
Name \a: #N/A
Name \a: #N/A
Name \a: #N/A
Name \a: #N/A
Name \a: #N/A
Name \a: #N/A
Name \a: #N/A
Name \a: #N/A
Name \a: #N/A
Name \a: #N/A
Name \a: #N/A
Name \a: #N/A
Name \a: #N/A
Name \a: #N/A
Name \a: #N/A
Name \a: #REF!
Name \b: #N/A
Name \c: #N/A
Name \d: #N/A
Name \e: #N/A
Name \f: #N/A
Name \g: #N/A
Name \h: [1]PP!$IC$5
Name \h: #N/A
Name \h: #N/A
Name \h: #N/A
Name \h: #N/A
Name \h: #N/A
Name \h: #N/A
Name \h: #N/A
Name \h: #N/A
Name \h: #N/A
Name \h: #N/A
Name \h: #N/A
Name \h: #N/A
Name \h: #N/A
Name \h: #N/A
Name \h: #N/A
Name \h: #REF!
Name \i: [1]PP!$IP$7844
Name \i: #N/A
Name \i: #N/A
Name \i: #N/A
Name \i: #N/A
Name \i: #N/A
Name \i: #N/A
Name \i: #N/A
Name \i: #N/A
Name \i: #N/A
Name \i: #N/A
Name \i: #N/A
Name \i: #N/A
Name \i: #N/A
Name \i: #N/A
Name \i: #N/A
Name \i: #REF!
Name \j: #N/A
Name \k: #N/A
Name \KWS123: #N/A

Sheet IBSHI đơn 5 (4)
B1: C¤NG TY tnhh tm ngäc hiÕu | D1: céng hoµ x· héi chñ nghÜa viÖt nam
B2: Sè 8 M¸y T¬ - Ng« QuyÒn - H¶i Phßng | D2: §éc LËp - Tù Do - H¹nh Phóc
A3: -----J----- | D3: ---------o0o--------
D4: H¶i Phßng, Ngµy 05 th¸ng 11 n¨m 2025
C6: b¸o gi¸
B7: Kính gửi: CÔNG TY IBSHI
A8: Theo yªu cÇu cña Quý C«ng ty. Chóng t«i cã thÓ cung cÊp cho C«ng ty c¸c mÆt hµng sau: | L8: =L5+L6 -> 0
A10: STT | B10: Quy cách | C10: Số lượng (cây) | D10: Trọng lượng | E10: Đơn Giá | F10: Thành tiền | G10: bazem
A11: I90-C5 | B11: Thép tấm 10*2000*12000 | C11: 1 | D11: =ROUND(10*2*12*7.85*C11,0) -> 1884 | E11: =ROUND(G11/1.1,2) -> 13636.36 | F11: =ROUND(E11*D11,0) -> 25690902 | G11: 15000 | H11: oke
A12: I90-C6 | B12: Thép tấm 12*2000*12000 | C12: 1 | D12: =ROUND(12*2*12*7.85*C12,0) -> 2261 | E12: =ROUND(G12/1.1,2) -> 13636.36 | F12: =ROUND(E12*D12,0) -> 30831810 | G12: 15000 | H12: oke
A13: I90-C7 | B13: Thép tấm 16*2000*6000 | C13: 1 | D13: =ROUND(16*2*6*7.85*C13,0) -> 1507 | E13: =ROUND(G13/1.1,2) -> 14000 | F13: =ROUND(E13*D13,0) -> 21098000 | G13: 15400 | H13: oke
A14: I90-C8 | B14: Thép tấm 20*2000*12000 | C14: 1 | D14: =ROUND(20*2*12*7.85*C14,0) -> 3768 | E14: =ROUND(G14/1.1,2) -> 14181.82 | F14: =ROUND(E14*D14,0) -> 53437098 | G14: 15600 | H14: oke
A15: I90-C12 | B15: Thép H125*125*6,5*9*12000 | C15: 6 | D15: =ROUND(23.6*12*C15,0) -> 1699 | E15: =ROUND(G15/1.1,2) -> 17545.45 | F15: =ROUND(E15*D15,0) -> 29809720 | G15: 19300 | H15: oke | I15: =C15*12 -> 72 | J15: 74 | K15: H125x125x6.5x9
A16: I90-C13 | B16: Thép H200*200*8*12*12000 | C16: 12 | D16: =ROUND(49.9*12*C16,0) -> 7186 | E16: =ROUND(G16/1.1,2) -> 17545.45 | F16: =ROUND(E16*D16,0) -> 126081604 | G16: 19300 | H16: oke | I16: =C16*12 -> 144 | J16: 139.26525 | K16: H200x200x8x12 | L16: H200x200x8x12
A17: I90-C15 | B17: Thép H250*250*9*14*12000 | C17: 3 | D17: =ROUND(71.8*12*C17,0) -> 2585 | E17: =ROUND(G17/1.1,2) -> 17545.45 | F17: =ROUND(E17*D17,0) -> 45354988 | G17: 19300 | H17: oke | I17: =C17*12 -> 36 | J17: 25.68 | K17: H250x250x9x14 | L17: H250x250x9x14
A18: I90-C16 | B18: Thép H150*150*7*10*12000 | C18: 3.5 | D18: =ROUND(31.1*12*C18,0) -> 1306 | E18: =ROUND(G18/1.1,2) -> 17545.45 | F18: =ROUND(E18*D18,0) -> 22914358 | G18: 19300 | H18: oke | I18: =C18*12 -> 42 | J18: 42 | K18: H150x150x7x10 | L18: H150x150x7x10
A19: I90-C21 | B19: Thép U200*90*8*13,5*12000 | C19: 8 | D19: =ROUND(30.3*12*C19,0) -> 2909 | E19: =ROUND(G19/1.1,2) -> 17545.45 | F19: =ROUND(E19*D19,0) -> 51039714 | G19: 19300 | H19: oke | I19: =C19*12 -> 96 | J19: 93.5 | K19: U200x90x8.5x13.5 | L19: Thép U200x90x8x13.5x12000 | M19: U200x90x8.5x13.5
A20: I90-C22 | B20: Thép U250*90*9*13*12000 | C20: 35 | D20: =ROUND(34.6*12*C20,0) -> 14532 | E20: =ROUND(G20/1.1,2) -> 17545.45 | F20: =ROUND(E20*D20,0) -> 254970479 | G20: 19300 | H20: oke | I20: =C20*12 -> 420 | J20: 420.7574 | K20: U250x90x9x13x120000 | L20: Thép U250x90x9x13x120000 | M20: U250x90x9x13x120000
A21: I90-C24 | B21: Thép U300x90x9x13 x120000 | C21: 1 | D21: =ROUND(38.1*12*C21,0) -> 457 | E21: =ROUND(G21/1.1,2) -> 17545.45 | F21: =ROUND(E21*D21,0) -> 8018271 | G21: 19300 | H21: oke | I21: =C21*12 -> 12 | J21: 12 | K21: U300x90x9x12 x120000 | L21: U280x100x9x13 | M21: U300x90x9x12 x120000
A22: I90-C26 | B22: Thép U125*65*6*8*12000 | C22: 11 | D22: =ROUND(13.4*12*C22,0) -> 1769 | E22: =ROUND(G22/1.1,2) -> 17545.45 | F22: =ROUND(E22*D22,0) -> 31037901 | G22: 19300 | H22: oke | I22: =C22*12 -> 132 | J22: 127 | K22: U125x65x6x8 | L22: Hùng Nguyên 4 cây (U125x65x6x8) | M22: U125x65x6x8
A23: I90-C28 | B23: Thép V150*150*10*6000 | C23: 1 | D23: =ROUND(23*6*C23,0) -> 138 | E23: =ROUND(G23/1.1,2) -> 15909.09 | F23: =ROUND(E23*D23,0) -> 2195454 | G23: 17500 | H23: oke | I23: =C23*12 -> 12 | J23: 3
A24: I90-C29 | B24: Thép V80*80*8*6000 | C24: 3 | D24: =ROUND(9.63*6*C24,0) -> 173 | E24: =ROUND(G24/1.1,2) -> 13909.09 | F24: =ROUND(E24*D24,0) -> 2406273 | G24: 15300 | H24: oke | I24: =C24*12 -> 36 | J24: 32.406312 | K24: Thép góc V75x75x7x6000
A25: I90-C30 | B25: Thép V75*75*6*12000 | C25: 3 | D25: =ROUND(6.85*12*C25,0) -> 247 | E25: =ROUND(G25/1.1,2) -> 13909.09 | F25: =ROUND(E25*D25,0) -> 3435545 | G25: 15300 | H25: oke | I25: =C25*12 -> 36 | J25: 15.84 | K25: Thép góc V80x80x8x6000
A26: 16 | F26: =ROUND(SUM(F11:F25),0) -> 708322117 | I26: =C26*12 -> 0
A27: 17 | B27: VAT 10% | F27: =ROUND(F26*10%,0) -> 70832212
A29: Tæng Céng | D29: =SUM(D11:D28) -> 42421 | F29: =F26+F27 -> 779154329
B30: - Hiệu lực báo giá: báo giá có giá trị hết ngày 10/11/2025 , giá đã bao gồm VAT 10% | H30: 1 | K30: hoan
B31: - Điều kiện giao hàng: hàng giao theo bazem kho bên bán trên phương tiện bên mua.
B32: - Thời hạn thanh toán: trước khi nhận hàng.
B33: - Nếu quý công ty chấp nhận xin vui lòng fax lại số: 0313.528921
B34: Xin trân trọng cảm ơn.
B35: XÁC NHẬN CỦA BÊN MUA | D35: CÔNG TY TNHH TM NGỌC HIẾU

Sheet Máy hàn
A1: BID ANALYSIS - GIẢI TRÌNH MUA SẮM/ĐẤU THẦU
A3: Project | B3: PROJECT No/ Dự án: Phục Vụ Sản Xuất
A4: Dự án
A5: Subject | B5: Cung cấp máy hàn
A6: Chủ đề
A8: No. | B8: CONTENT | D8: Dự toán | G8: Đã mua/Đã đặt | H8: Đơn vị cung cấp chào giá (vnđ) | K8: Lựa chọn | L8: Ghi chú
A9: Item | B9: Description/ Chi tiết | C9: Số lượng (PSC) | D9: Khối lượng/ Số lượng | E9: Đơn giá (vnd) | F9: Thành tiền (vnd) | G9: Thành tiền (vnd) | H9: C.Ty C.Phần Công Nghiệp WELDCOM
C10: Số lượng (cây) | H10: Phạm vi | I10: Đơn giá chưa VAT (VND) | J10: Thành Tiền ( có VAT 8%)
A11: Tổng | D11: N/A | E11: N/A | J11: =SUM(J12:J12) -> 600000000 | L11: =F11-G11-J11 -> -600000000
A12: 1 | B12: M01M-011437 Máy hàn bán tự động MIG500 N388- Jassic (TP5) Bảo hành: 18 tháng (Phụ kiện theo máy bao gồm: Cấp dây 15M cáp 50, súng QTB-500 3M, đồng hồ 36V) | C12: 20 | D12: N/A | E12: N/A | F12: N/A | G12: N/A | H12: V | I12: 27777778 | J12: 600000000 | K12: WELDCOM
B13: Đơn giá tổng hợp
A14: II | B14: Khối lượng dự kiến giao (Kg )/ Estimated weight (Kg):
A15: 1 | B15: …
A16: 2 | B16: …
A17: III | B17: Tiến độ/ Schedule
A18: 1 | B18: ….
A20: IV | B20: Nhân lực/ ManPower
A21: 1 | B21: Thợ Pha cắt / Thợ sắt / Thợ hàn / …
B22: ….
A23: V | B23: Yêu cầu kỹ thuật: Tham chiếu các tài liệu đính kèm/ Technical requirement – refer to document attached
B24: Xếp hạng | I24: 1
A25: Ghi Chú: PTM tiến hành ngay công tác mua hàng
A26: NGƯỜI ĐỀ NGHỊ/ RECOMMENDATION BY: | C26: NGƯỜI KIỂM TRA/ DEPARTMENT HEAD CHECK BY: | G26: APPROVED BY: PHÊ DUYỆT
G27: Nguyễn Quang Vinh | I27: Hoàng Ngọc Bằng | K27: Đoàn Văn Toàn
H30: Nguyễn Quang Vinh | J30: Hoàng Ngọc Bằng | M30: Đoàn Văn Toàn

Sheet Sàn nhựa Đại Việt
A1: BID ANALYSIS - GIẢI TRÌNH MUA SẮM/ĐẤU THẦU
A3: Project | B3: PROJECT No/ Dự án: 25-BRA-I-090
A4: Dự án
A5: Subject | B5: Cung cấp vật tư GRATING dự án 090
A6: Chủ đề
A8: No. | B8: CONTENT | G8: Dự toán | J8: Đã mua/Đã đặt | K8: Đơn vị cung cấp chào giá (vnđ) | N8: Lựa chọn | O8: Ghi chú
A9: Chủng loại | B9: Bản vẽ | C9: Length | D9: Width | E9: Thickness | F9: ĐVT | G9: Số lượng | H9: Đơn giá (vnd) | I9: Thành tiền (vnd) | J9: Thành tiền (vnd) | K9: CÔNG TY CỔ PHẦN ĐẠI PHÁT COMPOSITE
E10: Số lượng (cây) | F10: Trọng lượng | K10: Phạm vi | L10: Đơn giá (VND) | M10: Thành Tiền (Không có VAT)
M11: =SUM(M12:M89) -> 255444000 | O11: =I11-J11-M11 -> -255444000
A12: Tấm sàn grating ô 38*38*30mm | B12: 13105R-R001-Z301-000 | C12: 790 | D12: 600 | E12: 30 | F12: Tấm | G12: 10 | H12: N/A | I12: N/A | J12: N/A | K12: V | L12: 690000 | M12: 6900000 | N12: Đại Phát | O12: 13105R-R001-Z302-000 Đã giao
A13: Tấm sàn grating ô 38*38*30mm | B13: 13105R-R001-Z302-000 | C13: 790 | D13: 425 | E13: 30 | F13: Tấm | G13: 4 | H13: N/A | I13: N/A | J13: N/A | K13: V | L13: 590000 | M13: 2360000 | N13: Đại Phát
A14: Tấm sàn grating ô 38*38*30mm | B14: 13105R-R001-Z305-000 | C14: 790 | D14: 600 | E14: 30 | F14: Tấm | G14: 2 | H14: N/A | I14: N/A | J14: N/A | K14: V | L14: 690000 | M14: 1380000 | N14: Đại Phát
A15: Tấm sàn grating ô 38*38*30mm | B15: 13105R-R001-Z306-000 | C15: 679 | D15: 425 | E15: 30 | F15: Tấm | G15: 4 | H15: N/A | I15: N/A | J15: N/A | K15: V | L15: 510000 | M15: 2040000 | N15: Đại Phát
A16: Tấm sàn grating ô 38*38*30mm | B16: 13105R-R001-Z307-000 | C16: 679 | D16: 425 | E16: 30 | F16: Tấm | G16: 4 | H16: N/A | I16: N/A | J16: N/A | K16: V | L16: 510000 | M16: 2040000 | N16: Đại Phát
A17: GRP-Grating-thk 30mm | B17: 13164R-R001-Z301-000 | C17: 790 | D17: 600 | E17: 30 | F17: Tấm | G17: 15 | H17: N/A | I17: N/A | J17: N/A | K17: V | L17: 690000 | M17: 10350000 | N17: Đại Phát | O17: I90-Grating-Type H30mm-13164 (3units)-Rev00
A18: GRP-Grating-thk 30mm | B18: 13164R-R001-Z302-000 | C18: 790 | D18: 425 | E18: 30 | F18: Tấm | G18: 6 | H18: N/A | I18: N/A | J18: N/A | K18: V | L18: 590000 | M18: 3540000 | N18: Đại Phát
A19: GRP-Grating-thk 30mm | B19: 13164R-R001-Z303-000 | C19: 830 | D19: 425 | E19: 30 | F19: Tấm | G19: 6 | H19: N/A | I19: N/A | J19: N/A | K19: V | L19: 670000 | M19: 4020000 | N19: Đại Phát
A20: GRP-Grating-thk 30mm | B20: 13164R-R001-Z304-000 | C20: 860 | D20: 425 | E20: 30 | F20: Tấm | G20: 6 | H20: N/A | I20: N/A | J20: N/A | K20: V | L20: 670000 | M20: 4020000 | N20: Đại Phát
A21: GRP-Grating-thk 30mm | B21: 13164R-R001-Z305-000 | C21: 790 | D21: 600 | E21: 30 | F21: Tấm | G21: 3 | H21: N/A | I21: N/A | J21: N/A | K21: V | L21: 690000 | M21: 2070000 | N21: Đại Phát
A22: GRP-Grating-thk 50mm | B22: 13105R-R001-S116-005A | C22: 1172 | D22: 610 | E22: 50 | F22: Tấm | G22: 8 | H22: N/A | I22: N/A | J22: N/A | K22: V | L22: 1500000 | M22: 12000000 | N22: Đại Phát | O22: I90-Grating H50mm-BO SUNG (U1+U2)-REV00 Đã giao
A23: GRP-Grating-thk 50mm | B23: 13105R-R001-S117-005A | C23: 568 | D23: 610 | E23: 50 | F23: Tấm | G23: 8 | H23: N/A | I23: N/A | J23: N/A | K23: V | L23: 800000 | M23: 6400000 | N23: Đại Phát
A24: GRP-Grating-thk 50mm | B24: 13164R-R001-S108-000 | C24: 1485 | D24: 490 | E24: 50 | F24: Tấm | G24: 2 | H24: N/A | I24: N/A | J24: N/A | K24: V | L24: 1364000 | M24: 2728000 | N24: Đại Phát | O24: I090-Grating partlist-H50mm-U3
A25: GRP-Grating-thk 50mm | B25: 13164R-R001-S109-000 | C25: 1485 | D25: 299 | E25: 50 | F25: Tấm | G25: 1 | H25: N/A | I25: N/A | J25: N/A | K25: V | L25: 855000 | M25: 855000 | N25: Đại Phát
A26: GRP-Grating-thk 50mm | B26: 13164R-R001-S110-000 | C26: 1485 | D26: 259 | E26: 50 | F26: Tấm | G26: 1 | H26: N/A | I26: N/A | J26: N/A | L26: 770000 | M26: 770000 | N26: Đại Phát
A27: GRP-Grating-thk 50mm | B27: 13164R-R001-S112-000 | C27: 1750 | D27: 428.5 | E27: 50 | F27: Tấm | G27: 1 | H27: N/A | I27: N/A | J27: N/A | L27: 1350000 | M27: 1350000 | N27: Đại Phát
A28: GRP-Grating-thk 50mm | B28: 13164R-R001-S116-000 | C28: 1290 | D28: 660 | E28: 50 | F28: Tấm | G28: 1 | H28: N/A | I28: N/A | J28: N/A | L28: 1565000 | M28: 1565000 | N28: Đại Phát
A29: GRP-Grating-thk 50mm | B29: 13164R-R001-S118-000 | C29: 1750 | D29: 610 | E29: 50 | F29: Tấm | G29: 15 | H29: N/A | I29: N/A | J29: N/A | L29: 1905000 | M29: 28575000 | N29: Đại Phát
A30: GRP-Grating-thk 50mm | B30: 13164R-R001-S118-001 | C30: 1750 | D30: 396 | E30: 50 | F30: Tấm | G30: 1 | H30: N/A | I30: N/A | J30: N/A | L30: 1305000 | M30: 1305000 | N30: Đại Phát
A31: GRP-Grating-thk 50mm | B31: 13164R-R001-S118-002 | C31: 779 | D31: 642,5 | E31: 50 | F31: Tấm | G31: 1 | H31: N/A | I31: N/A | J31: N/A | L31: 955000 | M31: 955000 | N31: Đại Phát
A32: GRP-Grating-thk 50mm | B32: 13164R-R001-S118-003 | C32: 961 | D32: 643 | E32: 50 | F32: Tấm | G32: 1 | H32: N/A | I32: N/A | J32: N/A | L32: 1250000 | M32: 1250000 | N32: Đại Phát
A33: GRP-Grating-thk 50mm | B33: 13164R-R001-S119-000 | C33: 1243 | D33: 305 | E33: 50 | F33: Tấm | G33: 2 | H33: N/A | I33: N/A | J33: N/A | L33: 755000 | M33: 1510000 | N33: Đại Phát
A34: GRP-Grating-thk 50mm | B34: 13164R-R001-S120-000 | C34: 850 | D34: 738.5 | E34: 50 | F34: Tấm | G34: 1 | H34: N/A | I34: N/A | J34: N/A | L34: 1255000 | M34: 1255000 | N34: Đại Phát
A35: GRP-Grating-thk 50mm | B35: 13164R-R001-S120-005 | C35: 850 | D35: 738.5 | E35: 50 | F35: Tấm | G35: 1 | H35: N/A | I35: N/A | J35: N/A | L35: 1255000 | M35: 1255000 | N35: Đại Phát
A36: GRP-Grating-thk 50mm | B36: 13164R-R001-S127-001 | C36: 1610 | D36: 600 | E36: 50 | F36: Tấm | G36: 3 | H36: N/A | I36: N/A | J36: N/A | L36: 1750000 | M36: 5250000 | N36: Đại Phát
A37: GRP-Grating-thk 50mm | B37: 13164R-R001-S118-004 | C37: 1750 | D37: 565 | E37: 50 | F37: Tấm | G37: 2 | H37: N/A | I37: N/A | J37: N/A | L37: 1750000 | M37: 3500000 | N37: Đại Phát
A38: GRP-Grating-thk 50mm | B38: 13164R-R001-S127-000 | C38: 2695 | D38: 1220 | E38: 50 | F38: Tấm | G38: 1 | H38: N/A | I38: N/A | J38: N/A | L38: 5550000 | M38: 5550000 | N38: Đại Phát
A39: GRP-Grating-thk 50mm | B39: 13164R-R001-S127-002 | C39: 600 | D39: 501 | E39: 50 | F39: Tấm | G39: 1 | H39: N/A | I39: N/A | J39: N/A | L39: 615000 | M39: 615000 | N39: Đại Phát
A40: GRP-Grating-thk 50mm | B40: 13164R-R001-S127-003 | C40: 1109 | D40: 600 | E40: 50 | F40: Tấm | G40: 1 | H40: N/A | I40: N/A | J40: N/A | L40: 1265000 | M40: 1265000 | N40: Đại Phát
A41: GRP-Grating-thk 50mm | B41: 13164R-R001-S128-000 | C41: 1750 | D41: 517 | E41: 50 | F41: Tấm | G41: 1 | H41: N/A | I41: N/A | J41: N/A | L41: 1650000 | M41: 1650000 | N41: Đại Phát
A42: GRP-Grating-thk 50mm | B42: 13164R-R001-S128-002 | C42: 1750 | D42: 653 | E42: 50 | F42: Tấm | G42: 1 | H42: N/A | I42: N/A | J42: N/A | L42: 2250000 | M42: 2250000 | N42: Đại Phát
...

Sheet Vật tư đóng kiện Trân toàn
A1: BID ANALYSIS - GIẢI TRÌNH MUA SẮM/ĐẤU THẦU
A3: Project | B3: PROJECT No/ Dự án: 25-BRA-I-090
A4: Dự án
A5: Subject | B5: Cung cấp vật tư đóng kiện dự án 090
A6: Chủ đề
A8: No. | B8: CONTENT | C8: Phạm vi công việc | G8: Dự toán | J8: Đã mua/Đã đặt | K8: Đơn vị cung cấp chào giá (vnđ) | N8: Lựa chọn | O8: Ghi chú
A9: Item | B9: Description/ Chi tiết | C9: Profile/ Vật tư | D9: Grade/ Mác vật liệu | E9: Số lượng (M2) | F9: Trọng lượng (KG) | G9: Khối lượng/ Số lượng | H9: Đơn giá (vnd) | I9: Thành tiền (vnd) | J9: Thành tiền (vnd) | K9: Trần Toàn
E10: Số lượng (cây) | F10: Trọng lượng | K10: Phạm vi | L10: Đơn giá (VND) | M10: Thành Tiền (Không có VAT)
A11: Tổng | G11: N/A | H11: N/A | I11: ='DT04 (TM) 1 '!L17 -> 2538751590 | J11: ='Vật tư đóng kiện Ngọc hiếu 090'!K11+'Vật tư đóng kiện Ngọc hiếu 090'!N11 -> 4.994165e+09 | M11: =SUM(M12:M25) -> 262257375 | O11: =I11-J11-M11 -> -2.7176708e+09
A12: I90-C140 | B12: I90-C140 (10500 x 6500) x 3 tấm | D12: Bạt da | E12: 204.75 | F12: N/A | G12: N/A | H12: N/A | I12: N/A | J12: N/A | K12: V | L12: 50500 | M12: =L12*E12 -> 10339875 | N12: Trần Toàn | O12: -Giá trí mua đang vượt dự toán - PTM không nắm được vật tư phụ kiện còn phát sinh hàng không - Thông báo tới SALE để khách hàng hỗ trợ thêm chi phí
A13: I90-C141 | B13: I90-C141 (12000 x 8000) x 3 tấm | D13: Bạt da | E13: 288 | F13: N/A | G13: N/A | H13: N/A | I13: N/A | J13: N/A | K13: V | L13: 50500 | M13: =L13*E13 -> 14544000 | N13: Trần Toàn
A14: I90-C142 | B14: I90-C142 (1200 x 9500) x 1 tấm | D14: Bạt da | E14: 114 | F14: N/A | G14: N/A | H14: N/A | I14: N/A | J14: N/A | K14: V | L14: 50500 | M14: =L14*E14 -> 5757000 | N14: Trần Toàn
A15: I90-C143 | B15: I90-C143 (14000 x 7000) x 4 tấm | D15: Bạt da | E15: =392+196 -> 588 | F15: N/A | G15: N/A | H15: N/A | I15: N/A | J15: N/A | K15: V | L15: 50500 | M15: =L15*E15 -> 29694000 | N15: Trần Toàn
A16: I90-C144 | B16: I90-C144 (15000 x 11000) x 1 tấm | D16: Bạt da | E16: 165 | F16: N/A | G16: N/A | H16: N/A | I16: N/A | J16: N/A | K16: V | L16: 50500 | M16: =L16*E16 -> 8332500 | N16: Trần Toàn
A17: I90-C145 | B17: I90-C145 (15000 x 7000) x 3 tấm | D17: Bạt da | E17: 315 | F17: N/A | G17: N/A | H17: N/A | I17: N/A | J17: N/A | K17: V | L17: 50500 | M17: =L17*E17 -> 15907500 | N17: Trần Toàn
A18: I90-C146 | B18: I90-C146 (15500 x 9500) x 1 tấm | D18: Bạt da | E18: 147.25 | F18: N/A | G18: N/A | H18: N/A | I18: N/A | J18: N/A | K18: V | L18: 50500 | M18: =L18*E18 -> 7436125 | N18: Trần Toàn
A19: I90-C147 | B19: I90-C147 (15500 x 10000) x 1 tấm | D19: Bạt da | E19: 155 | F19: N/A | G19: N/A | H19: N/A | I19: N/A | J19: N/A | K19: V | L19: 50500 | M19: =L19*E19 -> 7827500 | N19: Trần Toàn
A20: I90-C148 | B20: I90-C148 (17000 x 12000) x 4 tấm | D20: Bạt da | E20: 816 | F20: N/A | G20: N/A | H20: N/A | I20: N/A | J20: N/A | K20: V | L20: 50500 | M20: =L20*E20 -> 41208000 | N20: Trần Toàn
A21: I90-C149 | B21: I90-C149 (16500 x 9000) x 3 tấm | D21: Bạt da | E21: 445.5 | F21: N/A | G21: N/A | H21: N/A | I21: N/A | J21: N/A | K21: V | L21: 50500 | M21: =L21*E21 -> 22497750 | N21: Trần Toàn
A22: I90-C150 | B22: I90-C150 (16500 x 10000) x 3 tấm | D22: Bạt da | E22: 495 | F22: N/A | G22: N/A | H22: N/A | I22: N/A | J22: N/A | K22: V | L22: 50500 | M22: =L22*E22 -> 24997500 | N22: Trần Toàn
A23: I90-C151 | B23: I90-C151 (17500 x 11500) x 3 tấm | D23: Bạt da | E23: 603.75 | F23: N/A | G23: N/A | H23: N/A | I23: N/A | J23: N/A | K23: V | L23: 50500 | M23: =L23*E23 -> 30489375 | N23: Trần Toàn
A24: I90-C152 | B24: I90-C152 (9000 x 7500) x 3 tấm | D24: Bạt da | E24: 202.5 | F24: N/A | G24: N/A | H24: N/A | I24: N/A | J24: N/A | K24: V | L24: 50500 | M24: =L24*E24 -> 10226250 | N24: Trần Toàn
A25: I90-C154 | B25: Bạt dứa I90 - C 154 ( 15000 x 20000 ) x 10 tấm | D25: Bạt dứa | E25: 3000 | F25: N/A | G25: N/A | H25: N/A | I25: N/A | J25: N/A | K25: V | L25: 11000 | M25: =L25*E25 -> 33000000 | N25: Trần Toàn
B26: Đơn giá tổng hợp
A27: II | B27: Khối lượng dự kiến giao (Kg )/ Estimated weight (Kg):
A28: 1 | B28: … | C28: kg
A29: 2 | B29: …
A30: III | B30: Tiến độ/ Schedule | C30: Bắt đầu/ Start | D30: Kết thúc/ Finish
A31: 1 | B31: ….
A33: IV | B33: Nhân lực/ ManPower
A34: 1 | B34: Thợ Pha cắt / Thợ sắt / Thợ hàn / …
B35: ….
A36: V | B36: Yêu cầu kỹ thuật: Tham chiếu các tài liệu đính kèm/ Technical requirement – refer to document attached
B37: Xếp hạng | L37: 1
A38: Ghi Chú: Vật tư đóng kiện dự án 090 tính tiền theo khối lượng thực tế, PTM tiến hành mua hàng
A39: NGƯỜI ĐỀ NGHỊ/ RECOMMENDATION BY: | C39: NGƯỜI KIỂM TRA/ DEPARTMENT HEAD CHECK BY: | F39: APPROVED BY: PHÊ DUYỆT
F40: Nguyễn Quang Vinh | H40: Hoàng Ngọc Bằng | K40: Đoàn Văn Toàn

Sheet Vật tư 
A1: BID ANALYSIS - GIẢI TRÌNH MUA SẮM/ĐẤU THẦU
A3: Project | B3: PROJECT No/ Dự án: 25-BRA-I-090
A4: Dự án
A5: Subject | B5: Cung cấp vật tư phục vụ dự án 090
A6: Chủ đề
A8: No. | B8: CONTENT | C8: Phạm vi công việc | F8: Dự toán | I8: Đã mua/Đã đặt | J8: Đơn vị cung cấp chào giá (vnđ) | M8: Lựa chọn | N8: Ghi chú
A9: Item | B9: Description/ Chi tiết | C9: Số thùng | D9: Đóng gói | E9: Trọng lượng (Lít) | F9: Khối lượng/ Số lượng | G9: Đơn giá (vnd) | H9: Thành tiền (vnd) | I9: Thành tiền (vnd) | J9: Phúc Châu
E10: Trọng lượng | J10: Phạm vi | K10: Đơn giá (VND) | L10: Thành Tiền (Không có VAT)
A11: Tổng | B11: Vật tư phục vụ sản xuất 090 | F11: N/A | G11: N/A | L11: =SUM(L12:L12) -> 79800000 | N11: =H11-I11-L11 -> -79800000
A12: 1 | B12: VPCI-386 (19L/Thùng) | C12: 7 | D12: 19L/Thùng | E12: 133 | F12: N/A | G12: N/A | H12: N/A | I12: N/A | J12: V | K12: 600000 | L12: =E12*K12 -> 79800000 | M12: Phúc Châu
A13: II | B13: Khối lượng dự kiến giao (Kg )/ Estimated weight (Kg):
A14: 1 | B14: … | C14: kg
A15: 2 | B15: …
A16: III | B16: Tiến độ/ Schedule | C16: Bắt đầu/ Start | D16: Kết thúc/ Finish
A17: 1 | B17: ….
A19: IV | B19: Nhân lực/ ManPower
A20: 1 | B20: Thợ Pha cắt / Thợ sắt / Thợ hàn / …
B21: ….
A22: V | B22: Yêu cầu kỹ thuật: Tham chiếu các tài liệu đính kèm/ Technical requirement – refer to document attached
B23: Xếp hạng | K23: 1
A24: Ghi Chú: Vật tư phục vụ sản xuất, PTM tiến hành mua hàng ngay để đảm bảo tiến độ
A25: NGƯỜI ĐỀ NGHỊ/ RECOMMENDATION BY: | C25: NGƯỜI KIỂM TRA/ DEPARTMENT HEAD CHECK BY: | E25: APPROVED BY: PHÊ DUYỆT
E26: Nguyễn Quang Vinh | G26: Hoàng Ngọc Bằng | J26: Đoàn Văn Toàn

Sheet Vật tư sơn 090
A1: BID ANALYSIS - GIẢI TRÌNH MUA SẮM/ĐẤU THẦU
A3: Project | B3: PROJECT No/ Dự án: 25-BRA-I-090
A4: Dự án
A5: Subject | B5: Cung cấp vật tư phục vụ dự án 090
A6: Chủ đề
A8: No. | B8: CONTENT | C8: Phạm vi công việc | F8: Dự toán | I8: Đã mua/Đã đặt | J8: Đơn vị cung cấp chào giá (vnđ) | M8: Lựa chọn | N8: Ghi chú
A9: Item | B9: Description/ Chi tiết | C9: Profile/ Vật tư | D9: Grade/ Mác vật liệu | E9: Trọng lượng (KG) | F9: Khối lượng/ Số lượng | G9: Đơn giá (vnd) | H9: Thành tiền (vnd) | I9: Thành tiền (vnd) | J9: Nguyên Hanh
E10: Trọng lượng | J10: Phạm vi | K10: Đơn giá (VND) | L10: Thành Tiền (Không có VAT)
A11: Tổng | B11: Vật tư phục vụ sản xuất 090 | F11: N/A | G11: N/A | L11: =SUM(L12:L12) -> 17400000 | N11: =H11-I11-L11 -> -17400000
A12: 1 | B12: Hạt Garmet 30/60 | C12: Hạt Garmet 30/60 | D12: N/A | E12: 2000 | F12: N/A | G12: N/A | H12: N/A | I12: N/A | J12: V | K12: 8700000 | L12: =K12*2 -> 17400000 | M12: Nguyên hanh
A13: II | B13: Khối lượng dự kiến giao (Kg )/ Estimated weight (Kg):
A14: 1 | B14: … | C14: kg
A15: 2 | B15: …
A16: III | B16: Tiến độ/ Schedule | C16: Bắt đầu/ Start | D16: Kết thúc/ Finish
A17: 1 | B17: ….
A19: IV | B19: Nhân lực/ ManPower
A20: 1 | B20: Thợ Pha cắt / Thợ sắt / Thợ hàn / …
B21: ….
A22: V | B22: Yêu cầu kỹ thuật: Tham chiếu các tài liệu đính kèm/ Technical requirement – refer to document attached
B23: Xếp hạng | K23: 1
A24: Ghi Chú: Vật tư phục vụ sản xuất, PTM tiến hành mua hàng ngay để đảm bảo tiến độ
A25: NGƯỜI ĐỀ NGHỊ/ RECOMMENDATION BY: | C25: NGƯỜI KIỂM TRA/ DEPARTMENT HEAD CHECK BY: | E25: APPROVED BY: PHÊ DUYỆT
E26: Nguyễn Quang Vinh | G26: Hoàng Ngọc Bằng | J26: Đoàn Văn Toàn

Sheet Vật tư Hùng Nguyên
A1: BID ANALYSIS - GIẢI TRÌNH MUA SẮM/ĐẤU THẦU
A3: Project | B3: PROJECT No/ Dự án: 25-BRA-I-090
A4: Dự án
A5: Subject | B5: Cung cấp vật tư chính và vật tư đóng kiện dự án 090
A6: Chủ đề
A8: No. | B8: CONTENT | C8: Phạm vi công việc | G8: Dự toán | J8: Đã mua/Đã đặt | K8: Đơn vị cung cấp chào giá (vnđ) | N8: Đơn vị cung cấp chào giá (vnđ) | Q8: Lựa chọn | R8: Ghi chú
A9: Item | B9: Description/ Chi tiết | C9: Profile/ Vật tư | D9: Grade/ Mác vật liệu | E9: Số lượng (mua) (M) | F9: Số lượng (PR) (M) | G9: Khối lượng/ Số lượng | H9: Đơn giá (vnd) | I9: Thành tiền (vnd) | J9: Thành tiền (vnd) | K9: Ngọc Hiếu | N9: Hùng Nguyên
E10: Số lượng (cây) | F10: Số lượng (cây) | K10: Phạm vi | L10: Đơn giá (VND) | M10: Thành Tiền (Không có VAT) | N10: Phạm vi | O10: Đơn giá (VND) | P10: Thành Tiền (Không có VAT)
A11: Tổng | G11: N/A | H11: N/A | I11: ='DT04 (TM) 1 '!L8 -> 2.6838359e+10 | J11: ='DT04 (TM) 1 '!Q8 -> 2.8199693e+10 | P11: =SUM(P12:P12) -> 6401319 | R11: =I11-J11-M11-P11 -> -1.3677356e+09
A12: I90-A5 | B12: PL5x1500x6000 | C12: PL5x200x6000 | D12: SS400 | E12: 12 | F12: 9 | G12: N/A | H12: N/A | I12: N/A | J12: N/A | K12: V | L12: 13636.36 | M12: N/A | N12: V | O12: 13727.27 | P12: 6401319 | Q12: Hùng Nguyên | R12: -Giá trí mua đang vượt dự toán
A13: Tổng | G13: N/A | H13: N/A | I13: ='DT04 (TM) 1 '!L17 -> 2538751590 | J13: ='Tổng hợp'!J16 -> 4.2279793e+09 | M13: =SUM(M14:M14) -> 0 | P13: =SUM(P14:P14) -> 156776769 | R13: =I13-J13-M13-P13 -> -1.8460045e+09
A14: I90-C100 | B14: HEA200(H190x200x6.5x10)-L12000 | C14: Thép hình H200x200x6x8x12000 | D14: SS400 | E14: 170 | F14: 170 | G14: N/A | H14: N/A | I14: N/A | J14: N/A | K14: V | L14: =19300/1.1 -> 17545.455 | M14: N/A | N14: V | O14: =19200/1.1 -> 17454.545 | P14: =3*52258923 -> 156776769 | Q14: Hùng Nguyên | R14: -Giá trí mua đang vượt dự toán
B15: Đơn giá tổng hợp
A16: II | B16: Khối lượng dự kiến giao (Kg )/ Estimated weight (Kg):
A17: 1 | B17: … | C17: kg
A18: 2 | B18: …
A19: III | B19: Tiến độ/ Schedule | C19: Bắt đầu/ Start | D19: Kết thúc/ Finish
A20: 1 | B20: ….
A22: IV | B22: Nhân lực/ ManPower
A23: 1 | B23: Thợ Pha cắt / Thợ sắt / Thợ hàn / …
B24: ….
A25: V | B25: Yêu cầu kỹ thuật: Tham chiếu các tài liệu đính kèm/ Technical requirement – refer to document attached
B26: Xếp hạng | L26: 2 | O26: 1
A27: Ghi Chú: PTM tiến hành mua hàng để đảm bảo tiến độ
A28: NGƯỜI ĐỀ NGHỊ/ RECOMMENDATION BY: | C28: NGƯỜI KIỂM TRA/ DEPARTMENT HEAD CHECK BY: | K28: APPROVED BY: PHÊ DUYỆT
J29: Nguyễn Quang Vinh | M29: Hoàng Ngọc Bằng | P29: Đoàn Văn Toàn

Sheet Vật tư Quang Thịnh Phát
A1: BID ANALYSIS - GIẢI TRÌNH MUA SẮM/ĐẤU THẦU
A3: Project | B3: PROJECT No/ Dự án: 25-BRA-I-090
A4: Dự án
A5: Subject | B5: Cung cấp vật tư hộp A36/SS400
A6: Chủ đề
A8: No. | B8: CONTENT | C8: Phạm vi công việc | H8: Dự toán | K8: Đã mua/Đã đặt | L8: Đơn vị cung cấp chào giá (vnđ) | O8: Đơn vị cung cấp chào giá (vnđ) | R8: Lựa chọn | S8: Ghi chú
A9: Item | B9: Description/ Chi tiết | C9: Profile/ Vật tư | D9: Grade/ Mác vật liệu | E9: Số lượng mua (M) | F9: Số lượng PR (M) | G9: Trọng lượng (KG) | H9: Khối lượng/ Số lượng | I9: Đơn giá (vnd) | J9: Thành tiền (vnd) | K9: Thành tiền (vnd) | L9: QUANG THỊNH PHÁT | O9: Hùng Nguyên
E10: Số lượng (cây) | F10: Số lượng (cây) | G10: Trọng lượng | L10: Phạm vi | M10: Đơn giá (VND) | N10: Thành Tiền (Không có VAT) | O10: Phạm vi | P10: Đơn giá (VND) | Q10: Thành Tiền (Không có VAT)
A11: Tổng | H11: N/A | I11: N/A | J11: ='Tổng hợp'!K14 -> 2.7375767e+10 | K11: ='Tổng hợp'!J14 -> 2.8199693e+10 | N11: =SUM(N12:N12) -> 31690449 | Q11: =SUM(Q12:Q12) -> 0 | S11: =J11-K11-N11 -> -8.5561675e+08
A12: I90-A127 | B12: SHS 40x40x3-L6000 | C12: Thép hộp đen 40 x 40 x 3,0 x 6.000 mm | D12: A36/SS400 | E12: =6*98 -> 588 | F12: 582 | G12: 2015 | H12: N/A | I12: N/A | J12: N/A | K12: N/A | L12: V | M12: 15727.27 | N12: 31690449 | O12: V | P12: =18000/1.1 -> 16363.636 | Q12: N/A | R12: Quang Thịnh Phát | S12: -Giá trí mua đang vượt dự toán - PTM không nắm được vật tư phụ kiện còn phát sinh hàng không - Thông báo tới SALE để khách hàng hỗ trợ thêm chi phí
B13: Đơn giá tổng hợp
A14: II | B14: Khối lượng dự kiến giao (Kg )/ Estimated weight (Kg):
A15: 1 | B15: … | C15: kg
A16: 2 | B16: …
A17: III | B17: Tiến độ/ Schedule | C17: Bắt đầu/ Start | D17: Kết thúc/ Finish
A18: 1 | B18: ….
A20: IV | B20: Nhân lực/ ManPower
A21: 1 | B21: Thợ Pha cắt / Thợ sắt / Thợ hàn / …
B22: ….
A23: V | B23: Yêu cầu kỹ thuật: Tham chiếu các tài liệu đính kèm/ Technical requirement – refer to document attached
B24: Xếp hạng | M24: 1 | P24: 2
A25: Ghi Chú: PTM tiến hành mua hàng để đảm bảo tiến độ
A26: NGƯỜI ĐỀ NGHỊ/ RECOMMENDATION BY: | C26: NGƯỜI KIỂM TRA/ DEPARTMENT HEAD CHECK BY: | K26: APPROVED BY: PHÊ DUYỆT
K27: Nguyễn Quang Vinh | M27: Hoàng Ngọc Bằng | P27: Đoàn Văn Toàn

Sheet Vật tư đóng kiện Ngọc hiếu 090
A1: BID ANALYSIS - GIẢI TRÌNH MUA SẮM/ĐẤU THẦU
A3: Project | B3: PROJECT No/ Dự án: 25-BRA-I-090
A4: Dự án
A5: Subject | B5: Cung cấp vật tư đóng kiện dự án 090
A6: Chủ đề
A8: No. | B8: CONTENT | C8: Phạm vi công việc | H8: Dự toán | K8: Đã mua/Đã đặt | L8: Đơn vị cung cấp chào giá (vnđ) | O8: Đơn vị cung cấp chào giá (vnđ) | R8: Lựa chọn | S8: Ghi chú
A9: Item | B9: Description/ Chi tiết | C9: Profile/ Vật tư | D9: Grade/ Mác vật liệu | E9: Số lượng (cây) | G9: Trọng lượng (KG) | H9: Khối lượng/ Số lượng | I9: Đơn giá (vnd) | J9: Thành tiền (vnd) | K9: Thành tiền (vnd) | L9: Ngọc Hiếu | O9: Hùng Nguyên
E10: Số lượng (cây) | G10: Trọng lượng | L10: Phạm vi | M10: Đơn giá (VND) | N10: Thành Tiền (Không có VAT) | O10: Phạm vi | P10: Đơn giá (VND) | Q10: Thành Tiền (Không có VAT)
A11: Tổng | H11: N/A | I11: N/A | J11: ='DT04 (TM) 1 '!L17 -> 2538751590 | K11: ='Tổng hợp'!J16+'Vật tư đóng kiện Hoàng hà 090'!N11 -> 4.2858429e+09 | N11: =SUM(N12:N26) -> 708322117 | Q11: =SUM(Q12:Q26) -> 0 | S11: =J11-K11-N11 -> -2.4554134e+09
A12: I90-C5 | B12: PL10x2000x12000 | C12: Thép tấm 10*2000*12000 | D12: SS400 | E12: 1 | F12: 24 | G12: 1884 | H12: N/A | I12: N/A | J12: N/A | K12: N/A | L12: V | M12: 13636.36 | N12: 25690902 | O12: V | P12: 13727.27 | Q12: N/A | R12: Ngọc Hiếu | S12: -Giá trí mua đang vượt dự toán - PTM không nắm được vật tư phụ kiện còn phát sinh hàng không - Thông báo tới SALE để khách hàng hỗ trợ thêm chi phí
A13: I90-C6 | B13: PL12x2000x12000 | C13: Thép tấm 12*2000*12000 | D13: SS400 | E13: 1 | F13: 24 | G13: 2261 | H13: N/A | I13: N/A | J13: N/A | K13: N/A | L13: V | M13: 13636.36 | N13: 30831810 | O13: V | P13: 13727.27 | Q13: N/A | R13: Ngọc Hiếu
A14: I90-C7 | B14: PL15x2000x12000 | C14: Thép tấm 16*2000*6000 | D14: SS400 | E14: 1 | F14: 12 | G14: 1507 | H14: N/A | I14: N/A | J14: N/A | K14: N/A | L14: V | M14: 14000 | N14: 21098000 | O14: V | P14: 14000 | Q14: N/A | R14: Ngọc Hiếu
A15: I90-C8 | B15: PL20x2000x12000 | C15: Thép tấm 20*2000*12000 | D15: SS400 | E15: 1 | F15: 24 | G15: 3768 | H15: N/A | I15: N/A | J15: N/A | K15: N/A | L15: V | M15: 14181.82 | N15: 53437098 | O15: V | P15: 14545.45 | Q15: N/A | R15: Ngọc Hiếu
A16: I90-C12 | B16: HEA120(H114x120x5x8)-L12000 | C16: Thép H125*125*6,5*9*12000 | D16: SS400 | E16: 6 | F16: 72 | G16: 1699 | H16: N/A | I16: N/A | J16: N/A | K16: N/A | L16: V | M16: 17545.45 | N16: 29809720 | O16: V | P16: 17636.36 | Q16: N/A | R16: Ngọc Hiếu
A17: I90-C13 | B17: HEA180(171x180x6x9.5)-L12000 | C17: Thép H200*200*8*12*12000 | D17: SS400 | E17: 12 | F17: =E17*12 -> 144 | G17: 7186 | H17: N/A | I17: N/A | J17: N/A | K17: N/A | L17: V | M17: 17545.45 | N17: 126081604 | O17: V | P17: 17636.36 | Q17: N/A | R17: Ngọc Hiếu
A18: I90-C15 | B18: HEA260(H250x260x7.5x12.5)-L12000 | C18: Thép H250*250*9*14*12000 | D18: SS400 | E18: 3 | F18: =E18*12 -> 36 | G18: 2585 | H18: N/A | I18: N/A | J18: N/A | K18: N/A | L18: V | M18: 17545.45 | N18: 45354988 | O18: V | P18: 17636.36 | Q18: N/A | R18: Ngọc Hiếu
A19: I90-C16 | B19: HEB140(H140x140x7x12)-L12000 | C19: Thép H150*150*7*10*12000 | D19: SS400 | E19: 3.5 | F19: =E19*12 -> 42 | G19: 1306 | H19: N/A | I19: N/A | J19: N/A | K19: N/A | L19: V | M19: 17545.45 | N19: 22914358 | O19: V | P19: 17636.36 | Q19: N/A | R19: Ngọc Hiếu
A20: I90-C21 | B20: UNP200(C200x75x8.5x11.5)-L12000 | C20: Thép U200*90*8*13,5*12000 | D20: SS400 | E20: 8 | F20: 96 | G20: 2909 | H20: N/A | I20: N/A | J20: N/A | K20: N/A | L20: V | M20: 17545.45 | N20: 51039714 | O20: V | P20: 17500 | Q20: N/A | R20: Ngọc Hiếu
A21: I90-C22 | B21: UNP220(C220x80x9x12.5)-L12000 | C21: Thép U250*90*9*13*12000 | D21: SS400 | E21: 35 | F21: 420 | G21: 14532 | H21: N/A | I21: N/A | J21: N/A | K21: N/A | L21: V | M21: 17545.45 | N21: 254970479 | O21: X | P21: N/A | Q21: N/A | R21: Ngọc Hiếu
A22: I90-C24 | B22: UNP260(C260x90x10x14)-L12000 | C22: Thép U300x90x9x13 x120000 | D22: SS400 | E22: 1 | F22: 12 | G22: 457 | H22: N/A | I22: N/A | J22: N/A | K22: N/A | L22: V | M22: 17545.45 | N22: 8018271 | O22: V | P22: 17772.73 | Q22: N/A | R22: Ngọc Hiếu
A23: I90-C26 | B23: UPN120(C120x55x7x9)-L12000 | C23: Thép U125*65*6*8*12000 | D23: SS400 | E23: 11 | F23: 132 | G23: 1769 | H23: N/A | I23: N/A | J23: N/A | K23: N/A | L23: V | M23: 17545.45 | N23: 31037901 | O23: X | P23: N/A | Q23: N/A | R23: Ngọc Hiếu
A24: I90-C28 | B24: L150x150x10-L6000 | C24: Thép V150*150*10*6000 | D24: SS400 | E24: 1 | F24: 6 | G24: 138 | H24: N/A | I24: N/A | J24: N/A | K24: N/A | L24: V | M24: 15909.09 | N24: 2195454 | O24: X | P24: N/A | Q24: N/A | R24: Ngọc Hiếu
A25: I90-C29 | B25: L75x75x6-L12000 | C25: Thép V80*80*8*6000 | D25: SS400 | E25: 3 | F25: 18 | G25: 173 | H25: N/A | I25: N/A | J25: N/A | K25: N/A | L25: V | M25: 13909.09 | N25: 2406273 | O25: V | P25: 14181.82 | Q25: N/A | R25: Ngọc Hiếu
A26: I90-C30 | B26: L80x80x8-L12000 | C26: Thép V75*75*6*12000 | D26: SS400 | E26: 3 | F26: 36 | G26: 247 | H26: N/A | I26: N/A | J26: N/A | K26: N/A | L26: V | M26: 13909.09 | N26: 3435545 | O26: V | P26: 14181.82 | Q26: N/A | R26: Ngọc Hiếu
B27: Đơn giá tổng hợp
A28: II | B28: Khối lượng dự kiến giao (Kg )/ Estimated weight (Kg):
A29: 1 | B29: … | C29: kg
A30: 2 | B30: …
A31: III | B31: Tiến độ/ Schedule | C31: Bắt đầu/ Start | D31: Kết thúc/ Finish
A32: 1 | B32: ….
A34: IV | B34: Nhân lực/ ManPower
A35: 1 | B35: Thợ Pha cắt / Thợ sắt / Thợ hàn / …
B36: ….
A37: V | B37: Yêu cầu kỹ thuật: Tham chiếu các tài liệu đính kèm/ Technical requirement – refer to document attached
B38: Xếp hạng | M38: 1 | P38: 2
A39: Ghi Chú: Vật tư đóng kiện dự án 090 tính tiền theo khối lượng thực tế, PTM tiến hành mua hàng
A40: NGƯỜI ĐỀ NGHỊ/ RECOMMENDATION BY: | C40: NGƯỜI KIỂM TRA/ DEPARTMENT HEAD CHECK BY: | G40: APPROVED BY: PHÊ DUYỆT
G41: Nguyễn Quang Vinh | I41: Hoàng Ngọc Bằng | L41: Đoàn Văn Toàn

Sheet Vật tư đóng kiện Hoàng hà2
A1: BID ANALYSIS - GIẢI TRÌNH MUA SẮM/ĐẤU THẦU
A3: Project | B3: PROJECT No/ Dự án: 25-BRA-I-090
A4: Dự án
A5: Subject | B5: Cung cấp vật tư đóng kiện dự án 090
A6: Chủ đề
A8: No. | B8: CONTENT | C8: Phạm vi công việc | H8: Dự toán | K8: Đã mua | L8: Đơn vị cung cấp chào giá (vnđ) | O8: Lựa chọn | P8: Ghi chú
A9: Item | B9: Description/ Chi tiết | C9: Profile/ Vật tư | D9: Grade/ Mác vật liệu | E9: Mặt hàng | F9: ĐVT | G9: Số lượng | H9: Khối lượng/ Số lượng | I9: Đơn giá (vnd) | J9: Thành tiền (vnd) | K9: Thành tiền (vnd) | L9: Hoàng Hà
L10: Phạm vi | M10: Đơn giá (VND) | N10: Thành Tiền (Không có VAT)
A11: Tổng | H11: N/A | I11: N/A | J11: ='DT04 (TM) 1 '!L17 -> 2538751590 | K11: ='Tổng hợp'!J16-N11 -> 4.2034457e+09 | N11: =SUM(N12:N21) -> 24533600 | P11: =J11-K11-N11 -> -1.6892277e+09
A12: I90-C107 | B12: Bu lông ren suốt | C12: M20*85 | D12: Mạ kẽm 8.8 | E12: Bulong M8x30 | F12: cái | G12: 8 | H12: N/A | I12: N/A | J12: N/A | L12: V | M12: 12000 | N12: 96000 | O12: Hoàng Hà | P12: -Giá trí mua đang vượt dự toán - PTM không nắm được vật tư phụ kiện còn phát sinh hàng không - Thông báo tới SALE để khách hàng hỗ trợ thêm chi phí
A13: I90-C116 | B13: Ecu | C13: M20 | D13: Mạ kẽm 8.8 | E13: Bulong M8x50 | F13: cái | G13: 8 | H13: N/A | I13: N/A | J13: N/A | L13: V | M13: 2900 | N13: 23200 | O13: Hoàng Hà
A14: I90-C127 | B14: Long đen phẳng | C14: M20 | D14: Mạ kẽm 8.8 | E14: Bulong M10x20 | F14: cái | G14: 16 | H14: N/A | I14: N/A | J14: N/A | L14: V | M14: 1050 | N14: 16800 | O14: Hoàng Hà
A15: I90-C50 | B15: Bu lông ren suốt | C15: M24*110 | D15: Mạ kẽm 8.8 | E15: Bulong M10x30 | F15: cái | G15: 24 | H15: N/A | I15: N/A | J15: N/A | L15: V | M15: 20800 | N15: 499200 | O15: Hoàng Hà
A16: I90-C60 | B16: Ecu | C16: M24 | D16: Mạ kẽm 8.8 | E16: Bulong M10x40 | F16: cái | G16: 24 | H16: N/A | I16: N/A | J16: N/A | L16: V | M16: 4800 | N16: 115200 | O16: Hoàng Hà
A17: I90-C72 | B17: Long đen phẳng | C17: M24 | D17: Mạ kẽm 8.8 | E17: Bulong M10x50 | F17: cái | G17: 48 | H17: N/A | I17: N/A | J17: N/A | L17: V | M17: 1150 | N17: 55200 | O17: Hoàng Hà
A18: I90-C93 | B18: Dây chằng hàng | C18: D50 | D18: Vải | E18: Bulong M12x40 | F18: met | G18: 1000 | H18: N/A | I18: N/A | J18: N/A | L18: V | M18: 5830 | N18: 5830000 | O18: Hoàng Hà
A19: I90-C93 | B19: Dây chằng hàng | C19: D50 | D19: Vải | E19: Bulong M12x40 | F19: cái | G19: 600 | H19: N/A | I19: N/A | J19: N/A | L19: V | M19: 5830 | N19: 3498000 | O19: Hoàng Hà
A20: I90-C94 | B20: Khóa dây chằng hàng | C20: D50 | D20: Thép mạ | E20: Bulong M12x70 | F20: cái | G20: 200 | H20: N/A | I20: N/A | J20: N/A | L20: V | M20: 36000 | N20: 7200000 | O20: Hoàng Hà
A21: I90-C94 | B21: Khóa dây chằng hàng | C21: D50 | D21: Thép mạ | E21: Bulong M12x80 | F21: cái | G21: 200 | H21: N/A | I21: N/A | J21: N/A | L21: V | M21: 36000 | N21: 7200000 | O21: Hoàng Hà
B22: Đơn giá tổng hợp
A23: II | B23: Khối lượng dự kiến giao (Kg )/ Estimated weight (Kg):
A24: 1 | B24: … | C24: kg
A25: 2 | B25: …
A26: III | B26: Tiến độ/ Schedule | C26: Bắt đầu/ Start | D26: Kết thúc/ Finish
A27: 1 | B27: ….
A29: IV | B29: Nhân lực/ ManPower
A30: 1 | B30: Thợ Pha cắt / Thợ sắt / Thợ hàn / …
B31: ….
A32: V | B32: Yêu cầu kỹ thuật: Tham chiếu các tài liệu đính kèm/ Technical requirement – refer to document attached
B33: Xếp hạng | M33: 1
A34: Ghi Chú: Vật tư đóng kiện dự án 090 tính tiền theo khối lượng thực tế, PTM tiến hành mua hàng
A35: NGƯỜI ĐỀ NGHỊ/ RECOMMENDATION BY: | C35: NGƯỜI KIỂM TRA/ DEPARTMENT HEAD CHECK BY: | G35: APPROVED BY: PHÊ DUYỆT
G36: Nguyễn Quang Vinh | I36: Hoàng Ngọc Bằng | L36: Đoàn Văn Toàn

Sheet Vật tư VSAN 21-3-
A1: BID ANALYSIS - GIẢI TRÌNH MUA SẮM/ĐẤU THẦU
A3: Project | B3: PROJECT No/ Dự án: 25-BRA-I-090
A4: Dự án
A5: Subject | B5: Cung cấp vật tư phụ kiện VSAN ngày 21-3
A6: Chủ đề
A8: No. | B8: CONTENT | C8: Phạm vi công việc | I8: Dự toán | L8: Đã mua | M8: Đơn vị cung cấp chào giá (vnđ) | P8: Lựa chọn | Q8: Ghi chú
A9: Item | B9: Description/ Chi tiết | C9: Profile/ Vật tư | D9: Số lượng PR PSC | E9: Grade/ Mác vật liệu | F9: Mặt hàng | G9: ĐVT | H9: Số lượng | I9: Khối lượng/ Số lượng | J9: Đơn giá (vnd) | K9: Thành tiền (vnd) | L9: Thành tiền (vnd) | M9: VSAN
M10: Phạm vi | N10: Đơn giá (VND) | O10: Thành Tiền (Không có VAT)
A11: Tổng | I11: N/A | J11: N/A | K11: ='Tổng hợp'!K14 -> 2.7375767e+10 | L11: ='Tổng hợp'!J14 -> 2.8199693e+10 | O11: =SUM(O12) -> 306000 | Q11: =K11-L11-O11 -> -8.242323e+08
A12: I90-A133 | B12: =VLOOKUP(A12,'25-BRA-I-090'!I:L,3,0) -> chốt chẻ D8x90-ISO 1234 | C12: =VLOOKUP(A12,'25-BRA-I-090'!I:L,4,0) -> Steel-hot dip gal'v or SUS304 | D12: =VLOOKUP(A12,'25-BRA-I-090'!I:FF,149,0) -> 0 | E12: Chốt chẻ M8x90 inox | F12: inox 304 | G12: PSC | H12: 6 | I12: N/A | J12: N/A | K12: N/A | M12: V | N12: 51000 | O12: =N12*H12 -> 306000 | P12: VSAN
A13: Tổng | I13: N/A | J13: N/A | K13: ='Tổng hợp'!K15 -> 1.703349e+09 | L13: ='Tổng hợp'!J15 -> 4.9994399e+09 | O13: =SUM(O14:O24) -> 8960150 | Q13: =K13-L13-O13 -> -3.305051e+09
A14: I90-B9 | B14: =VLOOKUP(A14,'25-BRA-I-090'!I:L,3,0) -> Bolt-M12x45-ISO4017-8.8-Galv | C14: =VLOOKUP(A14,'25-BRA-I-090'!I:L,4,0) -> 8.8-Galv | D14: =VLOOKUP(A14,'25-BRA-I-090'!I:FF,149,0) -> 0 | E14: Bulong M12x50 | F14: Gr 8.8 ISO 4017 HDG | G14: PSC | H14: 79 | I14: N/A | J14: N/A | K14: N/A | M14: V | N14: 3640 | O14: =N14*H14 -> 287560 | P14: VSAN
A15: I90-B17 | B15: =VLOOKUP(A15,'25-BRA-I-090'!I:L,3,0) -> Bolt-M16x70-DIN186B-8.8-Galv | C15: =VLOOKUP(A15,'25-BRA-I-090'!I:L,4,0) -> 8.8-Galv | D15: =VLOOKUP(A15,'25-BRA-I-090'!I:FF,149,0) -> -112 | E15: Bulong đầu búa M16x70 | F15: DIN186B-8.8-HDG | G15: PSC | H15: 154 | I15: N/A | J15: N/A | K15: N/A | M15: V | N15: 44000 | O15: =N15*H15 -> 6776000 | P15: VSAN
A16: I90-B40 | B16: =VLOOKUP(A16,'25-BRA-I-090'!I:L,3,0) -> Bolt-M5x16-DIN912-8.8-Galv | C16: =VLOOKUP(A16,'25-BRA-I-090'!I:L,4,0) -> 8.8-Galv | D16: =VLOOKUP(A16,'25-BRA-I-090'!I:FF,149,0) -> 0 | E16: Bulong LGC M5x16 | F16: Gr 10.9/ Gr 12.9 DIN 912 Geomet | G16: PSC | H16: 9 | I16: N/A | J16: N/A | K16: N/A | M16: V | N16: 3000 | O16: =N16*H16 -> 27000 | P16: VSAN
A17: I90-B43 | B17: =VLOOKUP(A17,'25-BRA-I-090'!I:L,3,0) -> Bolt-M6x12-ISO4017-8.8-Galv | C17: =VLOOKUP(A17,'25-BRA-I-090'!I:L,4,0) -> 8.8-Galv | D17: =VLOOKUP(A17,'25-BRA-I-090'!I:FF,149,0) -> 0 | E17: Bulong M6x12 | F17: Gr 8.8 ISO 4017 Geomet | G17: PSC | H17: 2 | I17: N/A | J17: N/A | K17: N/A | M17: V | N17: 4200 | O17: =N17*H17 -> 8400 | P17: VSAN
A18: I90-B49 | B18: =VLOOKUP(A18,'25-BRA-I-090'!I:L,3,0) -> BOLT-M8x20-ISO4017-8.8-Galv | C18: =VLOOKUP(A18,'25-BRA-I-090'!I:L,4,0) -> 8.8-Galv | D18: =VLOOKUP(A18,'25-BRA-I-090'!I:FF,149,0) -> 0 | E18: Bulong M8x20 | F18: Gr 8.8 ISO 4017 Geomet | G18: PSC | H18: 2 | I18: N/A | J18: N/A | K18: N/A | M18: V | N18: 860 | O18: =N18*H18 -> 1720 | P18: VSAN
A19: I90-B54 | B19: =VLOOKUP(A19,'25-BRA-I-090'!I:L,3,0) -> Nut-M10-ISO4032-8-Galv | C19: =VLOOKUP(A19,'25-BRA-I-090'!I:L,4,0) -> 8-Galv | D19: =VLOOKUP(A19,'25-BRA-I-090'!I:FF,149,0) -> 0 | E19: Ecu M10 | F19: Gr 8 ISO 4032 HDG | G19: PSC | H19: 860 | I19: N/A | J19: N/A | K19: N/A | M19: V | N19: 810 | O19: =N19*H19 -> 696600 | P19: VSAN
A20: I90-B73 | B20: =VLOOKUP(A20,'25-BRA-I-090'!I:L,3,0) -> NUT-M5-ISO4032-8-Galv | C20: =VLOOKUP(A20,'25-BRA-I-090'!I:L,4,0) -> 8-Galv | D20: =VLOOKUP(A20,'25-BRA-I-090'!I:FF,149,0) -> 0 | E20: Ecu M5 | F20: Gr 8 ISO 4032 Geomet | G20: PSC | H20: 11 | I20: N/A | J20: N/A | K20: N/A | M20: V | N20: 90 | O20: =N20*H20 -> 990 | P20: VSAN
A21: I90-B85 | B21: =VLOOKUP(A21,'25-BRA-I-090'!I:L,3,0) -> Washer-M10-ISO7089-St-200 HV-Galv | C21: =VLOOKUP(A21,'25-BRA-I-090'!I:L,4,0) -> St-200 HV-Galv | D21: =VLOOKUP(A21,'25-BRA-I-090'!I:FF,149,0) -> 0 | E21: Vòng đệm phẳng M10 | F21: 200HV ISO 7089 HDG | G21: PSC | H21: 738 | I21: N/A | J21: N/A | K21: N/A | M21: V | N21: 450 | O21: =N21*H21 -> 332100 | P21: VSAN
A22: I90-B105 | B22: =VLOOKUP(A22,'25-BRA-I-090'!I:L,3,0) -> Washer-M5-ISO7089-St-200 HV-tZn | C22: =VLOOKUP(A22,'25-BRA-I-090'!I:L,4,0) -> St-200 HV-tZn | D22: =VLOOKUP(A22,'25-BRA-I-090'!I:FF,149,0) -> 0 | E22: Vòng đệm phẳng M5 | F22: 200HV ISO 7089 Geomet | G22: PSC | H22: 7 | I22: N/A | J22: N/A | K22: N/A | M22: V | N22: 1000 | O22: =N22*H22 -> 7000 | P22: VSAN
A23: I90-B112 | B23: =VLOOKUP(A23,'25-BRA-I-090'!I:L,3,0) -> Washer-M8-ISO7093-St-Galv | C23: =VLOOKUP(A23,'25-BRA-I-090'!I:L,4,0) -> St-Galv | D23: =VLOOKUP(A23,'25-BRA-I-090'!I:FF,149,0) -> 0 | E23: Vòng đệm phẳng rộng M8 | F23: 200HV DIN 9021 Geomet | G23: PSC | H23: 8 | I23: N/A | J23: N/A | K23: N/A | M23: V | N23: 1560 | O23: =N23*H23 -> 12480 | P23: VSAN
A24: I90-B119 | B24: =VLOOKUP(A24,'25-BRA-I-090'!I:L,3,0) -> Washer M12-St-200 HV-ISO7093A-tZn | C24: =VLOOKUP(A24,'25-BRA-I-090'!I:L,4,0) -> St-Galv | D24: =VLOOKUP(A24,'25-BRA-I-090'!I:FF,149,0) -> 0 | E24: Vòng đệm phẳng rộng M12 | F24: 200HV DIN 9021 HDG | G24: PSC | H24: 146 | I24: N/A | J24: N/A | K24: N/A | M24: V | N24: 5550 | O24: =N24*H24 -> 810300 | P24: VSAN
B25: Xếp hạng | N25: 1
A26: Ghi Chú: PTM tiến hành mua hàng để đảm bảo tiến độ
A27: NGƯỜI ĐỀ NGHỊ/ RECOMMENDATION BY: | C27: NGƯỜI KIỂM TRA/ DEPARTMENT HEAD CHECK BY: | H27: APPROVED BY: PHÊ DUYỆT
H28: Nguyễn Quang Vinh | K28: Hoàng Ngọc Bằng | M28: Đoàn Văn Toàn

Sheet Vật tư Hoàng Hà 20-3
A1: BID ANALYSIS - GIẢI TRÌNH MUA SẮM/ĐẤU THẦU
A3: Project | B3: PROJECT No/ Dự án: 25-BRA-I-090
A4: Dự án
A5: Subject | B5: Cung cấp vật tư phụ kiện Hoàng Hà ngày 15-3
A6: Chủ đề
A8: No. | B8: CONTENT | C8: Phạm vi công việc | H8: Dự toán | K8: Đã mua | L8: Đơn vị cung cấp chào giá (vnđ) | O8: Lựa chọn | P8: Ghi chú
A9: Item | B9: Description/ Chi tiết | C9: Profile/ Vật tư | D9: Grade/ Mác vật liệu | E9: Mặt hàng | F9: ĐVT | G9: Số lượng | H9: Khối lượng/ Số lượng | I9: Đơn giá (vnd) | J9: Thành tiền (vnd) | K9: Thành tiền (vnd) | L9: Hoàng Hà
L10: Phạm vi | M10: Đơn giá (VND) | N10: Thành Tiền (Không có VAT)
A11: Tổng | H11: N/A | I11: N/A | J11: ='Tổng hợp'!K15 -> 1.703349e+09 | K11: ='Tổng hợp'!J15 -> 4.9994399e+09 | N11: =SUM(N12:N14) -> 35715600 | P11: =J11-K11-N11 -> -3.3318065e+09
A12: I90-B30 | B12: Bolt-M20x65-ISO4017-8.8-Galv | C12: 8.8-Galv | D12: Bulong M20x70 | E12: 8.8-Galv | F12: PSC | G12: 1539 | H12: N/A | I12: N/A | J12: N/A | L12: V | M12: 18000 | N12: =M12*G12 -> 27702000 | O12: Hoàng Hà
A13: I90-B63 | B13: Nut-M20-ISO4032-8-Galv | C13: 8.8-Galv | D13: Ecu M20 | E13: 8-Galv | F13: PSC | G13: 1364 | H13: N/A | I13: N/A | J13: N/A | L13: V | M13: 4000 | N13: =M13*G13 -> 5456000 | O13: Hoàng Hà
A14: I90-B98 | B14: Washer-M20-ISO7089-St-Galv | C14: St-Galv | D14: Vòng đệm phẳng M20 | E14: St-Galv | F14: PSC | G14: 3197 | H14: N/A | I14: N/A | J14: N/A | L14: V | M14: 800 | N14: =M14*G14 -> 2557600 | O14: Hoàng Hà
B15: Xếp hạng | M15: 1
A16: Ghi Chú: PTM tiến hành mua hàng để đảm bảo tiến độ
A17: NGƯỜI ĐỀ NGHỊ/ RECOMMENDATION BY: | C17: NGƯỜI KIỂM TRA/ DEPARTMENT HEAD CHECK BY: | G17: APPROVED BY: PHÊ DUYỆT
G18: Nguyễn Quang Vinh | J18: Hoàng Ngọc Bằng | L18: Đoàn Văn Toàn

Sheet Vật tư VSAN 9-3 
A1: BID ANALYSIS - GIẢI TRÌNH MUA SẮM/ĐẤU THẦU
A3: Project | B3: PROJECT No/ Dự án: 25-BRA-I-090
A4: Dự án
A5: Subject | B5: Cung cấp vật tư phụ kiện VSAN ngày 9-3
A6: Chủ đề
A8: No. | B8: CONTENT | C8: Phạm vi công việc | H8: Dự toán | K8: Đã mua | L8: Đơn vị cung cấp chào giá (vnđ) | O8: Lựa chọn | P8: Ghi chú
A9: Item | B9: Description/ Chi tiết | C9: Profile/ Vật tư | D9: Grade/ Mác vật liệu | E9: Mặt hàng | F9: ĐVT | G9: Số lượng | H9: Khối lượng/ Số lượng | I9: Đơn giá (vnd) | J9: Thành tiền (vnd) | K9: Thành tiền (vnd) | L9: VSAN
L10: Phạm vi | M10: Đơn giá (VND) | N10: Thành Tiền (Không có VAT)
A11: Tổng | H11: N/A | I11: N/A | J11: ='Tổng hợp'!K14 -> 2.7375767e+10 | K11: ='Tổng hợp'!J14-N11 -> 2.8198943e+10 | N11: =SUM(N12) -> 750000 | P11: =J11-K11-N11 -> -8.239263e+08
A12: I90-A131 | B12: Spring D2.2 | C12: Steel | D12: Lò xo D3 inox | E12: SS 304 | F12: PSC | G12: 5 | H12: N/A | I12: N/A | J12: N/A | L12: V | M12: 150000 | N12: =M12*G12 -> 750000 | O12: VSAN
B13: Xếp hạng | M13: 1
A14: Ghi Chú: PTM tiến hành mua hàng để đảm bảo tiến độ
A15: NGƯỜI ĐỀ NGHỊ/ RECOMMENDATION BY: | C15: NGƯỜI KIỂM TRA/ DEPARTMENT HEAD CHECK BY: | G15: APPROVED BY: PHÊ DUYỆT
G16: Nguyễn Quang Vinh | J16: Hoàng Ngọc Bằng | L16: Đoàn Văn Toàn

Sheet Vật tư VSAN 5-3
A1: BID ANALYSIS - GIẢI TRÌNH MUA SẮM/ĐẤU THẦU
A3: Project | B3: PROJECT No/ Dự án: 25-BRA-I-090
A4: Dự án
A5: Subject | B5: Cung cấp vật tư phụ kiện VSAN ngày 5-3
A6: Chủ đề
A8: No. | B8: CONTENT | C8: Phạm vi công việc | H8: Dự toán | K8: Đã mua | L8: Đơn vị cung cấp chào giá (vnđ) | O8: Lựa chọn | P8: Ghi chú
A9: Item | B9: Description/ Chi tiết | C9: Profile/ Vật tư | D9: Grade/ Mác vật liệu | E9: Mặt hàng | F9: ĐVT | G9: Số lượng | H9: Khối lượng/ Số lượng | I9: Đơn giá (vnd) | J9: Thành tiền (vnd) | K9: Thành tiền (vnd) | L9: VSAN
L10: Phạm vi | M10: Đơn giá (VND) | N10: Thành Tiền (Không có VAT)
A11: Tổng | H11: N/A | I11: N/A | J11: ='Tổng hợp'!K14 -> 2.7375767e+10 | K11: ='Tổng hợp'!J14-N11 -> 2.8199093e+10 | N11: =SUM(N12) -> 600000 | P11: =J11-K11-N11 -> -8.239263e+08
A12: I90-A131 | B12: Spring D2.2 | C12: Steel | D12: Lò xo D3 inox | E12: SS 304 | F12: PSC | G12: 3 | H12: N/A | I12: N/A | J12: N/A | L12: V | M12: 200000 | N12: =M12*G12 -> 600000 | O12: VSAN
A13: Tổng | H13: N/A | I13: N/A | J13: ='Tổng hợp'!K15 -> 1.703349e+09 | K13: ='Tổng hợp'!J15-N13 -> 4.9940097e+09 | N13: =SUM(N14:N25) -> 5430170 | P13: =J13-K13-N13 -> -3.2960909e+09
A14: I90-B8 | B14: Bolt-M12x40-ISO4017-8.8-Galv | C14: 8.8-Galv | D14: Bulong M12x40 | E14: Gr 8.8 ISO 4017 HDG | F14: PSC | G14: 70 | H14: N/A | I14: N/A | J14: N/A | L14: V | M14: 3140 | N14: =M14*G14 -> 219800 | O14: VSAN
A15: I90-B29 | B15: Bolt-M20x55-ISO4017-8.8-Galv | C15: 8.8-Galv | D15: Bulong M20x60 | E15: Gr 8.8 ISO 4017 HDG | F15: PSC | G15: 55 | H15: N/A | I15: N/A | J15: N/A | L15: V | M15: 13720 | N15: =M15*G15 -> 754600 | O15: VSAN
A16: I90-B42 | B16: Bolt-M6x12-DIN7500-St-Galv | C16: St-Galv | D16: Bulong M6x12 | E16: DIN7500-St Geomet | F16: PSC | G16: 125 | H16: N/A | I16: N/A | J16: N/A | L16: V | M16: 8200 | N16: =M16*G16 -> 1025000 | O16: VSAN
A17: I90-B46 | B17: Bolt-M6x20-DIN7500-St-Galv | C17: St-Galv | D17: Bulong M6x20 | E17: DIN7500-St Geomet | F17: PSC | G17: 8 | H17: N/A | I17: N/A | J17: N/A | L17: V | M17: 8400 | N17: =M17*G17 -> 67200 | O17: VSAN
A18: I90-B48 | B18: Bolt-M6x25-ISO4017-8.8-Galv | C18: 8.8-Galv | D18: Bulong M6x25 | E18: Gr 8.8 ISO 4017 Geomet | F18: PSC | G18: 80 | H18: N/A | I18: N/A | J18: N/A | L18: V | M18: 5500 | N18: =M18*G18 -> 440000 | O18: VSAN
A19: I90-B74 | B19: Nut-M6-ISO4032-8-Galv | C19: 8-Galv | D19: Ecu M6 | E19: Gr 8 ISO 4032 Geomet | F19: PSC | G19: 80 | H19: N/A | I19: N/A | J19: N/A | L19: V | M19: 180 | N19: =M19*G19 -> 14400 | O19: VSAN
A20: I90-B76 | B20: Nut-M8-ISO4032-8-Galv | C20: 8-Galv | D20: Ecu M8 | E20: Gr 8 ISO 4032 Geomet | F20: PSC | G20: 120 | H20: N/A | I20: N/A | J20: N/A | L20: V | M20: 360 | N20: =M20*G20 -> 43200 | O20: VSAN
A21: I90-B108 | B21: Washer-M6-ISO7089-St-200 HV-tZn | C21: St-200 HV-tZn | D21: Vòng đệm phẳng M6 | E21: 200HV ISO 7089 Geomet | F21: PSC | G21: 160 | H21: N/A | I21: N/A | J21: N/A | L21: V | M21: 1000 | N21: =M21*G21 -> 160000 | O21: VSAN
A22: I90-B119 | B22: Washer-M12-ISO7093-St-200 HV-Galv | C22: St-300 HV-Galv | D22: Vòng đệm phẳng rộng M12 | E22: 200HV DIN 9021 HDG | F22: PSC | G22: 103 | H22: N/A | I22: N/A | J22: N/A | L22: V | M22: 5550 | N22: =M22*G22 -> 571650 | O22: VSAN
A23: I90-B132 | B23: Bolt-M16x90-ISO4017-8.8-Galv | C23: 8.8-Galv | D23: Bulong M16x90 | E23: Gr 8.8 ISO 4017 HDG | F23: PSC | G23: 16 | H23: N/A | I23: N/A | J23: N/A | L23: V | M23: 9420 | N23: =M23*G23 -> 150720 | O23: VSAN
A24: I90-B133 | B24: Bolt-M20x60-ISO4017-8.8-Galv | C24: 8.8-Galv | D24: Bulong M20x60 | E24: Gr 8.8 ISO 4017 HDG | F24: PSC | G24: 160 | H24: N/A | I24: N/A | J24: N/A | L24: V | M24: 11760 | N24: =M24*G24 -> 1881600 | O24: VSAN
A25: I90-B134 | B25: Bolt-M6x25-DIN7500-St-Galv | C25: St-Galv | D25: Bulong M6x25 | E25: DIN7500-St Geomet | F25: PSC | G25: 10 | H25: N/A | I25: N/A | J25: N/A | L25: V | M25: 10200 | N25: =M25*G25 -> 102000 | O25: VSAN
B26: Xếp hạng | M26: 1
A27: Ghi Chú: PTM tiến hành mua hàng để đảm bảo tiến độ
A28: NGƯỜI ĐỀ NGHỊ/ RECOMMENDATION BY: | C28: NGƯỜI KIỂM TRA/ DEPARTMENT HEAD CHECK BY: | G28: APPROVED BY: PHÊ DUYỆT
G29: Nguyễn Quang Vinh | J29: Hoàng Ngọc Bằng | L29: Đoàn Văn Toàn

Sheet Vật tư đóng kiện Hoàng hà 090
A1: BID ANALYSIS - GIẢI TRÌNH MUA SẮM/ĐẤU THẦU
A3: Project | B3: PROJECT No/ Dự án: 25-BRA-I-090
A4: Dự án
A5: Subject | B5: Cung cấp vật tư đóng kiện dự án 090
A6: Chủ đề
A8: No. | B8: CONTENT | C8: Phạm vi công việc | H8: Dự toán | K8: Đã mua | L8: Đơn vị cung cấp chào giá (vnđ) | O8: Lựa chọn | P8: Ghi chú
A9: Item | B9: Description/ Chi tiết | C9: Profile/ Vật tư | D9: Grade/ Mác vật liệu | E9: Mặt hàng | F9: ĐVT | G9: Số lượng | H9: Khối lượng/ Số lượng | I9: Đơn giá (vnd) | J9: Thành tiền (vnd) | K9: Thành tiền (vnd) | L9: Hoàng Hà
L10: Phạm vi | M10: Đơn giá (VND) | N10: Thành Tiền (Không có VAT)
A11: Tổng | H11: N/A | I11: N/A | J11: ='DT04 (TM) 1 '!L17 -> 2538751590 | K11: ='Tổng hợp'!J16 -> 4.2279793e+09 | N11: =SUM(N12:N66) -> 57863610 | P11: =J11-K11-N11 -> -1.7470913e+09
A12: I90-C32 | B12: Bu lông ren suốt | C12: M16*50 | D12: Mạ kẽm 8.8 | E12: Bulong M8x30 | F12: PSC | G12: 788 | H12: N/A | I12: N/A | J12: N/A | L12: V | M12: 4600 | N12: =M12*G12 -> 3624800 | O12: Hoàng Hà | P12: -Giá trí mua đang vượt dự toán - PTM không nắm được vật tư phụ kiện còn phát sinh hàng không - Thông báo tới SALE để khách hàng hỗ trợ thêm chi phí
A13: I90-C33 | B13: Bu lông ren suốt | C13: M16*60 | D13: Mạ kẽm 8.8 | E13: Bulong M8x50 | F13: PSC | G13: 372 | H13: N/A | I13: N/A | J13: N/A | L13: V | M13: 5250 | N13: =M13*G13 -> 1953000 | O13: Hoàng Hà
A14: I90-C35 | B14: Bu lông ren suốt | C14: M16*70 | D14: Mạ kẽm 8.8 | E14: Bulong M10x20 | F14: PSC | G14: 48 | H14: N/A | I14: N/A | J14: N/A | L14: V | M14: 5850 | N14: =M14*G14 -> 280800 | O14: Hoàng Hà
A15: I90-C36 | B15: Bu lông ren suốt | C15: M16*80 | D15: Mạ kẽm 8.8 | E15: Bulong M10x30 | F15: PSC | G15: 36 | H15: N/A | I15: N/A | J15: N/A | L15: V | M15: 6500 | N15: =M15*G15 -> 234000 | O15: Hoàng Hà
A16: I90-C37 | B16: Bu lông ren suốt | C16: M16*90 | D16: Mạ kẽm 8.8 | E16: Bulong M10x40 | F16: PSC | G16: 24 | H16: N/A | I16: N/A | J16: N/A | L16: V | M16: 7100 | N16: =M16*G16 -> 170400 | O16: Hoàng Hà
A17: I90-C41 | B17: Bu lông ren suốt | C17: M20*50 | D17: Mạ kẽm 8.8 | E17: Bulong M10x50 | F17: PSC | G17: 48 | H17: N/A | I17: N/A | J17: N/A | L17: V | M17: 8150 | N17: =M17*G17 -> 391200 | O17: Hoàng Hà
A18: I90-C42 | B18: Bu lông ren suốt | C18: M20*55 | D18: Mạ kẽm 8.8 | E18: Bulong M12x40 | F18: PSC | G18: 213 | H18: N/A | I18: N/A | J18: N/A | L18: V | M18: 9000 | N18: =M18*G18 -> 1917000 | O18: Hoàng Hà
A19: I90-C44 | B19: Bu lông ren suốt | C19: M20*60 | D19: Mạ kẽm 8.8 | E19: Bulong M12x40 | F19: PSC | G19: 272 | H19: N/A | I19: N/A | J19: N/A | L19: V | M19: 9000 | N19: =M19*G19 -> 2448000 | O19: Hoàng Hà
A20: I90-C46 | B20: Bu lông ren suốt | C20: M20*70 | D20: Mạ kẽm 8.8 | E20: Bulong M12x70 | F20: PSC | G20: 192 | H20: N/A | I20: N/A | J20: N/A | L20: V | M20: 9900 | N20: =M20*G20 -> 1900800 | O20: Hoàng Hà
A21: I90-C48 | B21: Bu lông ren suốt | C21: M24*100 | D21: Mạ kẽm 8.8 | E21: Bulong M12x80 | F21: PSC | G21: 120 | H21: N/A | I21: N/A | J21: N/A | L21: V | M21: 19400 | N21: =M21*G21 -> 2328000 | O21: Hoàng Hà
A22: I90-C50 | B22: Bu lông ren suốt | C22: M24*110 | D22: Mạ kẽm 8.8 | E22: Bulong M16x40 | F22: PSC | G22: 48 | H22: N/A | I22: N/A | J22: N/A | L22: V | M22: 20800 | N22: =M22*G22 -> 998400 | O22: Hoàng Hà
A23: I90-C52 | B23: Bu lông ren suốt | C23: M24*90 | D23: Mạ kẽm 8.8 | E23: Bulong M16x50 | F23: PSC | G23: 120 | H23: N/A | I23: N/A | J23: N/A | L23: V | M23: 17900 | N23: =M23*G23 -> 2148000 | O23: Hoàng Hà
A24: I90-C54 | B24: Bu lông ren suốt | C24: M30*120 | D24: Mạ kẽm 8.8 | E24: Bulong M16x50 | F24: PSC | G24: 96 | H24: N/A | I24: N/A | J24: N/A | L24: V | M24: 46000 | N24: =M24*G24 -> 4416000 | O24: Hoàng Hà
... A66: I90-C139 | B66: Thanh ren | C66: M20*1000 | D66: Mạ kẽm 8.8 | E66: Vòng đệm phẳng rộng M20 | F66: PSC | G66: 12 | H66: N/A | I66: N/A | J66: N/A | L66: V | M66: 13700 | N66: =M66*G66 -> 164400 | O66: Hoàng Hà
B67: Đơn giá tổng hợp
A68: II | B68: Khối lượng dự kiến giao (Kg )/ Estimated weight (Kg):
A69: 1 | B69: … | C69: kg
A70: 2 | B70: …
A71: III | B71: Tiến độ/ Schedule | C71: Bắt đầu/ Start | D71: Kết thúc/ Finish
A72: 1 | B72: ….
A74: IV | B74: Nhân lực/ ManPower
A75: 1 | B75: Thợ Pha cắt / Thợ sắt / Thợ hàn / …
B76: ….
A77: V | B77: Yêu cầu kỹ thuật: Tham chiếu các tài liệu đính kèm/ Technical requirement – refer to document attached
B78: Xếp hạng | M78: 1
A79: Ghi Chú: Vật tư đóng kiện dự án 090 tính tiền theo khối lượng thực tế, PTM tiến hành mua hàng
A80: NGƯỜI ĐỀ NGHỊ/ RECOMMENDATION BY: | C80: NGƯỜI KIỂM TRA/ DEPARTMENT HEAD CHECK BY: | G80: APPROVED BY: PHÊ DUYỆT
G81: Nguyễn Quang Vinh | I81: Hoàng Ngọc Bằng | L81: Đoàn Văn Toàn

Sheet DT04 (TM) 1 
D1: CÔNG TY CỔ PHẦN CÔNG NGHIỆP NẶNG IBS IBS HEAVY INDUSTRY JOINT STOCK COMPANY Add.: KM6, Quốc lộ 5, Phường Hồng Bàng, Thành phố Hải Phòng
A2: BẢNG DỰ TOÁN CHI TIẾT VẬT TƯ
A3: Mẫu số: QT30-DT04 | M3: Mua sắm/ Ordered, Puchased (Đến hiện tại/ Up to now) | U3: THIẾT KẾ/ MUA SẮM THỰC TẾ
A4: STT | B4: Nhóm vật tư | C4: Mã vật tư | D4: Danh mục vật tư | E4: Đơn vị tính | F4: Mác vật liệu | G4: Quy cách | J4: Khối lượng/ Số lượng | K4: Đơn giá (vnd) | L4: Thành tiền (vnd) | M4: Hàng mua thêm | O4: Hàng tồn | Q4: Tổng Giá trị đã mua/ Total Cost (VND) | R4: Đânh giá | S4: Tỷ lệ | T4: Ghi chú | U4: Khối lượng | V4: Giá trị | W4: Chênh lệch | X4: Ghi chú
G5: Dài | H5: Rộng | I5: Dày | M5: Khối lượng/ Weight (Kg) | N5: Số lượng/ Q'ty (M/M2//PSC) | O5: Khối lượng/ Weight (Kg/N/A) Materials available at the factory | P5: Số lượng/ Q'ty (M/M2/PSC) Materials available at the factory
A6: A | B6: VTC | D6: Vật tư | L6: =SUM(L7:L26) -> 3.9012967e+10 | R6: =IF(L6>Q6," OKE MUA TIẾP","BÁO CÁO BOM") -> OKE MUA TIẾP
A7: 1 | D7: Vật tư chính | E7: kg | R7: =IF(L7>Q7," OKE MUA TIẾP","BÁO CÁO BOM") -> BÁO CÁO BOM
A8: 1.1 | D8: Thép carbon | E8: kg | J8: 1225.166 | L8: 2.6838359e+10 | M8: ='Tổng hợp'!F14 -> 1371496.8 | N8: ='Tổng hợp'!G14 -> 33225.763 | O8: ='Tổng hợp'!H14 -> 11796.06 | P8: ='Tổng hợp'!I14 -> 141.9749 | Q8: ='Tổng hợp'!J14 -> 2.8199693e+10 | R8: =IF(L8>Q8," OKE MUA TIẾP","BÁO CÁO BOM") -> BÁO CÁO BOM
A9: 1.2 | D9: Thép stainless | E9: kg | J9: 241.912
A10: 1.3 | D10: Tấm gratting nhựa | E10: kg | J10: 120 | L10: 537408000
A11: 1.4 | D11: Bảo ôn | J11: 10245.516
A12: 1.5 | D12: Các loại vật tư thép khác (cấp công trường | E12: kg
A13: 1.6 | D13: Bolt các loại, phụ kiện, gioăng,... | E13: kg | L13: 1.703349e+09 | M13: ='Tổng hợp'!F15 -> 174616.5 | N13: ='Tổng hợp'!G15 -> 178599.55 | O13: ='Tổng hợp'!H15 -> 6861.4896 | P13: ='Tổng hợp'!I15 -> 14559.671 | Q13: ='Tổng hợp'!J15 -> 4.9994399e+09 | R13: =IF(L13>Q13," OKE MUA TIẾP","BÁO CÁO BOM") -> BÁO CÁO BOM
A14: 2 | D14: Vật tư sơn
A15: 2.1 | D15: Vật tư sơn các loại. dung môi | J15: 8766.274 | L15: 1.615417e+09 | O15: ='Vật tư sơn BRA090'!AE7 -> 8374.56 | Q15: ='Vật tư sơn BRA090'!AH7 -> 2346421600 | R15: =IF(L15>Q15," OKE MUA TIẾP","BÁO CÁO BOM") -> BÁO CÁO BOM
A17: 3 | D17: Vật tư đóng kiện, biện pháp | E17: kg | L17: =SUM(L18:L20) -> 2538751590 | M17: ='Tổng hợp'!F16 -> 174616.5 | N17: ='Tổng hợp'!G16 -> 48456.55 | O17: ='Tổng hợp'!H16 -> 6861.4896 | P17: ='Tổng hợp'!I16 -> 14559.671 | Q17: ='Tổng hợp'!J16 -> 4.2279793e+09 | R17: =IF(L17>Q17," OKE MUA TIẾP","BÁO CÁO BOM") -> BÁO CÁO BOM
A18: 3.1 | D18: Vật tư biện pháp | L18: 839587140
A19: 3.2 | D19: Vật tư đóng kiện | L19: 3.998034e+08
A20: 3.3 | D20: Bạt che phủ các loại | E20: kg | L20: 1299361050
A21: 4 | D21: Vật tư tiêu hao
A22: 4.1 | D22: Vật liệu hàn | L22: 1652821140 | O22: ='Vat lieu han -BRA090'!AI7 -> 12225 | Q22: ='Vat lieu han -BRA090'!AL7 -> 775765000 | R22: =IF(L22>Q22," OKE MUA TIẾP","BÁO CÁO BOM") -> OKE MUA TIẾP | S22: lấy giữ liệu của kho xuất cho chính xác
A23: 4.2 | D23: Vật tư phụ (hàn), khí công nghiệp | L23: 1.1033447e+09
A24: 4.3 | D24: Đá mài các loại | L24: 1.6345848e+08
A25: 4.4 | D25: Hạt mài | L25: 175325480
A26: 5 | D26: Vật tư khác | L26: 145981218
A27: B | D27: Nhân công trực tiếp | J27: =SUM(J28:J36) -> 21590.066 | L27: =SUM(L28:L36) -> 2.3676403e+10
A28: 1 | D28: Pha cắt | J28: 1362.154 | L28: 1572005500
A29: 2 | D29: Lốc, sấn | J29: 573.388 | L29: 997070000
A30: 3 | D30: Gá hàn hoàn thiện | J30: 1362.154 | L30: 13134527000
A31: 4 | D31: Tổ hợp thử | J31: 1332.678 | L31: 3314816000
A32: 5 | D32: Thử chức năng | J32: 824.062 | L32: 1150986000
A33: 6 | D33: Làm sạch, sơn, rửa axit | J33: 13470.274 | L33: 869150550
A34: 7 | D34: Đóng kiện, giao hàng | J34: 1332.678 | L34: 9.328746e+08
A35: 8 | D35: Vận chuyển | J35: 1332.678 | L35: 1.999017e+08
A36: 9 | D36: Nhân công dự phòng | L36: 1.5050721e+09
A37: C | D37: Thầu phụ, dịch vụ thuê ngoài | L37: =SUM(L38:L45) -> 10721526300
A38: 1 | D38: Kiểm tra NDT, kiểm tra mẫu, quy trình | L38: 732972900
A39: 2 | D39: Mạ kẽm nhúng nóng | J39: 74 | L39: 888000000
A40: 3 | D40: Gia công cơ khí | J40: 602.062 | L40: 2500000000
A41: 4 | D41: Bảo ôn | J41: 10245.516 | L41: 4610482200
...

Sheet Vat lieu han -BRA090
A1: THEO DÕI VẬT TƯ DỰ ÁN/ MATERIAL CONTROL LOG | E1: Thời gian nộp bảng cập nhật:
A2: Tên dự án/ Project no.:25-SHI-I-084 | E2: - Trong ngày khi có biến động.
A3: Cập nhật ngày/ Update to: | E3: - Báo cáo hàng tuần vào 16:30 mỗi chiều thứ 2.
A4: Item/ STT | B4: Description/ Chi tiết | C4: Unit/ Đơn vị | D4: Current Ordered/Dự trù lần 1 (Ngà 2/6/2025 ) | F4: Current Ordered/Dự trù lần 2 (Ngày 11/8/2025 ) | H4: Current Ordered/Dự trù lần 3 (Ngày 19/8/2025 | J4: Current Ordered/Dự trù lần 3 (Ngày6/9/2025 | L4: Current Ordered/Dự trù lần 4 (Ngày 25/9/2025 | N4: Current Ordered/Dự trù lần 5 (Ngày 26/9/2025 | P4: Current Ordered/Dự trù lần 6 (Ngày 4/10/2025 | R4: Total Ordered/Tổng dự trù | T4: Remarks/ Ghi chú | U4: Tận dụng tồn kho/ Remain | Z4: Khối lượng phải mua sắm/ total order | AB4: Ngày bàn giao vật tư/ Material avaiable for hand over date | AC4: VẬT TƯ TRONG NƯỚC | AN4: ĐÃ MUA TRONG NƯỚC | AP4: QC Nghiệm thu | AT4: Remarks/ Ghi chú
