Workbook
Name \0: #REF!
Name \a: #N/A
Name \a: #N/A
Name \a: #N/A
Name \a: #N/A
Name \a: #N/A
Name \a: #N/A
Name \a: #N/A
Name \a: #N/A
Name \a: #N/A
Name \a: #N/A
Name \a: #N/A
Name \a: #N/A
Name \a: #N/A
Name \a: #N/A
Name \a: #REF!
Name \a: #N/A
Name \a: #N/A
Name \a: #N/A
Name \a: #N/A
Name \a: #N/A
Name \a: #REF!
Name \b: #N/A
Name \c: #N/A
Name \d: #N/A
Name \e: #N/A
Name \f: #N/A
Name \g: #N/A
Name \h: #N/A
Name \h: #N/A
Name \h: #N/A
Name \h: #N/A
Name \h: #N/A
Name \h: #N/A
Name \h: #N/A
Name \h: #N/A
Name \h: #N/A
Name \h: #N/A
Name \h: #N/A
Name \h: #N/A
Name \h: #N/A
Name \h: #N/A
Name \h: #N/A
Name \h: #N/A
Name \h: #N/A
Name \h: #N/A
Name \h: #N/A
Name \h: [1]PP!$IC$5
Name \i: #N/A
Name \i: #N/A
Name \i: #N/A
Name \i: #N/A
Name \i: #N/A
Name \i: #N/A
Name \i: #N/A
Name \i: #N/A
Name \i: #N/A
Name \i: #N/A
Name \i: #N/A
Name \i: #N/A

Sheet Giải tình Hùng nguyên
A1: BID ANALYSIS - GIẢI TRÌNH MUA SẮM/ĐẤU THẦU
A3: Project | B3: PROJECT No/ Dự án: 25-WNC-I-097
A4: Dự án
A5: Subject | B5: Cung cấp vật tư chính thép tấm của Hùng Nguyên
A6: Chủ đề
A8: No. | B8: CONTENT | C8: Phạm vi công việc | H8: Dự toán | K8: Đã mua | L8: Đơn vị cung cấp chào giá phần còn lại (VNĐ) | O8: Đơn vị cung cấp chào giá phần còn lại (VNĐ) | R8: Ghi chú
A9: Item | B9: Description/ Chi tiết | C9: Profile/ Vật tư | D9: Grade/ Mác vật liệu | E9: Số lượng Mua cây) | F9: Số lượng Mua (M) | G9: Số lượng PR (M) | H9: Khối lượng/ Số lượng | I9: Đơn giá (vnd) | J9: Thành tiền (vnd) | K9: Thành tiền (vnd) | L9: HÙNG NGUYÊN | O9: APEC
L10: Phạm vi | M10: Đơn giá trước VAT (VNĐ/KG) | N10: Thành Tiền (Không có VAT) | O10: Phạm vi | P10: Đơn giá trước VAT (VNĐ/KG) | Q10: Thành Tiền (Không có VAT)
A11: Tổng | B11: Main-Material / Vật tư chính thép đen | H11: N/A | I11: N/A | J11: ='DT04 (TM) 1 '!L7 -> 3001944110 | K11: ='DT04 (TM) 1 '!Q7 -> 3.0852474e+09 | N11: =SUM(N12:N17) -> 422127444 | R11: =J11-K11-N11 -> -5.0543075e+08
A12: I97-VTC01-028 | B12: =VLOOKUP(A12,'25-WNC-I-097'!I:CX,3,0) -> PL3X1500X6000 | C12: Thép tấm 3x1500x6000 | D12: =VLOOKUP(A12,'25-WNC-I-097'!I:CX,4,0) -> SS400 | E12: 5 | F12: 45 | G12: =VLOOKUP(A12,'25-WNC-I-097'!I:CX,83,0) -> 0 | H12: N/A | I12: N/A | J12: N/A | L12: V | M12: 13954.55 | N12: 14788334 | O12: X | P12: N/A | Q12: N/A | R12: Chọn Hùng Nguyên
A13: I97-VTC01-030 | B13: =VLOOKUP(A13,'25-WNC-I-097'!I:CX,3,0) -> PL5X1500X6000 | C13: Thép tấm 5x1500x6000 | D13: =VLOOKUP(A13,'25-WNC-I-097'!I:CX,4,0) -> SS400 | E13: 5 | F13: 45 | G13: =VLOOKUP(A13,'25-WNC-I-097'!I:CX,83,0) -> 0 | H13: N/A | I13: N/A | J13: N/A | L13: V | M13: 13954.55 | N13: 24647224 | O13: X | P13: N/A | Q13: N/A | R13: Chọn Hùng Nguyên
A14: I97-VTC01-031 | B14: =VLOOKUP(A14,'25-WNC-I-097'!I:CX,3,0) -> PL6X1500X6000 | C14: Thép tấm 6x1500x6000 | D14: =VLOOKUP(A14,'25-WNC-I-097'!I:CX,4,0) -> SS400 | E14: 4 | F14: 36 | G14: =VLOOKUP(A14,'25-WNC-I-097'!I:CX,83,0) -> 0 | H14: N/A | I14: N/A | J14: N/A | L14: V | M14: 13363.64 | N14: 22659388 | O14: X | P14: 13636.364 | Q14: N/A | R14: Chọn Hùng Nguyên
A15: I97-VTC01-059 | B15: =VLOOKUP(A15,'25-WNC-I-097'!I:CX,3,0) -> PL4x2000x12000 | C15: Thép tấm 4x2000x12000 | D15: =VLOOKUP(A15,'25-WNC-I-097'!I:CX,4,0) -> SS400 | E15: 29 | F15: 696 | G15: =VLOOKUP(A15,'25-WNC-I-097'!I:CX,83,0) -> 0 | H15: N/A | I15: N/A | J15: N/A | L15: V | M15: 13363.64 | N15: 292054334 | O15: X | P15: 13454.545 | Q15: N/A | R15: Chọn Hùng Nguyên
A16: I97-VTC01-060 | B16: =VLOOKUP(A16,'25-WNC-I-097'!I:CX,3,0) -> PL12x2000x12000 | C16: Thép tấm 12x2000x6000 | D16: =VLOOKUP(A16,'25-WNC-I-097'!I:CX,4,0) -> SS400 | E16: 1 | F16: 12 | G16: =VLOOKUP(A16,'25-WNC-I-097'!I:CX,83,0) -> 0 | H16: N/A | I16: N/A | J16: N/A | L16: V | M16: 13363.64 | N16: 15106259 | O16: X | P16: 13363.636 | Q16: N/A | R16: Chọn Hùng Nguyên
A17: I97-VTC01-065 | B17: =VLOOKUP(A17,'25-WNC-I-097'!I:CX,3,0) -> PL6X2000X6000 | C17: Thép tấm 6x2000x6000 | D17: =VLOOKUP(A17,'25-WNC-I-097'!I:CX,4,0) -> SS400 | E17: 7 | F17: 84 | G17: =VLOOKUP(A17,'25-WNC-I-097'!I:CX,83,0) -> 0 | H17: N/A | I17: N/A | J17: N/A | L17: V | M17: 13363.64 | N17: 52871905 | O17: V | P17: 13363.636 | Q17: N/A | R17: Chọn Hùng Nguyên
B18: Xếp hạng | M18: 1 | P18: 2
A19: Ghi chú: Tiếp tục công tác mua sắm để đảm báo tiến độ
A20: NGƯỜI ĐỀ NGHỊ/ RECOMMENDATION BY: | C20: NGƯỜI KIỂM TRA/ DEPARTMENT HEAD CHECK BY: | H20: APPROVED BY: PHÊ DUYỆT
H21: Nguyễn Quang Vinh | N21: Hoàng Ngọc Bằng | Q21: Đoàn Văn Toàn

Sheet Giải tình Ngọc Hiếu 26-2
A1: BID ANALYSIS - GIẢI TRÌNH MUA SẮM/ĐẤU THẦU
A3: Project | B3: PROJECT No/ Dự án: 25-WNC-I-097
A4: Dự án
A5: Subject | B5: Cung cấp vật tư chính thép hình của Ngọc Hiếu ngày 12-2-2026
A6: Chủ đề
A8: No. | B8: CONTENT | C8: Phạm vi công việc | H8: Dự toán | K8: Đã mua | L8: Đơn vị cung cấp chào giá phần còn lại (VNĐ) | O8: Đơn vị cung cấp chào giá phần còn lại (VNĐ) | R8: Đơn vị cung cấp chào giá phần còn lại (VNĐ) | U8: Ghi chú
A9: Item | B9: Description/ Chi tiết | C9: Profile/ Vật tư | D9: Grade/ Mác vật liệu | E9: Số lượng Mua cây) | F9: Số lượng Mua (M) | G9: Số lượng PR (M) | H9: Khối lượng/ Số lượng | I9: Đơn giá (vnd) | J9: Thành tiền (vnd) | K9: Thành tiền (vnd) | L9: HÙNG NGUYÊN | O9: NGỌC HIẾU | R9: APEC
L10: Phạm vi | M10: Đơn giá trước VAT (VNĐ/KG) | N10: Thành Tiền (Không có VAT) | O10: Phạm vi | P10: Đơn giá trước VAT (VNĐ/KG) | Q10: Thành Tiền (Không có VAT) | R10: Phạm vi | S10: Đơn giá trước VAT (VNĐ/KG) | T10: Thành Tiền (Không có VAT)
A11: Tổng | B11: Main-Material / Vật tư chính thép đen | H11: N/A | I11: N/A | J11: ='DT04 (TM) 1 '!L7 -> 3001944110 | K11: ='DT04 (TM) 1 '!Q7 -> 3.0852474e+09 | Q11: =SUM(Q12:Q13) -> 2828000 | U11: =J11-K11-Q11 -> -86131310
A12: I97-VTC01-021 | B12: =VLOOKUP(A12,'25-WNC-I-097'!I:CX,3,0) -> L75X50X7-6000L | C12: Thép góc V75x75x7x6000 | D12: =VLOOKUP(A12,'25-WNC-I-097'!I:CX,4,0) -> SS400 | E12: 2 | F12: =E12*6 -> 12 | G12: =VLOOKUP(A12,'25-WNC-I-097'!I:CX,91,0) -> 0 | H12: N/A | I12: N/A | J12: N/A | L12: X | M12: N/A | N12: N/A | O12: V | P12: 14000 | Q12: 1344000 | R12: X | S12: N/A | T12: N/A | U12: Chọn NGỌC HIẾU
A13: I97-VTC01-051 | B13: =VLOOKUP(A13,'25-WNC-I-097'!I:CX,3,0) -> L50X50X6 | C13: Thép góc L50X50X6x6000 | D13: =VLOOKUP(A13,'25-WNC-I-097'!I:CX,4,0) -> SS400 | E13: 4 | F13: =E13*6 -> 24 | G13: =VLOOKUP(A13,'25-WNC-I-097'!I:CX,91,0) -> 0 | H13: N/A | I13: N/A | J13: N/A | L13: X | M13: N/A | N13: N/A | O13: V | P13: 14000 | Q13: 1484000 | R13: X | S13: N/A | T13: N/A | U13: Chọn NGỌC HIẾU
B14: Xếp hạng | M14: 3 | P14: 1 | S14: 2
A15: Ghi chú: Tiếp tục công tác mua sắm để đảm báo tiến độ
A16: NGƯỜI ĐỀ NGHỊ/ RECOMMENDATION BY: | C16: NGƯỜI KIỂM TRA/ DEPARTMENT HEAD CHECK BY: | K16: APPROVED BY: PHÊ DUYỆT
K17: Nguyễn Quang Vinh | Q17: Hoàng Ngọc Bằng | T17: Đoàn Văn Toàn

Sheet HT-ADH VN Vải bảo ôn
A1: BID ANALYSIS - GIẢI TRÌNH MUA SẮM/ĐẤU THẦU
A3: Project | B3: PROJECT No/ Dự án: 25-WNC-I-097
A4: Dự án
A5: Subject | B5: Cung cấp vật tư vải bảo ôn dự án 097 ngày 09-02-2026
A6: Chủ đề
A8: No. | B8: CONTENT | C8: Phạm vi công việc | F8: Dự toán | I8: Đã mua | J8: Đơn vị cung cấp chào giá phần còn lại (VNĐ) | M8: Đơn vị cung cấp chào giá phần còn lại (VNĐ) | P8: Lựa chọn | Q8: Ghi chú
A9: Item | B9: Description/ Chi tiết | C9: Profile/ Vật tư | D9: Số lượng Mua (Cuộn/50M2) | E9: Số lượng PR (M2) | F9: Khối lượng/ Số lượng | G9: Đơn giá (vnd) | H9: Thành tiền (vnd) | I9: Thành tiền (vnd) | J9: CÔNG TY TNHH SẢN XUẤT & THƯƠNG MẠI HT - ADH VIỆT NAM | M9: KIÊN DŨNG
J10: Phạm vi | K10: Đơn giá trước VAT (VNĐ/CUỘN) | L10: Thành Tiền Chưa có 8% VAT | M10: Phạm vi | N10: Đơn giá trước VAT (VNĐ/CUỘN) | O10: Thành Tiền Chưa có 8% VAT
A11: Tổng | B11: Insulation-Material / Vật tư bảo ôn | F11: N/A | G11: N/A | H11: ='Tổng hợp'!K23 -> 1.9069559e+08 | I11: ='Tổng hợp'!J23 -> 2.0585973e+08 | L11: =SUM(L12:L12) -> 54600000 | O11: =SUM(O12:O12) -> 54600000 | Q11: =H11-I11-L11 -> -69764139
A12: I97-VTC04-004 | B12: vải bảo ôn | C12: vải bảo ôn-WFF108H FIBERGLASS FABRIC HT800 (1mmx1mx50m) | D12: 21 | E12: 1050 | F12: N/A | G12: N/A | H12: N/A | I12: N/A | J12: V | K12: 2600000 | L12: =K12*D12 -> 54600000 | M12: V | N12: 2600000 | O12: 54600000 | P12: HT - ADH VIỆT NAM | Q12: Chọn HT - ADH VIỆT NAM vì hàng đang ở Bắc Ninh
B13: Xếp hạng | K13: 1 | N13: 2
A14: Ghi chú: Tiếp tục công tác mua sắm để đảm báo tiến độ
A15: NGƯỜI ĐỀ NGHỊ/ RECOMMENDATION BY: | D15: NGƯỜI KIỂM TRA/ DEPARTMENT HEAD CHECK BY: | H15: APPROVED BY: PHÊ DUYỆT
H16: Nguyễn Quang Vinh | L16: Hoàng Ngọc Bằng | O16: Đoàn Văn Toàn

Sheet CKTEC- tăng đơ
A1: BID ANALYSIS - GIẢI TRÌNH MUA SẮM/ĐẤU THẦU
A3: Project | B3: PROJECT No/ Dự án: 25-WNC-I-097
A4: Dự án
A5: Subject | B5: Cung cấp vật tư tăng đơ dự án 097 ngày 30-1-2026
A6: Chủ đề
A8: No. | B8: CONTENT | C8: Phạm vi công việc | F8: Dự toán | I8: Đã mua | J8: Đơn vị cung cấp chào giá phần còn lại (VNĐ) | M8: Ghi chú
A9: Item | B9: Description/ Chi tiết | C9: Profile/ Vật tư | D9: Số lượng Mua (Cây) | E9: Số lượng PR (Cây) | F9: Khối lượng/ Số lượng | G9: Đơn giá (vnd) | H9: Thành tiền (vnd) | I9: Thành tiền (vnd) | J9: CKTEC
J10: Phạm vi | K10: Đơn giá trước VAT (VNĐ/CÂY) | L10: Thành Tiền
A11: Tổng | B11: Vật tư chế tạo theo yêu cầu của sản xuất | F11: N/A | G11: N/A | L11: =SUM(L12:L14) -> 38400000 | M11: =-L11 -> -38400000
A12: I97 | B12: Tăng đơ M12x675 | C12: Tăng đơ M12x675 | D12: 20 | E12: 20 | F12: N/A | G12: N/A | H12: N/A | I12: N/A | J12: V | K12: 630000 | L12: 12600000 | M12: Chọn CKTEC
A13: I97 | B13: Tăng đơ M12x927 | C13: Tăng đơ M12x927 | D13: 20 | E13: 20 | F13: N/A | G13: N/A | H13: N/A | I13: N/A | J13: V | K13: 650000 | L13: 13000000 | M13: Chọn CKTEC
A14: I97 | B14: Tăng đơ M12x866 | C14: Tăng đơ M12x866 | D14: 20 | E14: 20 | F14: N/A | G14: N/A | H14: N/A | I14: N/A | J14: V | K14: 640000 | L14: 12800000 | M14: Chọn CKTEC
B15: Xếp hạng | K15: 1
A16: Ghi chú: Tiếp tục công tác mua sắm để đảm báo tiến độ
A17: NGƯỜI ĐỀ NGHỊ/ RECOMMENDATION BY: | D17: NGƯỜI KIỂM TRA/ DEPARTMENT HEAD CHECK BY: | H17: APPROVED BY: PHÊ DUYỆT
H18: Nguyễn Quang Vinh | J18: Hoàng Ngọc Bằng | L18: Đoàn Văn Toàn

Sheet Hùng nguyen 16-1
A1: BID ANALYSIS - GIẢI TRÌNH MUA SẮM/ĐẤU THẦU
A3: Project | B3: PROJECT No/ Dự án: 25-WNC-I-097
A4: Dự án
A5: Subject | B5: Cung cấp vật tư đóng kiện của Hùng Nguyên ngày 16-1-2026
A6: Chủ đề
A8: No. | B8: CONTENT | C8: Phạm vi công việc | G8: Dự toán | J8: Đã mua | K8: Đơn vị cung cấp chào giá phần còn lại (VNĐ) | N8: Đơn vị cung cấp chào giá phần còn lại (VNĐ) | Q8: Ghi chú
A9: Item | B9: Description/ Chi tiết | C9: Profile/ Vật tư | D9: Số lượng Mua (Tấm) | E9: Số lượng Mua (M) | F9: Số lượng PR (M) | G9: Khối lượng/ Số lượng | H9: Đơn giá (vnd) | I9: Thành tiền (vnd) | J9: Thành tiền (vnd) | K9: HÙNG NGUYÊN | N9: APEC
K10: Phạm vi | L10: Đơn giá trước VAT (VNĐ/KG) | M10: Thành Tiền | N10: Phạm vi | O10: Đơn giá trước VAT (VNĐ/KG) | P10: Thành Tiền
A11: Tổng | B11: ='25-WNC-I-097'!J310 -> Packing Material / Vật tư kiện | G11: N/A | H11: N/A | I11: ='DT04 (TM) 1 '!L28 -> 503250000 | J11: ='25-WNC-I-097'!BM310 -> 7.9502514e+08 | M11: =SUM(M12:M12) -> 11406767 | Q11: =I11-J11-P11-M11 -> -3.031819e+08
A12: I97-VDK-031 | B12: PL3x1500x6000 | C12: Thép tấm 3x2000x6000 SS400 | D12: 3 | E12: 36 | F12: 36 | G12: N/A | H12: N/A | I12: N/A | J12: N/A | K12: V | L12: 13454.55 | M12: 11406767 | N12: X | O12: N//A | P12: N//A | Q12: Chọn Hùng Nguyên
B13: Xếp hạng | L13: 1 | O13: 2
A14: Ghi chú: Tiếp tục công tác mua sắm để đảm báo tiến độ
A15: NGƯỜI ĐỀ NGHỊ/ RECOMMENDATION BY: | E15: NGƯỜI KIỂM TRA/ DEPARTMENT HEAD CHECK BY: | J15: APPROVED BY: PHÊ DUYỆT
J16: Nguyễn Quang Vinh | M16: Hoàng Ngọc Bằng | P16: Đoàn Văn Toàn

Sheet Quang thịnh lần 2
A1: BID ANALYSIS - GIẢI TRÌNH MUA SẮM/ĐẤU THẦU
A3: Project | B3: PROJECT No/ Dự án: 25-WNC-I-097
A4: Dự án
A5: Subject | B5: Cung cấp vật tư đóng kiện
A6: Chủ đề
A8: No. | B8: CONTENT | C8: Phạm vi công việc | G8: Dự toán | J8: Đã mua | K8: Đơn vị cung cấp chào giá phần còn lại (VNĐ) | N8: Đơn vị cung cấp chào giá phần còn lại (VNĐ) | Q8: Ghi chú
A9: Item | B9: Description/ Chi tiết | C9: Profile/ Vật tư | D9: Số lượng Mua (Cây) | E9: Số lượng Mua (M) | F9: Số lượng PR (M) | G9: Khối lượng/ Số lượng | H9: Đơn giá (vnd) | I9: Thành tiền (vnd) | J9: Thành tiền (vnd) | K9: QUANG THỊNH PHAT | N9: TITAN
K10: Phạm vi | L10: Đơn giá trước VAT (VNĐ/KG) | M10: Thành Tiền | N10: Phạm vi | O10: Đơn giá trước VAT (VNĐ/KG) | P10: Thành Tiền
A11: Tổng | B11: ='25-WNC-I-097'!J310 -> Packing Material / Vật tư kiện | G11: N/A | H11: N/A | I11: ='DT04 (TM) 1 '!L28 -> 503250000 | J11: ='25-WNC-I-097'!BM310+'Giải tình Huy hoàng'!N11 -> 9.5442614e+08 | M11: =SUM(M12:M12) -> 9259090 | Q11: =I11-J11-P11-M11 -> -4.6043523e+08
A12: I97-VDK-020 | B12: RHS100X50X4 | C12: Thép hộp đen 50 x 100 x 4,0 x 6.000 mm | D12: 11 | E12: 66 | F12: 64 | G12: N/A | H12: N/A | I12: N/A | J12: N/A | K12: V | L12: 15909.09 | M12: 9259090 | N12: V | O12: =18800/1.1 -> 17090.909 | P12: N//A | Q12: Chọn Quang Thịnh Phát
B13: Xếp hạng | L13: 1 | O13: 2
A14: Ghi chú: Tiếp tục công tác mua sắm để đảm báo tiến độ
A15: NGƯỜI ĐỀ NGHỊ/ RECOMMENDATION BY: | E15: NGƯỜI KIỂM TRA/ DEPARTMENT HEAD CHECK BY: | J15: APPROVED BY: PHÊ DUYỆT
J16: Nguyễn Quang Vinh | M16: Hoàng Ngọc Bằng | P16: Đoàn Văn Toàn

Sheet Giải tình IPC
A1: BID ANALYSIS - GIẢI TRÌNH MUA SẮM/ĐẤU THẦU
A3: Project | B3: PROJECT No/ Dự án: 25-WNC-I-097
A4: Dự án
A5: Subject | B5: Cung cấp vật tư chính thép hình của IPC
A6: Chủ đề
A8: No. | B8: CONTENT | C8: Phạm vi công việc | H8: Dự toán | K8: Đã mua | L8: Đơn vị cung cấp chào giá phần còn lại (VNĐ) | O8: Đơn vị cung cấp chào giá phần còn lại (VNĐ) | R8: Đơn vị cung cấp chào giá phần còn lại (VNĐ) | U8: Lựa chọn | V8: Ghi chú
A9: Item | B9: Description/ Chi tiết | C9: Profile/ Vật tư | D9: Grade/ Mác vật liệu | E9: Số lượng Mua cây) | F9: Số lượng Mua (M) | G9: Số lượng PR (M) | H9: Khối lượng/ Số lượng | I9: Đơn giá (vnd) | J9: Thành tiền (vnd) | K9: Thành tiền (vnd) | L9: HÙNG NGUYÊN | O9: IPC | R9: APEC
L10: Phạm vi | M10: Đơn giá trước VAT (VNĐ/KG) | N10: Thành Tiền (Không có VAT) | O10: Phạm vi | P10: Đơn giá trước VAT (VNĐ/KG) | Q10: Thành Tiền (Không có VAT) | R10: Phạm vi | S10: Đơn giá trước VAT (VNĐ/KG) | T10: Thành Tiền (Không có VAT)
A11: Tổng | B11: Main-Material / Vật tư chính thép đen | H11: N/A | I11: N/A | J11: ='DT04 (TM) 1 '!L7 -> 3001944110 | K11: ='DT04 (TM) 1 '!Q7-Q11 -> 3.0739647e+09 | Q11: =SUM(Q12:Q12) -> 11282727 | V11: =J11-K11-Q11 -> -83303310
A12: I97-VTC01-054 | B12: =VLOOKUP(A12,'25-WNC-I-097'!I:CX,3,0) -> L125X75X10 | C12: L130x130x10x12000 | D12: =VLOOKUP(A12,'25-WNC-I-097'!I:CX,4,0) -> SS400 | E12: 3 | F12: 36 | G12: 33.0578 | H12: N/A | I12: N/A | J12: N/A | L12: X | M12: N/A | N12: N/A | O12: V | P12: 15909.09 | Q12: 11282727 | R12: X | S12: N/A | T12: N/A | U12: Chọn IPC | V12: - Vượt quá dự toán
B13: Xếp hạng | M13: 3 | P13: 1 | S13: 2
A14: Ghi chú: Tiếp tục công tác mua sắm để đảm báo tiến độ
A15: NGƯỜI ĐỀ NGHỊ/ RECOMMENDATION BY: | C15: NGƯỜI KIỂM TRA/ DEPARTMENT HEAD CHECK BY: | K15: APPROVED BY: PHÊ DUYỆT
K16: Nguyễn Quang Vinh | Q16: Hoàng Ngọc Bằng | T16: Đoàn Văn Toàn

Sheet Vật tư Đóng kiện trần toàn
A1: BID ANALYSIS - GIẢI TRÌNH MUA SẮM/ĐẤU THẦU
A3: Project | B3: PROJECT No/ Dự án: 25-WNC-I-097
A4: Dự án
A5: Subject | B5: Cung cấp vật tư đóng kiện dự án 097
A6: Chủ đề
A8: No. | B8: CONTENT | C8: Phạm vi công việc | G8: Dự toán | J8: Đã mua | K8: Đơn vị cung cấp chào giá (vnđ) | N8: Lựa chọn | O8: Ghi chú
A9: Item | B9: Description/ Chi tiết | C9: Profile/ Vật tư | D9: Grade/ Mác vật liệu | E9: ĐVT | F9: Số lượng | G9: Khối lượng/ Số lượng | H9: Đơn giá (vnd) | I9: Thành tiền (vnd) | J9: Thành tiền (vnd) | K9: TRẦN TOÀN
K10: Phạm vi | L10: Đơn giá (VND) | M10: Thành Tiền (Không có VAT)
A11: Tổng | B11: Vật tư đóng kiện | G11: N/A | H11: N/A | I11: ='Tổng hợp'!K25 -> 503250000 | J11: ='Tổng hợp'!J25 -> 7.9502514e+08 | M11: =SUM(M12:M12) -> 4810428 | O11: =I11-J11-M11 -> -2.9658556e+08
A12: I97-VDK-018 | B12: BẠT DA KÍCH THƯỚC 7000X4200- SỐ LƯỢNG 05 TẤM | C12: Bạt Da I97- VDK-018 ( 7000mm x 4200mm ) x 3 tấm | D12: BẠT DA CHỐNG NƯỚC 2 LỚP-KHUYÊN @500 | E12: M2 | F12: 88.2 | G12: N/A | H12: N/A | I12: N/A | K12: V | L12: 50500 | M12: 4810428 | N12: Trần Toàn | O12: - Đã vượt dự toán - Giá trị vượt dự toán chưa có phần vật tư tận dụng
B13: Xếp hạng | L13: 1
A14: Ghi chú: PTM tiếp tục triển khai công tác mua hàng
A15: NGƯỜI ĐỀ NGHỊ/ RECOMMENDATION BY: | C15: NGƯỜI KIỂM TRA/ DEPARTMENT HEAD CHECK BY: | I15: APPROVED BY: PHÊ DUYỆT
H16: Nguyễn Quang Vinh | K16: Hoàng Ngọc Bằng | N16: Đoàn Văn Toàn

Sheet Giải tình Hoàng Hà vit 26-1
A1: BID ANALYSIS - GIẢI TRÌNH MUA SẮM/ĐẤU THẦU
A3: Project | B3: PROJECT No/ Dự án: 25-WNC-I-097
A4: Dự án
A5: Subject | B5: Cung cấp vật tư đóng kiện Hoàng Hà 26-1
A6: Chủ đề
A8: No. | B8: CONTENT | C8: Phạm vi công việc | H8: Dự toán | K8: Đã mua | L8: Đơn vị cung cấp chào giá (vnđ) | O8: Ghi chú
A9: Item | B9: Description/ Chi tiết | C9: Profile/ Vật tư | D9: Grade/ Mác vật liệu | E9: Số lượng Mua | F9: Số lượng PR | G9: Đơn vị | H9: Khối lượng/ Số lượng | I9: Đơn giá (vnd) | J9: Thành tiền (vnd) | K9: Thành tiền (vnd) | L9: HOÀNG HÀ
L10: Phạm vi | M10: Đơn giá (VND) | N10: Thành Tiền (Không có VAT)
A11: Tổng | B11: Packing Material / Vật tư kiện | H11: N/A | I11: N/A | J11: ='DT04 (TM) 1 '!L28 -> 503250000 | K11: ='Tổng hợp'!J25 -> 7.9502514e+08 | N11: =SUM(N12:N12) -> 473000 | O11: =J11-K11-N11 -> -2.9224814e+08
A12: I97-VDK-032 | B12: BULONG | C12: BOLT-M24X60(1B+1N)-ISO4017-8.8-MẠ KẼM | D12: BOLT-M24X60(1B+1N)-ISO4017-8.8-MẠ KẼMM24x60Mạ kẽm | E12: 22 | F12: 22 | G12: Cái | H12: N/A | I12: N/A | J12: N/A | K12: N/A | L12: V | M12: 21500 | N12: =M12*F12 -> 473000 | O12: HOÀNG Hà
B13: Xếp hạng | M13: 1
A14: Ghi chú: Giá trị mua hàng đã vượt quá dự toán ' Tiếp tục công tác mua sắm để đảm báo tiến độ
A15: NGƯỜI ĐỀ NGHỊ/ RECOMMENDATION BY: | C15: NGƯỜI KIỂM TRA/ DEPARTMENT HEAD CHECK BY: | G15: APPROVED BY: PHÊ DUYỆT
G16: Nguyễn Quang Vinh | J16: Hoàng Ngọc Bằng | M16: Đoàn Văn Toàn

Sheet Giải tình Hoàng Hà vit
A1: BID ANALYSIS - GIẢI TRÌNH MUA SẮM/ĐẤU THẦU
A3: Project | B3: PROJECT No/ Dự án: 25-WNC-I-097
A4: Dự án
A5: Subject | B5: Cung cấp vật tư đóng kiện
A6: Chủ đề
A8: No. | B8: CONTENT | C8: Phạm vi công việc | H8: Dự toán | K8: Đã mua | L8: Đơn vị cung cấp chào giá (vnđ) | O8: Ghi chú
A9: Item | B9: Description/ Chi tiết | C9: Profile/ Vật tư | D9: Grade/ Mác vật liệu | E9: Số lượng Mua | F9: Số lượng PR | G9: Đơn vị | H9: Khối lượng/ Số lượng | I9: Đơn giá (vnd) | J9: Thành tiền (vnd) | K9: Thành tiền (vnd) | L9: HOÀNG HÀ
L10: Phạm vi | M10: Đơn giá (VND) | N10: Thành Tiền (Không có VAT)
A11: Tổng | B11: Packing Material / Vật tư kiện | H11: N/A | I11: N/A | J11: ='DT04 (TM) 1 '!L28 -> 503250000 | K11: ='Tổng hợp'!J25+159401000 -> 9.5442614e+08 | N11: =SUM(N12:N12) -> 1620000 | O11: =J11-K11-N11 -> -4.5279614e+08
A12: I97-VDK-030 | B12: VÍT BẮN TÔN M4X40 | C12: M5.5*38 | D12: Mạ cầu vồng | E12: 300 | F12: 300 | G12: Cái | H12: N/A | I12: N/A | J12: N/A | L12: V | M12: 540 | N12: 1620000 | O12: HOÀNG Hà
B13: Xếp hạng | M13: 1
A14: Ghi chú: Giá trị mua hàng đã vượt quá dự toán ' Tiếp tục công tác mua sắm để đảm báo tiến độ
A15: NGƯỜI ĐỀ NGHỊ/ RECOMMENDATION BY: | C15: NGƯỜI KIỂM TRA/ DEPARTMENT HEAD CHECK BY: | G15: APPROVED BY: PHÊ DUYỆT
G16: Nguyễn Quang Vinh | J16: Hoàng Ngọc Bằng | M16: Đoàn Văn Toàn

Sheet Giải tình Huy hoàng
A1: BID ANALYSIS - GIẢI TRÌNH MUA SẮM/ĐẤU THẦU
A3: Project | B3: PROJECT No/ Dự án: 25-WNC-I-097
A4: Dự án
A5: Subject | B5: Cung cấp vật tư đóng kiện
A6: Chủ đề
A8: No. | B8: CONTENT | C8: Phạm vi công việc | H8: Dự toán | K8: Đã mua | L8: Đơn vị cung cấp chào giá (vnđ) | O8: Ghi chú
A9: Item | B9: Description/ Chi tiết | C9: Profile/ Vật tư | D9: Grade/ Mác vật liệu | E9: Số lượng Mua | F9: Số lượng PR | G9: Đơn vị | H9: Khối lượng/ Số lượng | I9: Đơn giá (vnd) | J9: Thành tiền (vnd) | K9: Thành tiền (vnd) | L9: HOÀNG ANH MINH
L10: Phạm vi | M10: Đơn giá (VND) | N10: Thành Tiền (Không có VAT)
A11: Tổng | B11: Packing Material / Vật tư kiện | H11: N/A | I11: N/A | J11: ='DT04 (TM) 1 '!L28 -> 503250000 | K11: ='Tổng hợp'!J25 -> 7.9502514e+08 | N11: =SUM(N12:N16) -> 159401000 | O11: =J11-K11-N11 -> -4.5117614e+08
A12: I97-VDK-005 | B12: GỖ 100X100X2500 | C12: Gỗ thanh 2500*100*100 | D12: gỗ khử trùng-ISPM15 | E12: 510 | F12: 510 | G12: m | H12: N/A | I12: N/A | J12: N/A | L12: V | M12: 77000 | N12: =M12*E12 -> 39270000 | O12: Chọn HUY HOÀNG MINH
A13: I97-VDK-006 | B13: GỖ 100X20X2500 | C13: Gỗ thanh 2500*100*20 | D13: gỗ khử trùng-ISPM15 | E13: 270 | F13: 270 | G13: m | H13: N/A | I13: N/A | J13: N/A | L13: V | M13: 18000 | N13: =M13*E13 -> 4860000 | O13: Chọn HUY HOÀNG MINH
A14: I97-VDK-007 | B14: GỖ 100X50X2500 | C14: Gỗ thanh 2500*100*50 | D14: gỗ khử trùng-ISPM15 | E14: 301 | F14: 301 | G14: m | H14: N/A | I14: N/A | J14: N/A | L14: V | M14: 41000 | N14: =M14*E14 -> 12341000 | O14: Chọn HUY HOÀNG MINH
A15: I97-VDK-028 | B15: GỖ VÁN ÉP PL15X1220X2440 | C15: Gỗ tấm 2440*1220*15 | D15: gỗ ÉP khử trùng-ISPM15 | E15: 151 | F15: =450/2.44/1.22 -> 151.16904 | G15: Tấm | H15: N/A | I15: N/A | J15: N/A | L15: V | M15: 270000 | N15: =M15*E15 -> 40770000 | O15: Chọn HUY HOÀNG MINH
A16: I97-VDK-029 | B16: GỖ VÁN ÉP PL10X1220X2440 | C16: Gỗ tấm 2440*1220*10 | D16: gỗ ÉP khử trùng-ISPM15 | E16: 336 | F16: =1000/2.44/1.22 -> 335.9312 | G16: Tấm | H16: N/A | I16: N/A | J16: N/A | L16: V | M16: 185000 | N16: =M16*E16 -> 62160000 | O16: Chọn HUY HOÀNG MINH
B17: Xếp hạng | M17: 1
A18: Ghi chú: Giá trị mua hàng đã vượt quá dự toán ' Tiếp tục công tác mua sắm để đảm báo tiến độ
A19: NGƯỜI ĐỀ NGHỊ/ RECOMMENDATION BY: | C19: NGƯỜI KIỂM TRA/ DEPARTMENT HEAD CHECK BY: | G19: APPROVED BY: PHÊ DUYỆT
G20: Nguyễn Quang Vinh | J20: Hoàng Ngọc Bằng | M20: Đoàn Văn Toàn

Sheet Giải tình Ngọc Hiếu
A1: BID ANALYSIS - GIẢI TRÌNH MUA SẮM/ĐẤU THẦU
A3: Project | B3: PROJECT No/ Dự án: 25-WNC-I-097
A4: Dự án
A5: Subject | B5: Cung cấp vật tư chính thép hình của Ngọc Hiếu
A6: Chủ đề
A8: No. | B8: CONTENT | C8: Phạm vi công việc | H8: Dự toán | K8: Đã mua | L8: Đơn vị cung cấp chào giá phần còn lại (VNĐ) | O8: Đơn vị cung cấp chào giá phần còn lại (VNĐ) | R8: Đơn vị cung cấp chào giá phần còn lại (VNĐ) | U8: Ghi chú
A9: Item | B9: Description/ Chi tiết | C9: Profile/ Vật tư | D9: Grade/ Mác vật liệu | E9: Số lượng Mua cây) | F9: Số lượng Mua (M) | G9: Số lượng PR (M) | H9: Khối lượng/ Số lượng | I9: Đơn giá (vnd) | J9: Thành tiền (vnd) | K9: Thành tiền (vnd) | L9: HÙNG NGUYÊN | O9: NGỌC HIẾU/APEC | R9: APEC
L10: Phạm vi | M10: Đơn giá trước VAT (VNĐ/KG) | N10: Thành Tiền (Không có VAT) | O10: Phạm vi | P10: Đơn giá trước VAT (VNĐ/KG) | Q10: Thành Tiền (Không có VAT) | R10: Phạm vi | S10: Đơn giá trước VAT (VNĐ/KG) | T10: Thành Tiền (Không có VAT)
A11: Tổng | B11: Main-Material / Vật tư chính thép đen | H11: N/A | I11: N/A | J11: ='DT04 (TM) 1 '!L7 -> 3001944110 | K11: ='DT04 (TM) 1 '!Q7 -> 3.0852474e+09 | Q11: =SUM(Q12:Q20) -> 280781112 | U11: =J11-K11-Q11 -> -3.6408442e+08
A12: I97-VTC01-001 | B12: =VLOOKUP(A12,'25-WNC-I-097'!I:CX,3,0) -> C100X50X5X7.5-12000L | C12: Thép U100*50*5*7,5*12000 | D12: =VLOOKUP(A12,'25-WNC-I-097'!I:CX,4,0) -> SS400 | E12: 3 | F12: 36 | G12: =VLOOKUP(A12,'25-WNC-I-097'!I:CX,83,0) -> 0 | H12: N/A | I12: N/A | J12: N/A | L12: V | M12: 17500 | N12: N/A | O12: V | P12: 17090.91 | Q12: 5759637 | R12: V | S12: 17090.909 | T12: N/A | U12: Chọn NGỌC HIẾU
A13: I97-VTC01-002 | B13: =VLOOKUP(A13,'25-WNC-I-097'!I:CX,3,0) -> C125X65X6X8-12000L | C13: Thép U125*65*6*8*12000 | D13: =VLOOKUP(A13,'25-WNC-I-097'!I:CX,4,0) -> SS400 | E13: 20 | F13: 240 | G13: =VLOOKUP(A13,'25-WNC-I-097'!I:CX,83,0) -> 0 | H13: N/A | I13: N/A | J13: N/A | L13: X | M13: N/A | N13: N/A | O13: V | P13: 17090.91 | Q13: 54964367 | R13: V | S13: 17454.545 | T13: N/A | U13: Chọn NGỌC HIẾU
A14: I97-VTC01-003 | B14: =VLOOKUP(A14,'25-WNC-I-097'!I:CX,3,0) -> C200X90X8X13.5-12000L | C14: Thép U200*90*8*13,5*12000 | D14: =VLOOKUP(A14,'25-WNC-I-097'!I:CX,4,0) -> SS400 | E14: 4 | F14: 48 | G14: =VLOOKUP(A14,'25-WNC-I-097'!I:CX,83,0) -> 0 | H14: N/A | I14: N/A | J14: N/A | L14: X | M14: N/A | N14: N/A | O14: V | P14: 17272.73 | Q14: 25114549 | R14: X | S14: N/A | T14: N/A | U14: Chọn NGỌC HIẾU
A15: I97-VTC01-041 | B15: =VLOOKUP(A15,'25-WNC-I-097'!I:CX,3,0) -> C150X75X6.5X10 | C15: Thép U150*75*6,5*10*12000 | D15: =VLOOKUP(A15,'25-WNC-I-097'!I:CX,4,0) -> SS400 | E15: 39 | F15: 468 | G15: =VLOOKUP(A15,'25-WNC-I-097'!I:CX,83,0) -> 0 | H15: N/A | I15: N/A | J15: N/A | L15: X | M15: N/A | N15: N/A | O15: V | P15: 17090.91 | Q15: 148776372 | R15: X | S15: N/A | T15: N/A | U15: Chọn NGỌC HIẾU
A16: I97-VTC01-044 | B16: =VLOOKUP(A16,'25-WNC-I-097'!I:CX,3,0) -> C250X90X9X13 | C16: Thép U250*90*9*13*12000 | D16: =VLOOKUP(A16,'25-WNC-I-097'!I:CX,4,0) -> SS400 | E16: 5 | F16: 60 | G16: =VLOOKUP(A16,'25-WNC-I-097'!I:CX,83,0) -> 0 | H16: N/A | I16: N/A | J16: N/A | L16: X | M16: N/A | N16: N/A | O16: V | P16: 17272.73 | Q16: 35858187 | R16: X | S16: N/A | T16: N/A | U16: Chọn NGỌC HIẾU
A17: I97-VTC01-017 | B17: =VLOOKUP(A17,'25-WNC-I-097'!I:CX,3,0) -> L50X50X5-6000L | C17: Thép V50*50*5*6000 | D17: =VLOOKUP(A17,'25-WNC-I-097'!I:CX,4,0) -> SS400 | E17: 2 | F17: 12 | G17: =VLOOKUP(A17,'25-WNC-I-097'!I:CX,83,0) -> 0 | H17: N/A | I17: N/A | J17: N/A | L17: V | M17: 14090.91 | N17: N/A | O17: V | P17: 13909.09 | Q17: 625909 | R17: V | S17: 13727.273 | T17: N/A | U17: Chọn NGỌC HIẾU
A18: I97-VTC01-051 | B18: =VLOOKUP(A18,'25-WNC-I-097'!I:CX,3,0) -> L50X50X6 | C18: Thép V50*50*6*6000 | D18: =VLOOKUP(A18,'25-WNC-I-097'!I:CX,4,0) -> SS400 | E18: 9 | F18: 54 | G18: =VLOOKUP(A18,'25-WNC-I-097'!I:CX,83,0) -> 0 | H18: N/A | I18: N/A | J18: N/A | L18: V | M18: 14090.91 | N18: N/A | O18: V | P18: 13909.09 | Q18: 3324273 | R18: V | S18: 13727.273 | T18: N/A | U18: Chọn NGỌC HIẾU
A19: I97-VTC01-053 | B19: =VLOOKUP(A19,'25-WNC-I-097'!I:CX,3,0) -> L75X75X6 | C19: Thép V75*75*6*6000 | D19: =VLOOKUP(A19,'25-WNC-I-097'!I:CX,4,0) -> SS400 | E19: 11 | F19: 66 | G19: =VLOOKUP(A19,'25-WNC-I-097'!I:CX,83,0) -> 0 | H19: N/A | I19: N/A | J19: N/A | L19: V | M19: 14090.91 | N19: N/A | O19: V | P19: 13909.09 | Q19: 6286909 | R19: V | S19: 13727.273 | T19: N/A | U19: Chọn NGỌC HIẾU
A20: I97-VTC01-023 | B20: =VLOOKUP(A20,'25-WNC-I-097'!I:CX,3,0) -> RB12-6000L | C20: Thép tròn D12*6000 | D20: =VLOOKUP(A20,'25-WNC-I-097'!I:CX,4,0) -> SS400 | E20: 1 | F20: 6 | G20: =VLOOKUP(A20,'25-WNC-I-097'!I:CX,83,0) -> 0 | H20: N/A | I20: N/A | J20: N/A | L20: V | M20: 15272.73 | N20: N/A | O20: V | P20: 14181.82 | Q20: 70909 | R20: V | S20: 15000 | T20: N/A | U20: Chọn NGỌC HIẾU
B21: Xếp hạng | M21: 3 | P21: 1 | S21: 2
A22: Ghi chú: Tiếp tục công tác mua sắm để đảm báo tiến độ
A23: NGƯỜI ĐỀ NGHỊ/ RECOMMENDATION BY: | C23: NGƯỜI KIỂM TRA/ DEPARTMENT HEAD CHECK BY: | K23: APPROVED BY: PHÊ DUYỆT
K24: Nguyễn Quang Vinh | Q24: Hoàng Ngọc Bằng | T24: Đoàn Văn Toàn

Sheet Giải tình MCL đợt 2
A1: BID ANALYSIS - GIẢI TRÌNH MUA SẮM/ĐẤU THẦU
A3: Project | B3: PROJECT No/ Dự án: 25-WNC-I-097
A4: Dự án
A5: Subject | B5: Cung cấp vật tư chính thép hình của MCL
A6: Chủ đề
A8: No. | B8: CONTENT | C8: Phạm vi công việc | G8: Dự toán | J8: Đã mua | K8: Đơn vị cung cấp chào giá phần còn lại (USD) | N8: Đơn vị cung cấp chào giá phần còn lại (USD) | Q8: Đơn vị cung cấp chào giá phần còn lại (VNĐ) | T8: Đơn vị cung cấp chào giá phần còn lại (VNĐ) | W8: Ghi chú
A9: Item | B9: Description/ Chi tiết | C9: Profile/ Vật tư | D9: Grade/ Mác vật liệu | E9: Số lượng Mua (M2) | F9: Số lượng PR (M2) | G9: Khối lượng/ Số lượng | H9: Đơn giá (vnd) | I9: Thành tiền (vnd) | J9: Thành tiền (vnd) | K9: MCL | N9: GNEE | Q9: NGỌC HIẾU/APEC | T9: HÙNG NGUYÊN
K10: Phạm vi | L10: Đơn giá (USD/KG) | M10: Thành Tiền (Không có VAT) | N10: Phạm vi | O10: Đơn giá (USD/KG) | P10: Thành Tiền (Không có VAT) | Q10: Phạm vi | R10: Đơn giá trước VAT (VNĐ/KG) | S10: Thành Tiền (Không có VAT) | T10: Phạm vi | U10: Đơn giá trước VAT (VNĐ/KG) | V10: Thành Tiền (Không có VAT)
A11: Tổng | B11: Main-Material / Vật tư chính thép đen | G11: N/A | H11: N/A | I11: ='DT04 (TM) 1 '!L7 -> 3001944110 | J11: ='DT04 (TM) 1 '!Q7 -> 3.0852474e+09 | M11: =SUM(M12:M12)*(26300) -> 91134234 | S11: =SUM(S12:S12)*26300 -> 0 | W11: =I11-J11-S11-M11 -> -1.7443754e+08
A12: I97-VTC01-013 | B12: H300X300X10X15-12000L | C12: H300X300X10X15-12000L | D12: SS400 | E12: 60 | F12: 63 | G12: N/A | H12: N/A | I12: N/A | K12: V | L12: 0.621 | M12: 3465.18 | N12: V | O12: 0.6776368 | P12: N/A | Q12: V | R12: =19300/1.1 -> 17545.455 | S12: N/A | T12: V | U12: 17636.36 | V12: N/A | W12: Chọn MCL
A14: IV | B14: Nhân lực/ ManPower
A15: 1 | B15: Thợ Pha cắt / Thợ sắt / Thợ hàn / …
B16: ….
A17: V | B17: Yêu cầu kỹ thuật: Tham chiếu các tài liệu đính kèm/ Technical requirement – refer to document attached
B18: Xếp hạng | L18: 1 | O18: 2 | R18: 3 | U18: 4
A19: Ghi chú: Tiếp tục công tác mua sắm để đảm báo tiến độ
A20: NGƯỜI ĐỀ NGHỊ/ RECOMMENDATION BY: | C20: NGƯỜI KIỂM TRA/ DEPARTMENT HEAD CHECK BY: | M20: APPROVED BY: PHÊ DUYỆT
M21: Nguyễn Quang Vinh | S21: Hoàng Ngọc Bằng | V21: Đoàn Văn Toàn

Sheet Vật tư kẹp sàn
A1: BID ANALYSIS - GIẢI TRÌNH MUA SẮM/ĐẤU THẦU
A3: Project | B3: PROJECT No/ Dự án: 25-WNC-I-097
A4: Dự án
A5: Subject | B5: Cung cấp vật tư kẹp sàn dự án 097
A6: Chủ đề
A8: No. | B8: CONTENT | C8: Phạm vi công việc | F8: Dự toán | I8: Đơn vị cung cấp chào giá (VNĐ) | L8: Đơn vị cung cấp chào giá (USD) | O8: Lựa chọn | P8: Ghi chú
A9: Item | B9: Description/ Chi tiết | C9: Profile/ Vật tư | D9: Grade/ Mác vật liệu | E9: Số lượng PR (PSC) | F9: Khối lượng/ Số lượng | G9: Đơn giá (vnd) | H9: Thành tiền (vnd) | I9: VSAN | L9: WINWIN
E10: Số lượng (cây) | I10: Phạm vi | J10: Đơn giá (VNĐ) | K10: Thành Tiền (VNĐ) | L10: Phạm vi | M10: Đơn giá (VNĐ) | N10: Thành Tiền (VNĐ)
A11: Tổng | B11: Main-Material / Vật tư chính thép đen | F11: N/A | G11: N/A | K11: =SUM(K12:K12) -> 5405000
A12: 1 | B12: Kẹp sàn A30 | C12: kẹp trên + kẹp dưới + bulong + đai ốc vuông (Toàn bộ mạ kẽm nhúng nóng HDG) | E12: 235 | F12: N/A | G12: N/A | H12: N/A | I12: V | J12: 23000 | K12: 5405000 | L12: X | M12: N/A | N12: N/A | O12: VSAN
B13: Xếp hạng | J13: 1 | L13: 2
A14: Ghi Chú: PTM tiến hành đặt hàng để kịp tiến độ
A15: NGƯỜI ĐỀ NGHỊ/ RECOMMENDATION BY: | C15: NGƯỜI KIỂM TRA/ DEPARTMENT HEAD CHECK BY: | H15: APPROVED BY: PHÊ DUYỆT
H16: Nguyễn Quang Vinh | J16: Hoàng Ngọc Bằng | M16: Đoàn Văn Toàn

Sheet Vật tư U180
A1: BID ANALYSIS - GIẢI TRÌNH MUA SẮM/ĐẤU THẦU
A3: Project | B3: PROJECT No/ Dự án: 25-WNC-I-097
A4: Dự án
A5: Subject | B5: Cung cấp vật tư chính dự án 097
A6: Chủ đề
A8: No. | B8: CONTENT | C8: Phạm vi công việc | F8: Dự toán | I8: Đơn vị cung cấp chào giá (VNĐ) | L8: Đơn vị cung cấp chào giá (USD) | O8: Lựa chọn | P8: Ghi chú
A9: Item | B9: Description/ Chi tiết | C9: Profile/ Vật tư | D9: Grade/ Mác vật liệu | E9: Số lượng PR (PSC) | F9: Khối lượng/ Số lượng | G9: Đơn giá (vnd) | H9: Thành tiền (vnd) | I9: TRUNG HẢI | L9: NGỌC HIẾU/HÙNG NGUYÊN/APEC…
E10: Số lượng (cây) | I10: Phạm vi | J10: Đơn giá (VNĐ) | K10: Thành Tiền (VNĐ) | L10: Phạm vi | M10: Đơn giá (VNĐ) | N10: Thành Tiền (VNĐ)
A11: Tổng | B11: Main-Material / Vật tư chính thép đen | F11: N/A | G11: N/A | K11: =SUM(K12:K14) -> 66506200
A12: I97-VTC01-042 | B12: Thép hình C C180X90X7.5X12.5 | C12: Thép sấn U U180x90x10 | D12: SS400 | E12: 145 | F12: N/A | G12: N/A | H12: N/A | I12: V | J12: 19100 | K12: 66506200 | L12: X | M12: N/A | N12: N/A | O12: TRUNG HẢI
B13: Đơn giá tổng hợp
A14: II | B14: Khối lượng dự kiến giao (Kg )/ Estimated weight (Kg):
A15: 1 | B15: … | C15: kg
A16: 2 | B16: …
A17: III | B17: Tiến độ/ Schedule | C17: Bắt đầu/ Start | D17: Kết thúc/ Finish
A18: 1 | B18: ….
A20: IV | B20: Nhân lực/ ManPower
A21: 1 | B21: Thợ Pha cắt / Thợ sắt / Thợ hàn / …
B22: ….
A23: V | B23: Yêu cầu kỹ thuật: Tham chiếu các tài liệu đính kèm/ Technical requirement – refer to document attached
B24: Xếp hạng | J24: 1 | L24: 2
A25: Ghi Chú: PTM tiến hành đặt hàng để kịp tiến độ
A26: NGƯỜI ĐỀ NGHỊ/ RECOMMENDATION BY: | C26: NGƯỜI KIỂM TRA/ DEPARTMENT HEAD CHECK BY: | H26: APPROVED BY: PHÊ DUYỆT
H27: Nguyễn Quang Vinh | J27: Hoàng Ngọc Bằng | M27: Đoàn Văn Toàn

Sheet Vật tư U80
A1: BID ANALYSIS - GIẢI TRÌNH MUA SẮM/ĐẤU THẦU
A3: Project | B3: PROJECT No/ Dự án: 25-WNC-I-097
A4: Dự án
A5: Subject | B5: Cung cấp vật tư chính dự án 097
A6: Chủ đề
A8: No. | B8: CONTENT | C8: Phạm vi công việc | F8: Dự toán | I8: Đơn vị cung cấp chào giá (USD) | L8: Đơn vị cung cấp chào giá (USD) | O8: Lựa chọn | P8: Ghi chú
A9: Item | B9: Description/ Chi tiết | C9: Profile/ Vật tư | D9: Grade/ Mác vật liệu | E9: Số lượng PR (PSC) | F9: Khối lượng/ Số lượng | G9: Đơn giá (vnd) | H9: Thành tiền (vnd) | I9: MCL | L9: GNEE
E10: Số lượng (cây) | I10: Phạm vi | J10: Đơn giá (USD) | K10: Thành Tiền (CIF) | L10: Phạm vi | M10: Đơn giá (USD) | N10: Thành Tiền (CIF)
A11: Tổng | B11: Main-Material / Vật tư chính thép đen | F11: N/A | G11: N/A | H11: ='DT04 (TM) 1 '!L7 -> 3001944110 | K11: =SUM(K12:K14) -> 5225.472 | N11: =SUM(N12:N14) -> 6955.6838
A12: I97-VTC01-040 | B12: Thép hình C C80x45x5.5x7.5-12000L | C12: C80x45x6x8-12000L | D12: SS400 | E12: 56 | F12: N/A | G12: N/A | H12: N/A | I12: V | J12: 0.9 | K12: =8.64*12*E12*J12 -> 5225.472 | L12: V | M12: 1.198 | N12: =8.64*12*E12*M12 -> 6955.6838 | O12: MCL | P12: - Vật tư thép tấm PL6 (84m2) đã cấp cho sản xuất cắt để đưa đi sấn. Nhưng phôi cắt không đảm bảo công tác sấn. => Để đảm bảo chất lượng dự án GE, yêu cầu PTM tiến hành mua thép U80x6x8x12m (56 cây)
B13: Đơn giá tổng hợp
A14: II | B14: Khối lượng dự kiến giao (Kg )/ Estimated weight (Kg):
A15: 1 | B15: … | C15: kg
A16: 2 | B16: …
A17: III | B17: Tiến độ/ Schedule | C17: Bắt đầu/ Start | D17: Kết thúc/ Finish
A18: 1 | B18: ….
A20: IV | B20: Nhân lực/ ManPower
A21: 1 | B21: Thợ Pha cắt / Thợ sắt / Thợ hàn / …
B22: ….
A23: V | B23: Yêu cầu kỹ thuật: Tham chiếu các tài liệu đính kèm/ Technical requirement – refer to document attached
B24: Xếp hạng | J24: 1 | L24: 2
A25: Ghi Chú: PTM tiến hành đặt hàng để kịp tiến độ
A26: NGƯỜI ĐỀ NGHỊ/ RECOMMENDATION BY: | C26: NGƯỜI KIỂM TRA/ DEPARTMENT HEAD CHECK BY: | H26: APPROVED BY: PHÊ DUYỆT
H27: Nguyễn Quang Vinh | J27: Hoàng Ngọc Bằng | M27: Đoàn Văn Toàn

Sheet Hùng nguyen kien
A1: BID ANALYSIS - GIẢI TRÌNH MUA SẮM/ĐẤU THẦU
A3: Project | B3: PROJECT No/ Dự án: 25-WNC-I-097
A4: Dự án
A5: Subject | B5: Cung cấp vật tư đóng kiện
A6: Chủ đề
A8: No. | B8: CONTENT | C8: Phạm vi công việc | G8: Dự toán | J8: Đã mua | K8: Đơn vị cung cấp chào giá phần còn lại (VNĐ) | N8: Đơn vị cung cấp chào giá phần còn lại (VNĐ) | Q8: Ghi chú
A9: Item | B9: Description/ Chi tiết | C9: Profile/ Vật tư | D9: Số lượng Mua (Cây) | E9: Số lượng Mua (M) | F9: Số lượng PR (M) | G9: Khối lượng/ Số lượng | H9: Đơn giá (vnd) | I9: Thành tiền (vnd) | J9: Thành tiền (vnd) | K9: HÙNG NGUYÊN/NGỌC HIÊÚ | N9: TITAN
K10: Phạm vi | L10: Đơn giá trước VAT (VNĐ/KG) | M10: Thành Tiền | N10: Phạm vi | O10: Đơn giá trước VAT (VNĐ/KG) | P10: Thành Tiền
A11: Tổng | B11: ='25-WNC-I-097'!J310 -> Packing Material / Vật tư kiện | G11: N/A | H11: N/A | I11: ='DT04 (TM) 1 '!L28 -> 503250000 | J11: ='25-WNC-I-097'!BM310 -> 7.9502514e+08 | M11: =SUM(M12:M12) -> 92972969 | Q11: =I11-J11-P11-M11 -> -3.847481e+08
A12: I97-VDK-024 | B12: C150X75X6.5X10 | C12: C150X75X6.5X10x12000mm | D12: 29 | E12: =D12*12 -> 348 | F12: 338.1294 | G12: N/A | H12: N/A | I12: N/A | J12: N/A | K12: V | L12: 14363.64 | M12: 92972969 | N12: V | O12: =17000/1.1 -> 15454.545 | P12: N//A | Q12: Chọn Hùng Nguyên
B13: Xếp hạng | L13: 1 | O13: 2
A14: Ghi chú: Tiếp tục công tác mua sắm để đảm báo tiến độ
A15: NGƯỜI ĐỀ NGHỊ/ RECOMMENDATION BY: | E15: NGƯỜI KIỂM TRA/ DEPARTMENT HEAD CHECK BY: | J15: APPROVED BY: PHÊ DUYỆT
J16: Nguyễn Quang Vinh | M16: Hoàng Ngọc Bằng | P16: Đoàn Văn Toàn

Sheet DT04 (TM) 1 
D1: CÔNG TY CỔ PHẦN CÔNG NGHIỆP NẶNG IBS IBS HEAVY INDUSTRY JOINT STOCK COMPANY Add.: KM6, Quốc lộ 5, Phường Hồng Bàng, Thành phố Hải Phòng
A2: BẢNG DỰ TOÁN CHI TIẾT VẬT TƯ
L3: Mẫu số: QT30-DT04 | M3: Mua sắm/ Ordered, Puchased (Đến hiện tại/ Up to now)
A4: STT | B4: Nhóm vật tư | C4: Mã vật tư | D4: Danh mục vật tư | E4: Đơn vị tính | F4: Mác vật liệu | G4: Quy cách | J4: Khối lượng/ Số lượng | K4: Đơn giá (vnd) | L4: Thành tiền (vnd) | M4: Hàng mua thêm | O4: Hàng tồn | Q4: Tổng Giá trị đã mua/ Total Cost (VND) | R4: Đânh giá
G5: Dài | H5: Rộng | I5: Dày | M5: Khối lượng/ Weight (Kg) | N5: Số lượng/ Q'ty (M/M2//PSC) | O5: Khối lượng/ Weight (Kg/N/A) Materials available at the factory | P5: Số lượng/ Q'ty (M/M2/PSC) Materials available at the factory
A6: A | B6: VTC | D6: Vật tư chính | J6: =SUBTOTAL(9,J7:J20) -> 0 | L6: =SUM(L7:L22) -> 6.3904488e+09 | R6: =IF(L6>Q6," OKE MUA TIẾP","BÁO CÁO BOM") -> OKE MUA TIẾP
A7: 1 | B7: VTC01 | D7: Thép carbon các loại | E7: kg | L7: =L8+L9 -> 3001944110 | M7: ='Tổng hợp'!F20 -> 186779.34 | N7: ='Tổng hợp'!G20 -> 8152.1214 | O7: ='Tổng hợp'!H20 -> 3634.4786 | P7: ='Tổng hợp'!I20 -> 304.2928 | Q7: ='Tổng hợp'!J20 -> 3.0852474e+09 | R7: =IF(L7>Q7," OKE MUA TIẾP","BÁO CÁO BOM") -> BÁO CÁO BOM
A8: 1.1 | B8: VTC0101 | D8: Thép tấm carbon | E8: kg | L8: ='[116]Dự toán vật tư'!G7 -> 7.8006665e+08
A9: 1.2 | B9: VTC0102 | D9: Thép hình carbon | E9: kg | L9: ='[116]Dự toán vật tư'!G8 -> 2221877460
A10: 1.3 | B10: VTC0103 | D10: Thép ống carbon | E10: kg
A11: 1.4 | B11: VTC0104 | D11: Thép carbon khác
A12: 2 | B12: VTC02 | D12: Thép Hợp kim các loại | E12: kg | M12: ='Tổng hợp'!F21 -> 0 | N12: ='Tổng hợp'!G21 -> 0 | O12: ='Tổng hợp'!H21 -> 0 | P12: ='Tổng hợp'!I21 -> 0 | Q12: ='Tổng hợp'!J21 -> 0 | R12: =IF(L12>Q12," OKE MUA TIẾP","BÁO CÁO BOM") -> BÁO CÁO BOM
A13: 2.1 | B13: VTC0201 | D13: Thép tấm hợp kim | E13: kg
A14: 2.2 | B14: VTC0202 | D14: Thép hình hợp kim
A15: 2.3 | B15: VTC0203 | D15: Thép ống hợp kim
A16: 2.4 | B16: VTC0204 | D16: Thép hợp kim khác
A17: 3 | B17: VTC03 | D17: Tấm sàn, grating … | E17: kg | L17: ='[116]Dự toán vật tư'!G9 -> 195865000 | M17: ='Tổng hợp'!F22 -> 3622 | N17: ='Tổng hợp'!G22 -> 470 | O17: ='Tổng hợp'!H22 -> 0 | P17: ='Tổng hợp'!I22 -> 0 | Q17: ='Tổng hợp'!J22 -> 165851000 | R17: =IF(L17>Q17," OKE MUA TIẾP","BÁO CÁO BOM") -> OKE MUA TIẾP | S17: ='Sàn winwin'!G27 -> 160446000
A20: 4 | B20: VTC04 | D20: Vât tư bảo ôn | E20: kg | L20: ='[116]Dự toán vật tư'!G10 -> 1.9069559e+08 | M20: ='Tổng hợp'!F23 -> 0 | N20: ='Tổng hợp'!G23 -> 90.8928 | O20: ='Tổng hợp'!H23 -> 0 | P20: ='Tổng hợp'!I23 -> 0 | Q20: ='Tổng hợp'!J23 -> 2.0585973e+08 | R20: =IF(L20>Q20," OKE MUA TIẾP","BÁO CÁO BOM") -> BÁO CÁO BOM
A23: B | B23: VPK | D23: Vật tư phụ kiện, bu lông… | L23: ='[116]Dự toán vật tư'!G12 -> 213600000 | M23: ='Tổng hợp'!F24 -> 0 | N23: ='Tổng hợp'!G24 -> 49585 | O23: ='Tổng hợp'!H24 -> 0 | P23: ='Tổng hợp'!I24 -> 0 | Q23: ='Tổng hợp'!J24 -> 202484525 | R23: =IF(L23>Q23," OKE MUA TIẾP","BÁO CÁO BOM") -> OKE MUA TIẾP
A24: 1 | B24: VPK01 | D24: Phụ kiện
A25: 2 | B25: VPK02 | D25: Phụ kiện khác
A28: C | B28: VDK | D28: Vật tư đóng kiện | L28: ='[116]Dự toán vật tư'!G14 -> 503250000 | M28: ='Tổng hợp'!F25 -> 23146.8 | N28: ='Tổng hợp'!G25 -> 12576.902 | O28: ='Tổng hợp'!H25 -> 939.96862 | P28: ='Tổng hợp'!I25 -> 139.834 | Q28: ='Tổng hợp'!J25 -> 7.9502514e+08 | R28: =IF(L28>Q28," OKE MUA TIẾP","BÁO CÁO BOM") -> BÁO CÁO BOM
A29: 1 | B29: VDK01 | D29: Thép đen các loại | L29: ='[116]Dự toán vật tư'!G15 -> 347225000
A30: 2 | B30: VDK02 | D30: Vật tư phụ kiện, bu lông… | L30: ='[116]Dự toán vật tư'!G16 -> 69445000
A31: 3 | B31: VDK03 | D31: Vật tư phụ các loại | L31: ='[116]Dự toán vật tư'!G17 -> 86580000
A34: D | B34: VBP | D34: Vật tư làm biện pháp | L34: ='[116]Dự toán vật tư'!G18 -> 67000000 | R34: =IF(L34>Q34," OKE MUA TIẾP","BÁO CÁO BOM") -> OKE MUA TIẾP
A35: 1 | B35: VBP01 | D35: Thép đen các loại | L35: ='[116]Dự toán vật tư'!G19 -> 60000000
A38: 2 | B38: VBP02 | D38: Vật tư phụ kiện, bu lông… | L38: ='[116]Dự toán vật tư'!G20 -> 7000000
A41: E | B41: VTH | D41: Vật tư tiêu hao | L41: ='[116]Dự toán vật tư'!G21 -> 307343625 | R41: =IF(L41>Q41," OKE MUA TIẾP","BÁO CÁO BOM") -> OKE MUA TIẾP
A42: 1 | B42: VTH01 | D42: Vật tư hàn | L42: ='[116]Dự toán vật tư'!G22 -> 141900000
A43: 1.1 | B43: VTH0101 | D43: Dây hàn
A45: 1.2 | B45: VTH0102 | D45: Que hàn
A47: 1.3 | B47: VTH0103 | D47: Thuốc hàn
A49: 2 | B49: VTH02 | D49: Khí công nghiệp | L49: ='[116]Dự toán vật tư'!G23 -> 145490625
A50: 2.1 | B50: VTH0201 | D50: Khí Ôxy
A52: 2.2 | B52: VTH0202 | D52: Khí CO2
A54: 2.3 | B54: VTH0203 | D54: Khí Gas
A56: 2.4 | B56: VTH0204 | D56: Khí Argon
A58: 2.5 | B58: VTH0205 | D58: Khí công nghiệp khác
A61: 3 | B61: VTH03 | D61: Vật tư phụ các loại | L61: ='[116]Dự toán vật tư'!G24 -> 19953000
...

Sheet Vật tư sơn 097
A1: BID ANALYSIS - GIẢI TRÌNH MUA SẮM/ĐẤU THẦU
A3: Project | B3: PROJECT No/ Dự án: 25-WNC-I-097
A4: Dự án
A5: Subject | B5: Cung cấp vật tư sơn
A6: Chủ đề
A8: No. | B8: CONTENT | C8: Phạm vi công việc | G8: Dự toán | J8: Đã mua | K8: Đơn vị cung cấp chào giá (vnđ) | N8: Lựa chọn | O8: Ghi chú
A9: Item | B9: Description/ Chi tiết | C9: Profile/ Vật tư | D9: Grade/ Mác vật liệu | E9: ĐVT | F9: Số lượng | G9: Khối lượng/ Số lượng | H9: Đơn giá (vnd) | I9: Thành tiền (vnd) | J9: Thành tiền (vnd) | K9: CTY CP TM VÀ CN NGUYÊN HANH
K10: Phạm vi | L10: Đơn giá (VND) | M10: Thành Tiền (Không có VAT)
A11: Tổng | G11: N/A | H11: N/A | I11: N/A | J11: 81840000 | M11: =SUM(M12:M18) -> 358940000 | O11: =-J11-M11 -> -440780000
A12: 1 | B12: Sơn Interzinc 52 | C12: EPA142 | D12: Grey | E12: lít | F12: 640 | G12: N/A | H12: N/A | K12: V | L12: 350000 | M12: 224000000 | N12: Nguyên Hanh | O12: - Chưa có số liệu dự toán để so sánh
A13: 2 | B13: Sơn Intergard 475HS | C13: EVA010 | D13: Off White | E13: lít | F13: 520 | G13: N/A | H13: N/A | K13: V | L13: 118000 | M13: 61360000 | N13: Nguyên Hanh
A14: 3 | B14: Sơn Interthane 990 | C14: PHD704 | D14: Ral 7035 | E14: lít | F14: 320 | G14: N/A | H14: N/A | K14: V | L14: 172900 | M14: 55328000 | N14: Nguyên Hanh
A15: 4 | B15: Sơn Intergard 345 | C15: AAD704 | D15: Ral 7035 | E15: lít | F15: 20 | G15: N/A | H15: N/A | K15: V | L15: 208600 | M15: 4172000 | N15: Nguyên Hanh
A16: 5 | B16: Dung môi GTA220 | C16: GTA220 | D16: Clear | E16: lít | F16: 80 | G16: N/A | H16: N/A | K16: V | L16: 64000 | M16: 5120000 | N16: Nguyên Hanh
A17: 6 | B17: Dung môi GTA007 | C17: GTA007 | D17: Clear | E17: lít | F17: 80 | G17: N/A | H17: N/A | K17: V | L17: 64000 | M17: 5120000 | N17: Nguyên Hanh
A18: 7 | B18: Dung môi GTA733 | C18: GTA733 | D18: Clear | E18: lít | F18: 60 | G18: N/A | H18: N/A | K18: V | L18: 64000 | M18: 3840000 | N18: Nguyên Hanh
B19: Đơn giá tổng hợp
A20: II | B20: Khối lượng dự kiến giao (Kg )/ Estimated weight (Kg):
A21: 1 | B21: … | C21: kg
A22: 2 | B22: …
A23: III | B23: Tiến độ/ Schedule | C23: Bắt đầu/ Start | D23: Kết thúc/ Finish
A24: 1 | B24: ….
A26: IV | B26: Nhân lực/ ManPower
A27: 1 | B27: Thợ Pha cắt / Thợ sắt / Thợ hàn / …
B28: ….
A29: V | B29: Yêu cầu kỹ thuật: Tham chiếu các tài liệu đính kèm/ Technical requirement – refer to document attached
B30: Xếp hạng | L30: 1
A31: Ghi chú: PTM tiến hàng mua sắm đẻ đảm bảo tiến độ
A32: NGƯỜI ĐỀ NGHỊ/ RECOMMENDATION BY: | C32: NGƯỜI KIỂM TRA/ DEPARTMENT HEAD CHECK BY: | F32: APPROVED BY: PHÊ DUYỆT
E33: Nguyễn Quang Vinh | H33: Hoàng Ngọc Bằng | K33: Đoàn Văn Toàn

Sheet 25-WNC-I-097
I1: THEO DÕI VẬT TƯ DỰ ÁN/ MATERIAL CONTROL LOG | N1: Hướng dẫn cập nhật thông tin: | R1: Thời gian nộp bảng cập nhật: | CY1: DỰ TOÁN
I2: Tên dự án/ Project no.:25-WNC-I-097 | N2: - Chữ tô màu xanh: | P2: Chưa cập nhật | R2: - Trong ngày khi có biến động.
I3: Cập nhật ngày/ Update to: | K3: =TODAY() -> 46086 | N3: - Chữ tô màu đỏ: | P3: Đã cập nhật mới | R3: - Báo cáo hàng tuần vào 16:30 mỗi chiều thứ 2. | AV3: =SUBTOTAL(9,AV7:AV1406) -> 0
B4: Đánh giá (Thiếu/ Đủ/ Thừa) | I4: Item/ STT | J4: Description/ Chi tiết | K4: Profile/ Vật tư | L4: Grade/ Mác vật liệu | M4: Unit/ Đơn vị | N4: U.Weight/ Đ.Trọng (Kg/m2,m,pcs) | O4: Net Quantity/Số lượng tinh | Q4: Current Ordered/Dự trù lần 0 (Ngày 16/8/2025) | S4: Current Ordered/Dự trù lần 1 (Ngày 26/8/2025) | U4: Current Ordered/Dự trù lần 2 (Ngày 2/10/2025) | W4: Current Ordered/Dự trù lần 3 (Ngày 10/10/2025) | Y4: Current Ordered/Dự trù lần 4 (Ngày 18/10/2025) | AA4: Current Ordered/Dự trù lần 5 (Ngày 23/10/2025) | AC4: Current Ordered/Dự trù lần 6 (Ngày 1/11/2025) | AE4: Current Ordered/Dự trù lần 7 (Ngày 7/11/2025) | AG4: Current Ordered/Dự trù lần 8 (Ngày 16/12/2025) | AI4: Current Ordered/Dự trù lần 9 (Ngày 23/12/2025) | AK4: Current Ordered/Dự trù lần 10 (Ngày 10/1/2026) | AM4: Current Ordered/Dự trù lần 11 (Ngày 22/1/2026) | AO4: Current Ordered/Dự trù lần 12 (Ngày 07/2/2026) | AQ4: Total Ordered/Tổng dự trù | AS4: Remarks/ Ghi chú | AT4: Tận dụng tồn kho/ Remain | AY4: Khối lượng phải mua sắm/ total order | BA4: Ngày bàn giao vật tư/ Material avaiable for hand over date | BB4: VẬT TƯ TRONG NƯỚC | BO4: ĐÃ MUA TRONG NƯỚC | BQ4: QC Nghiệm thu | BU4: Mua sắm nước ngoài/ Oversea purchase | CM4: ĐÃ MUA NHẬP KHẨU | CO4: Nghiệm thu | CS4: TỔNG ĐÃ MUA TRONG VÀ NGOÀI NƯỚC | CU4: So sánh với số lượng vật tư PR | CX4: Remarks/ Ghi chú
O5: Q.Ty/ S.Lượng | P5: Weight/ K.Lượng (Kg) | Q5: Q.Ty/ S.Lượng | R5: Weight/ K.Lượng (Kg) | S5: Q.Ty/ S.Lượng | T5: Weight/ K.Lượng (Kg) | U5: Q.Ty/ S.Lượng | V5: Weight/ K.Lượng (Kg) | W5: Q.Ty/ S.Lượng | X5: Weight/ K.Lượng (Kg) | Y5: Q.Ty/ S.Lượng | Z5: Weight/ K.Lượng (Kg) | AA5: Q.Ty/ S.Lượng | AB5: Weight/ K.Lượng (Kg) | AC5: Q.Ty/ S.Lượng | AD5: Weight/ K.Lượng (Kg) | AE5: Q.Ty/ S.Lượng | AF5: Weight/ K.Lượng (Kg) | AG5: Q.Ty/ S.Lượng | AH5: Weight/ K.Lượng (Kg) | AI5: Q.Ty/ S.Lượng | AJ5: Weight/ K.Lượng (Kg) | AK5: Q.Ty/ S.Lượng | AL5: Weight/ K.Lượng (Kg) | AM5: Q.Ty/ S.Lượng | AN5: Weight/ K.Lượng (Kg) | AO5: Q.Ty/ S.Lượng | AP5: Weight/ K.Lượng (Kg) | AQ5: Q.Ty/ S.Lượng | AR5: Weight/ K.Lượng (Kg) | AT5: Report No. | AU5: Q.Ty/ S.Lượng | AV5: Weight/ K.Lượng (Kg) | AW5: Ngày nghiệm thu ACC | AX5: Remarks/ Ghi chú | AY5: Q.Ty/ S.Lượng | AZ5: Weight/ K.Lượng (Kg) | BB5: Số Hợp đồng / Contract No | BC5: Nhà cung cấp/ Vendor | BD5: Profile/ Vật tư | BE5: Grade/ Mác vật liệu | BF5: Contract weight ( K.Lượng theo HĐ) | BG5: Ngày ký HD/ Contract date | BH5: S.Lượng giao hàng thực tế/ Handover Q'ty | BI5: K.Lượng giao hàng thực tế// Handover weight | BJ5: Đơn giá / Unit Price (Not VAT) | BK5: Tổng tiền cả VAT (VNĐ) | BL5: VAT | BM5: Tổng tiền (VNĐ) | BN5: Bàn giao sản xuất/ Handover to Product | BO5: Q.Ty/ S.Lượng | BP5: Weight/ K.Lượng (Kg) | BQ5: Report No. | BR5: Inspection date | BS5: Khối lượng nghiệm thu đạt/ Weight Acc. Inspection | BT5: Results | BU5: Số Hợp đồng / Contract No | BV5: Nhà cung cấp/ Vendor | BW5: Profile/ Vật tư | BX5: Grade/ Mác vật liệu | BY5: Weight/ Khối lượng (Kg) | BZ5: Ngày ký HD/ Contract date | CA5: Số lượng giao hàng thực tế/ Handover Q'ty | CB5: Khối lượng giao hàng thực tế/ Handover Q'ty | CC5: Đơn giá / Unit Price | CD5: Thành tiền Hợp đồng/ total | CE5: Ngày mở L/C/ LC issued date | CF5: Hàng đi từ cảng nước ngoài/ Export Port | CG5: Hàng Đến cảng HP (CIF)/ HaiPhong CIF | CH5: Ngày thanh toán / Payment date | CI5: Thủ tục hải quan, vận chuyển/ Paper work, local transportaion date | CJ5: Ngày hàng về / Arived | CK5: Ngày mời nghiệm thu / invice QC date | CL5: Bàn giao sản xuất/ Handover to Product | CM5: Q.Ty/ S.Lượng | CN5: Weight/ K.Lượng (Kg) | CO5: Report No. | CP5: Inspection date | CQ5: Khối lượng nghiệm thu đạt/ Weight Acc. Inspection | CR5: Results | CS5: Q.Ty/ S.Lượng | CT5: Weight/ K.Lượng (Kg) | CU5: Q.Ty/ S.Lượng | CV5: Weight/ K.Lượng (Kg) | CW5: Đánh giá (Thiếu/ Đủ/ Thừa) | CY5: STT | CZ5: Chi tiết vật liệu | DB5: ĐVT | DC5: Định mức | DD5: Số lượng | DE5: Khối lượng | DF5: Đơn giá (VNĐ)
C6: Số lượng cần (M/M2) | D6: Xin chuyển đổi | E6: Đã đặt hàng | G6: Xin chuyển đổi | I6: 1 | J6: =I6+1 -> 2 | K6: =J6+1 -> 3 | L6: =K6+1 -> 4 | M6: =L6+1 -> 5 | N6: =M6+1 -> 6 | O6: =N6+1 -> 7 | P6: =O6+1 -> 8 | Q6: =P6+1 -> 9 | ... CX6: =CW6+1 -> 94
F7: Xin chuyển đổi | I7: VTC01 | J7: Main-Material / Vật tư chính thép đen | AQ7: =SUM(AQ8:AQ121) -> 7442.1193 | AR7: =SUM(AR8:AR121) -> 178328.59 | AS7: =SUM(AS8:AS121) -> 0 | AT7: =SUM(AT8:AT121) -> 0 | AU7: =SUM(AU8:AU121) -> 304.2928 | AV7: =SUM(AV8:AV121) -> 3634.4786 | AW7: =SUM(AW8:AW121) -> 0 | AX7: =SUM(AX8:AX121) -> 0 | ... CX7: =SUM(CX8:CX121) -> 0 | CY7: I
A8: =IF(I8=I7,"ok","Hiện") -> Hiện | B8: =CONCATENATE(CW8," Thiếu ít") -> Thiếu Thiếu ít | C8: =CU8 -> 1.3252 | E8: Thép U100x50x5x7.5x12000 | F8: Ngọc hiếu | I8: I97-VTC01-001 | J8: Thép hình C | K8: C100X50X5X7.5-12000L | L8: SS400 | M8: m | N8: 9.36 | O8: 90.232 | P8: 844 | Q8: 99.2552 | R8: 929.02867 | U8: 142.07 | V8: 1329.7752 | W8: 0 | X8: 0 | Y8: 0 | Z8: 0 | AG8: 0 | AH8: 0 | AK8: 0 | AL8: 0 | AM8: 0 | AN8: 0 | AO8: 0 | AP8: 0 | AQ8: =Q8+S8+U8+W8+Y8+AA8+AC8+AE8+AG8+AI8+AK8+AM8+AO8 -> 241.3252 | AR8: =R8+T8+V8+X8+Z8+AB8+AD8+AF8+AH8+AJ8+AL8+AN8+AP8 -> 2258.8039 | AS8: REV02-IBS REV | AY8: =IF(AQ8>AU8,AQ8-AU8,"0") -> 241.3252 | AZ8: =IF(AR8>AV8,AR8-AV8,"0") -> 2258.8039 | BA8: 45892 | BB8: 200825/HN-IBS | BC8: Hùng Nguyên | BD8: Thép U100x50x5x7.5x12000 = 9 Tấm/ Cây | BE8: A36/SS400 | BF8: 1010.88 | BG8: 45889 | BH8: 108 | BI8: 1010.88 | BJ8: 17636.36 | BK8: =BJ8*BI8*1.1 -> 19611068 | BL8: =(BK8-BM8)/BM8 -> 0.1 | BM8: =BJ8*BI8*1 -> 17828244 | BN8: 45892 | BO8: =SUMIF($I:$I,I8,$BH:$BH) -> 240 | BP8: =SUMIF($I:$I,I8,$BI:$BI) -> 2246.44 | CM8: =SUMIF($I:$I,I8,$CA:$CA) -> 0 | CN8: =SUMIF($I:$I,I8,$CB:$CB) -> 0 | CS8: =BO8+CM8 -> 240 | CT8: =BP8+CN8 -> 2246.44 | CU8: =AY8-CS8 -> 1.3252 | CV8: =AZ8-CT8 -> 12.363872 | CW8: =IF(CU8<0,"Thừa",IF(CU8=0,"Đủ","Thiếu")) -> Thiếu
A9: =IF(I9=I8,"ok","Hiện") -> ok | I9: I97-VTC01-001 | J9: Thép hình C | K9: C100X50X5X7.5-12000L | L9: SS400 | M9: m | BB9: 1912-2025/HĐKT/NH-IBS | BC9: Ngọc Hiếu | BD9: Thép U100*50*5*7,5*12000 ( 3 cây) | BE9: SS400 | BF9: 337 | BG9: 46010 | BH9: 36 | BI9: 337 | BJ9: 17090.91 | BK9: =BJ9*BI9*(1+BL9) -> 6335600.3 | BL9: 0.1 | BM9: =BJ9*BI9 -> 5759636.7 | BN9: 46029
A10: =IF(I10=I9,"ok","Hiện") -> ok | I10: I97-VTC01-001 | J10: Thép hình C | K10: C100X50X5X7.5-12000L | L10: SS400 | M10: m | BB10: I97-1010/HN-IBS | BC10: Hùng Nguyên | BD10: Thép U100x50x5x7.5x12000 = 8 CâySS400 | BF10: 898.56 | BG10: 45940 | BH10: 96 | BI10: 898.56 | BJ10: 17681.82 | BK10: =BJ10*BI10*1.1 -> 17476994 | BL10: =(BK10-BM10)/BM10 -> 0.1 | BM10: =BJ10*BI10*1 -> 15888176 | BN10: 45947
A11: =IF(I11=I10,"ok","Hiện") -> Hiện | B11: =CW11 -> Thừa | C11: =CU11 -> -4.91265 | E11: Thép U125x65x6x8x12000 thừa chuyển sang dự án 100 | F11: Ngọc hiếu | I11: I97-VTC01-002 | J11: Thép hình C | K11: C125X65X6X8-12000L | L11: SS400 | M11: m | N11: 13.4 | O11: 296.402 | P11: 3980.4 | Q11: 326.0422 | R11: 4368.9655 | U11: 629.04515 | V11: 8429.205 | W11: 0 | X11: 0 | Y11: 0 | Z11: 0 | AG11: 0 | AH11: 0 | AK11: 0 | AL11: 0 | AM11: 0 | AN11: 0 | AO11: 0 | AP11: 0 | AQ11: =Q11+S11+U11+W11+Y11+AA11+AC11+AE11+AG11+AI11+AK11+AM11+AO11 -> 955.08735 | AR11: =R11+T11+V11+X11+Z11+AB11+AD11+AF11+AH11+AJ11+AL11+AN11+AP11 -> 12798.17 | AS11: REV02-IBS REV | AY11: =IF(AQ11>AU11,AQ11-AU11,"0") -> 955.08735 | AZ11: =IF(AR11>AV11,AR11-AV11,"0") -> 12798.17 | BA11: 45892 | BB11: 200825/HN-IBS | BC11: Hùng Nguyên | BD11: Thép U125x65x6x8x12000 = 28 Tấm/ Cây | BE11: A36/SS400 | BF11: 4502.4 | BG11: 45889 | BH11: 336 | BI11: 4502.4 | BJ11: 17636.36 | BK11: =BJ11*BI11*1.1 -> 87346542 | BL11: =(BK11-BM11)/BM11 -> 0.1 | BM11: =BJ11*BI11*1 -> 79405947 | BN11: 45892 | BO11: =SUMIF($I:$I,I11,$BH:$BH) -> 960 | BP11: =SUMIF($I:$I,I11,$BI:$BI) -> 12864.4 | CM11: =SUMIF($I:$I,I11,$CA:$CA) -> 0 | CN11: =SUMIF($I:$I,I11,$CB:$CB) -> 0 | CS11: =BO11+CM11 -> 960 | CT11: =BP11+CN11 -> 12864.4 | CU11: =AY11-CS11 -> -4.91265 | CV11: =AZ11-CT11 -> -66.22951 | CW11: =IF(CU11<0,"Thừa",IF(CU11=0,"Đủ","Thiếu")) -> Thừa
A12: =IF(I12=I11,"ok","Hiện") -> ok | I12: I97-VTC01-002 | J12: Thép hình C | K12: C125X65X6X8-12000L | L12: SS400 | M12: m | BB12: 1912-2025/HĐKT/NH-IBS | BC12: Ngọc Hiếu | BD12: Thép U125*65*6*8*12000 ( 20 cây) | BE12: SS400 | BF12: 3216 | BG12: 46010 | BH12: 240 | BI12: 3216 | BJ12: 17090.91 | BK12: =BJ12*BI12*(1+BL12) -> 60460803 | BL12: 0.1 | BM12: =BJ12*BI12 -> 54964367 | BN12: 46029
A13: =IF(I13=I12,"ok","Hiện") -> ok | I13: I97-VTC01-002 | J13: Thép hình C | K13: C125X65X6X8-12000L | L13: SS400 | M13: m | BB13: 1510-2025/HĐKT/NH-IBS | BC13: Ngọc Hiếu | BD13: Thép U125*65*6*8*12000 = 32 Cây | BF13: 5146 | BG13: 45945 | BH13: 384 | BI13: 5146 | BJ13: 17545.45 | BK13: =BJ13*BI13*1.1 -> 99317774 | BL13: =(BK13-BM13)/BM13 -> 0.1 | BM13: =BJ13*BI13*1 -> 90288886 | BN13: 45954
A14: =IF(I14=I13,"ok","Hiện") -> Hiện | B14: =CW14 -> Thừa | C14: =CU14 -> -1.8881 | E14: Thép U200x90x8x13.5x12000 Hàng thiếu dùng dự án 100 | F14: Ngọc hiếu | I14: I97-VTC01-003 | J14: Thép hình C | K14: C200X90X8X13.5-12000L | L14: SS400 | M14: m | N14: 30.34 | O14: 71.076 | P14: 2167.8 | Q14: 78.1836 | R14: 2372.0904 | U14: 111.9283 | V14: 3395.9046 | W14: 0 | X14: 0 | Y14: 0 | Z14: 0 | AG14: 0 | AH14: 0 | AK14: 0 | AL14: 0 | AM14: 0 | AN14: 0 | AO14: 0 | AP14: 0 | AQ14: =Q14+S14+U14+W14+Y14+AA14+AC14+AE14+AG14+AI14+AK14+AM14+AO14 -> 190.1119 | AR14: =R14+T14+V14+X14+Z14+AB14+AD14+AF14+AH14+AJ14+AL14+AN14+AP14 -> 5767.995 | AS14: REV02-IBS REV | AY14: =IF(AQ14>AU14,AQ14-AU14,"0") -> 190.1119 | AZ14: =IF(AR14>AV14,AR14-AV14,"0") -> 5767.995 | BA14: 45892 | BB14: 200825/HN-IBS | BC14: Hùng Nguyên | BD14: Thép U200x90x8x13.5x12000 = 6 Tấm/ Cây | BE14: A36/SS400 | BF14: 2181.6 | BG14: 45889 | BH14: 72 | BI14: 2181.6 | BJ14: 17636.36 | BK14: =BJ14*BI14*1.1 -> 42323031 | BL14: =(BK14-BM14)/BM14 -> 0.1 | BM14: =BJ14*BI14*1 -> 38475483 | BN14: 45892 | BO14: =SUMIF($I:$I,I14,$BH:$BH) -> 192 | BP14: =SUMIF($I:$I,I14,$BI:$BI) -> 5819.36 | CM14: =SUMIF($I:$I,I14,$CA:$CA) -> 0 | CN14: =SUMIF($I:$I,I14,$CB:$CB) -> 0 | CS14: =BO14+CM14 -> 192 | CT14: =BP14+CN14 -> 5819.36 | CU14: =AY14-CS14 -> -1.8881 | CV14: =AZ14-CT14 -> -51.364954 | CW14: =IF(CU14<0,"Thừa",IF(CU14=0,"Đủ","Thiếu")) -> Thừa
A15: =IF(I15=I14,"ok","Hiện") -> ok | I15: I97-VTC01-003 | J15: Thép hình C | K15: C200X90X8X13.5-12000L | L15: SS400 | M15: m | BB15: 1912-2025/HĐKT/NH-IBS | BC15: Ngọc Hiếu | BD15: Thép U200*90*8*13,5*12000 ( 4 cây) | BE15: SS400 | BF15: 1454 | BG15: 46010 | BH15: 48 | BI15: 1454 | BJ15: 17272.73 | BK15: =BJ15*BI15*(1+BL15) -> 27626004 | BL15: 0.1 | BM15: =BJ15*BI15 -> 25114549 | BN15: 46036
A16: =IF(I16=I15,"ok","Hiện") -> ok | I16: I97-VTC01-003 | J16: Thép hình C | K16: C200X90X8X13.5-12000L | L16: SS400 | M16: m | BB16: I97-1010/HN-IBS | BC16: Hùng Nguyên | BD16: Thép U200x90x8x13.5x12000 = 6 CâySS400 | BF16: 2183.76 | BG16: 45940 | BH16: 72 | BI16: 2183.76 | BJ16: 17681.82 | BK16: =BJ16*BI16*1.1 -> 42474136 | BL16: =(BK16-BM16)/BM16 -> 0.1 | BM16: =BJ16*BI16*1 -> 38612851 | BN16: 45947
A17: =IF(I17=I16,"ok","Hiện") -> Hiện | B17: =CW17 -> Thừa | C17: =CU17 -> -0.8026 | D17: Dùng 3m hàng tồn của 102 | I17: I97-VTC01-004 | J17: Thép ống | K17: CHS33.7X2.6-6000L | L17: SS400 | M17: m | N17: 2.0267531 | O17: 4.934 | P17: 10 | Q17: 5.4274 | R17: 11 | U17: 7.77 | V17: 15.747872 | W17: 0 | X17: 0 | Y17: 0 | Z17: 0 | AG17: 0 | AH17: 0 | AK17: 0 | AL17: 0 | AM17: 0 | AN17: 0 | AO17: 0 | AP17: 0 | AQ17: =Q17+S17+U17+W17+Y17+AA17+AC17+AE17+AG17+AI17+AK17+AM17+AO17 -> 13.1974 | AR17: =R17+T17+V17+X17+Z17+AB17+AD17+AF17+AH17+AJ17+AL17+AN17+AP17 -> 26.747872 | AS17: REV02-IBS REV | AU17: 2 | AV17: =AU17*N17 -> 4.0535063 | AX17: Đã mời ngày 14/10 | AY17: =IF(AQ17>AU17,AQ17-AU17,"0") -> 11.1974 | AZ17: =IF(AR17>AV17,AR17-AV17,"0") -> 22.694366 | BA17: 45892 | BB17: Báo giá ngày 22/8/2025 | BC17: TITAN/190 | BD17: Thép ống đen 33,5 x 2,6 x 6.000 mm | BE17: STK R400 | BF17: 12 | BG17: 45891 | BH17: 6 | BI17: 12 | BJ17: 18500 | BK17: =BJ17*BI17*1.1 -> 244200 | BL17: =(BK17-BM17)/BM17 -> 0.1 | BM17: =BJ17*BI17*1 -> 222000 | BN17: 45903 | BO17: =SUMIF($I:$I,I17,$BH:$BH) -> 12 | BP17: =SUMIF($I:$I,I17,$BI:$BI) -> 24 | CM17: =SUMIF($I:$I,I17,$CA:$CA) -> 0 | CN17: =SUMIF($I:$I,I17,$CB:$CB) -> 0 | CS17: =BO17+CM17 -> 12 | CT17: =BP17+CN17 -> 24 | CU17: =AY17-CS17 -> -0.8026 | CV17: =AZ17-CT17 -> -1.3056344 | CW17: =IF(CU17<0,"Thừa",IF(CU17=0,"Đủ","Thiếu")) -> Thừa
A18: =IF(I18=I17,"ok","Hiện") -> ok | I18: I97-VTC01-004 | J18: Thép ống | K18: CHS33.7X2.6-6000L | L18: SS400 | BB18: Báo giá ngày 10/10/2025 | BC18: TITAN/190 | BD18: Thép ống đen 33.700 x 2.600 x 6000.0 mm = 1Cây | BF18: 12 | BG18: 45940 | BH18: 6 | BI18: 12 | BJ18: 16818.182 | BK18: =BJ18*BI18*1.1 -> 222000 | BL18: =(BK18-BM18)/BM18 -> 0.1 | BM18: =BJ18*BI18*1 -> 201818.18 | BN18: 45953
A19: =IF(I19=I18,"ok","Hiện") -> Hiện | B19: =CW19 -> Thừa | C19: =CU19 -> -0.7746 | I19: I97-VTC01-005 | J19: Thép ống | K19: CHS42.4X4-6000L | L19: SS400 | M19: m | N19: 3.9633806 | O19: 17.914 | P19: 71 | Q19: 19.7054 | R19: 78.1 | U19: 27.52 | V19: 109.07223 | W19: 0 | X19: 0 | Y19: 0 | Z19: 0 | AG19: 0 | AH19: 0 | AK19: 0 | AL19: 0 | AM19: 0 | AN19: 0 | AO19: 0 | AP19: 0 | AQ19: =Q19+S19+U19+W19+Y19+AA19+AC19+AE19+AG19+AI19+AK19+AM19+AO19 -> 47.2254 | AR19: =R19+T19+V19+X19+Z19+AB19+AD19+AF19+AH19+AJ19+AL19+AN19+AP19 -> 187.17223 | AS19: REV02-IBS REV | AY19: =IF(AQ19>AU19,AQ19-AU19,"0") -> 47.2254 | AZ19: =IF(AR19>AV19,AR19-AV19,"0") -> 187.17223 | BA19: 45892 | BB19: Báo giá ngày 22/8/2025 | BC19: TITAN/190 | BD19: Thép ống đen 42,2 x 4,0 x 6.000 mm | BE19: STK R400 | BF19: 90 | BG19: 45891 | BH19: 24 | BI19: 90 | BJ19: 18500 | BK19: =BJ19*BI19*1.1 -> 1831500 | BL19: =(BK19-BM19)/BM19 -> 0.1 | BM19: =BJ19*BI19*1 -> 1665000 | BN19: 45903 | BO19: =SUMIF($I:$I,I19,$BH:$BH) -> 48 | BP19: =SUMIF($I:$I,I19,$BI:$BI) -> 180 | CM19: =SUMIF($I:$I,I19,$CA:$CA) -> 0 | CN19: =SUMIF($I:$I,I19,$CB:$CB) -> 0 | CS19: =BO19+CM19 -> 48 | CT19: =BP19+CN19 -> 180 | CU19: =AY19-CS19 -> -0.7746 | CV19: =AZ19-CT19 -> 7.172234 | CW19: =IF(CU19<0,"Thừa",IF(CU19=0,"Đủ","Thiếu")) -> Thừa
A20: =IF(I20=I19,"ok","Hiện") -> ok | I20: I97-VTC01-005 | J20: Thép ống | K20: CHS42.4X4-6000L | L20: SS400 | BB20: Báo giá ngày 10/10/2025 | BC20: TITAN/190 | BD20: Thép ống đen 42.200 x 4.00 x 6000.0 mm = 4Cây | BF20: 90 | BG20: 45940 | BH20: 24 | BI20: 90 | BJ20: 16818.182 | BK20: =BJ20*BI20*1.1 -> 1665000 | BL20: =(BK20-BM20)/BM20 -> 0.1 | BM20: =BJ20*BI20*1 -> 1513636.4 | BN20: 45953
A21: =IF(I21=I20,"ok","Hiện") -> Hiện | B21: =CW21 -> Thừa | C21: =CU21 -> -96 | D21: CHS48.3x3.6-6000L / ASTM-A53-GR.B (Dự án 078 thừa 243m) | I21: I97-VTC01-006 | J21: Thép ống | K21: CHS48.3X3.7-6000L | L21: SS400 | M21: m | N21: 4.0427427 | O21: 85.348 | P21: 345.04 | Q21: 93.8828 | R21: 379.544 | U21: 134.41 | V21: 543.38504 | W21: 0 | X21: 0 | Y21: 0 | Z21: 0 | AG21: 0 | AH21: 0 | AK21: 0 | AL21: 0 | AM21: 0 | AN21: 0 | AO21: 0 | AP21: 0 | AQ21: =Q21+S21+U21+W21+Y21+AA21+AC21+AE21+AG21+AI21+AK21+AM21+AO21 -> 228.2928 | AR21: =R21+T21+V21+X21+Z21+AB21+AD21+AF21+AH21+AJ21+AL21+AN21+AP21 -> 922.92904 | AS21: REV02-IBS REV | AU21: 228.2928 | AV21: 922.92904 | AX21: Hàng tồn dự án 078/ Nhập Gnee | AY21: =IF(AQ21>AU21,AQ21-AU21,"0") -> 0 | AZ21: =IF(AR21>AV21,AR21-AV21,"0") -> 0 | BA21: 45892 | BB21: Báo giá ngày 22/8/2025 | BC21: TITAN/190 | BD21: Thép ống đen 48,3 x 3,7 x 6.000 mm | BE21: STK R400 | BF21: 391 | BG21: 45891 | BH21: 96 | BI21: 391 | BJ21: 18500 | BK21: =BJ21*BI21*1.1 -> 7956850 | BL21: =(BK21-BM21)/BM21 -> 0.1 | BM21: =BJ21*BI21*1 -> 7233500 | BN21: 45903 | BO21: =SUMIF($I:$I,I21,$BH:$BH) -> 96 | BP21: =SUMIF($I:$I,I21,$BI:$BI) -> 391 | CM21: =SUMIF($I:$I,I21,$CA:$CA) -> 0 | CN21: =SUMIF($I:$I,I21,$CB:$CB) -> 0 | CS21: =BO21+CM21 -> 96 | CT21: =BP21+CN21 -> 391 | CU21: =AY21-CS21 -> -96 | CV21: =AZ21-CT21 -> -391 | CW21: =IF(CU21<0,"Thừa",IF(CU21=0,"Đủ","Thiếu")) -> Thừa
