Workbook
Name \0: #REF!
Name \a: #N/A
Name \a: #N/A
Name \a: #N/A
Name \a: #N/A
Name \a: #N/A
Name \a: #N/A
Name \a: #N/A
Name \a: #N/A
Name \a: #N/A
Name \a: #N/A
Name \a: #N/A
Name \a: #REF!
Name \b: #N/A
Name \c: #N/A
Name \d: #N/A
Name \e: #N/A
Name \f: #N/A
Name \g: #N/A
Name \h: [1]PP!$IC$5
Name \h: #N/A
Name \h: #N/A
Name \h: #N/A
Name \h: #N/A
Name \h: #N/A
Name \h: #N/A
Name \h: #N/A
Name \h: #N/A
Name \h: #N/A
Name \h: #N/A
Name \h: #N/A
Name \h: #REF!
Name \i: [1]PP!$IP$7844
Name \i: #N/A
Name \i: #N/A
Name \i: #N/A
Name \i: #N/A
Name \i: #N/A
Name \i: #N/A
Name \i: #N/A
Name \i: #N/A
Name \i: #N/A
Name \i: #N/A
Name \i: #N/A
Name \i: #REF!
Name \j: #N/A
Name \k: #N/A
Name \KWS123: #N/A
Name \m: [1]PP!#REF!
Name \m: #N/A
Name \m: #N/A
Name \m: #N/A
Name \m: #N/A
Name \m: #N/A
Name \m: #N/A
Name \m: #N/A
Name \m: #N/A
Name \m: #N/A
Name \m: #N/A
Name \m: #N/A

Sheet IBSHI đơn 5 (4)
B1: C¤NG TY tnhh tm ngäc hiÕu | D1: céng hoµ x· héi chñ nghÜa viÖt nam
B2: Sè 8 M¸y T¬ - Ng« QuyÒn - H¶i Phßng | D2: §éc LËp - Tù Do - H¹nh Phóc
A3: -----J----- | D3: ---------o0o--------
D4: H¶i Phßng, Ngµy 05 th¸ng 11 n¨m 2025
C6: b¸o gi¸
B7: Kính gửi: CÔNG TY IBSHI
A8: Theo yªu cÇu cña Quý C«ng ty. Chóng t«i cã thÓ cung cÊp cho C«ng ty c¸c mÆt hµng sau: | L8: =L5+L6 -> 0
A10: STT | B10: Quy cách | C10: Số lượng (cây) | D10: Trọng lượng | E10: Đơn Giá | F10: Thành tiền | G10: bazem
A11: I90-C5 | B11: Thép tấm 10*2000*12000 | C11: 1 | D11: =ROUND(10*2*12*7.85*C11,0) -> 1884 | E11: =ROUND(G11/1.1,2) -> 13636.36 | F11: =ROUND(E11*D11,0) -> 25690902 | G11: 15000 | H11: oke
A12: I90-C6 | B12: Thép tấm 12*2000*12000 | C12: 1 | D12: =ROUND(12*2*12*7.85*C12,0) -> 2261 | E12: =ROUND(G12/1.1,2) -> 13636.36 | F12: =ROUND(E12*D12,0) -> 30831810 | G12: 15000 | H12: oke
A13: I90-C7 | B13: Thép tấm 16*2000*6000 | C13: 1 | D13: =ROUND(16*2*6*7.85*C13,0) -> 1507 | E13: =ROUND(G13/1.1,2) -> 14000 | F13: =ROUND(E13*D13,0) -> 21098000 | G13: 15400 | H13: oke
A14: I90-C8 | B14: Thép tấm 20*2000*12000 | C14: 1 | D14: =ROUND(20*2*12*7.85*C14,0) -> 3768 | E14: =ROUND(G14/1.1,2) -> 14181.82 | F14: =ROUND(E14*D14,0) -> 53437098 | G14: 15600 | H14: oke
A15: I90-C12 | B15: Thép H125*125*6,5*9*12000 | C15: 6 | D15: =ROUND(23.6*12*C15,0) -> 1699 | E15: =ROUND(G15/1.1,2) -> 17545.45 | F15: =ROUND(E15*D15,0) -> 29809720 | G15: 19300 | H15: oke | I15: =C15*12 -> 72 | J15: 74 | K15: H125x125x6.5x9
A16: I90-C13 | B16: Thép H200*200*8*12*12000 | C16: 12 | D16: =ROUND(49.9*12*C16,0) -> 7186 | E16: =ROUND(G16/1.1,2) -> 17545.45 | F16: =ROUND(E16*D16,0) -> 126081604 | G16: 19300 | H16: oke | I16: =C16*12 -> 144 | J16: 139.26525 | K16: H200x200x8x12 | L16: H200x200x8x12
A17: I90-C15 | B17: Thép H250*250*9*14*12000 | C17: 3 | D17: =ROUND(71.8*12*C17,0) -> 2585 | E17: =ROUND(G17/1.1,2) -> 17545.45 | F17: =ROUND(E17*D17,0) -> 45354988 | G17: 19300 | H17: oke | I17: =C17*12 -> 36 | J17: 25.68 | K17: H250x250x9x14 | L17: H250x250x9x14
A18: I90-C16 | B18: Thép H150*150*7*10*12000 | C18: 3.5 | D18: =ROUND(31.1*12*C18,0) -> 1306 | E18: =ROUND(G18/1.1,2) -> 17545.45 | F18: =ROUND(E18*D18,0) -> 22914358 | G18: 19300 | H18: oke | I18: =C18*12 -> 42 | J18: 42 | K18: H150x150x7x10 | L18: H150x150x7x10
A19: I90-C21 | B19: Thép U200*90*8*13,5*12000 | C19: 8 | D19: =ROUND(30.3*12*C19,0) -> 2909 | E19: =ROUND(G19/1.1,2) -> 17545.45 | F19: =ROUND(E19*D19,0) -> 51039714 | G19: 19300 | H19: oke | I19: =C19*12 -> 96 | J19: 93.5 | K19: U200x90x8.5x13.5 | L19: Thép U200x90x8x13.5x12000 | M19: U200x90x8.5x13.5
A20: I90-C22 | B20: Thép U250*90*9*13*12000 | C20: 35 | D20: =ROUND(34.6*12*C20,0) -> 14532 | E20: =ROUND(G20/1.1,2) -> 17545.45 | F20: =ROUND(E20*D20,0) -> 254970479 | G20: 19300 | H20: oke | I20: =C20*12 -> 420 | J20: 420.7574 | K20: U250x90x9x13x120000 | L20: Thép U250x90x9x13x120000 | M20: U250x90x9x13x120000
A21: I90-C24 | B21: Thép U300x90x9x13 x120000 | C21: 1 | D21: =ROUND(38.1*12*C21,0) -> 457 | E21: =ROUND(G21/1.1,2) -> 17545.45 | F21: =ROUND(E21*D21,0) -> 8018271 | G21: 19300 | H21: oke | I21: =C21*12 -> 12 | J21: 12 | K21: U300x90x9x12 x120000 | L21: U280x100x9x13 | M21: U300x90x9x12 x120000
A22: I90-C26 | B22: Thép U125*65*6*8*12000 | C22: 11 | D22: =ROUND(13.4*12*C22,0) -> 1769 | E22: =ROUND(G22/1.1,2) -> 17545.45 | F22: =ROUND(E22*D22,0) -> 31037901 | G22: 19300 | H22: oke | I22: =C22*12 -> 132 | J22: 127 | K22: U125x65x6x8 | L22: Hùng Nguyên 4 cây (U125x65x6x8) | M22: U125x65x6x8
A23: I90-C28 | B23: Thép V150*150*10*6000 | C23: 1 | D23: =ROUND(23*6*C23,0) -> 138 | E23: =ROUND(G23/1.1,2) -> 15909.09 | F23: =ROUND(E23*D23,0) -> 2195454 | G23: 17500 | H23: oke | I23: =C23*12 -> 12 | J23: 3
A24: I90-C29 | B24: Thép V80*80*8*6000 | C24: 3 | D24: =ROUND(9.63*6*C24,0) -> 173 | E24: =ROUND(G24/1.1,2) -> 13909.09 | F24: =ROUND(E24*D24,0) -> 2406273 | G24: 15300 | H24: oke | I24: =C24*12 -> 36 | J24: 32.406312 | K24: Thép góc V75x75x7x6000
A25: I90-C30 | B25: Thép V75*75*6*12000 | C25: 3 | D25: =ROUND(6.85*12*C25,0) -> 247 | E25: =ROUND(G25/1.1,2) -> 13909.09 | F25: =ROUND(E25*D25,0) -> 3435545 | G25: 15300 | H25: oke | I25: =C25*12 -> 36 | J25: 15.84 | K25: Thép góc V80x80x8x6000
A26: 16 | F26: =ROUND(SUM(F11:F25),0) -> 708322117 | I26: =C26*12 -> 0
A27: 17 | B27: VAT 10% | F27: =ROUND(F26*10%,0) -> 70832212
A29: Tæng Céng | D29: =SUM(D11:D28) -> 42421 | F29: =F26+F27 -> 779154329
B30: - Hiệu lực báo giá: báo giá có giá trị hết ngày 10/11/2025 , giá đã bao gồm VAT 10% | H30: 1 | K30: hoan
B31: - Điều kiện giao hàng: hàng giao theo bazem kho bên bán trên phương tiện bên mua.
B32: - Thời hạn thanh toán: trước khi nhận hàng.
B33: - Nếu quý công ty chấp nhận xin vui lòng fax lại số: 0313.528921
B34: Xin trân trọng cảm ơn.
B35: XÁC NHẬN CỦA BÊN MUA | D35: CÔNG TY TNHH TM NGỌC HIẾU

Sheet Máy hàn
A1: BID ANALYSIS - GIẢI TRÌNH MUA SẮM/ĐẤU THẦU
A3: Project | B3: PROJECT No/ Dự án: Phục Vụ Sản Xuất
A4: Dự án
A5: Subject | B5: Cung cấp máy hàn
A6: Chủ đề
A8: No. | B8: CONTENT | D8: Dự toán | G8: Đã mua/Đã đặt | H8: Đơn vị cung cấp chào giá (vnđ) | K8: Lựa chọn | L8: Ghi chú
A9: Item | B9: Description/ Chi tiết | C9: Số lượng (PSC) | D9: Khối lượng/ Số lượng | E9: Đơn giá (vnd) | F9: Thành tiền (vnd) | G9: Thành tiền (vnd) | H9: C.Ty C.Phần Công Nghiệp WELDCOM
C10: Số lượng (cây) | H10: Phạm vi | I10: Đơn giá chưa VAT (VND) | J10: Thành Tiền ( có VAT 8%)
A11: Tổng | D11: N/A | E11: N/A | J11: =SUM(J12:J12) -> 600000000 | L11: =F11-G11-J11 -> -600000000
A12: 1 | B12: M01M-011437 Máy hàn bán tự động MIG500 N388- Jassic (TP5) Bảo hành: 18 tháng (Phụ kiện theo máy bao gồm: Cấp dây 15M cáp 50, súng QTB-500 3M, đồng hồ 36V) | C12: 20 | D12: N/A | E12: N/A | F12: N/A | G12: N/A | H12: V | I12: 27777778 | J12: 600000000 | K12: WELDCOM
B13: Đơn giá tổng hợp
A14: II | B14: Khối lượng dự kiến giao (Kg )/ Estimated weight (Kg):
A15: 1 | B15: …
A16: 2 | B16: …
A17: III | B17: Tiến độ/ Schedule
A18: 1 | B18: ….
A20: IV | B20: Nhân lực/ ManPower
A21: 1 | B21: Thợ Pha cắt / Thợ sắt / Thợ hàn / …
B22: ….
A23: V | B23: Yêu cầu kỹ thuật: Tham chiếu các tài liệu đính kèm/ Technical requirement – refer to document attached
B24: Xếp hạng | I24: 1
A25: Ghi Chú: PTM tiến hành ngay công tác mua hàng
A26: NGƯỜI ĐỀ NGHỊ/ RECOMMENDATION BY: | C26: NGƯỜI KIỂM TRA/ DEPARTMENT HEAD CHECK BY: | G26: APPROVED BY: PHÊ DUYỆT
G27: Nguyễn Quang Vinh | I27: Hoàng Ngọc Bằng | K27: Đoàn Văn Toàn
H30: Nguyễn Quang Vinh | J30: Hoàng Ngọc Bằng | M30: Đoàn Văn Toàn

Sheet Sàn nhựa Đại Việt
A1: BID ANALYSIS - GIẢI TRÌNH MUA SẮM/ĐẤU THẦU
A3: Project | B3: PROJECT No/ Dự án: 25-BRA-I-090
A4: Dự án
A5: Subject | B5: Cung cấp vật tư GRATING dự án 090
A6: Chủ đề
A8: No. | B8: CONTENT | G8: Dự toán | J8: Đã mua/Đã đặt | K8: Đơn vị cung cấp chào giá (vnđ) | N8: Lựa chọn | O8: Ghi chú
A9: Chủng loại | B9: Bản vẽ | C9: Length | D9: Width | E9: Thickness | F9: ĐVT | G9: Số lượng | H9: Đơn giá (vnd) | I9: Thành tiền (vnd) | J9: Thành tiền (vnd) | K9: CÔNG TY CỔ PHẦN ĐẠI PHÁT COMPOSITE
E10: Số lượng (cây) | F10: Trọng lượng | K10: Phạm vi | L10: Đơn giá (VND) | M10: Thành Tiền (Không có VAT)
M11: =SUM(M12:M89) -> 255444000 | O11: =I11-J11-M11 -> -255444000
A12: Tấm sàn grating ô 38*38*30mm | B12: 13105R-R001-Z301-000 | C12: 790 | D12: 600 | E12: 30 | F12: Tấm | G12: 10 | H12: N/A | I12: N/A | J12: N/A | K12: V | L12: 690000 | M12: 6900000 | N12: Đại Phát | O12: 13105R-R001-Z302-000 Đã giao
A13: Tấm sàn grating ô 38*38*30mm | B13: 13105R-R001-Z302-000 | C13: 790 | D13: 425 | E13: 30 | F13: Tấm | G13: 4 | H13: N/A | I13: N/A | J13: N/A | K13: V | L13: 590000 | M13: 2360000 | N13: Đại Phát
A14: Tấm sàn grating ô 38*38*30mm | B14: 13105R-R001-Z305-000 | C14: 790 | D14: 600 | E14: 30 | F14: Tấm | G14: 2 | H14: N/A | I14: N/A | J14: N/A | K14: V | L14: 690000 | M14: 1380000 | N14: Đại Phát
A15: Tấm sàn grating ô 38*38*30mm | B15: 13105R-R001-Z306-000 | C15: 679 | D15: 425 | E15: 30 | F15: Tấm | G15: 4 | H15: N/A | I15: N/A | J15: N/A | K15: V | L15: 510000 | M15: 2040000 | N15: Đại Phát
A16: Tấm sàn grating ô 38*38*30mm | B16: 13105R-R001-Z307-000 | C16: 679 | D16: 425 | E16: 30 | F16: Tấm | G16: 4 | H16: N/A | I16: N/A | J16: N/A | K16: V | L16: 510000 | M16: 2040000 | N16: Đại Phát
A17: GRP-Grating-thk 30mm | B17: 13164R-R001-Z301-000 | C17: 790 | D17: 600 | E17: 30 | F17: Tấm | G17: 15 | H17: N/A | I17: N/A | J17: N/A | K17: V | L17: 690000 | M17: 10350000 | N17: Đại Phát | O17: I90-Grating-Type H30mm-13164 (3units)-Rev00
A18: GRP-Grating-thk 30mm | B18: 13164R-R001-Z302-000 | C18: 790 | D18: 425 | E18: 30 | F18: Tấm | G18: 6 | H18: N/A | I18: N/A | J18: N/A | K18: V | L18: 590000 | M18: 3540000 | N18: Đại Phát
A19: GRP-Grating-thk 30mm | B19: 13164R-R001-Z303-000 | C19: 830 | D19: 425 | E19: 30 | F19: Tấm | G19: 6 | H19: N/A | I19: N/A | J19: N/A | K19: V | L19: 670000 | M19: 4020000 | N19: Đại Phát
A20: GRP-Grating-thk 30mm | B20: 13164R-R001-Z304-000 | C20: 860 | D20: 425 | E20: 30 | F20: Tấm | G20: 6 | H20: N/A | I20: N/A | J20: N/A | K20: V | L20: 670000 | M20: 4020000 | N20: Đại Phát
A21: GRP-Grating-thk 30mm | B21: 13164R-R001-Z305-000 | C21: 790 | D21: 600 | E21: 30 | F21: Tấm | G21: 3 | H21: N/A | I21: N/A | J21: N/A | K21: V | L21: 690000 | M21: 2070000 | N21: Đại Phát
A22: GRP-Grating-thk 50mm | B22: 13105R-R001-S116-005A | C22: 1172 | D22: 610 | E22: 50 | F22: Tấm | G22: 8 | H22: N/A | I22: N/A | J22: N/A | K22: V | L22: 1500000 | M22: 12000000 | N22: Đại Phát | O22: I90-Grating H50mm-BO SUNG (U1+U2)-REV00 Đã giao
A23: GRP-Grating-thk 50mm | B23: 13105R-R001-S117-005A | C23: 568 | D23: 610 | E23: 50 | F23: Tấm | G23: 8 | H23: N/A | I23: N/A | J23: N/A | K23: V | L23: 800000 | M23: 6400000 | N23: Đại Phát
A24: GRP-Grating-thk 50mm | B24: 13164R-R001-S108-000 | C24: 1485 | D24: 490 | E24: 50 | F24: Tấm | G24: 2 | H24: N/A | I24: N/A | J24: N/A | K24: V | L24: 1364000 | M24: 2728000 | N24: Đại Phát | O24: I090-Grating partlist-H50mm-U3
A25: GRP-Grating-thk 50mm | B25: 13164R-R001-S109-000 | C25: 1485 | D25: 299 | E25: 50 | F25: Tấm | G25: 1 | H25: N/A | I25: N/A | J25: N/A | K25: V | L25: 855000 | M25: 855000 | N25: Đại Phát
A26: GRP-Grating-thk 50mm | B26: 13164R-R001-S110-000 | C26: 1485 | D26: 259 | E26: 50 | F26: Tấm | G26: 1 | H26: N/A | I26: N/A | J26: N/A | L26: 770000 | M26: 770000 | N26: Đại Phát
A27: GRP-Grating-thk 50mm | B27: 13164R-R001-S112-000 | C27: 1750 | D27: 428.5 | E27: 50 | F27: Tấm | G27: 1 | H27: N/A | I27: N/A | J27: N/A | L27: 1350000 | M27: 1350000 | N27: Đại Phát
A28: GRP-Grating-thk 50mm | B28: 13164R-R001-S116-000 | C28: 1290 | D28: 660 | E28: 50 | F28: Tấm | G28: 1 | H28: N/A | I28: N/A | J28: N/A | L28: 1565000 | M28: 1565000 | N28: Đại Phát
A29: GRP-Grating-thk 50mm | B29: 13164R-R001-S118-000 | C29: 1750 | D29: 610 | E29: 50 | F29: Tấm | G29: 15 | H29: N/A | I29: N/A | J29: N/A | L29: 1905000 | M29: 28575000 | N29: Đại Phát
A30: GRP-Grating-thk 50mm | B30: 13164R-R001-S118-001 | C30: 1750 | D30: 396 | E30: 50 | F30: Tấm | G30: 1 | H30: N/A | I30: N/A | J30: N/A | L30: 1305000 | M30: 1305000 | N30: Đại Phát
A31: GRP-Grating-thk 50mm | B31: 13164R-R001-S118-002 | C31: 779 | D31: 642,5 | E31: 50 | F31: Tấm | G31: 1 | H31: N/A | I31: N/A | J31: N/A | L31: 955000 | M31: 955000 | N31: Đại Phát
A32: GRP-Grating-thk 50mm | B32: 13164R-R001-S118-003 | C32: 961 | D32: 643 | E32: 50 | F32: Tấm | G32: 1 | H32: N/A | I32: N/A | J32: N/A | L32: 1250000 | M32: 1250000 | N32: Đại Phát
A33: GRP-Grating-thk 50mm | B33: 13164R-R001-S119-000 | C33: 1243 | D33: 305 | E33: 50 | F33: Tấm | G33: 2 | H33: N/A | I33: N/A | J33: N/A | L33: 755000 | M33: 1510000 | N33: Đại Phát
A34: GRP-Grating-thk 50mm | B34: 13164R-R001-S120-000 | C34: 850 | D34: 738.5 | E34: 50 | F34: Tấm | G34: 1 | H34: N/A | I34: N/A | J34: N/A | L34: 1255000 | M34: 1255000 | N34: Đại Phát
A35: GRP-Grating-thk 50mm | B35: 13164R-R001-S120-005 | C35: 850 | D35: 738.5 | E35: 50 | F35: Tấm | G35: 1 | H35: N/A | I35: N/A | J35: N/A | L35: 1255000 | M35: 1255000 | N35: Đại Phát
A36: GRP-Grating-thk 50mm | B36: 13164R-R001-S127-001 | C36: 1610 | D36: 600 | E36: 50 | F36: Tấm | G36: 3 | H36: N/A | I36: N/A | J36: N/A | L36: 1750000 | M36: 5250000 | N36: Đại Phát
A37: GRP-Grating-thk 50mm | B37: 13164R-R001-S118-004 | C37: 1750 | D37: 565 | E37: 50 | F37: Tấm | G37: 2 | H37: N/A | I37: N/A | J37: N/A | L37: 1750000 | M37: 3500000 | N37: Đại Phát
A38: GRP-Grating-thk 50mm | B38: 13164R-R001-S127-000 | C38: 2695 | D38: 1220 | E38: 50 | F38: Tấm | G38: 1 | H38: N/A | I38: N/A | J38: N/A | L38: 5550000 | M38: 5550000 | N38: Đại Phát
A39: GRP-Grating-thk 50mm | B39: 13164R-R001-S127-002 | C39: 600 | D39: 501 | E39: 50 | F39: Tấm | G39: 1 | H39: N/A | I39: N/A | J39: N/A | L39: 615000 | M39: 615000 | N39: Đại Phát
A40: GRP-Grating-thk 50mm | B40: 13164R-R001-S127-003 | C40: 1109 | D40: 600 | E40: 50 | F40: Tấm | G40: 1 | H40: N/A | I40: N/A | J40: N/A | L40: 1265000 | M40: 1265000 | N40: Đại Phát
A41: GRP-Grating-thk 50mm | B41: 13164R-R001-S128-000 | C41: 1750 | D41: 517 | E41: 50 | F41: Tấm | G41: 1 | H41: N/A | I41: N/A | J41: N/A | L41: 1650000 | M41: 1650000 | N41: Đại Phát
A42: GRP-Grating-thk 50mm | B42: 13164R-R001-S128-002 | C42: 1750 | D42: 653 | E42: 50 | F42: Tấm | G42: 1 | H42: N/A | I42: N/A | J42: N/A | L42: 2250000 | M42: 2250000 | N42: Đại Phát
...

Sheet Vật tư đóng kiện Trân toàn
A1: BID ANALYSIS - GIẢI TRÌNH MUA SẮM/ĐẤU THẦU
A3: Project | B3: PROJECT No/ Dự án: 25-BRA-I-090
A4: Dự án
A5: Subject | B5: Cung cấp vật tư đóng kiện dự án 090
A6: Chủ đề
A8: No. | B8: CONTENT | C8: Phạm vi công việc | G8: Dự toán | J8: Đã mua/Đã đặt | K8: Đơn vị cung cấp chào giá (vnđ) | N8: Lựa chọn | O8: Ghi chú
A9: Item | B9: Description/ Chi tiết | C9: Profile/ Vật tư | D9: Grade/ Mác vật liệu | E9: Số lượng (M2) | F9: Trọng lượng (KG) | G9: Khối lượng/ Số lượng | H9: Đơn giá (vnd) | I9: Thành tiền (vnd) | J9: Thành tiền (vnd) | K9: Trần Toàn
E10: Số lượng (cây) | F10: Trọng lượng | K10: Phạm vi | L10: Đơn giá (VND) | M10: Thành Tiền (Không có VAT)
A11: Tổng | G11: N/A | H11: N/A | I11: ='DT04 (TM) 1 '!L17 -> 2538751590 | J11: ='Vật tư đóng kiện Ngọc hiếu 090'!K11+'Vật tư đóng kiện Ngọc hiếu 090'!N11 -> 4.994165e+09 | M11: =SUM(M12:M25) -> 262257375 | O11: =I11-J11-M11 -> -2.7176708e+09
A12: I90-C140 | B12: I90-C140 (10500 x 6500) x 3 tấm | D12: Bạt da | E12: 204.75 | F12: N/A | G12: N/A | H12: N/A | I12: N/A | J12: N/A | K12: V | L12: 50500 | M12: =L12*E12 -> 10339875 | N12: Trần Toàn | O12: -Giá trí mua đang vượt dự toán - PTM không nắm được vật tư phụ kiện còn phát sinh hàng không - Thông báo tới SALE để khách hàng hỗ trợ thêm chi phí
A13: I90-C141 | B13: I90-C141 (12000 x 8000) x 3 tấm | D13: Bạt da | E13: 288 | F13: N/A | G13: N/A | H13: N/A | I13: N/A | J13: N/A | K13: V | L13: 50500 | M13: =L13*E13 -> 14544000 | N13: Trần Toàn
A14: I90-C142 | B14: I90-C142 (1200 x 9500) x 1 tấm | D14: Bạt da | E14: 114 | F14: N/A | G14: N/A | H14: N/A | I14: N/A | J14: N/A | K14: V | L14: 50500 | M14: =L14*E14 -> 5757000 | N14: Trần Toàn
A15: I90-C143 | B15: I90-C143 (14000 x 7000) x 4 tấm | D15: Bạt da | E15: =392+196 -> 588 | F15: N/A | G15: N/A | H15: N/A | I15: N/A | J15: N/A | K15: V | L15: 50500 | M15: =L15*E15 -> 29694000 | N15: Trần Toàn
A16: I90-C144 | B16: I90-C144 (15000 x 11000) x 1 tấm | D16: Bạt da | E16: 165 | F16: N/A | G16: N/A | H16: N/A | I16: N/A | J16: N/A | K16: V | L16: 50500 | M16: =L16*E16 -> 8332500 | N16: Trần Toàn
A17: I90-C145 | B17: I90-C145 (15000 x 7000) x 3 tấm | D17: Bạt da | E17: 315 | F17: N/A | G17: N/A | H17: N/A | I17: N/A | J17: N/A | K17: V | L17: 50500 | M17: =L17*E17 -> 15907500 | N17: Trần Toàn
A18: I90-C146 | B18: I90-C146 (15500 x 9500) x 1 tấm | D18: Bạt da | E18: 147.25 | F18: N/A | G18: N/A | H18: N/A | I18: N/A | J18: N/A | K18: V | L18: 50500 | M18: =L18*E18 -> 7436125 | N18: Trần Toàn
A19: I90-C147 | B19: I90-C147 (15500 x 10000) x 1 tấm | D19: Bạt da | E19: 155 | F19: N/A | G19: N/A | H19: N/A | I19: N/A | J19: N/A | K19: V | L19: 50500 | M19: =L19*E19 -> 7827500 | N19: Trần Toàn
A20: I90-C148 | B20: I90-C148 (17000 x 12000) x 4 tấm | D20: Bạt da | E20: 816 | F20: N/A | G20: N/A | H20: N/A | I20: N/A | J20: N/A | K20: V | L20: 50500 | M20: =L20*E20 -> 41208000 | N20: Trần Toàn
A21: I90-C149 | B21: I90-C149 (16500 x 9000) x 3 tấm | D21: Bạt da | E21: 445.5 | F21: N/A | G21: N/A | H21: N/A | I21: N/A | J21: N/A | K21: V | L21: 50500 | M21: =L21*E21 -> 22497750 | N21: Trần Toàn
A22: I90-C150 | B22: I90-C150 (16500 x 10000) x 3 tấm | D22: Bạt da | E22: 495 | F22: N/A | G22: N/A | H22: N/A | I22: N/A | J22: N/A | K22: V | L22: 50500 | M22: =L22*E22 -> 24997500 | N22: Trần Toàn
A23: I90-C151 | B23: I90-C151 (17500 x 11500) x 3 tấm | D23: Bạt da | E23: 603.75 | F23: N/A | G23: N/A | H23: N/A | I23: N/A | J23: N/A | K23: V | L23: 50500 | M23: =L23*E23 -> 30489375 | N23: Trần Toàn
A24: I90-C152 | B24: I90-C152 (9000 x 7500) x 3 tấm | D24: Bạt da | E24: 202.5 | F24: N/A | G24: N/A | H24: N/A | I24: N/A | J24: N/A | K24: V | L24: 50500 | M24: =L24*E24 -> 10226250 | N24: Trần Toàn
A25: I90-C154 | B25: Bạt dứa I90 - C 154 ( 15000 x 20000 ) x 10 tấm | D25: Bạt dứa | E25: 3000 | F25: N/A | G25: N/A | H25: N/A | I25: N/A | J25: N/A | K25: V | L25: 11000 | M25: =L25*E25 -> 33000000 | N25: Trần Toàn
B26: Đơn giá tổng hợp
A27: II | B27: Khối lượng dự kiến giao (Kg )/ Estimated weight (Kg):
A28: 1 | B28: … | C28: kg
A29: 2 | B29: …
A30: III | B30: Tiến độ/ Schedule | C30: Bắt đầu/ Start | D30: Kết thúc/ Finish
A31: 1 | B31: ….
A33: IV | B33: Nhân lực/ ManPower
A34: 1 | B34: Thợ Pha cắt / Thợ sắt / Thợ hàn / …
B35: ….
A36: V | B36: Yêu cầu kỹ thuật: Tham chiếu các tài liệu đính kèm/ Technical requirement – refer to document attached
B37: Xếp hạng | L37: 1
A38: Ghi Chú: Vật tư đóng kiện dự án 090 tính tiền theo khối lượng thực tế, PTM tiến hành mua hàng
A39: NGƯỜI ĐỀ NGHỊ/ RECOMMENDATION BY: | C39: NGƯỜI KIỂM TRA/ DEPARTMENT HEAD CHECK BY: | F39: APPROVED BY: PHÊ DUYỆT
F40: Nguyễn Quang Vinh | H40: Hoàng Ngọc Bằng | K40: Đoàn Văn Toàn

Sheet Vật tư 
A1: BID ANALYSIS - GIẢI TRÌNH MUA SẮM/ĐẤU THẦU
A3: Project | B3: PROJECT No/ Dự án: 25-BRA-I-090
A4: Dự án
A5: Subject | B5: Cung cấp vật tư phục vụ dự án 090
A6: Chủ đề
A8: No. | B8: CONTENT | C8: Phạm vi công việc | F8: Dự toán | I8: Đã mua/Đã đặt | J8: Đơn vị cung cấp chào giá (vnđ) | M8: Lựa chọn | N8: Ghi chú
A9: Item | B9: Description/ Chi tiết | C9: Số thùng | D9: Đóng gói | E9: Trọng lượng (Lít) | F9: Khối lượng/ Số lượng | G9: Đơn giá (vnd) | H9: Thành tiền (vnd) | I9: Thành tiền (vnd) | J9: Phúc Châu
E10: Trọng lượng | J10: Phạm vi | K10: Đơn giá (VND) | L10: Thành Tiền (Không có VAT)
A11: Tổng | B11: Vật tư phục vụ sản xuất 090 | F11: N/A | G11: N/A | L11: =SUM(L12:L12) -> 79800000 | N11: =H11-I11-L11 -> -79800000
A12: 1 | B12: VPCI-386 (19L/Thùng) | C12: 7 | D12: 19L/Thùng | E12: 133 | F12: N/A | G12: N/A | H12: N/A | I12: N/A | J12: V | K12: 600000 | L12: =E12*K12 -> 79800000 | M12: Phúc Châu
A13: II | B13: Khối lượng dự kiến giao (Kg )/ Estimated weight (Kg):
A14: 1 | B14: … | C14: kg
A15: 2 | B15: …
A16: III | B16: Tiến độ/ Schedule | C16: Bắt đầu/ Start | D16: Kết thúc/ Finish
A17: 1 | B17: ….
A19: IV | B19: Nhân lực/ ManPower
A20: 1 | B20: Thợ Pha cắt / Thợ sắt / Thợ hàn / …
B21: ….
A22: V | B22: Yêu cầu kỹ thuật: Tham chiếu các tài liệu đính kèm/ Technical requirement – refer to document attached
B23: Xếp hạng | K23: 1
A24: Ghi Chú: Vật tư phục vụ sản xuất, PTM tiến hành mua hàng ngay để đảm bảo tiến độ
A25: NGƯỜI ĐỀ NGHỊ/ RECOMMENDATION BY: | C25: NGƯỜI KIỂM TRA/ DEPARTMENT HEAD CHECK BY: | E25: APPROVED BY: PHÊ DUYỆT
E26: Nguyễn Quang Vinh | G26: Hoàng Ngọc Bằng | J26: Đoàn Văn Toàn

Sheet Vật tư sơn 090
A1: BID ANALYSIS - GIẢI TRÌNH MUA SẮM/ĐẤU THẦU
A3: Project | B3: PROJECT No/ Dự án: 25-BRA-I-090
A4: Dự án
A5: Subject | B5: Cung cấp vật tư phục vụ dự án 090
A6: Chủ đề
A8: No. | B8: CONTENT | C8: Phạm vi công việc | F8: Dự toán | I8: Đã mua/Đã đặt | J8: Đơn vị cung cấp chào giá (vnđ) | M8: Lựa chọn | N8: Ghi chú
A9: Item | B9: Description/ Chi tiết | C9: Profile/ Vật tư | D9: Grade/ Mác vật liệu | E9: Trọng lượng (KG) | F9: Khối lượng/ Số lượng | G9: Đơn giá (vnd) | H9: Thành tiền (vnd) | I9: Thành tiền (vnd) | J9: Nguyên Hanh
E10: Trọng lượng | J10: Phạm vi | K10: Đơn giá (VND) | L10: Thành Tiền (Không có VAT)
A11: Tổng | B11: Vật tư phục vụ sản xuất 090 | F11: N/A | G11: N/A | L11: =SUM(L12:L12) -> 17400000 | N11: =H11-I11-L11 -> -17400000
A12: 1 | B12: Hạt Garmet 30/60 | C12: Hạt Garmet 30/60 | D12: N/A | E12: 2000 | F12: N/A | G12: N/A | H12: N/A | I12: N/A | J12: V | K12: 8700000 | L12: =K12*2 -> 17400000 | M12: Nguyên hanh
A13: II | B13: Khối lượng dự kiến giao (Kg )/ Estimated weight (Kg):
A14: 1 | B14: … | C14: kg
A15: 2 | B15: …
A16: III | B16: Tiến độ/ Schedule | C16: Bắt đầu/ Start | D16: Kết thúc/ Finish
A17: 1 | B17: ….
A19: IV | B19: Nhân lực/ ManPower
A20: 1 | B20: Thợ Pha cắt / Thợ sắt / Thợ hàn / …
B21: ….
A22: V | B22: Yêu cầu kỹ thuật: Tham chiếu các tài liệu đính kèm/ Technical requirement – refer to document attached
B23: Xếp hạng | K23: 1
A24: Ghi Chú: Vật tư phục vụ sản xuất, PTM tiến hành mua hàng ngay để đảm bảo tiến độ
A25: NGƯỜI ĐỀ NGHỊ/ RECOMMENDATION BY: | C25: NGƯỜI KIỂM TRA/ DEPARTMENT HEAD CHECK BY: | E25: APPROVED BY: PHÊ DUYỆT
E26: Nguyễn Quang Vinh | G26: Hoàng Ngọc Bằng | J26: Đoàn Văn Toàn

Sheet Vật tư Hùng Nguyên
A1: BID ANALYSIS - GIẢI TRÌNH MUA SẮM/ĐẤU THẦU
A3: Project | B3: PROJECT No/ Dự án: 25-BRA-I-090
A4: Dự án
A5: Subject | B5: Cung cấp vật tư chính và vật tư đóng kiện dự án 090
A6: Chủ đề
A8: No. | B8: CONTENT | C8: Phạm vi công việc | G8: Dự toán | J8: Đã mua/Đã đặt | K8: Đơn vị cung cấp chào giá (vnđ) | N8: Đơn vị cung cấp chào giá (vnđ) | Q8: Lựa chọn | R8: Ghi chú
A9: Item | B9: Description/ Chi tiết | C9: Profile/ Vật tư | D9: Grade/ Mác vật liệu | E9: Số lượng (mua) (M) | F9: Số lượng (PR) (M) | G9: Khối lượng/ Số lượng | H9: Đơn giá (vnd) | I9: Thành tiền (vnd) | J9: Thành tiền (vnd) | K9: Ngọc Hiếu | N9: Hùng Nguyên
E10: Số lượng (cây) | F10: Số lượng (cây) | K10: Phạm vi | L10: Đơn giá (VND) | M10: Thành Tiền (Không có VAT) | N10: Phạm vi | O10: Đơn giá (VND) | P10: Thành Tiền (Không có VAT)
A11: Tổng | G11: N/A | H11: N/A | I11: ='DT04 (TM) 1 '!L8 -> 2.6838359e+10 | J11: ='DT04 (TM) 1 '!Q8 -> 2.8199093e+10 | P11: =SUM(P12:P12) -> 6401319 | R11: =I11-J11-M11-P11 -> -1.3671356e+09
A12: I90-A5 | B12: PL5x1500x6000 | C12: PL5x200x6000 | D12: SS400 | E12: 12 | F12: 9 | G12: N/A | H12: N/A | I12: N/A | J12: N/A | K12: V | L12: 13636.36 | M12: N/A | N12: V | O12: 13727.27 | P12: 6401319 | Q12: Hùng Nguyên | R12: -Giá trí mua đang vượt dự toán
A13: Tổng | G13: N/A | H13: N/A | I13: ='DT04 (TM) 1 '!L17 -> 2538751590 | J13: ='Tổng hợp'!J16 -> 4.2279793e+09 | M13: =SUM(M14:M14) -> 0 | P13: =SUM(P14:P14) -> 156776769 | R13: =I13-J13-M13-P13 -> -1.8460045e+09
A14: I90-C100 | B14: HEA200(H190x200x6.5x10)-L12000 | C14: Thép hình H200x200x6x8x12000 | D14: SS400 | E14: 170 | F14: 170 | G14: N/A | H14: N/A | I14: N/A | J14: N/A | K14: V | L14: =19300/1.1 -> 17545.455 | M14: N/A | N14: V | O14: =19200/1.1 -> 17454.545 | P14: =3*52258923 -> 156776769 | Q14: Hùng Nguyên | R14: -Giá trí mua đang vượt dự toán
B15: Đơn giá tổng hợp
A16: II | B16: Khối lượng dự kiến giao (Kg )/ Estimated weight (Kg):
A17: 1 | B17: … | C17: kg
A18: 2 | B18: …
A19: III | B19: Tiến độ/ Schedule | C19: Bắt đầu/ Start | D19: Kết thúc/ Finish
A20: 1 | B20: ….
A22: IV | B22: Nhân lực/ ManPower
A23: 1 | B23: Thợ Pha cắt / Thợ sắt / Thợ hàn / …
B24: ….
A25: V | B25: Yêu cầu kỹ thuật: Tham chiếu các tài liệu đính kèm/ Technical requirement – refer to document attached
B26: Xếp hạng | L26: 2 | O26: 1
A27: Ghi Chú: PTM tiến hành mua hàng để đảm bảo tiến độ
A28: NGƯỜI ĐỀ NGHỊ/ RECOMMENDATION BY: | C28: NGƯỜI KIỂM TRA/ DEPARTMENT HEAD CHECK BY: | K28: APPROVED BY: PHÊ DUYỆT
J29: Nguyễn Quang Vinh | M29: Hoàng Ngọc Bằng | P29: Đoàn Văn Toàn

Sheet Vật tư Quang Thịnh Phát
A1: BID ANALYSIS - GIẢI TRÌNH MUA SẮM/ĐẤU THẦU
A3: Project | B3: PROJECT No/ Dự án: 25-BRA-I-090
A4: Dự án
A5: Subject | B5: Cung cấp vật tư hộp A36/SS400
A6: Chủ đề
A8: No. | B8: CONTENT | C8: Phạm vi công việc | H8: Dự toán | K8: Đã mua/Đã đặt | L8: Đơn vị cung cấp chào giá (vnđ) | O8: Đơn vị cung cấp chào giá (vnđ) | R8: Lựa chọn | S8: Ghi chú
A9: Item | B9: Description/ Chi tiết | C9: Profile/ Vật tư | D9: Grade/ Mác vật liệu | E9: Số lượng mua (M) | F9: Số lượng PR (M) | G9: Trọng lượng (KG) | H9: Khối lượng/ Số lượng | I9: Đơn giá (vnd) | J9: Thành tiền (vnd) | K9: Thành tiền (vnd) | L9: QUANG THỊNH PHÁT | O9: Hùng Nguyên
E10: Số lượng (cây) | F10: Số lượng (cây) | G10: Trọng lượng | L10: Phạm vi | M10: Đơn giá (VND) | N10: Thành Tiền (Không có VAT) | O10: Phạm vi | P10: Đơn giá (VND) | Q10: Thành Tiền (Không có VAT)
A11: Tổng | H11: N/A | I11: N/A | J11: ='Tổng hợp'!K14 -> 2.7375767e+10 | K11: ='Tổng hợp'!J14 -> 2.8199093e+10 | N11: =SUM(N12:N12) -> 31690449 | Q11: =SUM(Q12:Q12) -> 0 | S11: =J11-K11-N11 -> -8.5501675e+08
A12: I90-A127 | B12: SHS 40x40x3-L6000 | C12: Thép hộp đen 40 x 40 x 3,0 x 6.000 mm | D12: A36/SS400 | E12: =6*98 -> 588 | F12: 582 | G12: 2015 | H12: N/A | I12: N/A | J12: N/A | K12: N/A | L12: V | M12: 15727.27 | N12: 31690449 | O12: V | P12: =18000/1.1 -> 16363.636 | Q12: N/A | R12: Quang Thịnh Phát | S12: -Giá trí mua đang vượt dự toán - PTM không nắm được vật tư phụ kiện còn phát sinh hàng không - Thông báo tới SALE để khách hàng hỗ trợ thêm chi phí
B13: Đơn giá tổng hợp
A14: II | B14: Khối lượng dự kiến giao (Kg )/ Estimated weight (Kg):
A15: 1 | B15: … | C15: kg
A16: 2 | B16: …
A17: III | B17: Tiến độ/ Schedule | C17: Bắt đầu/ Start | D17: Kết thúc/ Finish
A18: 1 | B18: ….
A20: IV | B20: Nhân lực/ ManPower
A21: 1 | B21: Thợ Pha cắt / Thợ sắt / Thợ hàn / …
B22: ….
A23: V | B23: Yêu cầu kỹ thuật: Tham chiếu các tài liệu đính kèm/ Technical requirement – refer to document attached
B24: Xếp hạng | M24: 1 | P24: 2
A25: Ghi Chú: PTM tiến hành mua hàng để đảm bảo tiến độ
A26: NGƯỜI ĐỀ NGHỊ/ RECOMMENDATION BY: | C26: NGƯỜI KIỂM TRA/ DEPARTMENT HEAD CHECK BY: | K26: APPROVED BY: PHÊ DUYỆT
K27: Nguyễn Quang Vinh | M27: Hoàng Ngọc Bằng | P27: Đoàn Văn Toàn

Sheet Vật tư đóng kiện Ngọc hiếu 090
A1: BID ANALYSIS - GIẢI TRÌNH MUA SẮM/ĐẤU THẦU
A3: Project | B3: PROJECT No/ Dự án: 25-BRA-I-090
A4: Dự án
A5: Subject | B5: Cung cấp vật tư đóng kiện dự án 090
A6: Chủ đề
A8: No. | B8: CONTENT | C8: Phạm vi công việc | H8: Dự toán | K8: Đã mua/Đã đặt | L8: Đơn vị cung cấp chào giá (vnđ) | O8: Đơn vị cung cấp chào giá (vnđ) | R8: Lựa chọn | S8: Ghi chú
A9: Item | B9: Description/ Chi tiết | C9: Profile/ Vật tư | D9: Grade/ Mác vật liệu | E9: Số lượng (cây) | G9: Trọng lượng (KG) | H9: Khối lượng/ Số lượng | I9: Đơn giá (vnd) | J9: Thành tiền (vnd) | K9: Thành tiền (vnd) | L9: Ngọc Hiếu | O9: Hùng Nguyên
E10: Số lượng (cây) | G10: Trọng lượng | L10: Phạm vi | M10: Đơn giá (VND) | N10: Thành Tiền (Không có VAT) | O10: Phạm vi | P10: Đơn giá (VND) | Q10: Thành Tiền (Không có VAT)
A11: Tổng | H11: N/A | I11: N/A | J11: ='DT04 (TM) 1 '!L17 -> 2538751590 | K11: ='Tổng hợp'!J16+'Vật tư đóng kiện Hoàng hà 090'!N11 -> 4.2858429e+09 | N11: =SUM(N12:N26) -> 708322117 | Q11: =SUM(Q12:Q26) -> 0 | S11: =J11-K11-N11 -> -2.4554134e+09
A12: I90-C5 | B12: PL10x2000x12000 | C12: Thép tấm 10*2000*12000 | D12: SS400 | E12: 1 | F12: 24 | G12: 1884 | H12: N/A | I12: N/A | J12: N/A | K12: N/A | L12: V | M12: 13636.36 | N12: 25690902 | O12: V | P12: 13727.27 | Q12: N/A | R12: Ngọc Hiếu | S12: -Giá trí mua đang vượt dự toán - PTM không nắm được vật tư phụ kiện còn phát sinh hàng không - Thông báo tới SALE để khách hàng hỗ trợ thêm chi phí
A13: I90-C6 | B13: PL12x2000x12000 | C13: Thép tấm 12*2000*12000 | D13: SS400 | E13: 1 | F13: 24 | G13: 2261 | H13: N/A | I13: N/A | J13: N/A | K13: N/A | L13: V | M13: 13636.36 | N13: 30831810 | O13: V | P13: 13727.27 | Q13: N/A | R13: Ngọc Hiếu
A14: I90-C7 | B14: PL15x2000x12000 | C14: Thép tấm 16*2000*6000 | D14: SS400 | E14: 1 | F14: 12 | G14: 1507 | H14: N/A | I14: N/A | J14: N/A | K14: N/A | L14: V | M14: 14000 | N14: 21098000 | O14: V | P14: 14000 | Q14: N/A | R14: Ngọc Hiếu
A15: I90-C8 | B15: PL20x2000x12000 | C15: Thép tấm 20*2000*12000 | D15: SS400 | E15: 1 | F15: 24 | G15: 3768 | H15: N/A | I15: N/A | J15: N/A | K15: N/A | L15: V | M15: 14181.82 | N15: 53437098 | O15: V | P15: 14545.45 | Q15: N/A | R15: Ngọc Hiếu
A16: I90-C12 | B16: HEA120(H114x120x5x8)-L12000 | C16: Thép H125*125*6,5*9*12000 | D16: SS400 | E16: 6 | F16: 72 | G16: 1699 | H16: N/A | I16: N/A | J16: N/A | K16: N/A | L16: V | M16: 17545.45 | N16: 29809720 | O16: V | P16: 17636.36 | Q16: N/A | R16: Ngọc Hiếu
A17: I90-C13 | B17: HEA180(171x180x6x9.5)-L12000 | C17: Thép H200*200*8*12*12000 | D17: SS400 | E17: 12 | F17: =E17*12 -> 144 | G17: 7186 | H17: N/A | I17: N/A | J17: N/A | K17: N/A | L17: V | M17: 17545.45 | N17: 126081604 | O17: V | P17: 17636.36 | Q17: N/A | R17: Ngọc Hiếu
A18: I90-C15 | B18: HEA260(H250x260x7.5x12.5)-L12000 | C18: Thép H250*250*9*14*12000 | D18: SS400 | E18: 3 | F18: =E18*12 -> 36 | G18: 2585 | H18: N/A | I18: N/A | J18: N/A | K18: N/A | L18: V | M18: 17545.45 | N18: 45354988 | O18: V | P18: 17636.36 | Q18: N/A | R18: Ngọc Hiếu
A19: I90-C16 | B19: HEB140(H140x140x7x12)-L12000 | C19: Thép H150*150*7*10*12000 | D19: SS400 | E19: 3.5 | F19: =E19*12 -> 42 | G19: 1306 | H19: N/A | I19: N/A | J19: N/A | K19: N/A | L19: V | M19: 17545.45 | N19: 22914358 | O19: V | P19: 17636.36 | Q19: N/A | R19: Ngọc Hiếu
A20: I90-C21 | B20: UNP200(C200x75x8.5x11.5)-L12000 | C20: Thép U200*90*8*13,5*12000 | D20: SS400 | E20: 8 | F20: 96 | G20: 2909 | H20: N/A | I20: N/A | J20: N/A | K20: N/A | L20: V | M20: 17545.45 | N20: 51039714 | O20: V | P20: 17500 | Q20: N/A | R20: Ngọc Hiếu
A21: I90-C22 | B21: UNP220(C220x80x9x12.5)-L12000 | C21: Thép U250*90*9*13*12000 | D21: SS400 | E21: 35 | F21: 420 | G21: 14532 | H21: N/A | I21: N/A | J21: N/A | K21: N/A | L21: V | M21: 17545.45 | N21: 254970479 | O21: X | P21: N/A | Q21: N/A | R21: Ngọc Hiếu
A22: I90-C24 | B22: UNP260(C260x90x10x14)-L12000 | C22: Thép U300x90x9x13 x120000 | D22: SS400 | E22: 1 | F22: 12 | G22: 457 | H22: N/A | I22: N/A | J22: N/A | K22: N/A | L22: V | M22: 17545.45 | N22: 8018271 | O22: V | P22: 17772.73 | Q22: N/A | R22: Ngọc Hiếu
A23: I90-C26 | B23: UPN120(C120x55x7x9)-L12000 | C23: Thép U125*65*6*8*12000 | D23: SS400 | E23: 11 | F23: 132 | G23: 1769 | H23: N/A | I23: N/A | J23: N/A | K23: N/A | L23: V | M23: 17545.45 | N23: 31037901 | O23: X | P23: N/A | Q23: N/A | R23: Ngọc Hiếu
A24: I90-C28 | B24: L150x150x10-L6000 | C24: Thép V150*150*10*6000 | D24: SS400 | E24: 1 | F24: 6 | G24: 138 | H24: N/A | I24: N/A | J24: N/A | K24: N/A | L24: V | M24: 15909.09 | N24: 2195454 | O24: X | P24: N/A | Q24: N/A | R24: Ngọc Hiếu
A25: I90-C29 | B25: L75x75x6-L12000 | C25: Thép V80*80*8*6000 | D25: SS400 | E25: 3 | F25: 18 | G25: 173 | H25: N/A | I25: N/A | J25: N/A | K25: N/A | L25: V | M25: 13909.09 | N25: 2406273 | O25: V | P25: 14181.82 | Q25: N/A | R25: Ngọc Hiếu
A26: I90-C30 | B26: L80x80x8-L12000 | C26: Thép V75*75*6*12000 | D26: SS400 | E26: 3 | F26: 36 | G26: 247 | H26: N/A | I26: N/A | J26: N/A | K26: N/A | L26: V | M26: 13909.09 | N26: 3435545 | O26: V | P26: 14181.82 | Q26: N/A | R26: Ngọc Hiếu
B27: Đơn giá tổng hợp
A28: II | B28: Khối lượng dự kiến giao (Kg )/ Estimated weight (Kg):
A29: 1 | B29: … | C29: kg
A30: 2 | B30: …
A31: III | B31: Tiến độ/ Schedule | C31: Bắt đầu/ Start | D31: Kết thúc/ Finish
A32: 1 | B32: ….
A34: IV | B34: Nhân lực/ ManPower
A35: 1 | B35: Thợ Pha cắt / Thợ sắt / Thợ hàn / …
B36: ….
A37: V | B37: Yêu cầu kỹ thuật: Tham chiếu các tài liệu đính kèm/ Technical requirement – refer to document attached
B38: Xếp hạng | M38: 1 | P38: 2
A39: Ghi Chú: Vật tư đóng kiện dự án 090 tính tiền theo khối lượng thực tế, PTM tiến hành mua hàng
A40: NGƯỜI ĐỀ NGHỊ/ RECOMMENDATION BY: | C40: NGƯỜI KIỂM TRA/ DEPARTMENT HEAD CHECK BY: | G40: APPROVED BY: PHÊ DUYỆT
G41: Nguyễn Quang Vinh | I41: Hoàng Ngọc Bằng | L41: Đoàn Văn Toàn

Sheet Vật tư đóng kiện Hoàng hà2
A1: BID ANALYSIS - GIẢI TRÌNH MUA SẮM/ĐẤU THẦU
A3: Project | B3: PROJECT No/ Dự án: 25-BRA-I-090
A4: Dự án
A5: Subject | B5: Cung cấp vật tư đóng kiện dự án 090
A6: Chủ đề
A8: No. | B8: CONTENT | C8: Phạm vi công việc | H8: Dự toán | K8: Đã mua | L8: Đơn vị cung cấp chào giá (vnđ) | O8: Lựa chọn | P8: Ghi chú
A9: Item | B9: Description/ Chi tiết | C9: Profile/ Vật tư | D9: Grade/ Mác vật liệu | E9: Mặt hàng | F9: ĐVT | G9: Số lượng | H9: Khối lượng/ Số lượng | I9: Đơn giá (vnd) | J9: Thành tiền (vnd) | K9: Thành tiền (vnd) | L9: Hoàng Hà
L10: Phạm vi | M10: Đơn giá (VND) | N10: Thành Tiền (Không có VAT)
A11: Tổng | H11: N/A | I11: N/A | J11: ='DT04 (TM) 1 '!L17 -> 2538751590 | K11: ='Tổng hợp'!J16-N11 -> 4.2034457e+09 | N11: =SUM(N12:N21) -> 24533600 | P11: =J11-K11-N11 -> -1.6892277e+09
A12: I90-C107 | B12: Bu lông ren suốt | C12: M20*85 | D12: Mạ kẽm 8.8 | E12: Bulong M8x30 | F12: cái | G12: 8 | H12: N/A | I12: N/A | J12: N/A | L12: V | M12: 12000 | N12: 96000 | O12: Hoàng Hà | P12: -Giá trí mua đang vượt dự toán - PTM không nắm được vật tư phụ kiện còn phát sinh hàng không - Thông báo tới SALE để khách hàng hỗ trợ thêm chi phí
A13: I90-C116 | B13: Ecu | C13: M20 | D13: Mạ kẽm 8.8 | E13: Bulong M8x50 | F13: cái | G13: 8 | H13: N/A | I13: N/A | J13: N/A | L13: V | M13: 2900 | N13: 23200 | O13: Hoàng Hà
A14: I90-C127 | B14: Long đen phẳng | C14: M20 | D14: Mạ kẽm 8.8 | E14: Bulong M10x20 | F14: cái | G14: 16 | H14: N/A | I14: N/A | J14: N/A | L14: V | M14: 1050 | N14: 16800 | O14: Hoàng Hà
A15: I90-C50 | B15: Bu lông ren suốt | C15: M24*110 | D15: Mạ kẽm 8.8 | E15: Bulong M10x30 | F15: cái | G15: 24 | H15: N/A | I15: N/A | J15: N/A | L15: V | M15: 20800 | N15: 499200 | O15: Hoàng Hà
A16: I90-C60 | B16: Ecu | C16: M24 | D16: Mạ kẽm 8.8 | E16: Bulong M10x40 | F16: cái | G16: 24 | H16: N/A | I16: N/A | J16: N/A | L16: V | M16: 4800 | N16: 115200 | O16: Hoàng Hà
A17: I90-C72 | B17: Long đen phẳng | C17: M24 | D17: Mạ kẽm 8.8 | E17: Bulong M10x50 | F17: cái | G17: 48 | H17: N/A | I17: N/A | J17: N/A | L17: V | M17: 1150 | N17: 55200 | O17: Hoàng Hà
A18: I90-C93 | B18: Dây chằng hàng | C18: D50 | D18: Vải | E18: Bulong M12x40 | F18: met | G18: 1000 | H18: N/A | I18: N/A | J18: N/A | L18: V | M18: 5830 | N18: 5830000 | O18: Hoàng Hà
A19: I90-C93 | B19: Dây chằng hàng | C19: D50 | D19: Vải | E19: Bulong M12x40 | F19: cái | G19: 600 | H19: N/A | I19: N/A | J19: N/A | L19: V | M19: 5830 | N19: 3498000 | O19: Hoàng Hà
A20: I90-C94 | B20: Khóa dây chằng hàng | C20: D50 | D20: Thép mạ | E20: Bulong M12x70 | F20: cái | G20: 200 | H20: N/A | I20: N/A | J20: N/A | L20: V | M20: 36000 | N20: 7200000 | O20: Hoàng Hà
A21: I90-C94 | B21: Khóa dây chằng hàng | C21: D50 | D21: Thép mạ | E21: Bulong M12x80 | F21: cái | G21: 200 | H21: N/A | I21: N/A | J21: N/A | L21: V | M21: 36000 | N21: 7200000 | O21: Hoàng Hà
B22: Đơn giá tổng hợp
A23: II | B23: Khối lượng dự kiến giao (Kg )/ Estimated weight (Kg):
A24: 1 | B24: … | C24: kg
A25: 2 | B25: …
A26: III | B26: Tiến độ/ Schedule | C26: Bắt đầu/ Start | D26: Kết thúc/ Finish
A27: 1 | B27: ….
A29: IV | B29: Nhân lực/ ManPower
A30: 1 | B30: Thợ Pha cắt / Thợ sắt / Thợ hàn / …
B31: ….
A32: V | B32: Yêu cầu kỹ thuật: Tham chiếu các tài liệu đính kèm/ Technical requirement – refer to document attached
B33: Xếp hạng | M33: 1
A34: Ghi Chú: Vật tư đóng kiện dự án 090 tính tiền theo khối lượng thực tế, PTM tiến hành mua hàng
A35: NGƯỜI ĐỀ NGHỊ/ RECOMMENDATION BY: | C35: NGƯỜI KIỂM TRA/ DEPARTMENT HEAD CHECK BY: | G35: APPROVED BY: PHÊ DUYỆT
G36: Nguyễn Quang Vinh | I36: Hoàng Ngọc Bằng | L36: Đoàn Văn Toàn

Sheet Vật tư đóng kiện Hoàng hà 090
A1: BID ANALYSIS - GIẢI TRÌNH MUA SẮM/ĐẤU THẦU
A3: Project | B3: PROJECT No/ Dự án: 25-BRA-I-090
A4: Dự án
A5: Subject | B5: Cung cấp vật tư đóng kiện dự án 090
A6: Chủ đề
A8: No. | B8: CONTENT | C8: Phạm vi công việc | H8: Dự toán | K8: Đã mua | L8: Đơn vị cung cấp chào giá (vnđ) | O8: Lựa chọn | P8: Ghi chú
A9: Item | B9: Description/ Chi tiết | C9: Profile/ Vật tư | D9: Grade/ Mác vật liệu | E9: Mặt hàng | F9: ĐVT | G9: Số lượng | H9: Khối lượng/ Số lượng | I9: Đơn giá (vnd) | J9: Thành tiền (vnd) | K9: Thành tiền (vnd) | L9: Hoàng Hà
L10: Phạm vi | M10: Đơn giá (VND) | N10: Thành Tiền (Không có VAT)
A11: Tổng | H11: N/A | I11: N/A | J11: ='DT04 (TM) 1 '!L17 -> 2538751590 | K11: ='Tổng hợp'!J16 -> 4.2279793e+09 | N11: =SUM(N12:N66) -> 57863610 | P11: =J11-K11-N11 -> -1.7470913e+09
A12: I90-C32 | B12: Bu lông ren suốt | C12: M16*50 | D12: Mạ kẽm 8.8 | E12: Bulong M8x30 | F12: PSC | G12: 788 | H12: N/A | I12: N/A | J12: N/A | L12: V | M12: 4600 | N12: =M12*G12 -> 3624800 | O12: Hoàng Hà | P12: -Giá trí mua đang vượt dự toán - PTM không nắm được vật tư phụ kiện còn phát sinh hàng không - Thông báo tới SALE để khách hàng hỗ trợ thêm chi phí
A13: I90-C33 | B13: Bu lông ren suốt | C13: M16*60 | D13: Mạ kẽm 8.8 | E13: Bulong M8x50 | F13: PSC | G13: 372 | H13: N/A | I13: N/A | J13: N/A | L13: V | M13: 5250 | N13: =M13*G13 -> 1953000 | O13: Hoàng Hà
A14: I90-C35 | B14: Bu lông ren suốt | C14: M16*70 | D14: Mạ kẽm 8.8 | E14: Bulong M10x20 | F14: PSC | G14: 48 | H14: N/A | I14: N/A | J14: N/A | L14: V | M14: 5850 | N14: =M14*G14 -> 280800 | O14: Hoàng Hà
A15: I90-C36 | B15: Bu lông ren suốt | C15: M16*80 | D15: Mạ kẽm 8.8 | E15: Bulong M10x30 | F15: PSC | G15: 36 | H15: N/A | I15: N/A | J15: N/A | L15: V | M15: 6500 | N15: =M15*G15 -> 234000 | O15: Hoàng Hà
A16: I90-C37 | B16: Bu lông ren suốt | C16: M16*90 | D16: Mạ kẽm 8.8 | E16: Bulong M10x40 | F16: PSC | G16: 24 | H16: N/A | I16: N/A | J16: N/A | L16: V | M16: 7100 | N16: =M16*G16 -> 170400 | O16: Hoàng Hà
A17: I90-C41 | B17: Bu lông ren suốt | C17: M20*50 | D17: Mạ kẽm 8.8 | E17: Bulong M10x50 | F17: PSC | G17: 48 | H17: N/A | I17: N/A | J17: N/A | L17: V | M17: 8150 | N17: =M17*G17 -> 391200 | O17: Hoàng Hà
A18: I90-C42 | B18: Bu lông ren suốt | C18: M20*55 | D18: Mạ kẽm 8.8 | E18: Bulong M12x40 | F18: PSC | G18: 213 | H18: N/A | I18: N/A | J18: N/A | L18: V | M18: 9000 | N18: =M18*G18 -> 1917000 | O18: Hoàng Hà
A19: I90-C44 | B19: Bu lông ren suốt | C19: M20*60 | D19: Mạ kẽm 8.8 | E19: Bulong M12x40 | F19: PSC | G19: 272 | H19: N/A | I19: N/A | J19: N/A | L19: V | M19: 9000 | N19: =M19*G19 -> 2448000 | O19: Hoàng Hà
A20: I90-C46 | B20: Bu lông ren suốt | C20: M20*70 | D20: Mạ kẽm 8.8 | E20: Bulong M12x70 | F20: PSC | G20: 192 | H20: N/A | I20: N/A | J20: N/A | L20: V | M20: 9900 | N20: =M20*G20 -> 1900800 | O20: Hoàng Hà
A21: I90-C48 | B21: Bu lông ren suốt | C21: M24*100 | D21: Mạ kẽm 8.8 | E21: Bulong M12x80 | F21: PSC | G21: 120 | H21: N/A | I21: N/A | J21: N/A | L21: V | M21: 19400 | N21: =M21*G21 -> 2328000 | O21: Hoàng Hà
A22: I90-C50 | B22: Bu lông ren suốt | C22: M24*110 | D22: Mạ kẽm 8.8 | E22: Bulong M16x40 | F22: PSC | G22: 48 | H22: N/A | I22: N/A | J22: N/A | L22: V | M22: 20800 | N22: =M22*G22 -> 998400 | O22: Hoàng Hà
A23: I90-C52 | B23: Bu lông ren suốt | C23: M24*90 | D23: Mạ kẽm 8.8 | E23: Bulong M16x50 | F23: PSC | G23: 120 | H23: N/A | I23: N/A | J23: N/A | L23: V | M23: 17900 | N23: =M23*G23 -> 2148000 | O23: Hoàng Hà
A24: I90-C54 | B24: Bu lông ren suốt | C24: M30*120 | D24: Mạ kẽm 8.8 | E24: Bulong M16x50 | F24: PSC | G24: 96 | H24: N/A | I24: N/A | J24: N/A | L24: V | M24: 46000 | N24: =M24*G24 -> 4416000 | O24: Hoàng Hà
... A66: I90-C139 | B66: Thanh ren | C66: M20*1000 | D66: Mạ kẽm 8.8 | E66: Vòng đệm phẳng rộng M20 | F66: PSC | G66: 12 | H66: N/A | I66: N/A | J66: N/A | L66: V | M66: 13700 | N66: =M66*G66 -> 164400 | O66: Hoàng Hà
B67: Đơn giá tổng hợp
A68: II | B68: Khối lượng dự kiến giao (Kg )/ Estimated weight (Kg):
A69: 1 | B69: … | C69: kg
A70: 2 | B70: …
A71: III | B71: Tiến độ/ Schedule | C71: Bắt đầu/ Start | D71: Kết thúc/ Finish
A72: 1 | B72: ….
A74: IV | B74: Nhân lực/ ManPower
A75: 1 | B75: Thợ Pha cắt / Thợ sắt / Thợ hàn / …
B76: ….
A77: V | B77: Yêu cầu kỹ thuật: Tham chiếu các tài liệu đính kèm/ Technical requirement – refer to document attached
B78: Xếp hạng | M78: 1
A79: Ghi Chú: Vật tư đóng kiện dự án 090 tính tiền theo khối lượng thực tế, PTM tiến hành mua hàng
A80: NGƯỜI ĐỀ NGHỊ/ RECOMMENDATION BY: | C80: NGƯỜI KIỂM TRA/ DEPARTMENT HEAD CHECK BY: | G80: APPROVED BY: PHÊ DUYỆT
G81: Nguyễn Quang Vinh | I81: Hoàng Ngọc Bằng | L81: Đoàn Văn Toàn

Sheet DT04 (TM) 1 
D1: CÔNG TY CỔ PHẦN CÔNG NGHIỆP NẶNG IBS IBS HEAVY INDUSTRY JOINT STOCK COMPANY Add.: KM6, Quốc lộ 5, Phường Hồng Bàng, Thành phố Hải Phòng
A2: BẢNG DỰ TOÁN CHI TIẾT VẬT TƯ
A3: Mẫu số: QT30-DT04 | M3: Mua sắm/ Ordered, Puchased (Đến hiện tại/ Up to now) | U3: THIẾT KẾ/ MUA SẮM THỰC TẾ
A4: STT | B4: Nhóm vật tư | C4: Mã vật tư | D4: Danh mục vật tư | E4: Đơn vị tính | F4: Mác vật liệu | G4: Quy cách | J4: Khối lượng/ Số lượng | K4: Đơn giá (vnd) | L4: Thành tiền (vnd) | M4: Hàng mua thêm | O4: Hàng tồn | Q4: Tổng Giá trị đã mua/ Total Cost (VND) | R4: Đânh giá | S4: Tỷ lệ | T4: Ghi chú | U4: Khối lượng | V4: Giá trị | W4: Chênh lệch | X4: Ghi chú
G5: Dài | H5: Rộng | I5: Dày | M5: Khối lượng/ Weight (Kg) | N5: Số lượng/ Q'ty (M/M2//PSC) | O5: Khối lượng/ Weight (Kg/N/A) Materials available at the factory | P5: Số lượng/ Q'ty (M/M2/PSC) Materials available at the factory
A6: A | B6: VTC | D6: Vật tư | L6: =SUM(L7:L26) -> 3.9012967e+10 | R6: =IF(L6>Q6," OKE MUA TIẾP","BÁO CÁO BOM") -> OKE MUA TIẾP
A7: 1 | D7: Vật tư chính | E7: kg | R7: =IF(L7>Q7," OKE MUA TIẾP","BÁO CÁO BOM") -> BÁO CÁO BOM
A8: 1.1 | D8: Thép carbon | E8: kg | J8: 1225.166 | L8: 2.6838359e+10 | M8: ='Tổng hợp'!F14 -> 1371496.8 | N8: ='Tổng hợp'!G14 -> 33222.763 | O8: ='Tổng hợp'!H14 -> 11796.06 | P8: ='Tổng hợp'!I14 -> 141.9749 | Q8: ='Tổng hợp'!J14 -> 2.8199093e+10 | R8: =IF(L8>Q8," OKE MUA TIẾP","BÁO CÁO BOM") -> BÁO CÁO BOM
A9: 1.2 | D9: Thép stainless | E9: kg | J9: 241.912
A10: 1.3 | D10: Tấm gratting nhựa | E10: kg | J10: 120 | L10: 537408000
A11: 1.4 | D11: Bảo ôn | J11: 10245.516
A12: 1.5 | D12: Các loại vật tư thép khác (cấp công trường | E12: kg
A13: 1.6 | D13: Bolt các loại, phụ kiện, gioăng,... | E13: kg | L13: 1.703349e+09 | M13: ='Tổng hợp'!F15 -> 174616.5 | N13: ='Tổng hợp'!G15 -> 169496.55 | O13: ='Tổng hợp'!H15 -> 6861.4896 | P13: ='Tổng hợp'!I15 -> 14559.671 | Q13: ='Tổng hợp'!J15 -> 4.9493339e+09 | R13: =IF(L13>Q13," OKE MUA TIẾP","BÁO CÁO BOM") -> BÁO CÁO BOM
A14: 2 | D14: Vật tư sơn
A15: 2.1 | D15: Vật tư sơn các loại. dung môi | J15: 8766.274 | L15: 1.615417e+09 | O15: ='Vật tư sơn BRA090'!AE7 -> 8374.56 | Q15: ='Vật tư sơn BRA090'!AH7 -> 2346421600 | R15: =IF(L15>Q15," OKE MUA TIẾP","BÁO CÁO BOM") -> BÁO CÁO BOM
A17: 3 | D17: Vật tư đóng kiện, biện pháp | E17: kg | L17: =SUM(L18:L20) -> 2538751590 | M17: ='Tổng hợp'!F16 -> 174616.5 | N17: ='Tổng hợp'!G16 -> 48456.55 | O17: ='Tổng hợp'!H16 -> 6861.4896 | P17: ='Tổng hợp'!I16 -> 14559.671 | Q17: ='Tổng hợp'!J16 -> 4.2279793e+09 | R17: =IF(L17>Q17," OKE MUA TIẾP","BÁO CÁO BOM") -> BÁO CÁO BOM
A18: 3.1 | D18: Vật tư biện pháp | L18: 839587140
A19: 3.2 | D19: Vật tư đóng kiện | L19: 3.998034e+08
A20: 3.3 | D20: Bạt che phủ các loại | E20: kg | L20: 1299361050
A21: 4 | D21: Vật tư tiêu hao
A22: 4.1 | D22: Vật liệu hàn | L22: 1652821140 | O22: ='Vat lieu han -BRA090'!AI7 -> 12225 | Q22: ='Vat lieu han -BRA090'!AL7 -> 775765000 | R22: =IF(L22>Q22," OKE MUA TIẾP","BÁO CÁO BOM") -> OKE MUA TIẾP | S22: lấy giữ liệu của kho xuất cho chính xác
A23: 4.2 | D23: Vật tư phụ (hàn), khí công nghiệp | L23: 1.1033447e+09
A24: 4.3 | D24: Đá mài các loại | L24: 1.6345848e+08
A25: 4.4 | D25: Hạt mài | L25: 175325480
A26: 5 | D26: Vật tư khác | L26: 145981218
A27: B | D27: Nhân công trực tiếp | J27: =SUM(J28:J36) -> 21590.066 | L27: =SUM(L28:L36) -> 2.3676403e+10
A28: 1 | D28: Pha cắt | J28: 1362.154 | L28: 1572005500
A29: 2 | D29: Lốc, sấn | J29: 573.388 | L29: 997070000
A30: 3 | D30: Gá hàn hoàn thiện | J30: 1362.154 | L30: 13134527000
A31: 4 | D31: Tổ hợp thử | J31: 1332.678 | L31: 3314816000
A32: 5 | D32: Thử chức năng | J32: 824.062 | L32: 1150986000
A33: 6 | D33: Làm sạch, sơn, rửa axit | J33: 13470.274 | L33: 869150550
A34: 7 | D34: Đóng kiện, giao hàng | J34: 1332.678 | L34: 9.328746e+08
A35: 8 | D35: Vận chuyển | J35: 1332.678 | L35: 1.999017e+08
A36: 9 | D36: Nhân công dự phòng | L36: 1.5050721e+09
A37: C | D37: Thầu phụ, dịch vụ thuê ngoài | L37: =SUM(L38:L45) -> 10721526300
A38: 1 | D38: Kiểm tra NDT, kiểm tra mẫu, quy trình | L38: 732972900
A39: 2 | D39: Mạ kẽm nhúng nóng | J39: 74 | L39: 888000000
A40: 3 | D40: Gia công cơ khí | J40: 602.062 | L40: 2500000000
A41: 4 | D41: Bảo ôn | J41: 10245.516 | L41: 4610482200
...

Sheet Vat lieu han -BRA090
A1: THEO DÕI VẬT TƯ DỰ ÁN/ MATERIAL CONTROL LOG | E1: Thời gian nộp bảng cập nhật:
A2: Tên dự án/ Project no.:25-SHI-I-084 | E2: - Trong ngày khi có biến động.
A3: Cập nhật ngày/ Update to: | E3: - Báo cáo hàng tuần vào 16:30 mỗi chiều thứ 2.
A4: Item/ STT | B4: Description/ Chi tiết | C4: Unit/ Đơn vị | D4: Current Ordered/Dự trù lần 1 (Ngà 2/6/2025 ) | F4: Current Ordered/Dự trù lần 2 (Ngày 11/8/2025 ) | H4: Current Ordered/Dự trù lần 3 (Ngày 19/8/2025 | J4: Current Ordered/Dự trù lần 3 (Ngày6/9/2025 | L4: Current Ordered/Dự trù lần 4 (Ngày 25/9/2025 | N4: Current Ordered/Dự trù lần 5 (Ngày 26/9/2025 | P4: Current Ordered/Dự trù lần 6 (Ngày 4/10/2025 | R4: Total Ordered/Tổng dự trù | T4: Remarks/ Ghi chú | U4: Tận dụng tồn kho/ Remain | Z4: Khối lượng phải mua sắm/ total order | AB4: Ngày bàn giao vật tư/ Material avaiable for hand over date | AC4: VẬT TƯ TRONG NƯỚC | AN4: ĐÃ MUA TRONG NƯỚC | AP4: QC Nghiệm thu | AT4: Remarks/ Ghi chú
D5: Q.Ty/ S.Lượng | E5: Weight/ K.Lượng (Kg) | F5: Q.Ty/ S.Lượng | G5: Weight/ K.Lượng (Kg) | H5: Q.Ty/ S.Lượng | I5: Weight/ K.Lượng (Kg) | J5: Q.Ty/ S.Lượng | K5: Weight/ K.Lượng (Kg) | L5: Q.Ty/ S.Lượng | M5: Weight/ K.Lượng (Kg) | N5: Q.Ty/ S.Lượng | O5: Weight/ K.Lượng (Kg) | P5: Q.Ty/ S.Lượng | Q5: Weight/ K.Lượng (Kg) | R5: Q.Ty/ S.Lượng | S5: Weight/ K.Lượng (Kg) | U5: Report No. | V5: Q.Ty/ S.Lượng | W5: Weight/ K.Lượng (Kg) | X5: Ngày nghiệm thu ACC | Y5: Remarks/ Ghi chú | Z5: Q.Ty/ S.Lượng | AA5: Weight/ K.Lượng (Kg) | AC5: Số Hợp đồng / Contract No | AD5: Nhà cung cấp/ Vendor | AE5: Profile/ Vật tư | AF5: Grade/ Mác vật liệu | AG5: Contract weight ( K.Lượng theo HĐ) | AH5: Ngày ký HD/ Contract date | AI5: S.Lượng giao hàng thực tế/ Handover Q'ty | AJ5: K.Lượng giao hàng thực tế// Handover weight | AK5: Đơn giá / Unit Price (Not VAT) | AL5: Tổng tiền (VNĐ) | AM5: Bàn giao sản xuất/ Handover to Product | AN5: Q.Ty/ S.Lượng | AO5: Weight/ K.Lượng (Kg) | AP5: Report No. | AQ5: Inspection date | AR5: Khối lượng nghiệm thu đạt/ Weight Acc. Inspection | AS5: Results
A6: 1 | B6: =A6+1 -> 2 | C6: 2 | D6: =C6+1 -> 3 | E6: 3 | F6: =E6+1 -> 4 | G6: 4 | H6: =G6+1 -> 5 | I6: 5 | J6: =I6+1 -> 6 | K6: 5 | L6: =K6+1 -> 6 | M6: 5 | N6: =M6+1 -> 6 | O6: 5 | P6: =O6+1 -> 6 | Q6: 5 | R6: =I6+1 -> 6 | S6: 6 | T6: =S6+1 -> 7 | U6: 7 | V6: =U6+1 -> 8 | W6: 8 | X6: =W6+1 -> 9 | Y6: 9 | Z6: =Y6+1 -> 10 | AA6: 10 | AB6: =AA6+1 -> 11 | AC6: 11 | AD6: =AC6+1 -> 12 | AE6: 12 | AF6: =AE6+1 -> 13 | AG6: 13 | AH6: =AG6+1 -> 14 | AI6: 14 | AJ6: =AI6+1 -> 15 | AK6: 15 | AL6: =AK6+1 -> 16 | AM6: 16 | AN6: =AM6+1 -> 17 | AO6: 17 | AP6: =AO6+1 -> 18 | AQ6: 18 | AR6: =AQ6+1 -> 19 | AS6: 19 | AT6: 34
A7: A. | B7: Main-Material / Vật tư chính | F7: =SUM(F8:F32) -> 1950 | G7: =SUM(G8:G32) -> 0 | H7: =SUM(H8:H32) -> 200 | I7: =SUM(I8:I32) -> 0 | J7: =SUM(J8:J32) -> 40 | K7: =SUM(K8:K32) -> 0 | L7: =SUM(L8:L32) -> 70 | M7: =SUM(M8:M32) -> 0 | ... S7: =SUM(S8:S32) -> 0 | V7: =SUM(V8:V32) -> 0 | W7: =SUM(W8:W32) -> 0 | Z7: =SUM(Z8:Z32) -> 13855 | AA7: =SUM(AA8:AA32) -> 0 | AC7: =SUM(AC8:AC32) -> 0 | AD7: =SUM(AD8:AD32) -> 0 | AE7: =SUM(AE8:AE32) -> 0 | AF7: =SUM(AF8:AF32) -> 0 | AG7: =SUM(AG8:AG32) -> 30435 | AI7: =SUM(AI8:AI32) -> 12225 | AJ7: =SUM(AJ8:AJ32) -> 0 | AL7: =SUM(AL8:AL32) -> 775765000 | AN7: =SUM(AN8:AN32) -> 11184 | AO7: =SUM(AO8:AO32) -> 15 | AP7: =SUM(AP8:AP32) -> 0 | AQ7: =SUM(AQ8:AQ32) -> 0 | AR7: =SUM(AR8:AR32) -> 0 | AS7: =SUM(AS8:AS32) -> 0 | AT7: =SUM(AT8:AT32) -> 0
A8: 1 | B8: Dây hàn E71T-1C( AWS A5.20) F1~1.2 | C8: kg | D8: 10000 | F8: 1500 | R8: =D8+F8+H8+J8+L8+N8+P8 -> 11500 | S8: =E8+G8 -> 0 | T8: Hyundai/Lincoln | Z8: =IF(R8>V8,R8-V8,"0") -> 11500 | AA8: =IF(S8>W8,S8-W8,"0") -> 0 | AB8: 17/05/2025, 27/5/20525 | AC8: Po/2025-05-16-0001 | AD8: Hai Tốt | AE8: COLC71CE21-1: Dây hàn lõi thuốc / Flux Wire Trade name: Lincoln 71C (AWS A5.20 E71T-1C) Dia: 1.2mm x 15kg/cuộn | AG8: =1065+23760 -> 24825 | AH8: 45793 | AI8: 10000 | AK8: 33000 | AL8: =+AI8*AK8 -> 330000000 | AN8: =SUMIF($A:$A,A8,$AI:$AI) -> 10014 | AO8: =SUMIF($A:$A,A8,$AJ:$AJ) -> 15
A9: 2 | B9: Dây hàn E308LT1-1 (AWS A5.22) F1~1.2 | C9: kg | D9: 100 | F9: 50 | R9: =D9+F9+H9+J9+L9+N9+P9 -> 150 | S9: =E9+G9 -> 0 | Z9: =IF(R9>V9,R9-V9,"0") -> 150 | AA9: =IF(S9>W9,S9-W9,"0") -> 0 | AB9: 45784 | AC9: HĐKT số. 02042025/HĐKT/IBSHI-TMV | AD9: Thương mại Việt | AE9: Dây hàn SW-309L Cored | AG9: 960 | AH9: 45793 | AI9: 500 | AK9: 240000 | AL9: =+AI9*AK9 -> 120000000 | AN9: =SUMIF($A:$A,A9,$AI:$AI) -> 500 | AO9: =SUMIF($A:$A,A9,$AJ:$AJ) -> 0
A10: 3 | B10: Dây hàn E309LT1-1 (AWS A5.22) F1~1.2 | C10: kg | D10: 500 | R10: =D10+F10+H10+J10+L10+N10+P10 -> 500 | S10: =E10+G10 -> 0 | Z10: =IF(R10>V10,R10-V10,"0") -> 500 | AA10: =IF(S10>W10,S10-W10,"0") -> 0 | AB10: 45784 | AC10: HĐKT số. 02042025/HĐKT/IBSHI-TMV | AD10: Thương mại Việt | AE10: Dây hàn SW-308L Cored | AG10: 240 | AH10: 45793 | AI10: 100 | AK10: 200000 | AL10: =+AI10*AK10 -> 20000000 | AN10: =SUMIF($A:$A,A10,$AI:$AI) -> 100 | AO10: =SUMIF($A:$A,A10,$AJ:$AJ) -> 0
A11: 4 | B11: Dây hàn E347T1-1/4 (AWS A5.22) F1~1.2 | C11: kg | D11: 500 | F11: 250 | R11: =D11+F11+H11+J11+L11+N11+P11 -> 750 | S11: =E11+G11 -> 0 | Z11: =IF(R11>V11,R11-V11,"0") -> 750 | AA11: =IF(S11>W11,S11-W11,"0") -> 0 | AB11: 45769 | AC11: HĐKT số. 03042025/HĐKT/IBSHI-NG | AD11: Nguyễn Gia | AG11: 3600 | AH11: 45750 | AI11: 500 | AK11: 260000 | AL11: =+AI11*AK11 -> 130000000 | AN11: =SUMIF($A:$A,A11,$AI:$AI) -> 500 | AO11: =SUMIF($A:$A,A11,$AJ:$AJ) -> 0
A12: 5 | B12: Que hàn Tig ER308L (AWS A5.9) F2~2.4 | C12: kg | D12: 20 | R12: =D12+F12+H12+J12+L12+N12+P12 -> 20 | S12: =E12+G12 -> 0 | Z12: =IF(R12>V12,R12-V12,"0") -> 20 | AA12: =IF(S12>W12,S12-W12,"0") -> 0 | AB12: 45784 | AC12: HĐKT số. 02042025/HĐKT/IBSHI-TMV | AD12: Thương mại Việt | AE12: Que hàn SMT-308L | AG12: 200 | AH12: 45793 | AI12: 20 | AK12: 200000 | AL12: =+AI12*AK12 -> 4000000 | AN12: =SUMIF($A:$A,A12,$AI:$AI) -> 20 | AO12: =SUMIF($A:$A,A12,$AJ:$AJ) -> 0
A13: 6 | B13: Que hàn Tig ER309L (AWS A5.9) F2~2.4 | C13: kg | D13: 50 | R13: =D13+F13+H13+J13+L13+N13+P13 -> 50 | S13: =E13+G13 -> 0 | Z13: =IF(R13>V13,R13-V13,"0") -> 50 | AA13: =IF(S13>W13,S13-W13,"0") -> 0 | AB13: 45784 | AC13: HĐKT số. 02042025/HĐKT/IBSHI-TMV | AD13: Thương mại Việt | AE13: Que hàn SMT-309L | AG13: 150 | AH13: 45793 | AI13: 50 | AK13: 252000 | AL13: =+AI13*AK13 -> 12600000 | AN13: =SUMIF($A:$A,A13,$AI:$AI) -> 50 | AO13: =SUMIF($A:$A,A13,$AJ:$AJ) -> 0
B14: Que hàn E7018A1 (AWS A5.5) F3.2 (Que CM78) | C14: kg | F14: 150 | P14: 110 | R14: =D14+F14+H14+J14+L14+N14+P14 -> 260 | S14: =E14+G14 -> 0 | Z14: =IF(R14>V14,R14-V14,"0") -> 260 | AA14: =IF(S14>W14,S14-W14,"0") -> 0 | AB14: 45912 | AC14: Nguyễn Gia | AD14: Nguyễn Gia | AE14: Que hàn T-347 2.4mm | AG14: 260 | AH14: 45894 | AI14: =60+200 -> 260 | AK14: 280000 | AL14: =+AI14*AK14 -> 72800000 | AN14: =SUMIF($A:$A,A14,$AI:$AI) -> 0 | AO14: =SUMIF($A:$A,A14,$AJ:$AJ) -> 0
B15: Que hàn KT421 (J), D3.2 | H15: 200 | R15: =D15+F15+H15+J15+L15+N15+P15 -> 200 | S15: =E15+G15 -> 0 | Z15: =IF(R15>V15,R15-V15,"0") -> 200 | AA15: =IF(S15>W15,S15-W15,"0") -> 0 | AB15: 45890 | AC15: Nguyễn Gia | AD15: Nguyễn Gia | AE15: Que hàn J-421 3.2mm | AG15: 200 | AH15: 45894 | AI15: 200 | AK15: 26000 | AL15: =+AI15*AK15 -> 5200000 | AN15: =SUMIF($A:$A,A15,$AI:$AI) -> 0 | AO15: =SUMIF($A:$A,A15,$AJ:$AJ) -> 0
B16: Que hàn Tig Inox Kiswwel T-347T ER (AWS A5.9) F2-2.4 | J16: 40 | R16: =D16+F16+H16+J16+L16+N16+P16 -> 40 | S16: =E16+G16 -> 0 | Z16: =IF(R16>V16,R16-V16,"0") -> 40 | AA16: =IF(S16>W16,S16-W16,"0") -> 0 | AB16: Về ngày 21/8/2025 và 12/9/2025 | AC16: Nguyễn Gia | AI16: 40 | AK16: 280000 | AL16: =+AI16*AK16 -> 11200000 | AN16: =SUMIF($A:$A,A16,$AI:$AI) -> 0 | AO16: =SUMIF($A:$A,A16,$AJ:$AJ) -> 0
B17: Que CM78 (chưa có PR) | R17: =D17+F17+H17+J17+L17+N17+P17 -> 0 | S17: =E17+G17 -> 0 | Z17: =IF(R17>V17,R17-V17,"0") -> 0 | AA17: =IF(S17>W17,S17-W17,"0") -> 0 | AB17: Về ngày 12/9/2025 | AC17: Nguyễn Gia | AI17: 200 | AK17: 135000 | AL17: =+AI17*AK17 -> 27000000 | AN17: =SUMIF($A:$A,A17,$AI:$AI) -> 0 | AO17: =SUMIF($A:$A,A17,$AJ:$AJ) -> 0
B18: Dây hàn lõi thuôc SC81B2 F1.2mm (chưa có PR) | N18: 315 | R18: =D18+F18+H18+J18+L18+N18+P18 -> 315 | S18: =E18+G18 -> 0 | Z18: =IF(R18>V18,R18-V18,"0") -> 315 | AA18: =IF(S18>W18,S18-W18,"0") -> 0 | AB18: Về ngày 20/9/2025 và 22/9/2025 | AC18: Thương Mại Việt | AI18: =105+210 -> 315 | AK18: 125000 | AL18: =+AI18*AK18 -> 39375000 | AN18: =SUMIF($A:$A,A18,$AI:$AI) -> 0 | AO18: =SUMIF($A:$A,A18,$AJ:$AJ) -> 0
B19: Dây hàn Mig SM -80G F1.2mm | C19: Hyundai | L19: 30 | R19: =D19+F19+H19+J19+L19+N19+P19 -> 30 | S19: =E19+G19 -> 0 | Z19: =IF(R19>V19,R19-V19,"0") -> 30 | AA19: =IF(S19>W19,S19-W19,"0") -> 0 | AB19: Về ngày 20/9/2025 | AC19: Thương Mại Việt | AI19: 30 | AK19: 78000 | AL19: =+AI19*AK19 -> 2340000 | AN19: =SUMIF($A:$A,A19,$AI:$AI) -> 0 | AO19: =SUMIF($A:$A,A19,$AJ:$AJ) -> 0
B20: Que hàn Tig T-80SB2 F2.4mm | C20: Hyundai | L20: 40 | R20: =D20+F20+H20+J20+L20+N20+P20 -> 40 | S20: =E20+G20 -> 0 | Z20: =IF(R20>V20,R20-V20,"0") -> 40 | AA20: =IF(S20>W20,S20-W20,"0") -> 0 | AB20: Về ngày 20/9/2025 | AC20: Thương Mại Việt | AI20: 10 | AK20: 125000 | AL20: =+AI20*AK20 -> 1250000 | AN20: =SUMIF($A:$A,A20,$AI:$AI) -> 0 | AO20: =SUMIF($A:$A,A20,$AJ:$AJ) -> 0
R21: =D21+F21+H21+J21+L21+N21+P21 -> 0 | S21: =E21+G21 -> 0 | Z21: =IF(R21>V21,R21-V21,"0") -> 0 | AA21: =IF(S21>W21,S21-W21,"0") -> 0 | AN21: =SUMIF($A:$A,A21,$AI:$AI) -> 0 | AO21: =SUMIF($A:$A,A21,$AJ:$AJ) -> 0
R22: =D22+F22+H22+J22+L22+N22+P22 -> 0 | S22: =E22+G22 -> 0 | Z22: =IF(R22>V22,R22-V22,"0") -> 0 | AA22: =IF(S22>W22,S22-W22,"0") -> 0 | AN22: =SUMIF($A:$A,A22,$AI:$AI) -> 0 | AO22: =SUMIF($A:$A,A22,$AJ:$AJ) -> 0
R23: =D23+F23+H23+J23+L23 -> 0 | S23: =E23+G23 -> 0 | Z23: =IF(R23>V23,R23-V23,"0") -> 0 | AA23: =IF(S23>W23,S23-W23,"0") -> 0 | AN23: =SUMIF($A:$A,A23,$AI:$AI) -> 0 | AO23: =SUMIF($A:$A,A23,$AJ:$AJ) -> 0
R24: =D24+F24+H24+J24+L24 -> 0 | S24: =E24+G24 -> 0 | Z24: =IF(R24>V24,R24-V24,"0") -> 0 | AA24: =IF(S24>W24,S24-W24,"0") -> 0 | AN24: =SUMIF($A:$A,A24,$AI:$AI) -> 0 | AO24: =SUMIF($A:$A,A24,$AJ:$AJ) -> 0
R25: =D25+F25+H25+J25+L25 -> 0 | S25: =E25+G25 -> 0 | Z25: =IF(R25>V25,R25-V25,"0") -> 0 | AA25: =IF(S25>W25,S25-W25,"0") -> 0 | AN25: =SUMIF($A:$A,A25,$AI:$AI) -> 0 | AO25: =SUMIF($A:$A,A25,$AJ:$AJ) -> 0
R26: =D26+F26+H26+J26+L26 -> 0 | S26: =E26+G26 -> 0 | Z26: =IF(R26>V26,R26-V26,"0") -> 0 | AA26: =IF(S26>W26,S26-W26,"0") -> 0 | AN26: =SUMIF($A:$A,A26,$AI:$AI) -> 0 | AO26: =SUMIF($A:$A,A26,$AJ:$AJ) -> 0
R27: =D27+F27+H27+J27+L27 -> 0 | S27: =E27+G27 -> 0 | Z27: =IF(R27>V27,R27-V27,"0") -> 0 | AA27: =IF(S27>W27,S27-W27,"0") -> 0 | AN27: =SUMIF($A:$A,A27,$AI:$AI) -> 0 | AO27: =SUMIF($A:$A,A27,$AJ:$AJ) -> 0
R28: =D28+F28+H28+J28+L28 -> 0 | S28: =E28+G28 -> 0 | Z28: =IF(R28>V28,R28-V28,"0") -> 0 | AA28: =IF(S28>W28,S28-W28,"0") -> 0 | AN28: =SUMIF($A:$A,A28,$AI:$AI) -> 0 | AO28: =SUMIF($A:$A,A28,$AJ:$AJ) -> 0
R29: =D29+F29+H29+J29+L29 -> 0 | S29: =E29+G29 -> 0 | Z29: =IF(R29>V29,R29-V29,"0") -> 0 | AA29: =IF(S29>W29,S29-W29,"0") -> 0 | AN29: =SUMIF($A:$A,A29,$AI:$AI) -> 0 | AO29: =SUMIF($A:$A,A29,$AJ:$AJ) -> 0
R30: =D30+F30+H30+J30+L30 -> 0 | S30: =E30+G30 -> 0 | Z30: =IF(R30>V30,R30-V30,"0") -> 0 | AA30: =IF(S30>W30,S30-W30,"0") -> 0 | AN30: =SUMIF($A:$A,A30,$AI:$AI) -> 0 | AO30: =SUMIF($A:$A,A30,$AJ:$AJ) -> 0
R31: =D31+F31+H31+J31+L31 -> 0 | S31: =E31+G31 -> 0 | Z31: =IF(R31>V31,R31-V31,"0") -> 0 | AA31: =IF(S31>W31,S31-W31,"0") -> 0 | AN31: =SUMIF($A:$A,A31,$AI:$AI) -> 0 | AO31: =SUMIF($A:$A,A31,$AJ:$AJ) -> 0
R32: =D32+F32+H32+J32+L32 -> 0 | S32: =E32+G32 -> 0 | Z32: =IF(R32>V32,R32-V32,"0") -> 0 | AA32: =IF(S32>W32,S32-W32,"0") -> 0 | AN32: =SUMIF($A:$A,A32,$AI:$AI) -> 0 | AO32: =SUMIF($A:$A,A32,$AJ:$AJ) -> 0

Sheet Vật tư sơn BRA090
A1: THEO DÕI VẬT TƯ DỰ ÁN/ MATERIAL CONTROL LOG | E1: Thời gian nộp bảng cập nhật:
A2: Tên dự án/ Project no.:25-SHI-I-084 | E2: - Trong ngày khi có biến động.
A3: Cập nhật ngày/ Update to: | E3: - Báo cáo hàng tuần vào 16:30 mỗi chiều thứ 2.
A4: Item/ STT | B4: Description/ Chi tiết | C4: Unit/ Đơn vị | D4: Current Ordered/Dự trù lần 1 (Ngày29/7/2025) | F4: Current Ordered/Dự trù lần 2 (Ngày 16/8/2025 | H4: Current Ordered/Dự trù lần 3 (Ngày 8/11/2025) | J4: Current Ordered/Dự trù nagyf 15/11/2025 | L4: Current Ordered/Dự trù lần 4 (Ngày 10/12/2025) | N4: Total Ordered/Tổng dự trù | P4: Remarks/ Ghi chú | Q4: Tận dụng tồn kho/ Remain | V4: Khối lượng phải mua sắm/ total order | X4: Ngày bàn giao vật tư/ Material avaiable for hand over date | Y4: VẬT TƯ TRONG NƯỚC | AJ4: ĐÃ MUA TRONG NƯỚC | AL4: QC Nghiệm thu | AP4: Remarks/ Ghi chú
D5: Q.Ty/ S.Lượng | E5: Weight/ K.Lượng (Kg) | F5: Q.Ty/ S.Lượng | G5: Weight/ K.Lượng (Kg) | H5: Q.Ty/ S.Lượng | I5: Weight/ K.Lượng (Kg) | J5: Q.Ty/ S.Lượng | K5: Weight/ K.Lượng (Kg) | L5: Q.Ty/ S.Lượng | M5: Weight/ K.Lượng (Kg) | N5: Q.Ty/ S.Lượng | O5: Weight/ K.Lượng (Kg) | Q5: Report No. | R5: Q.Ty/ S.Lượng | S5: Weight/ K.Lượng (Kg) | T5: Ngày nghiệm thu ACC | U5: Remarks/ Ghi chú | V5: Q.Ty/ S.Lượng | W5: Weight/ K.Lượng (Kg) | Y5: Số Hợp đồng / Contract No | Z5: Nhà cung cấp/ Vendor | AA5: Profile/ Vật tư | AB5: Grade/ Mác vật liệu | AC5: Contract weight ( K.Lượng theo HĐ) | AD5: Ngày ký HD/ Contract date | AE5: S.Lượng giao hàng thực tế/ Handover Q'ty | AF5: K.Lượng giao hàng thực tế// Handover weight | AG5: Đơn giá / Unit Price (Not VAT) | AH5: Tổng tiền (VNĐ) | AI5: Bàn giao sản xuất/ Handover to Product | AJ5: Q.Ty/ S.Lượng | AK5: Weight/ K.Lượng (Kg) | AL5: Report No. | AM5: Inspection date | AN5: Khối lượng nghiệm thu đạt/ Weight Acc. Inspection | AO5: Results
A6: 1 | B6: =A6+1 -> 2 | C6: 2 | D6: =C6+1 -> 3 | E6: 3 | F6: =E6+1 -> 4 | G6: 4 | H6: =G6+1 -> 5 | I6: 5 | J6: =G6+1 -> 5 | K6: 5 | L6: =I6+1 -> 6 | M6: 5 | N6: =I6+1 -> 6 | O6: 6 | P6: =O6+1 -> 7 | Q6: 7 | R6: =Q6+1 -> 8 | S6: 8 | T6: =S6+1 -> 9 | U6: 9 | V6: =U6+1 -> 10 | W6: 10 | X6: =W6+1 -> 11 | Y6: 11 | Z6: =Y6+1 -> 12 | AA6: 12 | AB6: =AA6+1 -> 13 | AC6: 13 | AD6: =AC6+1 -> 14 | AE6: 14 | AF6: =AE6+1 -> 15 | AG6: 15 | AH6: =AG6+1 -> 16 | AI6: 16 | AJ6: =AI6+1 -> 17 | AK6: 17 | AL6: =AK6+1 -> 18 | AM6: 18 | AN6: =AM6+1 -> 19 | AO6: 19 | AP6: 34
