Workbook
Name \0: #REF!
Name \a: #N/A
Name \a: #N/A
Name \a: #N/A
Name \a: #REF!
Name \b: #N/A
Name \c: #N/A
Name \d: #N/A
Name \e: #N/A
Name \f: #N/A
Name \g: #N/A
Name \h: #N/A
Name \h: #N/A
Name \h: #N/A
Name \h: #REF!
Name \i: #N/A
Name \i: #N/A
Name \i: #N/A
Name \i: #REF!
Name \j: #N/A
Name \k: #N/A
Name \KWS123: #N/A
Name \m: #N/A
Name \m: #N/A
Name \m: #N/A
Name \m: #REF!
Name \n: #N/A
Name \p: #REF!
Name \s: #N/A
Name \s: #N/A
Name \s: #N/A
Name \s: #REF!
Name \t: #N/A
Name \v: #REF!
Name \w: #REF!
Name \z: #REF!
Name ______________SC2: #REF!
Name _____________MAC12: #REF!
Name _____________SC2: #REF!
Name ____________HE08: #REF!
Name ____________NO1: #REF!
Name ___________ddn600: #REF!
Name ___________HE1: #REF!
Name ___________sc1: #REF!
Name ___________SN3: #REF!
Name ___________TX1: #REF!
Name ___________VL100: #REF!
Name ___________VL200: #REF!
Name ___________VL250: #REF!
Name __________HE11: #REF!
Name __________nin190: #REF!
Name _________ddn600: #REF!
Name _________HE2: #REF!
Name _________ro1: #REF!
Name _________SN3: #REF!
Name _________TL1: #REF!
Name _________TX1: #REF!
Name _________VL100: #REF!
Name _________VL200: #REF!
Name _________VL250: #REF!

Sheet Vật tư keo 078 sửa chữa
A1: BID ANALYSIS - GIẢI TRÌNH MUA SẮM/ĐẤU THẦU
A3: Project | B3: PROJECT No/ Dự án: 24-VPI-I-078
A4: Dự án
A5: Subject | B5: Cung cấp vật tư keo dính chống cháy chịu nhiệt
A6: Chủ đề
A8: No. | B8: CONTENT | E8: Dự toán | H8: Đã mua | I8: Đơn vị cung cấp chào giá (vnđ) | L8: Lựa chọn | M8: Ghi chú
A9: Item | B9: Description/ Chi tiết | C9: ĐVT | D9: Số lượng | E9: Khối lượng/ Số lượng | F9: Đơn giá (vnd) | G9: Thành tiền (vnd) | H9: Thành tiền (vnd) | I9: VSAN
I10: Phạm vi | J10: Đơn giá (VND) | K10: Thành Tiền (Không có 8% VAT)
A11: Tổng | E11: N/A | F11: N/A | G11: N/A | H11: N/A | K11: =SUM(K12:K12) -> 17880000 | M11: =-K11 -> -17880000
A12: I78-A-173 | B12: HIGH TEMPERATURE ADHESIVE -20 ĐỘ C ĐẾN 1250 ĐỘ C | C12: Cái | D12: 6 | E12: N/A | F12: N/A | I12: V | J12: 2980000 | K12: =J12*D12 -> 17880000 | L12: VSAN | M12: -Vật tư theo yêu cầu của sản xuất/ không có trong dự toán
B13: Xếp hạng | J13: 1
A14: Ghi chú: PTM tiến hàng mua sắm để đảm bảo tiến độ
A15: NGƯỜI ĐỀ NGHỊ/ RECOMMENDATION BY: | C15: NGƯỜI KIỂM TRA/ DEPARTMENT HEAD CHECK BY: | G15: APPROVED BY: PHÊ DUYỆT
F16: Nguyễn Quang Vinh | I16: Hoàng Ngọc Bằng | L16: Đoàn Văn Toàn

Sheet Vật tư bolt vsan 3-3
A1: BID ANALYSIS - GIẢI TRÌNH MUA SẮM/ĐẤU THẦU
A3: Project | B3: PROJECT No/ Dự án: 24-VPI-I-078
A4: Dự án
A5: Subject | B5: Cung cấp vật tư Nut của VSAN 27-2
A6: Chủ đề
A8: No. | B8: CONTENT | E8: Dự toán | H8: Đã mua | I8: Đơn vị cung cấp chào giá (vnđ) | L8: Lựa chọn | M8: Ghi chú
A9: Item | B9: Description/ Chi tiết | C9: ĐVT | D9: Số lượng | E9: Khối lượng/ Số lượng | F9: Đơn giá (vnd) | G9: Thành tiền (vnd) | H9: Thành tiền (vnd) | I9: VSAN
I10: Phạm vi | J10: Đơn giá (VND/PSC) | K10: Thành Tiền (Không có 8% VAT)
A11: Tổng | E11: N/A | F11: N/A | G11: N/A | H11: N/A | K11: =SUM(K12:K12) -> 1071900 | M11: =-K11 -> -1071900
A12: I78-B-65 | B12: HEAVY HEX NUT 7/8"-9UNC-A194-2H | C12: Cái | D12: 54 | E12: N/A | F12: N/A | I12: V | J12: 19850 | K12: =J12*D12 -> 1071900 | L12: VSAN
A13: II | B13: Khối lượng dự kiến giao (Kg )/ Estimated weight (Kg):
A14: 1 | B14: …
A15: 2 | B15: …
A16: III | B16: Tiến độ/ Schedule
A17: 1 | B17: ….
A19: IV | B19: Nhân lực/ ManPower
A20: 1 | B20: Thợ Pha cắt / Thợ sắt / Thợ hàn / …
B21: ….
A22: V | B22: Yêu cầu kỹ thuật: Tham chiếu các tài liệu đính kèm/ Technical requirement – refer to document attached
B23: Xếp hạng | J23: 1
A24: Ghi chú: PTM tiến hàng mua sắm để đảm bảo tiến độ
A25: NGƯỜI ĐỀ NGHỊ/ RECOMMENDATION BY: | C25: NGƯỜI KIỂM TRA/ DEPARTMENT HEAD CHECK BY: | G25: APPROVED BY: PHÊ DUYỆT
F26: Nguyễn Quang Vinh | I26: Hoàng Ngọc Bằng | L26: Đoàn Văn Toàn

Sheet Vật tư gioang xalaco
A1: BID ANALYSIS - GIẢI TRÌNH MUA SẮM/ĐẤU THẦU
A3: Project | B3: PROJECT No/ Dự án: 24-VPI-I-078
A4: Dự án
A5: Subject | B5: Cung cấp vật tư MC Master cart
A6: Chủ đề
A8: No. | B8: CONTENT | E8: Dự toán | H8: Đã mua | I8: Đơn vị cung cấp chào giá (vnđ) | L8: Lựa chọn | M8: Ghi chú
A9: Item | B9: Description/ Chi tiết | C9: ĐVT | D9: Số lượng | E9: Khối lượng/ Số lượng | F9: Đơn giá (vnd) | G9: Thành tiền (vnd) | H9: Thành tiền (vnd) | I9: XALACO
I10: Phạm vi | J10: Đơn giá (VND) | K10: Thành Tiền (Không có 8% VAT)
A11: Tổng | E11: N/A | F11: N/A | G11: N/A | H11: N/A | K11: =SUM(K12:K12) -> 267827643 | M11: =-K11 -> -267827643
A12: 1 | B12: 1-1/2" overal witdh, 3/4" bubble width,25ft-8853-K26 (MC MasterCarr) | C12: Cuộn | D12: 9 | E12: N/A | F12: N/A | I12: V | J12: 29758627 | K12: =J12*D12 -> 267827643 | L12: XALACO | M12: Hàng mua theo yêu cầu của sản xuất
A13: II | B13: Khối lượng dự kiến giao (Kg )/ Estimated weight (Kg):
A14: 1 | B14: …
A15: 2 | B15: …
A16: III | B16: Tiến độ/ Schedule
A17: 1 | B17: ….
A19: IV | B19: Nhân lực/ ManPower
A20: 1 | B20: Thợ Pha cắt / Thợ sắt / Thợ hàn / …
B21: ….
A22: V | B22: Yêu cầu kỹ thuật: Tham chiếu các tài liệu đính kèm/ Technical requirement – refer to document attached
B23: Xếp hạng | J23: 1
A24: Ghi chú: PTM tiến hàng mua sắm để đảm bảo tiến độ
A25: NGƯỜI ĐỀ NGHỊ/ RECOMMENDATION BY: | C25: NGƯỜI KIỂM TRA/ DEPARTMENT HEAD CHECK BY: | G25: APPROVED BY: PHÊ DUYỆT
F26: Nguyễn Quang Vinh | I26: Hoàng Ngọc Bằng | L26: Đoàn Văn Toàn

Sheet 078
J1: THEO DÕI VẬT TƯ DỰ ÁN/ MATERIAL CONTROL LOG | O1: Hướng dẫn cập nhật thông tin: | S1: Thời gian nộp bảng cập nhật:
J2: Tên dự án/ Project no.: 24-VPI-I-078 | O2: - Chữ tô màu xanh: | Q2: Chưa cập nhật | S2: - Trong ngày khi có biến động. | CX2: H.Đồng Chuyến giao hàng số 1 | CZ2: H.Đồng Chuyến giao hàng số 2 | DB2: H.Đồng Chuyến giao hàng số 2 | DD2: H.Đồng Chuyến giao hàng số 2 | DF2: H.Đồng Chuyến giao hàng số 2 | DH2: H.Đồng Chuyến giao hàng số 2 | DJ2: H.Đồng Chuyến giao hàng số 2 | DL2: H.Đồng Chuyến giao hàng số 2 | DN2: H.Đồng Chuyến giao hàng số 2 | DP2: H.Đồng Chuyến giao hàng số 2 | DR2: H.Đồng Chuyến giao hàng số 2 | DT2: H.Đồng Chuyến giao hàng số 2 | DV2: H.Đồng Chuyến giao hàng số 3 | DX2: H.Đồng Chuyến giao hàng số 4 | DZ2: H.Đồng Chuyến giao hàng số 5
J3: Cập nhật ngày/ Update to: | L3: =TODAY() -> 46086 | O3: - Chữ tô màu đỏ: | Q3: Đã cập nhật mới | S3: - Báo cáo hàng tuần vào 16:30 mỗi chiều thứ 2. | AR3: =SUBTOTAL(9,AR8:AR332) -> 0 | AS3: =SUBTOTAL(9,AS8:AS332) -> 0 | AV3: =SUBTOTAL(9,AV8:AV332) -> 0 | AW3: =SUBTOTAL(9,AW8:AW332) -> 0
B4: Đánh giá (Thiếu/ Đủ/ Thừa) | J4: Item/ STT | K4: Description/ Chi tiết | L4: Profile/ Vật tư | M4: Grade/ Mác vật liệu | N4: Unit/ Đơn vị | O4: U.Weight/ Đ.Trọng (Kg/m2,m,pcs) | P4: Net Quantity/Số lượng tinh | R4: Current Ordered/Dự trù lần 0 (Ngày 06/1/2025) | T4: Current Ordered/Dự trù lần 1 (Ngày 14/2/2025) | V4: Current Ordered/Dự trù lần 2 (Ngày 08/4/2025) | X4: Current Ordered/Dự trù lần 3 (Ngày 10/4/2025) | Z4: Current Ordered/Dự trù lần 4 (Ngày 21/4/2025) | AB4: Current Ordered/Dự trù lần 5 (Ngày 23/5/2025) | AD4: Current Ordered/Dự trù lần 6 (Ngày 21/6/2025) | AF4: Current Ordered/Dự trù lần 7 (Ngày 3/7/2025) | AH4: Current Ordered/Dự trù lần 8 (Ngày 1/8/2025) | AJ4: Current Ordered/Dự trù lần 9 (Ngày 13/8/2025) | AL4: Current Ordered/Dự trù lần 10 (Ngày 25/10/2025) | AN4: Current Ordered/Dự trù lần 11 (Ngày 04/12/2025) | AP4: Current Ordered/Dự trù lần 12 (Ngày 05/1/2026) | AR4: Total Ordered/Tổng dự trù | AT4: Remarks/ Ghi chú | AU4: Tận dụng tồn kho/ Remain | AZ4: Khối lượng phải mua sắm/ total order | BB4: Ngày bàn giao vật tư/ Material avaiable for hand over date | BC4: VẬT TƯ TRONG NƯỚC | BN4: ĐÃ MUA TRONG NƯỚC | BP4: QC Nghiệm thu | BT4: Mua sắm nước ngoài/ Oversea purchase | CL4: ĐÃ MUA NHẬP KHẨU | CN4: Nghiệm thu | CR4: TỔNG ĐÃ MUA TRONG VÀ NGOÀI NƯỚC | CT4: So sánh với số lượng vật tư PR | CW4: Remarks/ Ghi chú | CX4: STACK TEMPLATE(ID1) | CZ4: BASE PLATE(ID2) | DB4: ER+FIELD CONECTTION(ID3) | DD4: BURNER DUCT(ID4) | DF4: DISTRIBUTION GRID(ID4) | DH4: INLET DUCT(ID4) | DJ4: SPOOL DUCT 2 & 3(ID4) | DL4: SPOOL DUCT 3 & 4(ID4) | DN4: SPOOL DUCT 4 & 5(ID4) | DP4: OUTLET DUCT(ID4) | DR4: OUTLET STACK(ID4) | DT4: PLATFORM(ID4) | DV4: PIPE SUPORT(ID5) | DX4: DRAIN PIPE(ID6) | DZ4: Small Bore Field Fabricated Bulk(ID7)
P5: Q.Ty/ S.Lượng | Q5: Weight/ K.Lượng (Kg) | R5: Q.Ty/ S.Lượng | S5: Weight/ K.Lượng (Kg) | T5: Q.Ty/ S.Lượng | U5: Weight/ K.Lượng (Kg) | V5: Q.Ty/ S.Lượng | W5: Weight/ K.Lượng (Kg) | X5: Q.Ty/ S.Lượng | Y5: Weight/ K.Lượng (Kg) | Z5: Q.Ty/ S.Lượng | AA5: Weight/ K.Lượng (Kg) | AB5: Q.Ty/ S.Lượng | AC5: Weight/ K.Lượng (Kg) | AD5: Q.Ty/ S.Lượng | AE5: Weight/ K.Lượng (Kg) | AF5: Q.Ty/ S.Lượng | AG5: Weight/ K.Lượng (Kg) | AH5: Q.Ty/ S.Lượng | AI5: Weight/ K.Lượng (Kg) | AJ5: Q.Ty/ S.Lượng | AK5: Weight/ K.Lượng (Kg) | AL5: Q.Ty/ S.Lượng | AM5: Weight/ K.Lượng (Kg) | AN5: Q.Ty/ S.Lượng | AO5: Weight/ K.Lượng (Kg) | AP5: Q.Ty/ S.Lượng | AQ5: Weight/ K.Lượng (Kg) | AR5: Q.Ty/ S.Lượng | AS5: Weight/ K.Lượng (Kg) | AU5: Report No. | AV5: Q.Ty/ S.Lượng | AW5: Weight/ K.Lượng (Kg) | AX5: Ngày nghiệm thu ACC | AY5: Remarks/ Ghi chú | AZ5: Q.Ty/ S.Lượng | BA5: Weight/ K.Lượng (Kg) | BC5: Số Hợp đồng / Contract No | BD5: Nhà cung cấp/ Vendor | BE5: Profile/ Vật tư | BF5: Grade/ Mác vật liệu | BG5: Contract weight ( K.Lượng theo HĐ) | BH5: Ngày ký HD/ Contract date | BI5: S.Lượng giao hàng thực tế/ Handover Q'ty | BJ5: K.Lượng giao hàng thực tế// Handover weight | BK5: Đơn giá / Unit Price (Not VAT) | BL5: Tổng tiền / Total Price (Not VAT) | BM5: Bàn giao sản xuất/ Handover to Product | BN5: Q.Ty/ S.Lượng | BO5: Weight/ K.Lượng (Kg) | BP5: Report No. | BQ5: Inspection date | BR5: Khối lượng nghiệm thu đạt/ Weight Acc. Inspection | BS5: Results | BT5: Số Hợp đồng / Contract No | BU5: Nhà cung cấp/ Vendor | BV5: Profile/ Vật tư | BW5: Grade/ Mác vật liệu | BX5: Weight/ Khối lượng (Kg) | BY5: Ngày ký HD/ Contract date | BZ5: Số lượng giao hàng thực tế/ Handover Q'ty | CA5: Khối lượng giao hàng thực tế/ Handover Q'ty | CB5: Đơn giá / Unit Price | CC5: Thành tiền Hợp đồng/ total | CD5: Ngày mở L/C/ LC issued date | CE5: Hàng đi từ cảng nước ngoài/ Export Port | CF5: Hàng Đến cảng HP (CIF)/ HaiPhong CIF | CG5: Ngày thanh toán / Payment date | CH5: Thủ tục hải quan, vận chuyển/ Paper work, local transportaion date | CI5: Ngày hàng về / Arived | CJ5: Ngày mời nghiệm thu / invice QC date | CK5: Bàn giao sản xuất/ Handover to Product | CL5: Q.Ty/ S.Lượng | CM5: Weight/ K.Lượng (Kg) | CN5: Report No. | CO5: Inspection date | CP5: Khối lượng nghiệm thu đạt/ Weight Acc. Inspection | CQ5: Results | CR5: Q.Ty/ S.Lượng | CS5: Weight/ K.Lượng (Kg) | CT5: Q.Ty/ S.Lượng | CU5: Weight/ K.Lượng (Kg) | CV5: Đánh giá (Thiếu/ Đủ/ Thừa) | CX5: Q'TY | CY5: WEIGHT | CZ5: Q'TY | DA5: WEIGHT | DB5: Q'TY | DC5: WEIGHT | DD5: Q'TY | DE5: WEIGHT | DF5: Q'TY | DG5: WEIGHT | DH5: Q'TY | DI5: WEIGHT | DJ5: Q'TY | DK5: WEIGHT | DL5: Q'TY | DM5: WEIGHT | DN5: Q'TY | DO5: WEIGHT | DP5: Q'TY | DQ5: WEIGHT | DR5: Q'TY | DS5: WEIGHT | DT5: Q'TY | DU5: WEIGHT | DV5: Q'TY | DW5: WEIGHT | DX5: Q'TY | DY5: WEIGHT | DZ5: Q'TY | EA5: WEIGHT
C6: Số lượng cần (M/M2) | E6: Đơn vị cung cấp | F6: Tiền cần cho phần hàng chưa nhận được hoặc chưa đặt hàng | G6: Xin chuyển đổi | H6: Note | I6: Kế hoạch/ ghi chú | J6: 1 | K6: 2 | L6: 3 | M6: 4 | N6: 5 | O6: 6 | P6: 7 | Q6: 8 | R6: 9 | S6: 10 | T6: 11 | U6: 12 | V6: 13 | W6: 14 | X6: 15 | Y6: 16 | AR6: 17 | AS6: 18 | AT6: 19 | AU6: 16 | AV6: 17 | AW6: 18 | AX6: 19 | AY6: 20 | AZ6: 21 | BA6: 22 | BB6: 23 | BC6: 24 | BD6: 25 | BE6: 26 | BF6: 27 | BG6: 28 | BH6: 29 | BI6: 30 | BJ6: 31 | BK6: 32 | BL6: 33 | BM6: 34 | BN6: 35 | BO6: 36 | BP6: 37 | BQ6: 38 | BR6: 39 | BS6: 40 | BT6: 41 | BU6: 42 | BV6: 43 | BW6: 44 | BX6: 45 | BY6: 46 | BZ6: 47 | CA6: 48 | CB6: 49 | CC6: 50 | CD6: 51 | CE6: 52 | CF6: 53 | CG6: 54 | CH6: 55 | CI6: 56 | CJ6: 57 | CK6: 58 | CL6: 59 | CM6: 60 | CN6: 61 | CO6: 62 | CP6: 63 | CQ6: 64 | CR6: 65 | CS6: 66 | CT6: 67 | CU6: 68 | CV6: 69 | CW6: 70
J7: A. | K7: Main-Material / Vật tư chính | AR7: =SUM(AR8:AR242) -> 42283.706 | AS7: =SUM(AS8:AS242) -> 688314.75 | AT7: =SUM(AT8:AT242) -> 0 | AU7: =SUM(AU8:AU242) -> 0 | AV7: =SUM(AV8:AV242) -> 819.85066 | AW7: =SUM(AW8:AW242) -> 34363.468 | AX7: =SUM(AX8:AX242) -> 0 | AY7: =SUM(AY8:AY242) -> 0 | ... CW7: =SUM(CW8:CW242) -> 0 | CY7: =+SUM(CY8:CY239) -> 946.00664 | DA7: =+SUM(DA8:DA239) -> 16062.753 | DC7: =+SUM(DC8:DC239) -> 9590.2057 | DE7: =+SUM(DE8:DE239) -> 107945 | DG7: =+SUM(DG8:DG239) -> 3996.3354 | DI7: =+SUM(DI8:DI239) -> 138107.64 | DK7: =+SUM(DK8:DK239) -> 17348.14 | DM7: =+SUM(DM8:DM239) -> 14757.32 | DO7: =+SUM(DO8:DO239) -> 14414.74 | DQ7: =+SUM(DQ8:DQ239) -> 13539.32 | DS7: =+SUM(DS8:DS239) -> 85632.2 | DU7: =+SUM(DU8:DU239) -> 200103.2 | DW7: =+SUM(DW8:DW239) -> 6938.85 | DY7: =+SUM(DY8:DY239) -> 1251.24 | EA7: =+SUM(EA8:EA239) -> 6926.6903
A8: =IF(J8=J7,"ok","Hiện") -> Hiện | B8: =CV8 -> Đủ | C8: =CT8 -> 0 | H8: Vật tư phụ | J8: I78-A-1 | K8: Đệm làm kín | L8: 5"_GASKET_#150_SORF | M8: CERAMIC_FIBER | N8: pcs | P8: 2 | R8: 2 | V8: =VLOOKUP(J8,[113]PR!$A:$S,15,0) -> 0 | W8: =VLOOKUP(J8,[113]PR!$A:$S,16,0) -> 0 | X8: =VLOOKUP(J8,[114]PR!$A:$U,17,0) -> 0 | Y8: =VLOOKUP(J8,[114]PR!$A:$U,18,0) -> 0 | Z8: 0 | AA8: 0 | AB8: 0 | AC8: 0 | AD8: 0 | AE8: 0 | AF8: 0 | AG8: 0 | AH8: 0 | AI8: 0 | AJ8: 0 | AK8: 0 | AL8: 0 | AM8: 0 | AP8: 0 | AQ8: 0 | AR8: =R8+T8+V8+X8+Z8+AB8+AD8+AF8+AH8+AJ8+AL8+AN8+AP8 -> 2 | AS8: =S8+U8+W8+Y8+AA8+AC8+AE8+AG8+AI8+AK8+AM8+AO8+AQ8 -> 0 | AT8: MUA CẤP I59 | AZ8: =IF(AR8>AV8,AR8-AV8,"0") -> 2 | BA8: =IF(AS8>AW8,AS8-AW8,"0") -> 0 | BB8: Done | BC8: Báo giá 8/1/2025 | BD8: Tam Đa | BE8: OD175 x ID114 , t=3mm | BF8: GASKET NON METALIC | BG8: N/A | BH8: 45665 | BI8: 2 | BJ8: N/A | BK8: 130000 | BL8: =BK8*BI8*1.1 -> 286000 | BM8: 45674 | BN8: =SUMIF($J:$J,J8,$BI:$BI) -> 2 | BO8: =SUMIF($J:$J,J8,$BJ:$BJ) -> 0 | BP8: ACC | CL8: =SUMIF($J:$J,J8,$BZ:$BZ) -> 0 | CM8: =SUMIF($J:$J,J8,$CA:$CA) -> 0 | CR8: =BN8+CL8 -> 2 | CS8: =BO8+CM8 -> 0 | CT8: =AZ8-CR8 -> 0 | CU8: =BA8-CS8 -> 0 | CV8: =IF(CT8<0,"Thừa",IF(CT8=0,"Đủ","Thiếu")) -> Đủ
A9: =IF(J9=J8,"ok","Hiện") -> Hiện | B9: =CV9 -> Đủ | C9: =CT9 -> 0 | H9: Vật tư phụ | J9: I78-A-2 | K9: Đệm làm kín | L9: 6"_GASKET_#150_SORF | M9: CERAMIC_FIBER | N9: pcs | P9: 11 | R9: 11 | V9: =VLOOKUP(J9,[113]PR!$A:$S,15,0) -> 0 | W9: =VLOOKUP(J9,[113]PR!$A:$S,16,0) -> 0 | X9: =VLOOKUP(J9,[114]PR!$A:$U,17,0) -> 0 | Y9: =VLOOKUP(J9,[114]PR!$A:$U,18,0) -> 0 | Z9: 0 | AA9: 0 | AB9: 0 | AC9: 0 | AD9: 0 | AE9: 0 | AF9: 0 | AG9: 0 | AH9: 0 | AI9: 0 | AJ9: 0 | AK9: 0 | AL9: 0 | AM9: 0 | AP9: 0 | AQ9: 0 | AR9: =R9+T9+V9+X9+Z9+AB9+AD9+AF9+AH9+AJ9+AL9+AN9+AP9 -> 11 | AS9: =S9+U9+W9+Y9+AA9+AC9+AE9+AG9+AI9+AK9+AM9+AO9+AQ9 -> 0 | AT9: MUA CẤP I59 | AZ9: =IF(AR9>AV9,AR9-AV9,"0") -> 11 | BA9: =IF(AS9>AW9,AS9-AW9,"0") -> 0 | BB9: Done | BC9: Báo giá 8/1/2025 | BD9: Tam Đa | BE9: OD196 x ID141.2 , t=3mm | BF9: GASKET NON METALIC | BG9: N/A | BH9: 45665 | BI9: 11 | BJ9: N/A | BK9: 155000 | BL9: =BK9*BI9*1.1 -> 1875500 | BM9: 45674 | BN9: =SUMIF($J:$J,J9,$BI:$BI) -> 11 | BO9: =SUMIF($J:$J,J9,$BJ:$BJ) -> 0 | BP9: ACC | CL9: =SUMIF($J:$J,J9,$BZ:$BZ) -> 0 | CM9: =SUMIF($J:$J,J9,$CA:$CA) -> 0 | CR9: =BN9+CL9 -> 11 | CS9: =BO9+CM9 -> 0 | CT9: =AZ9-CR9 -> 0 | CU9: =BA9-CS9 -> 0 | CV9: =IF(CT9<0,"Thừa",IF(CT9=0,"Đủ","Thiếu")) -> Đủ
A10: =IF(J10=J9,"ok","Hiện") -> Hiện | B10: =CV10 -> Đủ | C10: =CT10 -> 0 | H10: Vật tư phụ | J10: I78-A-3 | K10: Đệm làm kín | L10: 4"_GASKET_#150_SORF | M10: CERAMIC_FIBER | N10: pcs | P10: 3 | R10: 3 | V10: =VLOOKUP(J10,[113]PR!$A:$S,15,0) -> 0 | W10: =VLOOKUP(J10,[113]PR!$A:$S,16,0) -> 0 | X10: =VLOOKUP(J10,[114]PR!$A:$U,17,0) -> 0 | Y10: =VLOOKUP(J10,[114]PR!$A:$U,18,0) -> 0 | Z10: 0 | AA10: 0 | AB10: 0 | AC10: 0 | AD10: 0 | AE10: 0 | AF10: 0 | AG10: 0 | AH10: 0 | AI10: 0 | AJ10: 0 | AK10: 0 | AL10: 0 | AM10: 0 | AP10: 0 | AQ10: 0 | AR10: =R10+T10+V10+X10+Z10+AB10+AD10+AF10+AH10+AJ10+AL10+AN10+AP10 -> 3 | AS10: =S10+U10+W10+Y10+AA10+AC10+AE10+AG10+AI10+AK10+AM10+AO10+AQ10 -> 0 | AT10: MUA CẤP I59 | AZ10: =IF(AR10>AV10,AR10-AV10,"0") -> 3 | BA10: =IF(AS10>AW10,AS10-AW10,"0") -> 0 | BB10: Done | BC10: Báo giá 8/1/2025 | BD10: Tam Đa | BE10: OD222 x ID168 , t=3mm | BF10: GASKET NON METALIC | BG10: N/A | BH10: 45665 | BI10: 3 | BJ10: N/A | BK10: 180000 | BL10: =BK10*BI10*1.1 -> 594000 | BM10: 45674 | BN10: =SUMIF($J:$J,J10,$BI:$BI) -> 3 | BO10: =SUMIF($J:$J,J10,$BJ:$BJ) -> 0 | BP10: ACC | CL10: =SUMIF($J:$J,J10,$BZ:$BZ) -> 0 | CM10: =SUMIF($J:$J,J10,$CA:$CA) -> 0 | CR10: =BN10+CL10 -> 3 | CS10: =BO10+CM10 -> 0 | CT10: =AZ10-CR10 -> 0 | CU10: =BA10-CS10 -> 0 | CV10: =IF(CT10<0,"Thừa",IF(CT10=0,"Đủ","Thiếu")) -> Đủ
A11: =IF(J11=J10,"ok","Hiện") -> Hiện | B11: =CONCATENATE(CV11," Dùng cùng mã A-8") -> Thiếu Dùng cùng mã A-8 | C11: =CT11 -> 1.93637 | H11: Thép đen | J11: I78-A-4 | K11: tôn tấm | L11: PL1.5x1250x2500 | M11: JIS G3101-SS400 | N11: m2 | O11: 11.775 | P11: 1.6838 | Q11: 19.826745 | T11: 1.93637 | U11: 22.800757 | V11: =VLOOKUP(J11,[113]PR!$A:$S,15,0) -> 0 | W11: =VLOOKUP(J11,[113]PR!$A:$S,16,0) -> 0 | X11: =VLOOKUP(J11,[114]PR!$A:$U,17,0) -> 0 | Y11: =VLOOKUP(J11,[114]PR!$A:$U,18,0) -> 0 | Z11: 0 | AA11: 0 | AB11: 0 | AC11: 0 | AD11: 0 | AE11: 0 | AF11: 0 | AG11: 0 | AH11: 0 | AI11: 0 | AJ11: 0 | AK11: 0 | AL11: 0 | AM11: 0 | AP11: 0 | AQ11: 0 | AR11: =R11+T11+V11+X11+Z11+AB11+AD11+AF11+AH11+AJ11+AL11+AN11+AP11 -> 1.93637 | AS11: =S11+U11+W11+Y11+AA11+AC11+AE11+AG11+AI11+AK11+AM11+AO11+AQ11 -> 22.800757 | AT11: REV2-A572-->SS400 khách hàng REV | AZ11: =IF(AR11>AV11,AR11-AV11,"0") -> 1.93637 | BA11: =IF(AS11>AW11,AS11-AW11,"0") -> 22.800757 | BB11: 45762 | BN11: =SUMIF($J:$J,J11,$BI:$BI) -> 0 | BO11: =SUMIF($J:$J,J11,$BJ:$BJ) -> 0 | CL11: =SUMIF($J:$J,J11,$BZ:$BZ) -> 0 | CM11: =SUMIF($J:$J,J11,$CA:$CA) -> 0 | CR11: =BN11+CL11 -> 0 | CS11: =BO11+CM11 -> 0 | CT11: =AZ11-CR11 -> 1.93637 | CU11: =BA11-CS11 -> 22.800757 | CV11: =IF(CT11<0,"Thừa",IF(CT11=0,"Đủ","Thiếu")) -> Thiếu | CZ11: 1.6838 | DA11: 19.826745
A12: =IF(J12=J11,"ok","Hiện") -> Hiện | B12: =CONCATENATE(CV12," TK báo đủ") -> Thiếu TK báo đủ | C12: =CT12 -> 7.1458621 | E12: Thiếu 1 tờ mua thêm/ kiêm tra lại hàng tồn | H12: Thép trắng nhập | I12: Tấm PL1,5mmx1.22m*2.44m= 84 Tờ | J12: I78-A-5 | K12: tôn tấm( % C min 0.04%) | L12: PL1.5x1250x2500 | M12: JIS G4312 SUH409 | N12: m2 | O12: 11.55 | P12: 463.10156 | Q12: 5348.8231 | T12: 504.22026 | U12: 5823.744 | V12: =VLOOKUP(J12,[113]PR!$A:$S,15,0) -> 0 | W12: =VLOOKUP(J12,[113]PR!$A:$S,16,0) -> 0 | X12: =VLOOKUP(J12,[114]PR!$A:$U,17,0) -> 0 | Y12: =VLOOKUP(J12,[114]PR!$A:$U,18,0) -> 0 | Z12: 0 | AA12: 0 | AB12: 0 | AC12: 0 | AD12: 0 | AE12: 0 | AF12: 0 | AG12: 0 | AH12: 0 | AI12: 0 | AJ12: 0 | AK12: 0 | AL12: 0 | AM12: 0 | AP12: 0 | AQ12: 0 | AR12: =R12+T12+V12+X12+Z12+AB12+AD12+AF12+AH12+AJ12+AL12+AN12+AP12 -> 504.22026 | AS12: =S12+U12+W12+Y12+AA12+AC12+AE12+AG12+AI12+AK12+AM12+AO12+AQ12 -> 5823.744 | AV12: =1.22*2.44 * 83 -> 247.0744 | AW12: =AV12*O12 -> 2853.7093 | AZ12: =IF(AR12>AV12,AR12-AV12,"0") -> 257.14586 | BA12: =IF(AS12>AW12,AS12-AW12,"0") -> 2970.0347 | BN12: =SUMIF($J:$J,J12,$BI:$BI) -> 0 | BO12: =SUMIF($J:$J,J12,$BJ:$BJ) -> 0 | BT12: EYANG-IBS/25048HP01 | BU12: EYANG | BV12: PL1.5 x 1250 x 2500mm (CR/2B) | BW12: Stainless Steel ASTM A240 TP409 - Plate | BX12: 2887.5 | BY12: 45873 | BZ12: =1.25*2.5*80 -> 250 | CA12: 2887.5 | CB12: 1.422 | CC12: =CB12*CA12 -> 4106.025 | CH12: 45797 | CI12: 45798 | CJ12: 45798 | CK12: 45798 | CL12: =SUMIF($J:$J,J12,$BZ:$BZ) -> 250 | CM12: =SUMIF($J:$J,J12,$CA:$CA) -> 2887.5 | CR12: =BN12+CL12 -> 250 | CS12: =BO12+CM12 -> 2887.5 | CT12: =AZ12-CR12 -> 7.1458621 | CU12: =BA12-CS12 -> 82.534708 | CV12: =IF(CT12<0,"Thừa",IF(CT12=0,"Đủ","Thiếu")) -> Thiếu | DB12: 99.877966 | DC12: 1176.0631 | DJ12: 118.63 | DK12: 1396.9 | DL12: 118.63 | DM12: 1396.9 | DN12: 117.1 | DO12: 1378.9
A13: =IF(J13=J12,"ok","Hiện") -> Hiện | B13: =CV13 -> Thừa | C13: =CT13 -> -0.4586548 | J13: I78-A-6 | K13: tôn tấm( % C min 0.04%) | L13: PL1.5x1250x2500 | M13: JIS.G4304_SUS304 | N13: m2 | O13: 11.895 | P13: 451.73984 | Q13: 5373.4454 | T13: 506.54135 | U13: 6025.3093 | V13: =VLOOKUP(J13,[113]PR!$A:$S,15,0) -> 0 | W13: =VLOOKUP(J13,[113]PR!$A:$S,16,0) -> 0 | X13: =VLOOKUP(J13,[114]PR!$A:$U,17,0) -> 0 | Y13: =VLOOKUP(J13,[114]PR!$A:$U,18,0) -> 0 | Z13: 0 | AA13: 0 | AB13: 0 | AC13: 0 | AD13: 0 | AE13: 0 | AF13: 0 | AG13: 0 | AH13: 0 | AI13: 0 | AJ13: 0 | AK13: 0 | AL13: 8.625 | AM13: 102.59437 | AP13: 0 | AQ13: 0 | AR13: =R13+T13+V13+X13+Z13+AB13+AD13+AF13+AH13+AJ13+AL13+AN13+AP13 -> 515.16635 | AS13: =S13+U13+W13+Y13+AA13+AC13+AE13+AG13+AI13+AK13+AM13+AO13+AQ13 -> 6127.9037 | AT13: REV10-IBS REV | AZ13: =IF(AR13>AV13,AR13-AV13,"0") -> 515.16635 | BA13: =IF(AS13>AW13,AS13-AW13,"0") -> 6127.9037 | BC13: 0310-25/HĐKT?IBSHI-TP | BD13: Thịnh Phát | BE13: PL1.5x1250x2500 ( 3 tấm ) | BF13: JIS.G4304_SUS304 | BG13: 112 | BH13: 45933 | BI13: =3*1.25*2.5 -> 9.375 | BJ13: 112 | BK13: =65000/1.1 -> 59090.909 | BL13: =BK13*BJ13*1.1 -> 7280000 | BM13: 45934 | BN13: =SUMIF($J:$J,J13,$BI:$BI) -> 9.375 | BO13: =SUMIF($J:$J,J13,$BJ:$BJ) -> 112 | BT13: IBSHI-GNEE/2504-08 | BU13: GNEE | BV13: 1.5*1250*2500 | BW13: SUS304 PLATE | BX13: 6026.4 | BY13: 45755 | BZ13: 506.25 | CA13: 6026.4 | CB13: 2.61 | CC13: =CB13*CA13 -> 15728.904 | CI13: 45791 | CJ13: 45792 | CL13: =SUMIF($J:$J,J13,$BZ:$BZ) -> 506.25 | CM13: =SUMIF($J:$J,J13,$CA:$CA) -> 6026.4 | CR13: =BN13+CL13 -> 515.625 | CS13: =BO13+CM13 -> 6138.4 | CT13: =AZ13-CR13 -> -0.4586548 | CU13: =BA13-CS13 -> -10.496324 | CV13: =IF(CT13<0,"Thừa",IF(CT13=0,"Đủ","Thiếu")) -> Thừa | DB13: 53.732939 | DC13: 632.70535 | DH13: 402.61062 | DI13: 4740.74
A14: =IF(J14=J13,"ok","Hiện") -> Hiện | B14: =CONCATENATE(CV14," đủ") -> Thiếu đủ | C14: =CT14 -> 0.063129074 | H14: Thép trắng nhập | J14: I78-A-7 | K14: tôn tấm( % C min 0.04%) | L14: PL1.5x1250x2500 | M14: JIS.G4304_SUS310S | N14: m2 | O14: 11.625 | P14: 48.53552 | Q14: 564.22542 | T14: 53.188129 | U14: 618.312 | V14: =VLOOKUP(J14,[113]PR!$A:$S,15,0) -> 0 | W14: =VLOOKUP(J14,[113]PR!$A:$S,16,0) -> 0 | X14: =VLOOKUP(J14,[114]PR!$A:$U,17,0) -> 0 | Y14: =VLOOKUP(J14,[114]PR!$A:$U,18,0) -> 0 | Z14: 0 | AA14: 0 | AB14: 0 | AC14: 0 | AD14: 0 | AE14: 0 | AF14: 0 | AG14: 0 | AH14: 0 | AI14: 0 | AJ14: 0 | AK14: 0 | AL14: 0 | AM14: 0 | AP14: 0 | AQ14: 0 | AR14: =R14+T14+V14+X14+Z14+AB14+AD14+AF14+AH14+AJ14+AL14+AN14+AP14 -> 53.188129 | AS14: =S14+U14+W14+Y14+AA14+AC14+AE14+AG14+AI14+AK14+AM14+AO14+AQ14 -> 618.312 | AZ14: =IF(AR14>AV14,AR14-AV14,"0") -> 53.188129 | BA14: =IF(AS14>AW14,AS14-AW14,"0") -> 618.312 | BN14: =SUMIF($J:$J,J14,$BI:$BI) -> 0 | BO14: =SUMIF($J:$J,J14,$BJ:$BJ) -> 0 | BT14: IBSHI-GNEE/2504-08 | BU14: GNEE | BV14: 1.5*1250*2500 | BW14: SUS310S PLATE | BX14: 635.8 | BY14: 45755 | BZ14: 53.125 | CA14: 635.8 | CB14: 6.11 | CC14: =CB14*CA14 -> 3884.738 | CI14: 45791 | CJ14: 45792 | CL14: =SUMIF($J:$J,J14,$BZ:$BZ) -> 53.125 | CM14: =SUMIF($J:$J,J14,$CA:$CA) -> 635.8 | CR14: =BN14+CL14 -> 53.125 | CS14: =BO14+CM14 -> 635.8 | CT14: =AZ14-CR14 -> 0.063129074 | CU14: =BA14-CS14 -> -17.488 | CV14: =IF(CT14<0,"Thừa",IF(CT14=0,"Đủ","Thiếu")) -> Thiếu | DB14: 36.968613 | DC14: 435.30542 | DD14: 10.94862 | DE14: 128.92
A15: =IF(J15=J14,"ok","Hiện") -> Hiện | B15: =CV15 -> Thừa | C15: =CT15 -> -3.25 | H15: Thép đen | I15: Thép thường | J15: I78-A-8 | K15: tôn tấm | L15: PL1.5x1250x2500 | M15: JIS G3101-SS400 | N15: m2 | O15: 11.775 | P15: 1.6917197 | Q15: 19.92 | T15: 3 | U15: 35.325 | V15: =VLOOKUP(J15,[113]PR!$A:$S,15,0) -> 0 | W15: =VLOOKUP(J15,[113]PR!$A:$S,16,0) -> 0 | X15: =VLOOKUP(J15,[114]PR!$A:$U,17,0) -> 0 | Y15: =VLOOKUP(J15,[114]PR!$A:$U,18,0) -> 0 | Z15: 0 | AA15: 0 | AB15: 0 | AC15: 0 | AD15: 0 | AE15: 0 | AF15: 0 | AG15: 0 | AH15: 0 | AI15: 0 | AJ15: 0 | AK15: 0 | AL15: 0 | AM15: 0 | AP15: 0 | AQ15: 0 | AR15: =R15+T15+V15+X15+Z15+AB15+AD15+AF15+AH15+AJ15+AL15+AN15+AP15 -> 3 | AS15: =S15+U15+W15+Y15+AA15+AC15+AE15+AG15+AI15+AK15+AM15+AO15+AQ15 -> 35.325 | AZ15: =IF(AR15>AV15,AR15-AV15,"0") -> 3 | BA15: =IF(AS15>AW15,AS15-AW15,"0") -> 35.325 | BC15: 100425HN-IBS | BD15: Hùng Nguyên | BE15: Thép tấm 1.5x1250x2500 | BF15: SS400 | BG15: 73.59 | BH15: 45757 | BI15: 6.25 | BJ15: 73.59 | BK15: 20000 | BL15: =BK15*BJ15*1.1 -> 1618980 | BM15: 45758 | BN15: =SUMIF($J:$J,J15,$BI:$BI) -> 6.25 | BO15: =SUMIF($J:$J,J15,$BJ:$BJ) -> 73.59 | BP15: ACC | CL15: =SUMIF($J:$J,J15,$BZ:$BZ) -> 0 | CM15: =SUMIF($J:$J,J15,$CA:$CA) -> 0 | CR15: =BN15+CL15 -> 6.25 | CS15: =BO15+CM15 -> 73.59 | CT15: =AZ15-CR15 -> -3.25 | CU15: =BA15-CS15 -> -38.265 | CV15: =IF(CT15<0,"Thừa",IF(CT15=0,"Đủ","Thiếu")) -> Thừa | DP15: 1.6917197 | DQ15: 19.92
A16: =IF(J16=J15,"ok","Hiện") -> Hiện | B16: =CV16 -> Đủ | C16: =CT16 -> 0 | F16: Lấy 1 tờ tồn dự án 090 | J16: I78-A-9 | K16: tôn tấm( % C min 0.04%) | L16: PL2x1250x2500 | M16: JIS.G4304_SUS304 | N16: m2 | O16: 15.86 | P16: 427.02864 | Q16: 6772.6742 | T16: 478.83238 | U16: 7594.2815 | V16: =VLOOKUP(J16,[113]PR!$A:$S,15,0) -> 0 | W16: =VLOOKUP(J16,[113]PR!$A:$S,16,0) -> 0 | X16: =VLOOKUP(J16,[114]PR!$A:$U,17,0) -> 0 | Y16: =VLOOKUP(J16,[114]PR!$A:$U,18,0) -> 0 | Z16: 0 | AA16: 0 | AB16: 0 | AC16: 0 | AD16: 0 | AE16: 0 | AF16: 0 | AG16: 0 | AH16: 0 | AI16: 0 | AJ16: 0 | AK16: 0 | AL16: 24.125 | AM16: 382.6225 | AP16: 0 | AQ16: 0 | AR16: =R16+T16+V16+X16+Z16+AB16+AD16+AF16+AH16+AJ16+AL16+AN16+AP16 -> 502.95738 | AS16: =S16+U16+W16+Y16+AA16+AC16+AE16+AG16+AI16+AK16+AM16+AO16+AQ16 -> 7976.904 | AT16: REV10-IBS REV | AV16: 2.9573795 | AW16: 46.904038 | AY16: Lấy hàng tồn dự án 090 | AZ16: =IF(AR16>AV16,AR16-AV16,"0") -> 500 | BA16: =IF(AS16>AW16,AS16-AW16,"0") -> 7930 | BC16: 0310-25/HĐKT?IBSHI-TP | BD16: Thịnh Phát | BE16: PL2x1250x2500 (7 tấm ) | BF16: JIS.G4304_SUS304 | BG16: 344 | BH16: 45933 | BI16: =7*1.25*2.5 -> 21.875 | BJ16: 344 | BK16: =65000/1.1 -> 59090.909 | BL16: =BK16*BJ16*1.1 -> 22360000 | BM16: 45934 | BN16: =SUMIF($J:$J,J16,$BI:$BI) -> 21.875 | BO16: =SUMIF($J:$J,J16,$BJ:$BJ) -> 344 | BT16: IBSHI-GNEE/2504-08 | BU16: GNEE | BV16: 2*1250*2500 | BW16: SUS304 PLATE | BX16: 7588.8 | BY16: 45755 | BZ16: 478.125 | CA16: 7588.8 | CB16: 2.61 | CC16: =CB16*CA16 -> 19806.768 | CI16: 45791 | CJ16: 45792 | CL16: =SUMIF($J:$J,J16,$BZ:$BZ) -> 478.125 | CM16: =SUMIF($J:$J,J16,$CA:$CA) -> 7588.8 | CR16: =BN16+CL16 -> 500 | CS16: =BO16+CM16 -> 7932.8 | CT16: =AZ16-CR16 -> 0 | CU16: =BA16-CS16 -> -2.8 | CV16: =IF(CT16<0,"Thừa",IF(CT16=0,"Đủ","Thiếu")) -> Đủ | DB16: 6.8072736 | DC16: 106.8742 | DH16: 424.57325 | DI16: 6665.8
A17: =IF(J17=J16,"ok","Hiện") -> Hiện | B17: =CV17 -> Thừa | C17: =CT17 -> -3.2341072 | J17: I78-A-10 | K17: tôn tấm( % C min 0.04%) | L17: PL2x1250x2500 | M17: JIS.G4304_SUS310S | N17: m2 | O17: 15.5 | P17: 584.82924 | Q17: 9064.8532 | T17: 640.89089 | U17: 9933.8088 | V17: =VLOOKUP(J17,[113]PR!$A:$S,15,0) -> 0 | W17: =VLOOKUP(J17,[113]PR!$A:$S,16,0) -> 0 | X17: =VLOOKUP(J17,[114]PR!$A:$U,17,0) -> 0 | Y17: =VLOOKUP(J17,[114]PR!$A:$U,18,0) -> 0 | Z17: 0 | AA17: 0 | AB17: 0 | AC17: 0 | AD17: 70 | AE17: 1085 | AF17: 0 | AG17: 0 | AH17: 0 | AI17: 0 | AJ17: 0 | AK17: 0 | AL17: 29.625 | AM17: 459.1875 | AP17: 0 | AQ17: 0 | AR17: =R17+T17+V17+X17+Z17+AB17+AD17+AF17+AH17+AJ17+AL17+AN17+AP17 -> 740.51589 | AS17: =S17+U17+W17+Y17+AA17+AC17+AE17+AG17+AI17+AK17+AM17+AO17+AQ17 -> 11477.996 | AT17: REV10-IBS REV | AZ17: =IF(AR17>AV17,AR17-AV17,"0") -> 740.51589 | BA17: =IF(AS17>AW17,AS17-AW17,"0") -> 11477.996 | BN17: =SUMIF($J:$J,J17,$BI:$BI) -> 31.25 | BO17: =SUMIF($J:$J,J17,$BJ:$BJ) -> 478 | BT17: IBSHI-GNEE/2504-08 | BU17: GNEE | BV17: 2*1250*2500 | BW17: SUS310S PLATE | BX17: 10250 | BY17: 45755 | BZ17: 640.625 | CA17: 10250 | CB17: 6.11 | CC17: =CB17*CA17 -> 62627.5 | CI17: 45791 | CJ17: 45792 | CL17: =SUMIF($J:$J,J17,$BZ:$BZ) -> 712.5 | CM17: =SUMIF($J:$J,J17,$CA:$CA) -> 11400 | CR17: =BN17+CL17 -> 743.75 | CS17: =BO17+CM17 -> 11878 | CT17: =AZ17-CR17 -> -3.2341072 | CU17: =BA17-CS17 -> -400.00366 | CV17: =IF(CT17<0,"Thừa",IF(CT17=0,"Đủ","Thiếu")) -> Thừa | DB17: 1.786826 | DC17: 28.053168 | DD17: 575.22038 | DE17: 9030.96 | DJ17: 0.12356688 | DK17: 1.94 | DL17: 0.12356688 | DM17: 1.94 | DN17: 0.12356688 | DO17: 1.94
A18: =IF(J18=J17,"ok","Hiện") -> ok | J18: I78-A-10 | K18: tôn tấm( % C min 0.04%) | L18: PL2x1250x2500 | M18: JIS.G4304_SUS310S | N18: m2 | BT18: IBSHI-GNEE/2506-25 | BU18: GNEE | BV18: 2*1250*2500 | BW18: SUS310S PLATE | BX18: 1150 | BY18: 45833 | BZ18: =23*1250*2500/1000000 -> 71.875 | CA18: 1150 | CB18: 6.11 | CC18: =CB18*CA18 -> 7026.5 | CD18: 45846 | CF18: 45857 | CI18: 45867 | CJ18: 45868 | CL18: =SUMIF($J:$J,J18,$BZ:$BZ) -> 712.5 | CM18: =SUMIF($J:$J,J18,$CA:$CA) -> 11400
A19: =IF(J19=J18,"ok","Hiện") -> ok | J19: I78-A-10 | K19: tôn tấm( % C min 0.04%) | L19: PL2x1250x2500 | M19: JIS.G4304_SUS310S | N19: m2 | BC19: 1510-25/HĐKT?IBSHI-TP | BD19: Thịnh Phát | BE19: PL2x1250x2500 (10 tấm ) mác 310S (2mm) | BF19: 310S | BG19: 478 | BH19: 45945 | BI19: =10*1.25*2.5 -> 31.25 | BJ19: 478 | BK19: 222727 | BL19: =BK19*BJ19*1.1 -> 1.1710986e+08 | BM19: 45947
A20: =IF(J20=J19,"ok","Hiện") -> Hiện | B20: =CV20 -> Đủ | C20: =CT20 -> 0 | E20: Hàng tồn, đã mời | H20: Thép trắng nhập | I20: Tấm PL2mmx1.22m*2.44m= 20 Tờ | J20: I78-A-11 | K20: tôn tấm( % C min 0.04%) | L20: PL2x1250x2500 | M20: JIS G4312 SUH409 | N20: m2 | O20: 11.55 | P20: 52.501246 | Q20: 606.38939 | T20: 45 | U20: 519.75 | V20: =VLOOKUP(J20,[113]PR!$A:$S,15,0) -> 0 | W20: =VLOOKUP(J20,[113]PR!$A:$S,16,0) -> 0 | X20: =VLOOKUP(J20,[114]PR!$A:$U,17,0) -> 0 | Y20: =VLOOKUP(J20,[114]PR!$A:$U,18,0) -> 0 | Z20: 0 | AA20: 0 | AB20: 0 | AC20: 0 | AD20: 0 | AE20: 0 | AF20: 0 | AG20: 0 | AH20: 0 | AI20: 0 | AJ20: 0 | AK20: 0 | AL20: 1.875 | AM20: 28.875 | AP20: 0 | AQ20: 0 | AR20: =R20+T20+V20+X20+Z20+AB20+AD20+AF20+AH20+AJ20+AL20+AN20+AP20 -> 46.875 | AS20: =S20+U20+W20+Y20+AA20+AC20+AE20+AG20+AI20+AK20+AM20+AO20+AQ20 -> 548.625 | AT20: REV10-IBS REV | AV20: =1.22*2.44 * 20 -> 59.536 | AW20: =AV20*O20 -> 687.6408 | AZ20: =IF(AR20>AV20,AR20-AV20,"0") -> 0 | BA20: =IF(AS20>AW20,AS20-AW20,"0") -> 0 | BN20: =SUMIF($J:$J,J20,$BI:$BI) -> 0 | BO20: =SUMIF($J:$J,J20,$BJ:$BJ) -> 0 | CL20: =SUMIF($J:$J,J20,$BZ:$BZ) -> 0 | CM20: =SUMIF($J:$J,J20,$CA:$CA) -> 0 | CR20: =BN20+CL20 -> 0 | CS20: =BO20+CM20 -> 0 | CT20: =AZ20-CR20 -> 0 | CU20: =BA20-CS20 -> 0 | CV20: =IF(CT20<0,"Thừa",IF(CT20=0,"Đủ","Thiếu")) -> Đủ | DB20: 7.8235279 | DC20: 122.82939 | DJ20: 10.263694 | DK20: 161.14 | DL20: 10.263694 | DM20: 161.14 | DN20: 10.275159 | DO20: 161.32
A21: =IF(J21=J20,"ok","Hiện") -> Hiện | B21: =CV21 -> Đủ | C21: =CT21 -> 0 | H21: Thép trắng nhập | J21: I78-A-12 | K21: tôn tấm( % C min 0.04%) | L21: PL3 | M21: ASTM-A240-TP304H | N21: m2 | O21: 23.79 | P21: 81.054093 | Q21: =1840.5768608+87.7 -> 1928.2769 | T21: 90 | U21: 2141.1 | V21: =VLOOKUP(J21,[113]PR!$A:$S,15,0) -> 0 | W21: =VLOOKUP(J21,[113]PR!$A:$S,16,0) -> 0 | X21: =VLOOKUP(J21,[114]PR!$A:$U,17,0) -> 0 | Y21: =VLOOKUP(J21,[114]PR!$A:$U,18,0) -> 0 | Z21: 0 | AA21: 0 | AB21: 0 | AC21: 0 | AD21: 0 | AE21: 0 | AF21: 0 | AG21: 0 | AH21: 0 | AI21: 0 | AJ21: 0 | AK21: 0 | AL21: 0 | AM21: 0 | AP21: 0 | AQ21: 0 | AR21: =R21+T21+V21+X21+Z21+AB21+AD21+AF21+AH21+AJ21+AL21+AN21+AP21 -> 90 | AS21: =S21+U21+W21+Y21+AA21+AC21+AE21+AG21+AI21+AK21+AM21+AO21+AQ21 -> 2141.1 | AT21: 03 TỜ PL3x1500x5000 03 TỜ PL3x2000x5000 12 TỜ PL3x1250x2500 | AZ21: =IF(AR21>AV21,AR21-AV21,"0") -> 90 | BA21: =IF(AS21>AW21,AS21-AW21,"0") -> 2141.1 | BN21: =SUMIF($J:$J,J21,$BI:$BI) -> 0 | BO21: =SUMIF($J:$J,J21,$BJ:$BJ) -> 0 | BT21: IBSHI-GNEE/2504-08 | BU21: GNEE | BV21: 3*1500*5000 | BW21: A240-TP304H PLATE | BX21: 535.2 | BY21: 45755 | BZ21: 22.5 | CA21: 535.2 | CB21: 2.61 | CC21: =CB21*CA21 -> 1396.872 | CI21: 45791 | CJ21: 45792 | CL21: =SUMIF($J:$J,J21,$BZ:$BZ) -> 90 | CM21: =SUMIF($J:$J,J21,$CA:$CA) -> 2140.5 | CR21: =BN21+CL21 -> 90 | CS21: =BO21+CM21 -> 2140.5 | CT21: =AZ21-CR21 -> 0 | CU21: =BA21-CS21 -> 0.6 | CV21: =IF(CT21<0,"Thừa",IF(CT21=0,"Đủ","Thiếu")) -> Đủ | DF21: 78.119612 | DG21: 1839.7169 | DH21: 3.76 | DI21: 88.56
A22: =IF(J22=J21,"ok","Hiện") -> ok | H22: Thép trắng nhập | J22: I78-A-12 | K22: tôn tấm( % C min 0.04%) | L22: PL3 | M22: ASTM-A240-TP304H | BT22: IBSHI-GNEE/2504-08 | BU22: GNEE | BV22: 3*2000*5000 | BW22: A240-TP304H PLATE | BX22: 713.7 | BY22: 45755 | BZ22: 30 | CA22: 713.7 | CB22: 2.96 | CC22: =CB22*CA22 -> 2112.552 | CI22: 45791 | CJ22: 45792
A23: =IF(J23=J22,"ok","Hiện") -> ok | H23: Thép trắng nhập | J23: I78-A-12 | K23: tôn tấm( % C min 0.04%) | L23: PL3 | M23: ASTM-A240-TP304H | BT23: IBSHI-GNEE/2504-08 | BU23: GNEE | BV23: 3*1250*2500 | BW23: A240-TP304H PLATE | BX23: 891.6 | BY23: 45755 | BZ23: 37.5 | CA23: 891.6 | CB23: 2.91 | CC23: =CB23*CA23 -> 2594.556 | CI23: 45791 | CJ23: 45792
A24: =IF(J24=J23,"ok","Hiện") -> Hiện | B24: =CONCATENATE(CV24," Dùng cùng A-16") -> Thiếu Dùng cùng A-16 | C24: =CT24 -> 2.18894 | E24: Dùng cùng A-16 | H24: Thép đen | J24: I78-A-13 | K24: tôn tấm | L24: PL3x1500x6000 | M24: JIS G3101-SS400 | N24: m2 | O24: 23.55 | P24: 1.6838 | Q24: 39.65349 | T24: 2.18894 | U24: 51.549537 | V24: =VLOOKUP(J24,[113]PR!$A:$S,15,0) -> 0 | W24: =VLOOKUP(J24,[113]PR!$A:$S,16,0) -> 0 | X24: =VLOOKUP(J24,[114]PR!$A:$U,17,0) -> 0 | Y24: =VLOOKUP(J24,[114]PR!$A:$U,18,0) -> 0 | Z24: 0 | AA24: 0 | AB24: 0 | AC24: 0 | AD24: 0 | AE24: 0 | AF24: 0 | AG24: 0 | AH24: 0 | AI24: 0 | AJ24: 0 | AK24: 0 | AL24: 0 | AM24: 0 | AP24: 0 | AQ24: 0 | AR24: =R24+T24+V24+X24+Z24+AB24+AD24+AF24+AH24+AJ24+AL24+AN24+AP24 -> 2.18894 | AS24: =S24+U24+W24+Y24+AA24+AC24+AE24+AG24+AI24+AK24+AM24+AO24+AQ24 -> 51.549537 | AZ24: =IF(AR24>AV24,AR24-AV24,"0") -> 2.18894 | BA24: =IF(AS24>AW24,AS24-AW24,"0") -> 51.549537 | BB24: 45762 | BN24: =SUMIF($J:$J,J24,$BI:$BI) -> 0 | BO24: =SUMIF($J:$J,J24,$BJ:$BJ) -> 0 | CL24: =SUMIF($J:$J,J24,$BZ:$BZ) -> 0 | CM24: =SUMIF($J:$J,J24,$CA:$CA) -> 0 | CR24: =BN24+CL24 -> 0 | CS24: =BO24+CM24 -> 0 | CT24: =AZ24-CR24 -> 2.18894 | CU24: =BA24-CS24 -> 51.549537 | CV24: =IF(CT24<0,"Thừa",IF(CT24=0,"Đủ","Thiếu")) -> Thiếu | CZ24: 1.6838 | DA24: 39.65349
A25: =IF(J25=J24,"ok","Hiện") -> Hiện | B25: =CV25 -> Thừa | C25: =CT25 -> -0.125 | H25: Thép trắng nhập | J25: I78-A-14 | K25: tôn tấm( % C min 0.04%) | L25: PL3x1250x2500 | M25: JIS G4312 SUH409 | N25: m2 | O25: 11.55 | P25: 4.5264069 | Q25: 52.28 | T25: 3 | U25: 69.3 | V25: =VLOOKUP(J25,[113]PR!$A:$S,15,0) -> 0 | W25: =VLOOKUP(J25,[113]PR!$A:$S,16,0) -> 0 | X25: =VLOOKUP(J25,[114]PR!$A:$U,17,0) -> 0 | Y25: =VLOOKUP(J25,[114]PR!$A:$U,18,0) -> 0 | Z25: 0 | AA25: 0 | AB25: 0 | AC25: 0 | AD25: 0 | AE25: 0 | AF25: 0 | AG25: 0 | AH25: 0 | AI25: 0 | AJ25: 0 | AK25: 0 | AL25: 0 | AM25: 0 | AP25: 0 | AQ25: 0 | AR25: =R25+T25+V25+X25+Z25+AB25+AD25+AF25+AH25+AJ25+AL25+AN25+AP25 -> 3 | AS25: =S25+U25+W25+Y25+AA25+AC25+AE25+AG25+AI25+AK25+AM25+AO25+AQ25 -> 69.3 | AZ25: =IF(AR25>AV25,AR25-AV25,"0") -> 3 | BA25: =IF(AS25>AW25,AS25-AW25,"0") -> 69.3 | BN25: =SUMIF($J:$J,J25,$BI:$BI) -> 0 | BO25: =SUMIF($J:$J,J25,$BJ:$BJ) -> 0 | BT25: EYANG-IBS/25048HP01 | BU25: EYANG | BV25: PL3 x 1250 x 2500mm ( HR/No1) | BW25: Stainless Steel ASTM A240 TP409 - Plate | BX25: 72.1875 | BY25: 45873 | BZ25: =1.25*2.5*1 -> 3.125 | CA25: 72.1875 | CB25: 1.502 | CC25: =CB25*CA25 -> 108.42562 | CH25: 45797 | CI25: 45798 | CJ25: 45798 | CK25: 45798 | CL25: =SUMIF($J:$J,J25,$BZ:$BZ) -> 3.125 | CM25: =SUMIF($J:$J,J25,$CA:$CA) -> 72.1875 | CR25: =BN25+CL25 -> 3.125 | CS25: =BO25+CM25 -> 72.1875 | CT25: =AZ25-CR25 -> -0.125 | CU25: =BA25-CS25 -> -2.8875 | CV25: =IF(CT25<0,"Thừa",IF(CT25=0,"Đủ","Thiếu")) -> Thừa | DJ25: 1 | DK25: 23.46 | DL25: 0.55 | DM25: 12.98 | DN25: 0.67 | DO25: 15.84
A26: =IF(J26=J25,"ok","Hiện") -> Hiện | B26: =CV26 -> Thừa | C26: =CT26 -> -0.125 | H26: Thép trắng nhập | J26: I78-A-15 | K26: tôn tấm( % C min 0.04%) | L26: PL3x1250x2500 | M26: JIS.G4304_SUS310S | N26: m2 | O26: 23.25 | P26: 2.6615054 | Q26: 61.88 | T26: 3 | U26: 69.75 | V26: =VLOOKUP(J26,[113]PR!$A:$S,15,0) -> 0 | W26: =VLOOKUP(J26,[113]PR!$A:$S,16,0) -> 0 | X26: =VLOOKUP(J26,[114]PR!$A:$U,17,0) -> 0 | Y26: =VLOOKUP(J26,[114]PR!$A:$U,18,0) -> 0 | Z26: 0 | AA26: 0 | AB26: 0 | AC26: 0 | AD26: 0 | AE26: 0 | AF26: 0 | AG26: 0 | AH26: 0 | AI26: 0 | AJ26: 0 | AK26: 0 | AL26: 0 | AM26: 0 | AP26: 0 | AQ26: 0 | AR26: =R26+T26+V26+X26+Z26+AB26+AD26+AF26+AH26+AJ26+AL26+AN26+AP26 -> 3 | AS26: =S26+U26+W26+Y26+AA26+AC26+AE26+AG26+AI26+AK26+AM26+AO26+AQ26 -> 69.75 | AZ26: =IF(AR26>AV26,AR26-AV26,"0") -> 3 | BA26: =IF(AS26>AW26,AS26-AW26,"0") -> 69.75 | BN26: =SUMIF($J:$J,J26,$BI:$BI) -> 0 | BO26: =SUMIF($J:$J,J26,$BJ:$BJ) -> 0 | BT26: IBSHI-GNEE/2504-08 | BU26: GNEE | BV26: 3*1250*2500 | BW26: SUS310S PLATE | BX26: 74.8 | BY26: 45755 | BZ26: 3.125 | CA26: 74.8 | CB26: 6.11 | CC26: =CB26*CA26 -> 457.028 | CI26: 45791 | CJ26: 45792 | CL26: =SUMIF($J:$J,J26,$BZ:$BZ) -> 3.125 | CM26: =SUMIF($J:$J,J26,$CA:$CA) -> 74.8 | CR26: =BN26+CL26 -> 3.125 | CS26: =BO26+CM26 -> 74.8 | CT26: =AZ26-CR26 -> -0.125 | CU26: =BA26-CS26 -> -5.05 | CV26: =IF(CT26<0,"Thừa",IF(CT26=0,"Đủ","Thiếu")) -> Thừa | DD26: 2.6276008 | DE26: 61.88
A27: =IF(J27=J26,"ok","Hiện") -> Hiện | B27: =CONCATENATE(CV27," Thiếu do tính") -> Thiếu Thiếu do tính | C27: =CT27 -> 0.0022059448 | H27: Thép đen | J27: I78-A-16 | K27: tôn tấm | L27: PL3x1500x6000 | M27: JIS G3101-SS400 | N27: m2 | O27: 23.55 | P27: 16.622505 | Q27: 391.46 | T27: 18.617206 | U27: 438.4352 | V27: =VLOOKUP(J27,[113]PR!$A:$S,15,0) -> 0 | W27: =VLOOKUP(J27,[113]PR!$A:$S,16,0) -> 0 | X27: =VLOOKUP(J27,[114]PR!$A:$U,17,0) -> 0 | Y27: =VLOOKUP(J27,[114]PR!$A:$U,18,0) -> 0 | Z27: 0 | AA27: 0 | AB27: 0 | AC27: 0 | AD27: 0 | AE27: 0 | AF27: 0 | AG27: 0 | AH27: 0 | AI27: 0 | AJ27: 0 | AK27: 0 | AL27: 0 | AM27: 0 | AP27: 0 | AQ27: 0 | AR27: =R27+T27+V27+X27+Z27+AB27+AD27+AF27+AH27+AJ27+AL27+AN27+AP27 -> 18.617206 | AS27: =S27+U27+W27+Y27+AA27+AC27+AE27+AG27+AI27+AK27+AM27+AO27+AQ27 -> 438.4352 | AZ27: =IF(AR27>AV27,AR27-AV27,"0") -> 18.617206 | BA27: =IF(AS27>AW27,AS27-AW27,"0") -> 438.4352 | BC27: 030325HN-IBS | BD27: Hùng Nguyên | BE27: Thép tấm 3x1500x6000 | BF27: SS400 | BG27: 211.95 | BH27: 45719 | BI27: 9 | BJ27: 211.95 | BK27: 13181.82 | BL27: =BK27*BJ27*1.1 -> 3073275.4 | BM27: 45757 | BN27: =SUMIF($J:$J,J27,$BI:$BI) -> 18.615 | BO27: =SUMIF($J:$J,J27,$BJ:$BJ) -> 438.38 | BP27: ACC | CL27: =SUMIF($J:$J,J27,$BZ:$BZ) -> 0 | CM27: =SUMIF($J:$J,J27,$CA:$CA) -> 0 | CR27: =BN27+CL27 -> 18.615 | CS27: =BO27+CM27 -> 438.38 | CT27: =AZ27-CR27 -> 0.0022059448 | CU27: =BA27-CS27 -> 0.0552 | CV27: =IF(CT27<0,"Thừa",IF(CT27=0,"Đủ","Thiếu")) -> Thiếu | DP27: 0.017834395 | DQ27: 0.42 | DR27: 0.5418259 | DS27: 12.76 | DT27: 16.062845 | DU27: 378.28
A28: =IF(J28=J27,"ok","Hiện") -> ok | H28: Thép đen | J28: I78-A-16 | K28: tôn tấm | L28: PL3x1500x6000 | M28: JIS G3101-SS400 | N28: m2 | O28: 23.55 | P28: 16.622505 | Q28: 391.46 | BC28: 030325HN-IBS | BD28: Hùng Nguyên | BE28: Thép tấm 3x1500x6410 | BF28: SS400 | BG28: 226.43 | BH28: 45719 | BI28: 9.615 | BJ28: 226.43 | BK28: 13181.82 | BL28: =BK28*BJ28*1.1 -> 3283235.5 | BM28: 45757 | BP28: ACC
A29: =IF(J29=J28,"ok","Hiện") -> Hiện | B29: =CV29 -> Đủ | C29: =CT29 -> 0 | G29: Hàng tồn | H29: Thép trắng nhập | J29: I78-A-17 | K29: tôn tấm( % C min 0.04%) | L29: PL4x500x1000 | M29: ASTM-A240-TP304H | N29: m2 | O29: 31.72 | P29: 0.36672 | Q29: 11.632358 | T29: 0.5 | U29: 15.86 | V29: =VLOOKUP(J29,[113]PR!$A:$S,15,0) -> 0 | W29: =VLOOKUP(J29,[113]PR!$A:$S,16,0) -> 0 | X29: =VLOOKUP(J29,[114]PR!$A:$U,17,0) -> 0 | Y29: =VLOOKUP(J29,[114]PR!$A:$U,18,0) -> 0 | Z29: 0 | AA29: 0 | AB29: 0 | AC29: 0 | AD29: 0 | AE29: 0 | AF29: 0 | AG29: 0 | AH29: 0 | AI29: 0 | AJ29: 0 | AK29: 0 | AL29: 0 | AM29: 0 | AP29: 0 | AQ29: 0 | AR29: =R29+T29+V29+X29+Z29+AB29+AD29+AF29+AH29+AJ29+AL29+AN29+AP29 -> 0.5 | AS29: =S29+U29+W29+Y29+AA29+AC29+AE29+AG29+AI29+AK29+AM29+AO29+AQ29 -> 15.86 | AV29: 0.5 | AW29: =AV29*O29 -> 15.86 | AY29: Đã mời nghiệm thu ngày 15/5 | AZ29: =IF(AR29>AV29,AR29-AV29,"0") -> 0 | BA29: =IF(AS29>AW29,AS29-AW29,"0") -> 0 | BN29: =SUMIF($J:$J,J29,$BI:$BI) -> 0 | BO29: =SUMIF($J:$J,J29,$BJ:$BJ) -> 0 | CL29: =SUMIF($J:$J,J29,$BZ:$BZ) -> 0 | CM29: =SUMIF($J:$J,J29,$CA:$CA) -> 0 | CR29: =BN29+CL29 -> 0 | CS29: =BO29+CM29 -> 0 | CT29: =AZ29-CR29 -> 0 | CU29: =BA29-CS29 -> 0 | CV29: =IF(CT29<0,"Thừa",IF(CT29=0,"Đủ","Thiếu")) -> Đủ | DF29: 0.37045727 | DG29: 11.632358
A30: =IF(J30=J29,"ok","Hiện") -> Hiện | B30: =CV30 -> Thừa | C30: =CT30 -> -0.5 | H30: Thép đen | J30: I78-A-18 | K30: tôn tấm | L30: PL4x1500x6000 | M30: JIS G3101-SS400 | N30: m2 | O30: 31.4 | P30: 3.447056 | Q30: 108.23756 | T30: 4 | U30: 125.6 | V30: =VLOOKUP(J30,[113]PR!$A:$S,15,0) -> 0 | W30: =VLOOKUP(J30,[113]PR!$A:$S,16,0) -> 0 | X30: =VLOOKUP(J30,[114]PR!$A:$U,17,0) -> 0 | Y30: =VLOOKUP(J30,[114]PR!$A:$U,18,0) -> 0 | Z30: 0 | AA30: 0 | AB30: 0 | AC30: 0 | AD30: 0 | AE30: 0 | AF30: 0 | AG30: 0 | AH30: 0 | AI30: 0 | AJ30: 0 | AK30: 0 | AL30: 0 | AM30: 0 | AP30: 0 | AQ30: 0 | AR30: =R30+T30+V30+X30+Z30+AB30+AD30+AF30+AH30+AJ30+AL30+AN30+AP30 -> 4 | AS30: =S30+U30+W30+Y30+AA30+AC30+AE30+AG30+AI30+AK30+AM30+AO30+AQ30 -> 125.6 | AZ30: =IF(AR30>AV30,AR30-AV30,"0") -> 4 | BA30: =IF(AS30>AW30,AS30-AW30,"0") -> 125.6 | BC30: 030325HN-IBS | BD30: Hùng Nguyên | BE30: Thép tấm 4x1500x3000 | BF30: SS400 | BG30: 141.3 | BH30: 45719 | BI30: 4.5 | BJ30: 141.3 | BK30: 13181.82 | BL30: =BK30*BJ30*1.1 -> 2048850.3 | BM30: 45757 | BN30: =SUMIF($J:$J,J30,$BI:$BI) -> 4.5 | BO30: =SUMIF($J:$J,J30,$BJ:$BJ) -> 141.3 | BP30: ACC | CL30: =SUMIF($J:$J,J30,$BZ:$BZ) -> 0 | CM30: =SUMIF($J:$J,J30,$CA:$CA) -> 0 | CR30: =BN30+CL30 -> 4.5 | CS30: =BO30+CM30 -> 141.3 | CT30: =AZ30-CR30 -> -0.5 | CU30: =BA30-CS30 -> -15.7 | CV30: =IF(CT30<0,"Thừa",IF(CT30=0,"Đủ","Thiếu")) -> Thừa | DB30: 3.447056 | DC30: 108.23756
A31: =IF(J31=J30,"ok","Hiện") -> Hiện | B31: =CV31 -> Đủ | C31: =CT31 -> 0 | H31: Thép trắng nhập | J31: I78-A-19 | K31: tôn tấm( % C min 0.04%) | L31: PL5x1500x1200 | M31: ASTM-A240-TP304H | N31: m2 | O31: 39.65 | P31: 1.37408 | Q31: 54.482272 | T31: 1.8 | U31: 71.37 | V31: =VLOOKUP(J31,[113]PR!$A:$S,15,0) -> 0 | W31: =VLOOKUP(J31,[113]PR!$A:$S,16,0) -> 0 | X31: =VLOOKUP(J31,[114]PR!$A:$U,17,0) -> 0 | Y31: =VLOOKUP(J31,[114]PR!$A:$U,18,0) -> 0 | Z31: 0 | AA31: 0 | AB31: 0 | AC31: 0 | AD31: 0 | AE31: 0 | AF31: 0 | AG31: 0 | AH31: 0 | AI31: 0 | AJ31: 0 | AK31: 0 | AL31: 0 | AM31: 0 | AP31: 0 | AQ31: 0 | AR31: =R31+T31+V31+X31+Z31+AB31+AD31+AF31+AH31+AJ31+AL31+AN31+AP31 -> 1.8 | AS31: =S31+U31+W31+Y31+AA31+AC31+AE31+AG31+AI31+AK31+AM31+AO31+AQ31 -> 71.37 | AZ31: =IF(AR31>AV31,AR31-AV31,"0") -> 1.8 | BA31: =IF(AS31>AW31,AS31-AW31,"0") -> 71.37 | BN31: =SUMIF($J:$J,J31,$BI:$BI) -> 0 | BO31: =SUMIF($J:$J,J31,$BJ:$BJ) -> 0 | BT31: IBSHI-GNEE/2504-08 | BU31: GNEE | BV31: 5*1500*1200 | BW31: A240-TP304H PLATE | BX31: 71.4 | BY31: 45755 | BZ31: 1.8 | CA31: 71.4 | CB31: 2.88 | CC31: =CB31*CA31 -> 205.632 | CI31: 45791 | CJ31: 45792 | CL31: =SUMIF($J:$J,J31,$BZ:$BZ) -> 1.8 | CM31: =SUMIF($J:$J,J31,$CA:$CA) -> 71.4 | CR31: =BN31+CL31 -> 1.8 | CS31: =BO31+CM31 -> 71.4 | CT31: =AZ31-CR31 -> 0 | CU31: =BA31-CS31 -> -0.03 | CV31: =IF(CT31<0,"Thừa",IF(CT31=0,"Đủ","Thiếu")) -> Đủ | DF31: 1.3880834 | DG31: 54.482272
A32: =IF(J32=J31,"ok","Hiện") -> Hiện | B32: =CV32 -> Thừa | C32: =CT32 -> -2.2040886 | H32: Thép đen | J32: I78-A-20 | K32: tôn tấm | L32: PL5x1500x6000 | M32: JIS G3101-SS400 | N32: m2 | O32: 39.25 | P32: 1.9964447 | Q32: 78.360454 | T32: 2.2959114 | U32: 90.114522 | V32: =VLOOKUP(J32,[113]PR!$A:$S,15,0) -> 0 | W32: =VLOOKUP(J32,[113]PR!$A:$S,16,0) -> 0 | X32: =VLOOKUP(J32,[114]PR!$A:$U,17,0) -> 0 | Y32: =VLOOKUP(J32,[114]PR!$A:$U,18,0) -> 0 | Z32: 0 | AA32: 0 | AB32: 0 | AC32: 0 | AD32: 0 | AE32: 0 | AF32: 0 | AG32: 0 | AH32: 0 | AI32: 0 | AJ32: 0 | AK32: 0 | AL32: 0 | AM32: 0 | AP32: 0 | AQ32: 0 | AR32: =R32+T32+V32+X32+Z32+AB32+AD32+AF32+AH32+AJ32+AL32+AN32+AP32 -> 2.2959114 | AS32: =S32+U32+W32+Y32+AA32+AC32+AE32+AG32+AI32+AK32+AM32+AO32+AQ32 -> 90.114522 | AZ32: =IF(AR32>AV32,AR32-AV32,"0") -> 2.2959114 | BA32: =IF(AS32>AW32,AS32-AW32,"0") -> 90.114522 | BC32: 030325HN-IBS | BD32: Hùng Nguyên | BE32: Thép tấm 5x1500x3000 | BF32: SS400 | BG32: 176.63 | BH32: 45719 | BI32: 4.5 | BJ32: 176.63 | BK32: 13181.82 | BL32: =BK32*BJ32*1.1 -> 2561135.4 | BM32: 45757 | BN32: =SUMIF($J:$J,J32,$BI:$BI) -> 4.5 | BO32: =SUMIF($J:$J,J32,$BJ:$BJ) -> 176.63 | BP32: ACC | CL32: =SUMIF($J:$J,J32,$BZ:$BZ) -> 0 | CM32: =SUMIF($J:$J,J32,$CA:$CA) -> 0 | CR32: =BN32+CL32 -> 4.5 | CS32: =BO32+CM32 -> 176.63 | CT32: =AZ32-CR32 -> -2.2040886 | CU32: =BA32-CS32 -> -86.515478 | CV32: =IF(CT32<0,"Thừa",IF(CT32=0,"Đủ","Thiếu")) -> Thừa | DB32: 1.9964447 | DC32: 78.360454
A33: =IF(J33=J32,"ok","Hiện") -> Hiện | B33: =CV33 -> Đủ | C33: =CT33 -> 0 | H33: Thép trắng nhập | J33: I78-A-21 | K33: tôn tấm( % C min 0.04%) | L33: PL6x1500x6000 | M33: ASTM-A240-TP304H | N33: m2 | O33: 47.58 | P33: 5.5152768 | Q33: =250.8368696+11.58 -> 262.41687 | T33: 7.5 | U33: 356.85 | V33: =VLOOKUP(J33,[113]PR!$A:$S,15,0) -> 0 | W33: =VLOOKUP(J33,[113]PR!$A:$S,16,0) -> 0 | X33: =VLOOKUP(J33,[114]PR!$A:$U,17,0) -> 0 | Y33: =VLOOKUP(J33,[114]PR!$A:$U,18,0) -> 0 | Z33: 0 | AA33: 0 | AB33: 0 | AC33: 0 | AD33: 0 | AE33: 0 | AF33: 0 | AG33: 0 | AH33: 0 | AI33: 0 | AJ33: 0 | AK33: 0 | AL33: 0 | AM33: 0 | AP33: 0 | AQ33: 0 | AR33: =R33+T33+V33+X33+Z33+AB33+AD33+AF33+AH33+AJ33+AL33+AN33+AP33 -> 7.5 | AS33: =S33+U33+W33+Y33+AA33+AC33+AE33+AG33+AI33+AK33+AM33+AO33+AQ33 -> 356.85 | AZ33: =IF(AR33>AV33,AR33-AV33,"0") -> 7.5 | BA33: =IF(AS33>AW33,AS33-AW33,"0") -> 356.85 | BN33: =SUMIF($J:$J,J33,$BI:$BI) -> 0 | BO33: =SUMIF($J:$J,J33,$BJ:$BJ) -> 0 | BT33: IBSHI-GNEE/2504-08 | BU33: GNEE | BV33: 6*1500*5000 | BW33: A240-TP304H PLATE | BX33: 356.9 | BY33: 45755 | BZ33: 7.5 | CA33: 356.9 | CB33: 2.88 | CC33: =CB33*CA33 -> 1027.872 | CI33: 45791 | CJ33: 45792 | CL33: =SUMIF($J:$J,J33,$BZ:$BZ) -> 7.5 | CM33: =SUMIF($J:$J,J33,$CA:$CA) -> 356.9 | CR33: =BN33+CL33 -> 7.5 | CS33: =BO33+CM33 -> 356.9 | CT33: =AZ33-CR33 -> 0 | CU33: =BA33-CS33 -> -0.05 | CV33: =IF(CT33<0,"Thừa",IF(CT33=0,"Đủ","Thiếu")) -> Đủ | DF33: 5.2551352 | DG33: 247.51687 | DH33: 0.070488323 | DI33: 3.32
A34: =IF(J34=J33,"ok","Hiện") -> Hiện | B34: =CV34 -> Đủ | C34: =CT34 -> 0 | H34: Thép trắng nhập | J34: I78-A-22 | K34: tôn tấm( % C min 0.04%) | L34: PL6x1500x2500 | M34: ASTM-A240-TP310S | N34: m2 | O34: 46.5 | P34: 2.1713978 | Q34: 100.97 | T34: 3.75 | U34: 174.375 | V34: =VLOOKUP(J34,[113]PR!$A:$S,15,0) -> 0 | W34: =VLOOKUP(J34,[113]PR!$A:$S,16,0) -> 0 | X34: =VLOOKUP(J34,[114]PR!$A:$U,17,0) -> 0 | Y34: =VLOOKUP(J34,[114]PR!$A:$U,18,0) -> 0 | Z34: 0 | AA34: 0 | AB34: 0 | AC34: 0 | AD34: 0 | AE34: 0 | AF34: 0 | AG34: 0 | AH34: 0 | AI34: 0 | AJ34: 0 | AK34: 0 | AL34: 0 | AM34: 0 | AP34: 0 | AQ34: 0 | AR34: =R34+T34+V34+X34+Z34+AB34+AD34+AF34+AH34+AJ34+AL34+AN34+AP34 -> 3.75 | AS34: =S34+U34+W34+Y34+AA34+AC34+AE34+AG34+AI34+AK34+AM34+AO34+AQ34 -> 174.375 | AZ34: =IF(AR34>AV34,AR34-AV34,"0") -> 3.75 | BA34: =IF(AS34>AW34,AS34-AW34,"0") -> 174.375 | BN34: =SUMIF($J:$J,J34,$BI:$BI) -> 0 | BO34: =SUMIF($J:$J,J34,$BJ:$BJ) -> 0 | BT34: IBSHI-GNEE/2504-08 | BU34: GNEE | BV34: 6*1500*2500 | BW34: A240-TP310S PLATE | BX34: 180 | BY34: 45755 | BZ34: 3.75 | CA34: 180 | CB34: 6.11 | CC34: =CB34*CA34 -> 1099.8 | CI34: 45791 | CJ34: 45792 | CL34: =SUMIF($J:$J,J34,$BZ:$BZ) -> 3.75 | CM34: =SUMIF($J:$J,J34,$CA:$CA) -> 180 | CR34: =BN34+CL34 -> 3.75 | CS34: =BO34+CM34 -> 180 | CT34: =AZ34-CR34 -> 0 | CU34: =BA34-CS34 -> -5.625 | CV34: =IF(CT34<0,"Thừa",IF(CT34=0,"Đủ","Thiếu")) -> Đủ | DB34: 1.8980359 | DC34: 89.397491 | DD34: 0.24585987 | DE34: 11.58
A35: =IF(J35=J34,"ok","Hiện") -> Hiện | B35: =CV35 -> Đủ | C35: =CT35 -> 0 | H35: Thép đen | J35: I78-A-23 | K35: tôn tấm | L35: PL6x500x1000 | M35: A387-GR22 | N35: m2 | O35: 47.1 | P35: 0.3 | Q35: 14.13 | T35: 0.5 | U35: 23.55 | V35: =VLOOKUP(J35,[113]PR!$A:$S,15,0) -> -0.5 | W35: -23.55 | X35: =VLOOKUP(J35,[114]PR!$A:$U,17,0) -> 0 | Y35: =VLOOKUP(J35,[114]PR!$A:$U,18,0) -> 0 | Z35: 0 | AA35: 0 | AB35: 0 | AC35: 0 | AD35: 0 | AE35: 0 | AF35: 0 | AG35: 0 | AH35: 0 | AI35: 0 | AJ35: 0 | AK35: 0 | AL35: 0 | AM35: 0 | AP35: 0 | AQ35: 0 | AR35: =R35+T35+V35+X35+Z35+AB35+AD35+AF35+AH35+AJ35+AL35+AN35+AP35 -> 0 | AS35: =S35+U35+W35+Y35+AA35+AC35+AE35+AG35+AI35+AK35+AM35+AO35+AQ35 -> 0 | AT35: REV2-VOGT CẤP | AZ35: =IF(AR35>AV35,AR35-AV35,"0") -> 0 | BA35: =IF(AS35>AW35,AS35-AW35,"0") -> 0 | BN35: =SUMIF($J:$J,J35,$BI:$BI) -> 0 | BO35: =SUMIF($J:$J,J35,$BJ:$BJ) -> 0 | CL35: =SUMIF($J:$J,J35,$BZ:$BZ) -> 0 | CM35: =SUMIF($J:$J,J35,$CA:$CA) -> 0 | CR35: =BN35+CL35 -> 0 | CS35: =BO35+CM35 -> 0 | CT35: =AZ35-CR35 -> 0 | CU35: =BA35-CS35 -> 0 | CV35: =IF(CT35<0,"Thừa",IF(CT35=0,"Đủ","Thiếu")) -> Đủ | DZ35: 0.3 | EA35: 14.13
A36: =IF(J36=J35,"ok","Hiện") -> Hiện | B36: =CONCATENATE(CV36," Mua đủ theo Pr") -> Thiếu Mua đủ theo Pr | C36: =CT36 -> 8.4981285 | H36: Thép đen | J36: I78-A-24 | K36: tôn tấm | L36: PL6-cuộn | M36: JIS G3101-SS400 | N36: m2 | O36: 47.1 | P36: 1896.724 | Q36: 89335.701 | T36: 2143.2981 | U36: 100949.34 | V36: =VLOOKUP(J36,[113]PR!$A:$S,15,0) -> 0 | W36: =VLOOKUP(J36,[113]PR!$A:$S,16,0) -> 0 | X36: =VLOOKUP(J36,[114]PR!$A:$U,17,0) -> 0 | Y36: =VLOOKUP(J36,[114]PR!$A:$U,18,0) -> 0 | Z36: 0 | AA36: 0 | AB36: 0 | AC36: 0 | AD36: 0 | AE36: 0 | AF36: 0 | AG36: 0 | AH36: 0 | AI36: 0 | AJ36: 0 | AK36: 0 | AL36: 0 | AM36: 0 | AP36: 0 | AQ36: 0 | AR36: =R36+T36+V36+X36+Z36+AB36+AD36+AF36+AH36+AJ36+AL36+AN36+AP36 -> 2143.2981 | AS36: =S36+U36+W36+Y36+AA36+AC36+AE36+AG36+AI36+AK36+AM36+AO36+AQ36 -> 100949.34 | AT36: (REV4-KHỔ TÔN) PL6x2000x12000-45 TỜ PL6x1500x12600-28 TỜ PL6x1500X9400-8 TỜ PL6x2000x12900-16 TỜ | AZ36: =IF(AR36>AV36,AR36-AV36,"0") -> 2143.2981 | BA36: =IF(AS36>AW36,AS36-AW36,"0") -> 100949.34 | BC36: 030325HN-IBS | BD36: Hùng Nguyên | BE36: Thép tấm 6x2000x12000 | BF36: SS400 | BG36: 50868 | BH36: 45719 | BI36: 1080 | BJ36: 50868 | BK36: 13363.64 | BL36: =BK36*BJ36*1.1 -> 7.477598e+08 | BM36: 45757 | BN36: =SUMIF($J:$J,J36,$BI:$BI) -> 2134.8 | BO36: =SUMIF($J:$J,J36,$BJ:$BJ) -> 100549.08 | BP36: ACC | CL36: =SUMIF($J:$J,J36,$BZ:$BZ) -> 0 | CM36: =SUMIF($J:$J,J36,$CA:$CA) -> 0 | CR36: =BN36+CL36 -> 2134.8 | CS36: =BO36+CM36 -> 100549.08 | CT36: =AZ36-CR36 -> 8.4981285 | CU36: =BA36-CS36 -> 400.26185 | CV36: =IF(CT36<0,"Thừa",IF(CT36=0,"Đủ","Thiếu")) -> Thiếu | DB36: 1.3151001 | DC36: 61.941217 | DD36: 495.10955 | DE36: 23319.66 | DF36: 0.62016 | DG36: 29.209536 | DH36: 706.96943 | DI36: 33298.26 | DJ36: 108.66667 | DK36: 5118.2 | DL36: 107.50573 | DM36: 5063.52 | DN36: 107.3448 | DO36: 5055.94 | DP36: 153.85478 | DQ36: 7246.56 | DR36: 53.32017 | DS36: 2511.38 | DT36: 159.52527 | DU36: 7513.64 | DV36: 1.2008493 | DW36: 56.56 | DZ36: 0.5 | EA36: 23.55
A37: =IF(J37=J36,"ok","Hiện") -> ok | H37: Thép đen | J37: I78-A-24 | K37: tôn tấm | L37: PL6-cuộn | M37: JIS G3101-SS400 | N37: m2 | BC37: 150425HN-IBS | BD37: Hùng Nguyên | BE37: Thép tấm 6x1500x12600 | BF37: SS400 | BG37: 24925.32 | BH37: 45762 | BI37: =1.5*12.6*28 -> 529.2 | BJ37: 24925.32 | BK37: 13090.91 | BL37: =BK37*BJ37*1.1 -> 3.5892463e+08 | BM37: 45765 | BP37: ACC
A38: =IF(J38=J37,"ok","Hiện") -> ok | H38: Thép đen | J38: I78-A-24 | K38: tôn tấm | L38: PL6-cuộn | M38: JIS G3101-SS400 | N38: m2 | BC38: 150425HN-IBS | BD38: Hùng Nguyên | BE38: Thép tấm 6x1500x9400 | BF38: SS400 | BG38: 5312.88 | BH38: 45762 | BI38: =1.5*9.4*8 -> 112.8 | BJ38: 5312.88 | BK38: 13090.91 | BL38: =BK38*BJ38*1.1 -> 76505477 | BM38: 45765 | BP38: ACC
A39: =IF(J39=J38,"ok","Hiện") -> ok | H39: Thép đen | J39: I78-A-24 | K39: tôn tấm | L39: PL6-cuộn | M39: JIS G3101-SS400 | N39: m2 | BC39: 150425HN-IBS | BD39: Hùng Nguyên | BE39: Thép tấm 6x2000x12900 | BF39: SS400 | BG39: 19442.88 | BH39: 45762 | BI39: =2*12.9*16 -> 412.8 | BJ39: 19442.88 | BK39: 13181.82 | BL39: =BK39*BJ39*1.1 -> 2.819218e+08 | BM39: 45765 | BP39: ACC
A40: =IF(J40=J39,"ok","Hiện") -> Hiện | B40: =CV40 -> Đủ | C40: =CT40 -> 0 | H40: Thép đen | J40: I78-A-25 | K40: tôn tấm cuộn | L40: PL6-cuộn | M40: JIS G3101-SS400 | N40: m2 | O40: 47.1 | P40: 488.16985 | Q40: 22992.8 | T40: 510.3 | U40: 24035.13 | V40: =VLOOKUP(J40,[113]PR!$A:$S,15,0) -> 0 | W40: =VLOOKUP(J40,[113]PR!$A:$S,16,0) -> 0 | X40: =VLOOKUP(J40,[114]PR!$A:$U,17,0) -> 0 | Y40: =VLOOKUP(J40,[114]PR!$A:$U,18,0) -> 0 | Z40: 0 | AA40: 0 | AB40: 0 | AC40: 0 | AD40: 0 | AE40: 0 | AF40: 0 | AG40: 0 | AH40: 0 | AI40: 0 | AJ40: 0 | AK40: 0 | AL40: 0 | AM40: 0 | AP40: 0 | AQ40: 0 | AR40: =R40+T40+V40+X40+Z40+AB40+AD40+AF40+AH40+AJ40+AL40+AN40+AP40 -> 510.3 | AS40: =S40+U40+W40+Y40+AA40+AC40+AE40+AG40+AI40+AK40+AM40+AO40+AQ40 -> 24035.13 | AT40: 27 tờ PL6X1500x12600 | AZ40: =IF(AR40>AV40,AR40-AV40,"0") -> 510.3 | BA40: =IF(AS40>AW40,AS40-AW40,"0") -> 24035.13 | BC40: 030325HN-IBS | BD40: Hùng Nguyên | BE40: Thép tấm 6x1500x12600 | BF40: SS400 | BG40: 16023.42 | BH40: 45719 | BI40: 340.2 | BJ40: 16023.42 | BK40: 13181.82 | BL40: =BK40*BJ40*1.1 -> 2.3233962e+08 | BM40: 45751 | BN40: =SUMIF($J:$J,J40,$BI:$BI) -> 510.3 | BO40: =SUMIF($J:$J,J40,$BJ:$BJ) -> 24035.13 | BP40: ACC | CL40: =SUMIF($J:$J,J40,$BZ:$BZ) -> 0 | CM40: =SUMIF($J:$J,J40,$CA:$CA) -> 0 | CR40: =BN40+CL40 -> 510.3 | CS40: =BO40+CM40 -> 24035.13 | CT40: =AZ40-CR40 -> 0 | CU40: =BA40-CS40 -> 0 | CV40: =IF(CT40<0,"Thừa",IF(CT40=0,"Đủ","Thiếu")) -> Đủ | DR40: 488.16985 | DS40: 22992.8
...

Sheet Tổng hợp
A1: Item/ STT | B1: Total Ordered/Tổng dự trù | D1: Tận dụng tồn kho/ Remain | G1: Khối lượng phải mua sắm/ total order | I1: VẬT TƯ TRONG NƯỚC | L1: VẬT TƯ OVERSEA | O1: Khối lượng phải mua còn lại theo PR/ total order from PR | Q1: Khối lượng phải mua còn lại/ total order
B2: Q.Ty/S.Lượng (M/M2/Set) | C2: Weight/K.Lượng (Kg) | D2: Q.Ty/S.Lượng (M/M2/Set) | E2: Weight/K.Lượng (Kg) | F2: Đã nghiệm thu (Kg) | G2: Q.Ty/ S.Lượng | H2: Weight/ K.Lượng (Kg) | I2: S.Lượng giao hàng thực tế/ Handover Q'ty | J2: K.Lượng giao hàng thực tế// Handover weight | K2: Khối lượng nghiệm thu đạt/ Weight Acc. Inspection | L2: S.Lượng giao hàng thực tế/ Handover Q'ty | M2: K.Lượng giao hàng thực tế// Handover weight | N2: Khối lượng nghiệm thu đạt/ Weight Acc. Inspection | O2: Q.Ty/S.Lượng (M/M2/Set) | P2: Weight/ K.Lượng (Kg) | Q2: Q.Ty/S.Lượng (M/M2/Set) | R2: Weight/ K.Lượng (Kg)
A3: A. | B3: Main-Material / Vật tư chính
A4: 1 | B4: ='078'!AR7 -> 42283.706 | C4: ='078'!AS7 -> 688314.75 | D4: ='078'!AV7 -> 819.85066 | E4: ='078'!AW7 -> 34363.468 | F4: =E4 -> 34363.468 | G4: ='078'!AZ7 -> 41489.675 | H4: ='078'!BA7 -> 654353.36 | I4: ='078'!BI7 -> 33991.021 | J4: ='078'!BJ7 -> 481149.21 | K4: ='078'!BR7 -> 0 | L4: ='078'!BZ7 -> 10816.6 | M4: ='078'!CA7 -> 166044.39 | N4: 0 | O4: =B4-I4-L4-E4 -> -36887.383 | P4: =C4-J4-M4-F4 -> 6757.6852 | Q4: ='078'!CT7 -> -3317.9457 | R4: ='078'!CU7 -> 7159.76
A5: B. | B5: Accessory-Material / Vật tư phụ
A6: 1 | B6: ='078'!AR243 -> 19395 | C6: ='078'!AS243 -> 0 | D6: ='078'!AV243 -> 0 | E6: ='078'!AW243 -> 0 | F6: =E6 -> 0 | G6: ='078'!AZ243 -> 19449 | H6: ='078'!BA9 -> 0 | I6: ='078'!BI243 -> 19429 | J6: ='078'!BJ243 -> 0 | K6: ='078'!BR243 -> 0 | O6: =B6-I6 -> -34 | P6: =C6-J6 -> 0 | Q6: ='078'!CT243 -> 20 | R6: ='078'!CU243 -> 0
A7: C. | B7: Packing Material / Vật tư kiện
A8: 1 | B8: ='078'!AR310 -> 26592.682 | C8: ='078'!AS310 -> 77765.554 | D8: ='078'!AV310 -> 1634.9042 | E8: ='078'!AW310 -> 7177.7415 | F8: =E8 -> 7177.7415 | G8: ='078'!AZ310 -> 24957.778 | H8: ='078'!BA310 -> 70587.812 | I8: ='078'!BI310 -> 21445.505 | J8: ='078'!BJ310 -> 72120.6 | K8: ='078'!BR310 -> 0 | O8: =B8-I8 -> 5147.1772 | P8: =C8-J8 -> 5644.9539 | Q8: ='078'!CT310 -> 3512.273 | R8: ='078'!CU310 -> -1532.7876
A11: STT/ No. | B11: Dự án/ Hạng mục/ Project/ Items | C11: Thiết kế, Dự toán/ Design, Estimation | F11: Mua sắm/ Ordered, Puchased (Đến hiện tại/ Up to now) | K11: Chênh lệch/ Diff. (VND) | L11: Ghi chú/ Remarks
F12: Hàng mua thêm | H12: Hàng tồn
C13: Khối lượng/ Weight (Kg) | D13: Số lượng/ Q'ty (M/M2//PSC) | E13: Tổng Giá trị/ Total Cost (VND) | F13: Khối lượng/ Weight (Kg) | G13: Số lượng/ Q'ty (M/M2//PSC) | H13: Khối lượng/ Weight (Kg/N/A) Materials available at the factory | I13: Số lượng/ Q'ty (M/M2/PSC) Materials available at the factory | J13: Tổng Giá trị mua thêm/ Total Cost (VND)
A14: 1.1 | B14: Vật tư chính/ Main-Material | C14: =C4 -> 688314.75 | D14: =B4 -> 42283.706 | F14: =J4+M4 -> 647193.6 | G14: =I4+L4 -> 44807.621 | H14: =E4 -> 34363.468 | I14: =D4 -> 819.85066 | J14: ='078'!BL7+'078'!CC7*26200 -> 1.8949359e+10
A15: 1.2 | B15: Vật tư phụ/ Accessory-Material | C15: =C6 -> 0 | D15: =B6 -> 19395 | F15: =J6+M6 -> 0 | G15: =I6+L6 -> 19429 | H15: =E6 -> 0 | I15: =D6 -> 0 | J15: ='078'!BL243+'078'!CC243*26200 -> 547538486
A16: 1.3 | B16: Vật tư kiện/ Packing Material | C16: =C8 -> 77765.554 | D16: =B8 -> 26592.682 | F16: =J8+M8 -> 72120.6 | G16: =I8+L8 -> 21445.505 | H16: =E8 -> 7177.7415 | I16: =D8 -> 1634.9042 | J16: ='078'!BL310+'078'!CC310*26200 -> 1.4114211e+09

Sheet BG Gnee 2
B1: GNEE STEEL CO.,LIMITED
B2: FLAT/RM 1512 15/F LUCKY CENTRE NO.165-171 WAN CHAI ROAD WAN CHAI HK
A3: TEL: +86 15286968617 E-mail:alice@gescosteel.com
A4: QUOTATION SHEET
A5: QUOTATION NO.: GNEEYPH20240527-1
A6: DATE: MAY.27TH,2024
A7: TO:IBS
A8: SR NO. | B8: PRODUCT NAME | C8: SPECIFICATION (mm) | F8: UNIT WEIGHT (KG/PCS) | G8: QUANTITY | I8: FOB CHINA
E9: Số lượng (m/m2) | G9: QTY (PCS) | H9: WEIGHT (KG) | I9: UNIT PRICE（USD/KG) | J9: AMOUNT (USD) | K9: lead time
A10: A-8 | B10: HARDOX 450 PLATE | C10: 6*2000*6000 | E10: =G10*2*6 -> 36 | F10: 565.2 | G10: 3 | H10: =G10*F10 -> 1695.6 | I10: 3.16 | J10: =I10*H10 -> 5358.096 | K10: 20days
A11: A-15 | B11: NM400 PLATE | C11: 12*1500*3700 | E11: =G11*1.5*3.7 -> 5.55 | F11: 653.5 | G11: 1 | H11: =G11*F11 -> 653.5 | I11: 1.1 | J11: =I11*H11 -> 718.85 | K11: 20days
A12: A-20 | B12: HARDOX 500 PLATE | C12: 16*2000*6000 | E12: =G12*2*6 -> 12 | F12: 1507.2 | G12: 1 | H12: =G12*F12 -> 1507.2 | I12: 3.07 | J12: =I12*H12 -> 4627.104 | K12: 20days
A13: A-27 | B13: HARDOX 500 PLATE | C13: 22*2000*6000 | E13: =G13*2*6 -> 12 | F13: =22*2*6*7.85 -> 2072.4 | G13: 1 | H13: =G13*F13 -> 2072.4 | I13: 3.16 | J13: =I13*H13 -> 6548.784 | K13: 20days
A14: A-5 | B14: SA240-304 PLATE | C14: 2*1219*2438 | E14: =G14*1.219*2.438 -> 2.971922 | F14: 47.2 | G14: 1 | H14: =G14*F14 -> 47.2 | I14: 3.29 | J14: =I14*H14 -> 155.288
A15: A-64 | B15: SUS 304 ROUND BAR | C15: 40*6000 | E15: =G15*6 -> 12 | F15: 59.8 | G15: 2 | H15: =G15*F15 -> 119.6 | I15: 3.72 | J15: =I15*H15 -> 444.912
A16: A-46 | B16: Q235B PIPE | C16: 102*6*6000 | E16: =G16*6 -> 6 | F16: 85.2 | G16: 1 | H16: =G16*F16 -> 85.2 | I16: 0.91 | J16: =I16*H16 -> 77.532
A17: A-47 | B17: Q235B PIPE | C17: 108*5*6000 | E17: =G17*6 -> 126 | F17: 76.2 | G17: 21 | H17: =G17*F17 -> 1600.2 | I17: 0.91 | J17: =I17*H17 -> 1456.182
A18: A-48 | B18: Q235B PIPE | C18: 121*5*6000 | E18: =G18*6 -> 60 | F18: 85.8 | G18: 10 | H18: =G18*F18 -> 858 | I18: 0.91 | J18: =I18*H18 -> 780.78
A19: A-49 | B19: Q235B PIPE | C19: 140*6*6000 | E19: =G19*6 -> 150 | F19: 119 | G19: 25 | H19: =G19*F19 -> 2975 | I19: 0.91 | J19: =I19*H19 -> 2707.25
A20: A-50 | B20: Q235B PIPE | C20: 168*8*6000 | E20: =G20*6 -> 18 | F20: 189.4 | G20: 3 | H20: =G20*F20 -> 568.2 | I20: 0.91 | J20: =I20*H20 -> 517.062
A21: A-51 | B21: Q235B PIPE | C21: 194*8*6000 | E21: =G21*6 -> 6 | F21: 220.2 | G21: 1 | H21: =G21*F21 -> 220.2 | I21: 0.91 | J21: =I21*H21 -> 200.382
A22: A-52 | B22: Q235B PIPE | C22: 245*10*12000 | E22: =G22*12 -> 12 | F22: 695.5 | G22: 1 | H22: =G22*F22 -> 695.5 | I22: 0.91 | J22: =I22*H22 -> 632.905
A23: A-53 | B23: Q235B PIPE | C23: 32*4*6000 | E23: =G23*6 -> 6 | F23: 16.6 | G23: 1 | H23: =G23*F23 -> 16.6 | I23: 0.91 | J23: =I23*H23 -> 15.106
A24: A-54 | B24: Q235B PIPE | C24: 60*3.5*6000 | E24: =G24*6 -> 6 | F24: 29.3 | G24: 1 | H24: =G24*F24 -> 29.3 | I24: 0.91 | J24: =I24*H24 -> 26.663
A25: A-55 | B25: Q235B PIPE | C25: 60*6*6000 | E25: =G25*6 -> 6 | F25: 47.9 | G25: 1 | H25: =G25*F25 -> 47.9 | I25: 0.91 | J25: =I25*H25 -> 43.589
A26: A-57 | B26: Q235B PIPE | C26: 76*5*6000 | E26: =G26*6 -> 36 | F26: 52.6 | G26: 6 | H26: =G26*F26 -> 315.6 | I26: 0.91 | J26: =I26*H26 -> 287.196
A27: AMOUNT | G27: =SUM(G10:G26) -> 80 | H27: =SUM(H10:H26) -> 13507.2 | J27: =SUM(J10:J26) -> 24597.681
A28: SPECIFICATION:
