Workbook
Name \0: #REF!
Name \a: #N/A
Name \a: #N/A
Name \a: #N/A
Name \a: #N/A
Name \a: #N/A
Name \a: #N/A
Name \a: #N/A
Name \a: #N/A
Name \a: #REF!
Name \b: #N/A
Name \c: #N/A
Name \d: #N/A
Name \e: #N/A
Name \f: #N/A
Name \g: #N/A
Name \h: #N/A
Name \h: #N/A
Name \h: #N/A
Name \h: #N/A
Name \h: #N/A
Name \h: #N/A
Name \h: #N/A
Name \h: #N/A
Name \h: [1]PP!$IC$5
Name \i: #N/A
Name \i: #N/A
Name \i: #N/A
Name \i: #N/A
Name \i: #N/A
Name \i: #N/A
Name \i: #N/A
Name \i: #N/A
Name \i: [1]PP!$IP$7844
Name \j: #N/A
Name \k: #N/A
Name \KWS123: #N/A
Name \m: #N/A
Name \m: #N/A
Name \m: #N/A
Name \m: #N/A
Name \m: #N/A
Name \m: #N/A
Name \m: #N/A
Name \m: #N/A
Name \m: [1]PP!#REF!
Name \n: #N/A
Name \p: #REF!
Name \s: #N/A
Name \s: #N/A
Name \s: #N/A
Name \s: #N/A
Name \s: #N/A
Name \s: #N/A
Name \s: #N/A
Name \s: #N/A
Name \s: [1]PP!$HX$3
Name \t: #N/A
Name \v: #REF!
Name \w: #REF!

Sheet Giải tình Tam Đa
A1: BID ANALYSIS - GIẢI TRÌNH MUA SẮM/ĐẤU THẦU
A3: Project | B3: PROJECT No/ Dự án: 25-GEN-G-07
A4: Dự án
A5: Subject | B5: Cung cấp vật tư bu lông, phụ kiện
A6: Chủ đề
A8: No. | B8: CONTENT | C8: Phạm vi công việc | H8: Dự toán | K8: Đã mua | L8: Đơn vị cung cấp chào giá (vnđ) | O8: Lựa chọn | P8: Ghi chú
A9: Item | B9: Description/ Chi tiết | C9: Profile/ Vật tư | D9: Grade/ Mác vật liệu | E9: Số lượng Mua | F9: Số lượng PR | G9: Đơn vị | H9: Khối lượng/ Số lượng | I9: Đơn giá (vnd) | J9: Thành tiền (vnd) | K9: Thành tiền (vnd) | L9: Tam Đa
L10: Phạm vi | M10: Đơn giá (VND) | N10: Thành Tiền (Không có VAT)
A11: Tổng | B11: Bolt-Material / Vật tư bulong, phụ kiện | H11: N/A | I11: N/A | N11: =SUM(N12:N16) -> 5580000 | P11: =J11-K11-N11 -> -5580000
A12: G07-VPK-020 | B12: Threaded half coupling-không mạ | C12: 3/8" NPS Threaded half coupling #3000-ASME B16.11 | D12: ASME-SA105M | E12: 4 | F12: 4 | G12: cái | H12: N/A | I12: N/A | J12: N/A | L12: V | M12: N/A | N12: N/A | O12: Tam Đa
A13: G07-VPK-021 | B13: Threaded half coupling-không mạ | C13: 3/4" NPS Threaded half coupling #3000-ASME B16.11 | D13: ASME-SA105M | E13: 4 | F13: 4 | G13: cái | H13: N/A | I13: N/A | J13: N/A | L13: V | M13: 65000 | N13: =M13*F13 -> 260000 | O13: Tam Đa
A14: G07-VPK-022 | B14: Threaded half coupling-không mạ | C14: 1" NPS Threaded half coupling #3000-ASME B16.11 | D14: ASME-SA105M | E14: 4 | F14: 4 | G14: cái | H14: N/A | I14: N/A | J14: N/A | L14: V | M14: 95000 | N14: =M14*F14 -> 380000 | O14: Tam Đa
A15: G07-VPK-023 | B15: Threaded half coupling-không mạ | C15: 2" NPS Threaded half coupling #3000-ASME B16.11 | D15: ASME-SA105M | E15: 20 | F15: 20 | G15: cái | H15: N/A | I15: N/A | J15: N/A | L15: V | M15: 195000 | N15: =M15*F15 -> 3900000 | O15: Tam Đa
A16: G07-VPK-024 | B16: plug | C16: 2" NPS Threaded hex head plug #3000-ASME B16.11 | D16: ASME-SA105M | E16: 4 | F16: 4 | G16: cái | H16: N/A | I16: N/A | J16: N/A | L16: V | M16: 260000 | N16: =M16*F16 -> 1040000 | O16: Tam Đa
B17: Xếp hạng | M17: 1
A18: Ghi chú: Tiếp tục công tác mua sắm để đảm báo tiến độ
A19: NGƯỜI ĐỀ NGHỊ/ RECOMMENDATION BY: | C19: NGƯỜI KIỂM TRA/ DEPARTMENT HEAD CHECK BY: | G19: APPROVED BY: PHÊ DUYỆT
G20: Nguyễn Quang Vinh | K20: Hoàng Ngọc Bằng | O20: Đoàn Văn Toàn

Sheet Giải tình ngọc hiếu
A1: BID ANALYSIS - GIẢI TRÌNH MUA SẮM/ĐẤU THẦU
A3: Project | B3: PROJECT No/ Dự án: 25-GEN-G-07
A4: Dự án
A5: Subject | B5: Cung cấp vật tư thép hình
A6: Chủ đề
A8: No. | B8: CONTENT | C8: Phạm vi công việc | H8: Dự toán | K8: Đã mua | L8: Đơn vị cung cấp chào giá (vnđ) | O8: Đơn vị cung cấp chào giá (vnđ) | R8: Lựa chọn | S8: Ghi chú
A9: Item | B9: Description/ Chi tiết | C9: Profile/ Vật tư | D9: Grade/ Mác vật liệu | E9: Số lượng Mua | F9: Số lượng PR | G9: Đơn vị | H9: Khối lượng/ Số lượng | I9: Đơn giá (vnd) | J9: Thành tiền (vnd) | K9: Thành tiền (vnd) | L9: HÙNG NGUYÊN | O9: NGỌC HIẾU
L10: Phạm vi | M10: Đơn giá (VND) | N10: Thành Tiền (Không có VAT) | O10: Phạm vi | P10: Đơn giá (VND) | Q10: Thành Tiền (Không có VAT)
A11: Tổng | B11: Main-Material / Vật tư chính thép đen | H11: N/A | I11: N/A | K11: ='Tổng hợp'!J20 -> 4.3019969e+08 | Q11: =SUM(Q12:Q12) -> 45173648 | S11: =J11-K11-N11-Q11 -> -4.7537334e+08
A12: G07-VTC01-006 | B12: Thép U100*50*5*7,5*6000 | C12: C100x50x5x7.5-L6000 | D12: Q235A/SS400 | E12: =56*6 -> 336 | F12: 336 | G12: m2 | H12: N/A | I12: N/A | J12: N/A | K12: N/A | L12: V | M12: =19000/1.1 -> 17272.727 | N12: N/A | O12: V | P12: 14363.64 | Q12: 45173648 | R12: Ngọc Hiếu | S12: Chưa có dự toán
B13: Xếp hạng | M13: 2 | P13: 1
A14: Ghi chú: Tiếp tục công tác mua sắm để đảm báo tiến độ
A15: NGƯỜI ĐỀ NGHỊ/ RECOMMENDATION BY: | C15: NGƯỜI KIỂM TRA/ DEPARTMENT HEAD CHECK BY: | G15: APPROVED BY: PHÊ DUYỆT
G16: Nguyễn Quang Vinh | N16: Hoàng Ngọc Bằng | Q16: Đoàn Văn Toàn

Sheet Giải tình hùng nguyên
A1: BID ANALYSIS - GIẢI TRÌNH MUA SẮM/ĐẤU THẦU
A3: Project | B3: PROJECT No/ Dự án: 25-GEN-G-07
A4: Dự án
A5: Subject | B5: Cung cấp vật tư thép tấm
A6: Chủ đề
A8: No. | B8: CONTENT | C8: Phạm vi công việc | H8: Dự toán | K8: Đã mua | L8: Đơn vị cung cấp chào giá (vnđ) | O8: Đơn vị cung cấp chào giá (vnđ) | R8: Lựa chọn | S8: Ghi chú
A9: Item | B9: Description/ Chi tiết | C9: Profile/ Vật tư | D9: Grade/ Mác vật liệu | E9: Số lượng Mua | F9: Số lượng PR | G9: Đơn vị | H9: Khối lượng/ Số lượng | I9: Đơn giá (vnd) | J9: Thành tiền (vnd) | K9: Thành tiền (vnd) | L9: HÙNG NGUYÊN | O9: APEC
L10: Phạm vi | M10: Đơn giá (VND) | N10: Thành Tiền (Không có VAT) | O10: Phạm vi | P10: Đơn giá (VND) | Q10: Thành Tiền (Không có VAT)
A11: Tổng | B11: Main-Material / Vật tư chính thép đen | H11: N/A | I11: N/A | K11: ='Tổng hợp'!J20-N11 -> 2.1240928e+08 | N11: =SUM(N12:N13) -> 217790411 | Q11: =SUM(Q12:Q12) -> 0 | S11: =J11-K11-N11 -> -4.3019969e+08
A12: G07-VTC01-003 | B12: PL6X2000X12000 | C12: Thép tấm 6x2000x12000 | D12: Q235A/SS400 | E12: 216 | F12: 216 | G12: m2 | H12: N/A | I12: N/A | J12: N/A | K12: N/A | L12: V | M12: 13272.73 | N12: 135031446 | O12: V | P12: =14700/1.1 -> 13363.636 | Q12: N/A | R12: HÙNG NGUYÊN | S12: Chưa có dự toán
A13: G07-VTC01-005 | B13: PL16X2000X12000 | C13: Thép tấm 16x2000x12000 | D13: Q235A/SS400 | E13: 36 | F13: 36 | G13: m2 | H13: N/A | I13: N/A | J13: N/A | K13: N/A | L13: V | M13: 13727.27 | N13: 82758965 | O13: V | P13: =15400/1.1 -> 14000 | Q13: N/A | R13: HÙNG NGUYÊN
B14: Xếp hạng | M14: 1 | P14: 2
A15: Ghi chú: Tiếp tục công tác mua sắm để đảm báo tiến độ
A16: NGƯỜI ĐỀ NGHỊ/ RECOMMENDATION BY: | C16: NGƯỜI KIỂM TRA/ DEPARTMENT HEAD CHECK BY: | G16: APPROVED BY: PHÊ DUYỆT
G17: Nguyễn Quang Vinh | N17: Hoàng Ngọc Bằng | Q17: Đoàn Văn Toàn

Sheet Giải tình Quang Thịnh Phát
A1: BID ANALYSIS - GIẢI TRÌNH MUA SẮM/ĐẤU THẦU
A3: Project | B3: PROJECT No/ Dự án: 25-GEN-G-08
A4: Dự án
A5: Subject | B5: Cung cấp vật tư bu lông, phụ kiện
A6: Chủ đề
A8: No. | B8: CONTENT | C8: Phạm vi công việc | H8: Dự toán | K8: Đã mua | L8: Đơn vị cung cấp chào giá (vnđ) | O8: Lựa chọn | P8: Ghi chú
A9: Item | B9: Description/ Chi tiết | C9: Profile/ Vật tư | D9: Grade/ Mác vật liệu | E9: Số lượng Mua | F9: Số lượng PR | G9: Đơn vị | H9: Khối lượng/ Số lượng | I9: Đơn giá (vnd) | J9: Thành tiền (vnd) | K9: Thành tiền (vnd) | L9: Quang Thịnh Phát
L10: Phạm vi | M10: Đơn giá (VND) | N10: Thành Tiền (Không có VAT)
A11: Tổng | B11: Main-Material / Vật tư chính thép đen | H11: N/A | I11: N/A | N11: =SUM(N12:N12) -> 14079545 | P11: =J11-K11-N11 -> -14079545
A12: G07-VTC01-007 | B12: SHS 70x70x5-L6000 | C12: Thép hộp đen 60 x 60 x 5,5 x 6.000 mm | D12: Q235A/SS400 | E12: =16*6 -> 96 | F12: 96 | G12: m | H12: N/A | I12: N/A | J12: N/A | L12: V | M12: 15909.09 | N12: 14079545 | O12: Quang thịnh Phát | P12: Chưa có dự toán
B13: Xếp hạng | M13: 1
A14: Ghi chú: Tiếp tục công tác mua sắm để đảm báo tiến độ
A15: NGƯỜI ĐỀ NGHỊ/ RECOMMENDATION BY: | C15: NGƯỜI KIỂM TRA/ DEPARTMENT HEAD CHECK BY: | G15: APPROVED BY: PHÊ DUYỆT
G16: Nguyễn Quang Vinh | K16: Hoàng Ngọc Bằng | O16: Đoàn Văn Toàn

Sheet 25-GEN-G-07
G1: THEO DÕI VẬT TƯ DỰ ÁN/ MATERIAL CONTROL LOG | L1: Hướng dẫn cập nhật thông tin: | P1: Thời gian nộp bảng cập nhật: | CI1: DỰ TOÁN
G2: Tên dự án/ Project no.:25-GEN-G-07 | L2: - Chữ tô màu xanh: | N2: Chưa cập nhật | P2: - Trong ngày khi có biến động.
G3: Cập nhật ngày/ Update to: | I3: =TODAY() -> 46086 | L3: - Chữ tô màu đỏ: | N3: Đã cập nhật mới | P3: - Báo cáo hàng tuần vào 16:30 mỗi chiều thứ 2. | AF3: =SUBTOTAL(9,AF7:AF1148) -> 0
B4: Đánh giá (Thiếu/ Đủ/ Thừa) | G4: Item/ STT | H4: Description/ Chi tiết | I4: Profile/ Vật tư | J4: Grade/ Mác vật liệu | K4: Unit/ Đơn vị | L4: U.Weight/ Đ.Trọng (Kg/m2,m,pcs) | M4: Net Quantity/Số lượng tinh | O4: Current Ordered/Dự trù lần 0 (Ngày 20/12/2025) | Q4: Current Ordered/Dự trù lần 1 (Ngày 13/1/2026) | S4: Current Ordered/Dự trù lần 2 (Ngày 14/1/2026) | U4: Current Ordered/Dự trù lần 3 (Ngày 21/1/2026) | W4: Current Ordered/Dự trù lần 4 (Ngày 27/1/2026) | Y4: Current Ordered/Dự trù lần 5 (Ngày 11/2/2026) | AA4: Total Ordered/Tổng dự trù | AC4: Remarks/ Ghi chú | AD4: Tận dụng tồn kho/ Remain | AI4: Khối lượng phải mua sắm/ total order | AK4: Ngày bàn giao vật tư/ Material avaiable for hand over date | AL4: VẬT TƯ TRONG NƯỚC | AY4: ĐÃ MUA TRONG NƯỚC | BA4: QC Nghiệm thu | BE4: Mua sắm nước ngoài/ Oversea purchase | BW4: ĐÃ MUA NHẬP KHẨU | BY4: Nghiệm thu | CC4: TỔNG ĐÃ MUA TRONG VÀ NGOÀI NƯỚC | CE4: So sánh với số lượng vật tư PR | CH4: Remarks/ Ghi chú
M5: Q.Ty/ S.Lượng | N5: Weight/ K.Lượng (Kg) | O5: Q.Ty/ S.Lượng | P5: Weight/ K.Lượng (Kg) | Q5: Q.Ty/ S.Lượng | R5: Weight/ K.Lượng (Kg) | S5: Q.Ty/ S.Lượng | T5: Weight/ K.Lượng (Kg) | U5: Q.Ty/ S.Lượng | V5: Weight/ K.Lượng (Kg) | W5: Q.Ty/ S.Lượng | X5: Weight/ K.Lượng (Kg) | Y5: Q.Ty/ S.Lượng | Z5: Weight/ K.Lượng (Kg) | AA5: Q.Ty/ S.Lượng | AB5: Weight/ K.Lượng (Kg) | AD5: Report No. | AE5: Q.Ty/ S.Lượng | AF5: Weight/ K.Lượng (Kg) | AG5: Ngày nghiệm thu ACC | AH5: Remarks/ Ghi chú | AI5: Q.Ty/ S.Lượng | AJ5: Weight/ K.Lượng (Kg) | AL5: Số Hợp đồng / Contract No | AM5: Nhà cung cấp/ Vendor | AN5: Profile/ Vật tư | AO5: Grade/ Mác vật liệu | AP5: Contract weight ( K.Lượng theo HĐ) | AQ5: Ngày ký HD/ Contract date | AR5: S.Lượng giao hàng thực tế/ Handover Q'ty | AS5: K.Lượng giao hàng thực tế// Handover weight | AT5: Đơn giá / Unit Price (Not VAT) | AU5: Tổng tiền bao gồm cả VAT (VNĐ) | AV5: Tiền VAT | AW5: Tổng tiền chưa VAT (VNĐ) | AX5: Bàn giao sản xuất/ Handover to Product | AY5: Q.Ty/ S.Lượng | AZ5: Weight/ K.Lượng (Kg) | BA5: Report No. | BB5: Inspection date | BC5: Khối lượng nghiệm thu đạt/ Weight Acc. Inspection | BD5: Results | BE5: Số Hợp đồng / Contract No | BF5: Nhà cung cấp/ Vendor | BG5: Profile/ Vật tư | BH5: Grade/ Mác vật liệu | BI5: Weight/ Khối lượng (Kg) | BJ5: Ngày ký HD/ Contract date | BK5: Số lượng giao hàng thực tế/ Handover Q'ty | BL5: Khối lượng giao hàng thực tế/ Handover Q'ty | BM5: Đơn giá / Unit Price | BN5: Thành tiền Hợp đồng/ total | BO5: Ngày mở L/C/ LC issued date | BP5: Hàng đi từ cảng nước ngoài/ Export Port | BQ5: Hàng Đến cảng HP (CIF)/ HaiPhong CIF | BR5: Ngày thanh toán / Payment date | BS5: Thủ tục hải quan, vận chuyển/ Paper work, local transportaion date | BT5: Ngày hàng về / Arived | BU5: Ngày mời nghiệm thu / invice QC date | BV5: Bàn giao sản xuất/ Handover to Product | BW5: Q.Ty/ S.Lượng | BX5: Weight/ K.Lượng (Kg) | BY5: Report No. | BZ5: Inspection date | CA5: Khối lượng nghiệm thu đạt/ Weight Acc. Inspection | CB5: Results | CC5: Q.Ty/ S.Lượng | CD5: Weight/ K.Lượng (Kg) | CE5: Q.Ty/ S.Lượng | CF5: Weight/ K.Lượng (Kg) | CG5: Đánh giá (Thiếu/ Đủ/ Thừa) | CI5: STT | CJ5: Chi tiết vật liệu | CL5: ĐVT | CM5: Định mức | CN5: Số lượng | CO5: Khối lượng | CP5: Đơn giá (VNĐ)
C6: Số lượng cần (M/M2) | D6: Xin chuyển đổi | E6: Tiền cần cho phần hàng chưa nhận được hoặc chưa đặt hàng | F6: Kế hoạch | G6: 1 | H6: =G6+1 -> 2 | I6: =H6+1 -> 3 | J6: =I6+1 -> 4 | K6: =J6+1 -> 5 | L6: =K6+1 -> 6 | M6: =L6+1 -> 7 | N6: =M6+1 -> 8 | O6: =N6+1 -> 9 | P6: =O6+1 -> 10 | AA6: =P6+1 -> 11 | AB6: =AA6+1 -> 12 | AC6: =AB6+1 -> 13 | AD6: =AC6+1 -> 14 | AE6: =AD6+1 -> 15 | AF6: =AE6+1 -> 16 | AG6: =AF6+1 -> 17 | AH6: =AG6+1 -> 18 | AI6: =AH6+1 -> 19 | ... AT6: =AS6+1 -> 30 | AX6: =AT6+1 -> 31 | AY6: =AX6+1 -> 32 | AZ6: =AY6+1 -> 33 | BA6: =AZ6+1 -> 34 | BB6: =BA6+1 -> 35 | BC6: =BB6+1 -> 36 | BD6: =BC6+1 -> 37 | BE6: =BD6+1 -> 38 | BF6: =BE6+1 -> 39 | ... CH6: =CG6+1 -> 67
G7: VTC01 | H7: Main-Material / Vật tư chính thép đen | AA7: =SUM(AA8:AA24) -> 931.375 | AB7: =SUM(AB8:AB24) -> 31090.659 | AC7: =SUM(AC8:AC24) -> 0 | AD7: =SUM(AD8:AD24) -> 0 | AE7: =SUM(AE8:AE24) -> 40.375 | AF7: =SUM(AF8:AF24) -> 1107.6395 | AG7: =SUM(AG8:AG24) -> 0 | AH7: =SUM(AH8:AH24) -> 0 | ... CH7: =SUM(CH8:CH24) -> 0 | CI7: I
A8: =IF(G8=G7,"ok","Hiện") -> Hiện | B8: =CG8 -> Đủ | C8: =CE8 -> 0 | G8: G07-VTC01-001 | H8: Tôn tấm | I8: PL3X1500X6000 | J8: Q235A/SS400 | K8: m2 | L8: 23.55 | M8: =+N8/L8 -> 0 | N8: 0 | O8: 45 | P8: 1059.75 | Q8: -45 | R8: -1059.75 | U8: 108 | V8: 2543.4 | W8: 0 | X8: 0 | AA8: =O8+Q8+S8+U8+W8+Y8 -> 108 | AB8: =P8+R8+T8+V8+X8+Z8 -> 2543.4 | AC8: REV03-khay đựng | AI8: =IF(AA8>AE8,AA8-AE8,"0") -> 108 | AJ8: =IF(AB8>AF8,AB8-AF8,"0") -> 2543.4 | AK8: Chưa có | AY8: =SUMIF($I:$I,I8,$AR:$AR) -> 108 | AZ8: =SUMIF($I:$I,I8,$AS:$AS) -> 2543.4 | BW8: =SUMIF($I:$I,I8,$BK:$BK) -> 0 | BX8: =SUMIF($I:$I,I8,$BL:$BL) -> 0 | CC8: =AY8+BW8 -> 108 | CD8: =AZ8+BX8 -> 2543.4 | CE8: =AI8-CC8 -> 0 | CF8: =AJ8-CD8 -> 0 | CG8: =IF(CE8<0,"Thừa",IF(CE8=0,"Đủ","Thiếu")) -> Đủ
A9: =IF(G9=G8,"ok","Hiện") -> ok | G9: G07-VTC01-001 | H9: Tôn tấm | I9: PL3X1500X6000 | J9: Q235A/SS400 | K9: m2 | AL9: ? | AM9: Hùng Nguyên | AN9: Thép tấm 6x2000x12000 | AO9: SS400 | AP9: 2543.4 | AQ9: 46048 | AR9: 108 | AS9: 2543.4 | AT9: 13363.64 | AU9: =AT9*AS9*1.1 -> 37387990 | AV9: 0.1 | AW9: =AT9*AS9 -> 33989082 | AX9: 46051
A10: =IF(G10=G9,"ok","Hiện") -> Hiện | B10: =CG10 -> Đủ | C10: =CE10 -> 0 | G10: G07-VTC01-002 | H10: Tôn tấm | I10: PL5X1500X3200 | J10: Q235A/SS400 | K10: m2 | L10: 39.25 | M10: =+N10/L10 -> 3.87008 | N10: 151.90064 | O10: 4.8 | P10: 188.4 | U10: 0 | V10: 0 | W10: 0 | X10: 0 | AA10: =O10+Q10+S10+U10+W10+Y10 -> 4.8 | AB10: =P10+R10+T10+V10+X10+Z10 -> 188.4 | AE10: 4.8 | AF10: 188.4 | AH10: Hàng tồn | AI10: =IF(AA10>AE10,AA10-AE10,"0") -> 0 | AJ10: =IF(AB10>AF10,AB10-AF10,"0") -> 0 | AK10: Chưa có | AY10: =SUMIF($I:$I,I10,$AR:$AR) -> 0 | AZ10: =SUMIF($I:$I,I10,$AS:$AS) -> 0 | BW10: =SUMIF($I:$I,I10,$BK:$BK) -> 0 | BX10: =SUMIF($I:$I,I10,$BL:$BL) -> 0 | CC10: =AY10+BW10 -> 0 | CD10: =AZ10+BX10 -> 0 | CE10: =AI10-CC10 -> 0 | CF10: =AJ10-CD10 -> 0 | CG10: =IF(CE10<0,"Thừa",IF(CE10=0,"Đủ","Thiếu")) -> Đủ
A11: =IF(G11=G10,"ok","Hiện") -> Hiện | B11: =CG11 -> Đủ | C11: =CE11 -> 0 | G11: G07-VTC01-003 | H11: Tôn tấm | I11: PL6X2000X12000 | J11: Q235A/SS400 | K11: m2 | L11: 47.1 | M11: =+N11/L11 -> 196.80073 | N11: =7693.71435+1575.6 -> 9269.3144 | O11: 216 | P11: 10173.6 | U11: 0 | V11: 0 | W11: 0 | X11: 0 | AA11: =O11+Q11+S11+U11+W11+Y11 -> 216 | AB11: =P11+R11+T11+V11+X11+Z11 -> 10173.6 | AC11: REV03-tăng khối lượng tinh 201.4 kg | AI11: =IF(AA11>AE11,AA11-AE11,"0") -> 216 | AJ11: =IF(AB11>AF11,AB11-AF11,"0") -> 10173.6 | AK11: Chưa có | AL11: ? | AM11: Hùng Nguyên | AN11: Thép tấm 6x2000x12000 | AO11: SS400 | AP11: 10173.6 | AQ11: 46036 | AR11: 216 | AS11: 10173.6 | AT11: 13272.73 | AU11: =AT11*AS11*1.1 -> 1.4853459e+08 | AV11: 0.1 | AW11: =AT11*AS11 -> 1.3503145e+08 | AX11: 46041 | AY11: =SUMIF($I:$I,I11,$AR:$AR) -> 216 | AZ11: =SUMIF($I:$I,I11,$AS:$AS) -> 10173.6 | BW11: =SUMIF($I:$I,I11,$BK:$BK) -> 0 | BX11: =SUMIF($I:$I,I11,$BL:$BL) -> 0 | CC11: =AY11+BW11 -> 216 | CD11: =AZ11+BX11 -> 10173.6 | CE11: =AI11-CC11 -> 0 | CF11: =AJ11-CD11 -> 0 | CG11: =IF(CE11<0,"Thừa",IF(CE11=0,"Đủ","Thiếu")) -> Đủ
A12: =IF(G12=G11,"ok","Hiện") -> ok | B12: =CG12 -> Đủ | C12: =CE12 -> 0 | G12: G07-VTC01-003 | H12: Tôn tấm | I12: PL8X1000X1000 | J12: Q235A/SS400 | K12: m2 | L12: 62.8 | M12: =+N12/L12 -> 0.56050955 | N12: 35.2 | O12: 1 | P12: 62.8 | AA12: =O12+Q12+S12 -> 1 | AB12: =P12+R12+T12 -> 62.8 | AE12: 1 | AF12: 62.8 | AH12: Hàng tồn | AI12: =IF(AA12>AE12,AA12-AE12,"0") -> 0 | AJ12: =IF(AB12>AF12,AB12-AF12,"0") -> 0 | AK12: Chưa có | AY12: =SUMIF($I:$I,I12,$AR:$AR) -> 0 | AZ12: =SUMIF($I:$I,I12,$AS:$AS) -> 0 | BW12: =SUMIF($I:$I,I12,$BK:$BK) -> 0 | BX12: =SUMIF($I:$I,I12,$BL:$BL) -> 0 | CC12: =AY12+BW12 -> 0 | CD12: =AZ12+BX12 -> 0 | CE12: =AI12-CC12 -> 0 | CF12: =AJ12-CD12 -> 0 | CG12: =IF(CE12<0,"Thừa",IF(CE12=0,"Đủ","Thiếu")) -> Đủ
A13: =IF(G13=G12,"ok","Hiện") -> Hiện | B13: =CG13 -> Đủ | C13: =CE13 -> 0 | G13: G07-VTC01-004 | H13: Tôn tấm | I13: PL10X1500X1800 | J13: Q235A/SS400 | K13: m2 | L13: 78.5 | M13: =+N13/L13 -> 2.238 | N13: 175.683 | O13: 2.775 | P13: 217.8375 | U13: 0 | V13: 0 | W13: 0 | X13: 0 | AA13: =O13+Q13+S13+U13+W13+Y13 -> 2.775 | AB13: =P13+R13+T13+V13+X13+Z13 -> 217.8375 | AC13: REV03-tăng khối lượng tinh 488.7 kg | AE13: 2.775 | AF13: 217.8375 | AH13: Hàng tồn | AI13: =IF(AA13>AE13,AA13-AE13,"0") -> 0 | AJ13: =IF(AB13>AF13,AB13-AF13,"0") -> 0 | AK13: Chưa có | AY13: =SUMIF($I:$I,I13,$AR:$AR) -> 0 | AZ13: =SUMIF($I:$I,I13,$AS:$AS) -> 0 | BW13: =SUMIF($I:$I,I13,$BK:$BK) -> 0 | BX13: =SUMIF($I:$I,I13,$BL:$BL) -> 0 | CC13: =AY13+BW13 -> 0 | CD13: =AZ13+BX13 -> 0 | CE13: =AI13-CC13 -> 0 | CF13: =AJ13-CD13 -> 0 | CG13: =IF(CE13<0,"Thừa",IF(CE13=0,"Đủ","Thiếu")) -> Đủ
A14: =IF(G14=G13,"ok","Hiện") -> Hiện | B14: =CG14 -> Đủ | C14: =CE14 -> 0 | G14: G07-VTC01-005 | H14: Tôn tấm | I14: PL16X2000X12000 | J14: Q235A/SS400 | K14: m2 | L14: 125.6 | M14: =+N14/L14 -> 30.36668 | N14: 3814.055 | O14: 36 | P14: 4521.6 | U14: 0 | V14: 0 | W14: 0 | X14: 0 | AA14: =O14+Q14+S14+U14+W14+Y14 -> 36 | AB14: =P14+R14+T14+V14+X14+Z14 -> 4521.6 | AI14: =IF(AA14>AE14,AA14-AE14,"0") -> 36 | AJ14: =IF(AB14>AF14,AB14-AF14,"0") -> 4521.6 | AK14: Chưa có | AL14: ? | AM14: Hùng Nguyên | AN14: Thép tấm 16x2000x12000 | AO14: SS400 | AP14: 6028.8 | AQ14: 46036 | AR14: 36 | AS14: 6028.8 | AT14: 13727.27 | AU14: =AT14*AS14*1.1 -> 91034862 | AV14: 0.1 | AW14: =AT14*AS14 -> 82758965 | AX14: 46041 | AY14: =SUMIF($I:$I,I14,$AR:$AR) -> 36 | AZ14: =SUMIF($I:$I,I14,$AS:$AS) -> 6028.8 | BW14: =SUMIF($I:$I,I14,$BK:$BK) -> 0 | BX14: =SUMIF($I:$I,I14,$BL:$BL) -> 0 | CC14: =AY14+BW14 -> 36 | CD14: =AZ14+BX14 -> 6028.8 | CE14: =AI14-CC14 -> 0 | CF14: =AJ14-CD14 -> -1507.2 | CG14: =IF(CE14<0,"Thừa",IF(CE14=0,"Đủ","Thiếu")) -> Đủ
A15: =IF(G15=G14,"ok","Hiện") -> Hiện | B15: =CG15 -> Đủ | C15: =CE15 -> 0 | G15: G07-VTC01-006 | H15: Thép hình C | I15: C100x50x5x7.5-L6000 | J15: Q235A/SS400 | K15: m2 | L15: 9.36 | M15: 328.95 | N15: 3078.972 | O15: 336 | P15: 3144.96 | U15: 0 | V15: 0 | W15: 0 | X15: 0 | AA15: =O15+Q15+S15+U15+W15+Y15 -> 336 | AB15: =P15+R15+T15+V15+X15+Z15 -> 3144.96 | AC15: REV01-đổi profile | AI15: =IF(AA15>AE15,AA15-AE15,"0") -> 336 | AJ15: =IF(AB15>AF15,AB15-AF15,"0") -> 3144.96 | AK15: Chưa có | AL15: ? | AM15: Ngọc Hiếu | AN15: Thép U100*50*5*7,5*6000 (56 cây) | AO15: SS400 | AP15: 3145 | AQ15: 46036 | AR15: =56*6 -> 336 | AS15: 3145 | AT15: 14363.64 | AU15: =AT15*AS15*1.1 -> 49691013 | AV15: 0.1 | AW15: =AT15*AS15 -> 45173648 | AX15: 46045 | AY15: =SUMIF($I:$I,I15,$AR:$AR) -> 336 | AZ15: =SUMIF($I:$I,I15,$AS:$AS) -> 3145 | BW15: =SUMIF($I:$I,I15,$BK:$BK) -> 0 | BX15: =SUMIF($I:$I,I15,$BL:$BL) -> 0 | CC15: =AY15+BW15 -> 336 | CD15: =AZ15+BX15 -> 3145 | CE15: =AI15-CC15 -> 0 | CF15: =AJ15-CD15 -> -0.04 | CG15: =IF(CE15<0,"Thừa",IF(CE15=0,"Đủ","Thiếu")) -> Đủ
A16: =IF(G16=G15,"ok","Hiện") -> Hiện | B16: =CG16 -> Đủ | C16: =CE16 -> 0 | G16: G07-VTC01-007 | H16: Thép hộp | I16: SHS 60x60x5-L6000 | J16: Q235A/SS400 | K16: m2 | L16: 10.21 | M16: 86.562 | N16: 883.79802 | O16: 96 | P16: 980.16 | U16: 0 | V16: 0 | W16: 0 | X16: 0 | AA16: =O16+Q16+S16+U16+W16+Y16 -> 96 | AB16: =P16+R16+T16+V16+X16+Z16 -> 980.16 | AC16: REV01-đổi profile | AI16: =IF(AA16>AE16,AA16-AE16,"0") -> 96 | AJ16: =IF(AB16>AF16,AB16-AF16,"0") -> 980.16 | AK16: Chưa có | AL16: 1201/2026/QTP-IBS | AM16: Quang Thịnh Phát | AN16: Thép hộp đen 60 x 60 x 5,5 x 6.000 mm | AO16: SS400 | AP16: 885 | AQ16: 46034 | AR16: =16*6 -> 96 | AS16: 885 | AT16: 15909.09 | AU16: =AT16*AS16*1.1 -> 15487499 | AV16: 0.1 | AW16: =AT16*AS16 -> 14079545 | AX16: 46038 | AY16: =SUMIF($I:$I,I16,$AR:$AR) -> 96 | AZ16: =SUMIF($I:$I,I16,$AS:$AS) -> 885 | BW16: =SUMIF($I:$I,I16,$BK:$BK) -> 0 | BX16: =SUMIF($I:$I,I16,$BL:$BL) -> 0 | CC16: =AY16+BW16 -> 96 | CD16: =AZ16+BX16 -> 885 | CE16: =AI16-CC16 -> 0 | CF16: =AJ16-CD16 -> 95.16 | CG16: =IF(CE16<0,"Thừa",IF(CE16=0,"Đủ","Thiếu")) -> Đủ
A17: =IF(G17=G16,"ok","Hiện") -> Hiện | B17: =CG17 -> Thừa | C17: =CE17 -> -1.25 | G17: G07-VTC01-008 | H17: Tôn tấm | I17: PL2X1200X2500 | J17: Q235A/SS400 | K17: m2 | L17: =2*7.85 -> 15.7 | M17: =+N17/L17 -> 27.32508 | N17: 429.00376 | U17: 30 | V17: 471 | W17: 0 | X17: 0 | AA17: =O17+Q17+S17+U17+W17+Y17 -> 30 | AB17: =P17+R17+T17+V17+X17+Z17 -> 471 | AC17: REV03-khay đựng | AI17: =IF(AA17>AE17,AA17-AE17,"0") -> 30 | AJ17: =IF(AB17>AF17,AB17-AF17,"0") -> 471 | AY17: =SUMIF($I:$I,I17,$AR:$AR) -> 31.25 | AZ17: =SUMIF($I:$I,I17,$AS:$AS) -> 491 | BW17: =SUMIF($I:$I,I17,$BK:$BK) -> 0 | BX17: =SUMIF($I:$I,I17,$BL:$BL) -> 0 | CC17: =AY17+BW17 -> 31.25 | CD17: =AZ17+BX17 -> 491 | CE17: =AI17-CC17 -> -1.25 | CF17: =AJ17-CD17 -> -20 | CG17: =IF(CE17<0,"Thừa",IF(CE17=0,"Đủ","Thiếu")) -> Thừa
A18: =IF(G18=G17,"ok","Hiện") -> ok | G18: G07-VTC01-008 | H18: Tôn tấm | I18: PL2X1200X2500 | J18: Q235A/SS400 | K18: m2 | AL18: ? | AM18: Ngọc Hiếu | AN18: Thép tấm 2*1250*2500 | AO18: SS400 | AP18: 491 | AQ18: 46048 | AR18: =10*1.25*2.5 -> 31.25 | AS18: 491 | AT18: 14545.45 | AU18: =AT18*AS18*1.1 -> 7855997.5 | AV18: 0.1 | AW18: =AT18*AS18 -> 7141816 | AX18: 46051
A19: =IF(G19=G18,"ok","Hiện") -> Hiện | B19: =CG19 -> Đủ | C19: =CE19 -> 0 | G19: G07-VTC01-009 | H19: Ống | I19: Pipe D33.4x2.77 | J19: Q235A/SS400 | K19: m | L19: 2.69 | M19: 1.692 | N19: =+M19*L19 -> 4.55148 | U19: 1.8 | V19: 4.842 | W19: 0 | X19: 0 | AA19: =O19+Q19+S19+U19+W19+Y19 -> 1.8 | AB19: =P19+R19+T19+V19+X19+Z19 -> 4.842 | AC19: REV03-khay đựng | AE19: 1.8 | AF19: 4.842 | AH19: Sử dụng hàng tồn | AI19: =IF(AA19>AE19,AA19-AE19,"0") -> 0 | AJ19: =IF(AB19>AF19,AB19-AF19,"0") -> 0 | AY19: =SUMIF($I:$I,I19,$AR:$AR) -> 0 | AZ19: =SUMIF($I:$I,I19,$AS:$AS) -> 0 | BW19: =SUMIF($I:$I,I19,$BK:$BK) -> 0 | BX19: =SUMIF($I:$I,I19,$BL:$BL) -> 0 | CC19: =AY19+BW19 -> 0 | CD19: =AZ19+BX19 -> 0 | CE19: =AI19-CC19 -> 0 | CF19: =AJ19-CD19 -> 0 | CG19: =IF(CE19<0,"Thừa",IF(CE19=0,"Đủ","Thiếu")) -> Đủ
A20: =IF(G20=G19,"ok","Hiện") -> Hiện | B20: =CG20 -> Đủ | C20: =CE20 -> 0 | G20: G07-VTC01-010 | H20: Ống | I20: Pipe D42.2x2.27 | J20: Q235A/SS400 | K20: m | L20: 3.74 | M20: =0.13*27 -> 3.51 | N20: =+M20*L20 -> 13.1274 | U20: 4 | V20: 14.96 | W20: 0 | X20: 0 | AA20: =O20+Q20+S20+U20+W20+Y20 -> 4 | AB20: =P20+R20+T20+V20+X20+Z20 -> 14.96 | AC20: REV03-khay đựng | AE20: 4 | AF20: 14.96 | AH20: Sử dụng hàng tồn | AI20: =IF(AA20>AE20,AA20-AE20,"0") -> 0 | AJ20: =IF(AB20>AF20,AB20-AF20,"0") -> 0 | AY20: =SUMIF($I:$I,I20,$AR:$AR) -> 0 | AZ20: =SUMIF($I:$I,I20,$AS:$AS) -> 0 | BW20: =SUMIF($I:$I,I20,$BK:$BK) -> 0 | BX20: =SUMIF($I:$I,I20,$BL:$BL) -> 0 | CC20: =AY20+BW20 -> 0 | CD20: =AZ20+BX20 -> 0 | CE20: =AI20-CC20 -> 0 | CF20: =AJ20-CD20 -> 0 | CG20: =IF(CE20<0,"Thừa",IF(CE20=0,"Đủ","Thiếu")) -> Đủ
A21: =IF(G21=G20,"ok","Hiện") -> Hiện | B21: =CG21 -> Đủ | C21: =CE21 -> 0 | G21: G07-VTC01-011 | H21: Tôn tấm | I21: PL14x2000x12000 (2 tờ) PL14x2000x4500 (1 tầm) | J21: Q235A/SS400 | K21: m2 | L21: =7.85*14 -> 109.9 | M21: =+N21/L21 -> 47.190173 | N21: 5186.2 | W21: 57 | X21: 6264.3 | AA21: =O21+Q21+S21+U21+W21+Y21 -> 57 | AB21: =P21+R21+T21+V21+X21+Z21 -> 6264.3 | AC21: REV04-tank | AI21: =IF(AA21>AE21,AA21-AE21,"0") -> 57 | AJ21: =IF(AB21>AF21,AB21-AF21,"0") -> 6264.3 | AL21: ? | AM21: Hùng Nguyên | AN21: Thép tấm 14x2000x12000 SS400 | AO21: SS400 | AP21: 5275.2 | AQ21: 46050 | AR21: =2*(24) -> 48 | AS21: 5275.2 | AT21: 13727.27 | AU21: =AT21*AS21*1.1 -> 79655504 | AV21: 0.1 | AW21: =AT21*AS21 -> 72414095 | AX21: 46050 | AY21: =SUMIF($I:$I,I21,$AR:$AR) -> 57 | AZ21: =SUMIF($I:$I,I21,$AS:$AS) -> 6264.3 | BW21: =SUMIF($I:$I,I21,$BK:$BK) -> 0 | BX21: =SUMIF($I:$I,I21,$BL:$BL) -> 0 | CC21: =AY21+BW21 -> 57 | CD21: =AZ21+BX21 -> 6264.3 | CE21: =AI21-CC21 -> 0 | CF21: =AJ21-CD21 -> 0 | CG21: =IF(CE21<0,"Thừa",IF(CE21=0,"Đủ","Thiếu")) -> Đủ
A22: =IF(G22=G21,"ok","Hiện") -> ok | G22: G07-VTC01-011 | H22: Tôn tấm | I22: PL14x2000x12000 (2 tờ) PL14x2000x4500 (1 tầm) | J22: Q235A/SS400 | K22: m2 | AL22: ? | AM22: Hùng Nguyên | AN22: Thép tấm 14x2000x4500 SS400 | AO22: SS400 | AP22: 989.1 | AQ22: 46050 | AR22: 9 | AS22: 989.1 | AT22: 13727.27 | AU22: =AT22*AS22*1.1 -> 14935407 | AV22: 0.1 | AW22: =AT22*AS22 -> 13577643 | AX22: 46050
A23: =IF(G23=G22,"ok","Hiện") -> Hiện | B23: =CG23 -> Đủ | C23: =CE23 -> 0 | G23: G07-VTC01-012 | H23: Tôn tấm | I23: PL20x2000x6000 | J23: Q235A/SS400 | K23: m2 | L23: =7.85*20 -> 157 | M23: =+N23/L23 -> 10.34868 | N23: 1624.7428 | W23: 12 | X23: 1884 | AA23: =O23+Q23+S23+U23+W23+Y23 -> 12 | AB23: =P23+R23+T23+V23+X23+Z23 -> 1884 | AC23: REV04-support dầm chính | AI23: =IF(AA23>AE23,AA23-AE23,"0") -> 12 | AJ23: =IF(AB23>AF23,AB23-AF23,"0") -> 1884 | AL23: ? | AM23: Hùng Nguyên | AN23: Thép tấm 20x2000x6000 SS400 | AO23: SS400 | AP23: 1884 | AQ23: 46050 | AR23: 12 | AS23: 1884 | AT23: 13818.18 | AU23: =AT23*AS23*1.1 -> 28636796 | AV23: 0.1 | AW23: =AT23*AS23 -> 26033451 | AX23: 46050 | AY23: =SUMIF($I:$I,I23,$AR:$AR) -> 12 | AZ23: =SUMIF($I:$I,I23,$AS:$AS) -> 1884 | BW23: =SUMIF($I:$I,I23,$BK:$BK) -> 0 | BX23: =SUMIF($I:$I,I23,$BL:$BL) -> 0 | CC23: =AY23+BW23 -> 12 | CD23: =AZ23+BX23 -> 1884 | CE23: =AI23-CC23 -> 0 | CF23: =AJ23-CD23 -> 0 | CG23: =IF(CE23<0,"Thừa",IF(CE23=0,"Đủ","Thiếu")) -> Đủ
A24: =IF(G24=G23,"ok","Hiện") -> Hiện | B24: =CG24 -> Đủ | C24: =CE24 -> 0 | G24: G07-VTC01-013 | H24: Thép hình H | I24: H125x125x6.5.9 | J24: Q235A/SS400 | K24: m | L24: 23.8 | M24: =0.237*108 -> 25.596 | N24: =+M24*L24 -> 609.1848 | W24: 26 | X24: 618.8 | AA24: =O24+Q24+S24+U24+W24+Y24 -> 26 | AB24: =P24+R24+T24+V24+X24+Z24 -> 618.8 | AC24: REV04-support dầm chính | AE24: 26 | AF24: 618.8 | AH24: Sử dụng hàng tồn | AI24: =IF(AA24>AE24,AA24-AE24,"0") -> 0 | AJ24: =IF(AB24>AF24,AB24-AF24,"0") -> 0 | AY24: =SUMIF($I:$I,I24,$AR:$AR) -> 0 | AZ24: =SUMIF($I:$I,I24,$AS:$AS) -> 0 | BW24: =SUMIF($I:$I,I24,$BK:$BK) -> 0 | BX24: =SUMIF($I:$I,I24,$BL:$BL) -> 0 | CC24: =AY24+BW24 -> 0 | CD24: =AZ24+BX24 -> 0 | CE24: =AI24-CC24 -> 0 | CF24: =AJ24-CD24 -> 0 | CG24: =IF(CE24<0,"Thừa",IF(CE24=0,"Đủ","Thiếu")) -> Đủ
G25: VTC02 | H25: Main-Material / Vật tư chính thép trắng | AA25: =SUM(AA26:AA27) -> 0 | AB25: =SUM(AB26:AB27) -> 0 | AC25: =SUM(AC26:AC27) -> 0 | AD25: =SUM(AD26:AD27) -> 0 | AE25: =SUM(AE26:AE27) -> 0 | AF25: =SUM(AF26:AF27) -> 0 | AG25: =SUM(AG26:AG27) -> 0 | AH25: =SUM(AH26:AH27) -> 0 | ... CH25: =SUM(CH26:CH27) -> 0
G28: VTC03 | H28: Gratting-Material / Vật tư gratting | AA28: =SUM(AA29:AA30) -> 0 | AB28: =SUM(AB29:AB30) -> 0 | AC28: =SUM(AC29:AC30) -> 0 | AD28: =SUM(AD29:AD30) -> 0 | AE28: =SUM(AE29:AE30) -> 0 | AF28: =SUM(AF29:AF30) -> 0 | AG28: =SUM(AG29:AG30) -> 0 | AH28: =SUM(AH29:AH30) -> 0 | ... CH28: =SUM(CH29:CH30) -> 0
G31: VTC04 | H31: Insulation-Material / Vật tư bảo ôn | AA31: =SUM(AA32) -> 0 | AB31: =SUM(AB32) -> 0 | AC31: =SUM(AC32) -> 0 | AD31: =SUM(AD32) -> 0 | AE31: =SUM(AE32) -> 0 | AF31: =SUM(AF32) -> 0 | AG31: =SUM(AG32) -> 0 | AH31: =SUM(AH32) -> 0 | ... CH31: =SUM(CH32) -> 0
G33: VPK | H33: Bolt-Material / Vật tư bulong, phụ kiện | AA33: =SUM(AA34:AA58) -> 3981 | AB33: =SUM(AB34:AB58) -> 0 | AC33: =SUM(AC34:AC58) -> 0 | AD33: =SUM(AD34:AD58) -> 0 | AE33: =SUM(AE34:AE58) -> 0 | AF33: =SUM(AF34:AF58) -> 0 | AG33: =SUM(AG34:AG58) -> 0 | AH33: =SUM(AH34:AH58) -> 0 | ... CH33: =SUM(CH34:CH58) -> 0
A34: =IF(G34=G33,"ok","Hiện") -> Hiện | B34: =CG34 -> Đủ | C34: =CE34 -> 0 | G34: G07-VPK-001 | H34: Bolt | I34: Bolt M24x150-8.8-DIN933-HDG | J34: mạ kẽm nhúng nóng | K34: pcs | M34: 61 | O34: 61 | P34: 0 | U34: 0 | V34: 0 | W34: 0 | X34: 0 | AA34: =O34+Q34+S34+U34+W34+Y34 -> 61 | AB34: =P34+R34+T34+V34+X34+Z34 -> 0 | AC34: REV02-Sửa lại cho đúng số lượng do rev1 bi sai | AI34: =IF(AA34>AE34,AA34-AE34,"0") -> 61 | AJ34: =IF(AB34>AF34,AB34-AF34,"0") -> 0 | AK34: Chưa có | AL34: ? | AM34: VSAN | AN34: M24*150 | AO34: Mạ kẽm nhúng nóng 5.6 | AP34: N/A | AQ34: ? | AR34: 61 | AS34: N/A | AT34: 52000 | AU34: =AT34*AR34*1.08 -> 3425760 | AV34: 0.08 | AW34: =AT34*AR34 -> 3172000 | AX34: 46079 | AY34: =SUMIF($I:$I,I34,$AR:$AR) -> 61 | AZ34: =SUMIF($I:$I,I34,$AS:$AS) -> 0 | BW34: =SUMIF($I:$I,I34,$BK:$BK) -> 0 | BX34: =SUMIF($I:$I,I34,$BL:$BL) -> 0 | CC34: =AY34+BW34 -> 61 | CD34: =AZ34+BX34 -> 0 | CE34: =AI34-CC34 -> 0 | CF34: =AJ34-CD34 -> 0 | CG34: =IF(CE34<0,"Thừa",IF(CE34=0,"Đủ","Thiếu")) -> Đủ
A35: =IF(G35=G34,"ok","Hiện") -> Hiện | B35: =CG35 -> Đủ | C35: =CE35 -> 0 | G35: G07-VPK-002 | H35: Bolt | I35: Bolt M6x20-DIN912 | J35: SUS304 | K35: pcs | M35: 350 | O35: 350 | P35: 0 | U35: 0 | V35: 0 | W35: 0 | X35: 0 | AA35: =O35+Q35+S35+U35+W35+Y35 -> 350 | AB35: =P35+R35+T35+V35+X35+Z35 -> 0 | AC35: REV02-Sửa lại cho đúng số lượng do rev1 bi sai | AI35: =IF(AA35>AE35,AA35-AE35,"0") -> 350 | AJ35: =IF(AB35>AF35,AB35-AF35,"0") -> 0 | AK35: Chưa có | AL35: ? | AM35: Hoàng Hà | AN35: M6*20 | AO35: Inox 304 | AP35: N/A | AQ35: ? | AR35: 350 | AS35: N/A | AT35: 914 | AU35: =AT35*AR35*1.08 -> 345492 | AV35: 0.08 | AW35: =AT35*AR35 -> 319900 | AX35: 46062 | AY35: =SUMIF($I:$I,I35,$AR:$AR) -> 350 | AZ35: =SUMIF($I:$I,I35,$AS:$AS) -> 0 | BW35: =SUMIF($I:$I,I35,$BK:$BK) -> 0 | BX35: =SUMIF($I:$I,I35,$BL:$BL) -> 0 | CC35: =AY35+BW35 -> 350 | CD35: =AZ35+BX35 -> 0 | CE35: =AI35-CC35 -> 0 | CF35: =AJ35-CD35 -> 0 | CG35: =IF(CE35<0,"Thừa",IF(CE35=0,"Đủ","Thiếu")) -> Đủ
A36: =IF(G36=G35,"ok","Hiện") -> Hiện | B36: =CG36 -> Đủ | C36: =CE36 -> 0 | G36: G07-VPK-003 | H36: Bolt | I36: Bolt M6x50-DIN912 | J36: SUS304 | K36: pcs | M36: 380 | O36: 380 | P36: 0 | U36: 0 | V36: 0 | W36: 0 | X36: 0 | AA36: =O36+Q36+S36+U36+W36+Y36 -> 380 | AB36: =P36+R36+T36+V36+X36+Z36 -> 0 | AC36: REV01-bỏ cấp bền thừa ở profile, chuyển sang DIN912 | AI36: =IF(AA36>AE36,AA36-AE36,"0") -> 380 | AJ36: =IF(AB36>AF36,AB36-AF36,"0") -> 0 | AK36: Chưa có | AL36: ? | AM36: Hoàng Hà | AN36: M6*50 | AO36: Inox 304 | AP36: N/A | AQ36: ? | AR36: 380 | AS36: N/A | AT36: 1711 | AU36: =AT36*AR36*1.08 -> 702194.4 | AV36: 0.08 | AW36: =AT36*AR36 -> 650180 | AX36: 46062 | AY36: =SUMIF($I:$I,I36,$AR:$AR) -> 380 | AZ36: =SUMIF($I:$I,I36,$AS:$AS) -> 0 | BW36: =SUMIF($I:$I,I36,$BK:$BK) -> 0 | BX36: =SUMIF($I:$I,I36,$BL:$BL) -> 0 | CC36: =AY36+BW36 -> 380 | CD36: =AZ36+BX36 -> 0 | CE36: =AI36-CC36 -> 0 | CF36: =AJ36-CD36 -> 0 | CG36: =IF(CE36<0,"Thừa",IF(CE36=0,"Đủ","Thiếu")) -> Đủ
A37: =IF(G37=G36,"ok","Hiện") -> Hiện | B37: =CG37 -> Đủ | C37: =CE37 -> 0 | G37: G07-VPK-004 | H37: Bolt | I37: Bolt M8x30-8.8-DIN912 | J37: SUS304 | K37: pcs | M37: 120 | O37: 120 | P37: 0 | U37: 0 | V37: 0 | W37: 0 | X37: 0 | AA37: =O37+Q37+S37+U37+W37+Y37 -> 120 | AB37: =P37+R37+T37+V37+X37+Z37 -> 0 | AC37: REV01-đổi cấp bền, , chuyển sang DIN912 | AI37: =IF(AA37>AE37,AA37-AE37,"0") -> 120 | AJ37: =IF(AB37>AF37,AB37-AF37,"0") -> 0 | AK37: Chưa có | AL37: ? | AM37: Hoàng Hà | AN37: M8*30 | AO37: Inox 304 | AP37: N/A | AQ37: ? | AR37: 120 | AS37: N/A | AT37: 2277 | AU37: =AT37*AR37*1.08 -> 295099.2 | AV37: 0.08 | AW37: =AT37*AR37 -> 273240 | AX37: 46062 | AY37: =SUMIF($I:$I,I37,$AR:$AR) -> 120 | AZ37: =SUMIF($I:$I,I37,$AS:$AS) -> 0 | BW37: =SUMIF($I:$I,I37,$BK:$BK) -> 0 | BX37: =SUMIF($I:$I,I37,$BL:$BL) -> 0 | CC37: =AY37+BW37 -> 120 | CD37: =AZ37+BX37 -> 0 | CE37: =AI37-CC37 -> 0 | CF37: =AJ37-CD37 -> 0 | CG37: =IF(CE37<0,"Thừa",IF(CE37=0,"Đủ","Thiếu")) -> Đủ
A38: =IF(G38=G37,"ok","Hiện") -> Hiện | B38: =CG38 -> Đủ | C38: =CE38 -> 0 | G38: G07-VPK-005 | H38: Nut | I38: Nut M24-8.0-DIN934-HDG | J38: mạ kẽm nhúng nóng | K38: pcs | M38: 122 | O38: 122 | P38: 0 | U38: 0 | V38: 0 | W38: 0 | X38: 0 | AA38: =O38+Q38+S38+U38+W38+Y38 -> 122 | AB38: =P38+R38+T38+V38+X38+Z38 -> 0 | AI38: =IF(AA38>AE38,AA38-AE38,"0") -> 122 | AJ38: =IF(AB38>AF38,AB38-AF38,"0") -> 0 | AK38: Chưa có | AL38: ? | AM38: VSAN | AN38: M24 | AO38: Mạ kẽm nhúng nóng 5.6 | AP38: N/A | AQ38: ? | AR38: 122 | AS38: N/A | AT38: 7500 | AU38: =AT38*AR38*1.08 -> 988200 | AV38: 0.08 | AW38: =AT38*AR38 -> 915000 | AX38: 46079 | AY38: =SUMIF($I:$I,I38,$AR:$AR) -> 122 | AZ38: =SUMIF($I:$I,I38,$AS:$AS) -> 0 | BW38: =SUMIF($I:$I,I38,$BK:$BK) -> 0 | BX38: =SUMIF($I:$I,I38,$BL:$BL) -> 0 | CC38: =AY38+BW38 -> 122 | CD38: =AZ38+BX38 -> 0 | CE38: =AI38-CC38 -> 0 | CF38: =AJ38-CD38 -> 0 | CG38: =IF(CE38<0,"Thừa",IF(CE38=0,"Đủ","Thiếu")) -> Đủ
A39: =IF(G39=G38,"ok","Hiện") -> Hiện | B39: =CG39 -> Đủ | C39: =CE39 -> 0 | G39: G07-VPK-006 | H39: Washer | I39: Washer M24-8.8-DIN127-HDG | J39: mạ kẽm nhúng nóng | K39: pcs | M39: 61 | O39: 61 | P39: 0 | U39: 0 | V39: 0 | W39: 0 | X39: 0 | AA39: =O39+Q39+S39+U39+W39+Y39 -> 61 | AB39: =P39+R39+T39+V39+X39+Z39 -> 0 | AI39: =IF(AA39>AE39,AA39-AE39,"0") -> 61 | AJ39: =IF(AB39>AF39,AB39-AF39,"0") -> 0 | AK39: Chưa có | AL39: ? | AM39: VSAN | AN39: M24 | AO39: Mạ kẽm nhúng nóng | AP39: N/A | AQ39: ? | AR39: 61 | AS39: N/A | AT39: 1450 | AU39: =AT39*AR39*1.08 -> 95526 | AV39: 0.08 | AW39: =AT39*AR39 -> 88450 | AX39: 46079 | AY39: =SUMIF($I:$I,I39,$AR:$AR) -> 61 | AZ39: =SUMIF($I:$I,I39,$AS:$AS) -> 0 | BW39: =SUMIF($I:$I,I39,$BK:$BK) -> 0 | BX39: =SUMIF($I:$I,I39,$BL:$BL) -> 0 | CC39: =AY39+BW39 -> 61 | CD39: =AZ39+BX39 -> 0 | CE39: =AI39-CC39 -> 0 | CF39: =AJ39-CD39 -> 0 | CG39: =IF(CE39<0,"Thừa",IF(CE39=0,"Đủ","Thiếu")) -> Đủ
A40: =IF(G40=G39,"ok","Hiện") -> Hiện | B40: =CG40 -> Đủ | C40: =CE40 -> 0 | G40: G07-VPK-007 | H40: Washer | I40: Washer M6-DIN125A | J40: SUS304 | K40: pcs | M40: 380 | O40: 380 | P40: 0 | U40: 0 | V40: 0 | W40: 0 | X40: 0 | AA40: =O40+Q40+S40+U40+W40+Y40 -> 380 | AB40: =P40+R40+T40+V40+X40+Z40 -> 0 | AC40: REV01-bỏ cấp bền thừa ở profile | AI40: =IF(AA40>AE40,AA40-AE40,"0") -> 380 | AJ40: =IF(AB40>AF40,AB40-AF40,"0") -> 0 | AK40: Chưa có | AL40: ? | AM40: Hoàng Hà | AN40: M6 | AO40: Inox 304 | AP40: N/A | AQ40: ? | AR40: 380 | AS40: N/A | AT40: 150 | AU40: =AT40*AR40*1.08 -> 61560 | AV40: 0.08 | AW40: =AT40*AR40 -> 57000 | AX40: 46062 | AY40: =SUMIF($I:$I,I40,$AR:$AR) -> 380 | AZ40: =SUMIF($I:$I,I40,$AS:$AS) -> 0 | BW40: =SUMIF($I:$I,I40,$BK:$BK) -> 0 | BX40: =SUMIF($I:$I,I40,$BL:$BL) -> 0 | CC40: =AY40+BW40 -> 380 | CD40: =AZ40+BX40 -> 0 | CE40: =AI40-CC40 -> 0 | CF40: =AJ40-CD40 -> 0 | CG40: =IF(CE40<0,"Thừa",IF(CE40=0,"Đủ","Thiếu")) -> Đủ
A41: =IF(G41=G40,"ok","Hiện") -> Hiện | B41: =CG41 -> Đủ | C41: =CE41 -> 0 | G41: G07-VPK-008 | H41: Washer | I41: Washer M6-DIN127 | J41: SUS304 | K41: pcs | M41: 730 | O41: 730 | P41: 0 | U41: 0 | V41: 0 | W41: 0 | X41: 0 | AA41: =O41+Q41+S41+U41+W41+Y41 -> 730 | AB41: =P41+R41+T41+V41+X41+Z41 -> 0 | AC41: REV01-bỏ cấp bền thừa ở profile | AI41: =IF(AA41>AE41,AA41-AE41,"0") -> 730 | AJ41: =IF(AB41>AF41,AB41-AF41,"0") -> 0 | AK41: Chưa có | AL41: ? | AM41: Hoàng Hà | AN41: M6 | AO41: Inox 304 | AP41: N/A | AQ41: ? | AR41: 730 | AS41: N/A | AT41: 150 | AU41: =AT41*AR41*1.08 -> 118260 | AV41: 0.08 | AW41: =AT41*AR41 -> 109500 | AX41: 46062 | AY41: =SUMIF($I:$I,I41,$AR:$AR) -> 730 | AZ41: =SUMIF($I:$I,I41,$AS:$AS) -> 0 | BW41: =SUMIF($I:$I,I41,$BK:$BK) -> 0 | BX41: =SUMIF($I:$I,I41,$BL:$BL) -> 0 | CC41: =AY41+BW41 -> 730 | CD41: =AZ41+BX41 -> 0 | CE41: =AI41-CC41 -> 0 | CF41: =AJ41-CD41 -> 0 | CG41: =IF(CE41<0,"Thừa",IF(CE41=0,"Đủ","Thiếu")) -> Đủ
A42: =IF(G42=G41,"ok","Hiện") -> Hiện | B42: =CG42 -> Đủ | C42: =CE42 -> 0 | G42: G07-VPK-009 | H42: Washer | I42: Washer M8-DIN125A | J42: SUS304 | K42: pcs | M42: 120 | O42: 120 | P42: 0 | U42: 0 | V42: 0 | W42: 0 | X42: 0 | AA42: =O42+Q42+S42+U42+W42+Y42 -> 120 | AB42: =P42+R42+T42+V42+X42+Z42 -> 0 | AC42: REV01-đổi cấp bền | AI42: =IF(AA42>AE42,AA42-AE42,"0") -> 120 | AJ42: =IF(AB42>AF42,AB42-AF42,"0") -> 0 | AK42: Chưa có | AL42: ? | AM42: Hoàng Hà | AN42: M8 | AO42: Inox 304 | AP42: N/A | AQ42: ? | AR42: 120 | AS42: N/A | AT42: 300 | AU42: =AT42*AR42*1.08 -> 38880 | AV42: 0.08 | AW42: =AT42*AR42 -> 36000 | AX42: 46062 | AY42: =SUMIF($I:$I,I42,$AR:$AR) -> 120 | AZ42: =SUMIF($I:$I,I42,$AS:$AS) -> 0 | BW42: =SUMIF($I:$I,I42,$BK:$BK) -> 0 | BX42: =SUMIF($I:$I,I42,$BL:$BL) -> 0 | CC42: =AY42+BW42 -> 120 | CD42: =AZ42+BX42 -> 0 | CE42: =AI42-CC42 -> 0 | CF42: =AJ42-CD42 -> 0 | CG42: =IF(CE42<0,"Thừa",IF(CE42=0,"Đủ","Thiếu")) -> Đủ
A43: =IF(G43=G42,"ok","Hiện") -> Hiện | B43: =CG43 -> Đủ | C43: =CE43 -> 0 | G43: G07-VPK-010 | H43: Washer | I43: Washer M8-DIN127 | J43: SUS304 | K43: pcs | M43: 120 | O43: 120 | P43: 0 | U43: 0 | V43: 0 | W43: 0 | X43: 0 | AA43: =O43+Q43+S43+U43+W43+Y43 -> 120 | AB43: =P43+R43+T43+V43+X43+Z43 -> 0 | AC43: REV01-đổi cấp bền | AI43: =IF(AA43>AE43,AA43-AE43,"0") -> 120 | AJ43: =IF(AB43>AF43,AB43-AF43,"0") -> 0 | AK43: Chưa có | AL43: ? | AM43: Hoàng Hà | AN43: M8 | AO43: Inox 304 | AP43: N/A | AQ43: ? | AR43: 120 | AS43: N/A | AT43: 300 | AU43: =AT43*AR43*1.08 -> 38880 | AV43: 0.08 | AW43: =AT43*AR43 -> 36000 | AX43: 46062 | AY43: =SUMIF($I:$I,I43,$AR:$AR) -> 120 | AZ43: =SUMIF($I:$I,I43,$AS:$AS) -> 0 | BW43: =SUMIF($I:$I,I43,$BK:$BK) -> 0 | BX43: =SUMIF($I:$I,I43,$BL:$BL) -> 0 | CC43: =AY43+BW43 -> 120 | CD43: =AZ43+BX43 -> 0 | CE43: =AI43-CC43 -> 0 | CF43: =AJ43-CD43 -> 0 | CG43: =IF(CE43<0,"Thừa",IF(CE43=0,"Đủ","Thiếu")) -> Đủ
A44: =IF(G44=G43,"ok","Hiện") -> Hiện | B44: =CG44 -> Đủ | C44: =CE44 -> 0 | G44: G07-VPK-011 | H44: Tấm chống cháy SILICON-20mm | I44: PL20x190x500xSILICON COMPOSTE, 60 SHORE A | J44: SILICON COMPOSTE, 60 SHORE A | K44: pcs | M44: 330 | O44: 330 | P44: 0 | Q44: -330 | R44: 0 | U44: 0 | V44: 0 | W44: 0 | X44: 0 | AA44: =O44+Q44+S44+U44+W44+Y44 -> 0 | AB44: =P44+R44+T44+V44+X44+Z44 -> 0 | AC44: REV01-hủy không dùng | AI44: =IF(AA44>AE44,AA44-AE44,"0") -> 0 | AJ44: =IF(AB44>AF44,AB44-AF44,"0") -> 0 | AK44: Chưa có | AY44: =SUMIF($I:$I,I44,$AR:$AR) -> 0 | AZ44: =SUMIF($I:$I,I44,$AS:$AS) -> 0 | BW44: =SUMIF($I:$I,I44,$BK:$BK) -> 0 | BX44: =SUMIF($I:$I,I44,$BL:$BL) -> 0 | CC44: =AY44+BW44 -> 0 | CD44: =AZ44+BX44 -> 0 | CE44: =AI44-CC44 -> 0 | CF44: =AJ44-CD44 -> 0 | CG44: =IF(CE44<0,"Thừa",IF(CE44=0,"Đủ","Thiếu")) -> Đủ
A45: =IF(G45=G44,"ok","Hiện") -> Hiện | B45: =CG45 -> Đủ | C45: =CE45 -> 0 | G45: G07-VPK-012 | H45: Bánh xe -loại cổ quay | I45: SUPO 12J-65S-PA (loại cổ quay) | J45: Steel-mạ kẽm | K45: pcs | M45: 162 | U45: 165 | V45: 0 | W45: 0 | X45: 0 | AA45: =O45+Q45+S45+U45+W45+Y45 -> 165 | AB45: =P45+R45+T45+V45+X45+Z45 -> 0 | AC45: REV03-bổ sung mới | AI45: =IF(AA45>AE45,AA45-AE45,"0") -> 165 | AJ45: =IF(AB45>AF45,AB45-AF45,"0") -> 0 | AL45: ? | AM45: MRO | AN45: Bánh xe | AP45: N/A | AQ45: ? | AR45: 165 | AS45: N/A | AT45: =1.4*96000 -> 134400 | AU45: =AT45*AR45*1.08 -> 23950080 | AV45: 0.08 | AW45: =AT45*AR45 -> 22176000 | AX45: 46058 | AY45: =SUMIF($I:$I,I45,$AR:$AR) -> 165 | AZ45: =SUMIF($I:$I,I45,$AS:$AS) -> 0 | BW45: =SUMIF($I:$I,I45,$BK:$BK) -> 0 | BX45: =SUMIF($I:$I,I45,$BL:$BL) -> 0 | CC45: =AY45+BW45 -> 165 | CD45: =AZ45+BX45 -> 0 | CE45: =AI45-CC45 -> 0 | CF45: =AJ45-CD45 -> 0 | CG45: =IF(CE45<0,"Thừa",IF(CE45=0,"Đủ","Thiếu")) -> Đủ
...

Sheet Tổng hợp
A1: Item/ STT | B1: Total Ordered/Tổng dự trù | D1: Tận dụng tồn kho/ Remain | G1: Khối lượng phải mua sắm/ total order | I1: VẬT TƯ TRONG NƯỚC | L1: VẬT TƯ OVERSEA | O1: Khối lượng phải mua còn lại theo PR/ total order from PR | Q1: Khối lượng phải mua còn lại/ total order
B2: Q.Ty/S.Lượng (M/M2/Set) | C2: Weight/K.Lượng (Kg) | D2: Q.Ty/S.Lượng (M/M2/Set) | E2: Weight/K.Lượng (Kg) | F2: Đã nghiệm thu (Kg) | G2: Q.Ty/ S.Lượng | H2: Weight/ K.Lượng (Kg) | I2: S.Lượng giao hàng thực tế/ Handover Q'ty | J2: K.Lượng giao hàng thực tế// Handover weight | K2: Khối lượng nghiệm thu đạt/ Weight Acc. Inspection | L2: S.Lượng giao hàng thực tế/ Handover Q'ty | M2: K.Lượng giao hàng thực tế// Handover weight | N2: Khối lượng nghiệm thu đạt/ Weight Acc. Inspection | O2: Q.Ty/S.Lượng (M/M2/Set) | P2: Weight/ K.Lượng (Kg) | Q2: Q.Ty/S.Lượng (M/M2/Set) | R2: Weight/ K.Lượng (Kg)
A3: VTC01 | B3: Main-Material / Vật tư chính thép đen
A4: 1 | B4: ='25-GEN-G-07'!AA7 -> 931.375 | C4: ='25-GEN-G-07'!AB7 -> 31090.659 | D4: ='25-GEN-G-07'!AE7 -> 40.375 | E4: ='25-GEN-G-07'!AF7 -> 1107.6395 | F4: =E4 -> 1107.6395 | G4: ='25-GEN-G-07'!AI7 -> 891 | H4: ='25-GEN-G-07'!AJ7 -> 29983.02 | I4: ='25-GEN-G-07'!AY7 -> 892.25 | J4: ='25-GEN-G-07'!AZ7 -> 31415.1 | K4: ='25-GEN-G-07'!BC7 -> 0 | L4: ='25-GEN-G-07'!BW7 -> 0 | M4: ='25-GEN-G-07'!BX7 -> 0 | N4: ='25-GEN-G-07'!CA7 -> 0 | O4: =B4-I4-L4 -> 39.125 | P4: =C4-J4-M4 -> -324.4405 | Q4: ='25-GEN-G-07'!CE7 -> -1.25 | R4: ='25-GEN-G-07'!CF7 -> -1432.08
A5: VTC02 | B5: Main-Material / Vật tư chính thép trắng
A6: 1 | B6: ='25-GEN-G-07'!AA25 -> 0 | C6: ='25-GEN-G-07'!AB25 -> 0 | D6: ='25-GEN-G-07'!AE25 -> 0 | E6: ='25-GEN-G-07'!AF25 -> 0 | F6: =E6 -> 0 | G6: ='25-GEN-G-07'!AI25 -> 0 | H6: ='25-GEN-G-07'!AJ25 -> 0 | I6: ='25-GEN-G-07'!AY25 -> 0 | J6: ='25-GEN-G-07'!AZ25 -> 0 | K6: ='25-GEN-G-07'!BC25 -> 0 | L6: ='25-GEN-G-07'!BW25 -> 0 | M6: ='25-GEN-G-07'!BX25 -> 0 | N6: ='25-GEN-G-07'!CA25 -> 0 | O6: =B6-I6-L6 -> 0 | P6: =C6-J6-M6 -> 0 | Q6: ='25-GEN-G-07'!CE25 -> 0 | R6: ='25-GEN-G-07'!CF25 -> 0
A7: VTC03 | B7: Gratting-Material / Vật tư gratting
A8: 1 | B8: ='25-GEN-G-07'!AA28 -> 0 | C8: ='25-GEN-G-07'!AB28 -> 0 | D8: ='25-GEN-G-07'!AE28 -> 0 | E8: ='25-GEN-G-07'!AF28 -> 0 | F8: =E8 -> 0 | G8: ='25-GEN-G-07'!AI28 -> 0 | H8: ='25-GEN-G-07'!AJ28 -> 0 | I8: ='25-GEN-G-07'!AY28 -> 0 | J8: ='25-GEN-G-07'!AZ28 -> 0 | K8: ='25-GEN-G-07'!BC28 -> 0 | L8: ='25-GEN-G-07'!BW28 -> 0 | M8: ='25-GEN-G-07'!BX28 -> 0 | N8: ='25-GEN-G-07'!CA28 -> 0 | O8: =B8-I8-L8 -> 0 | P8: =C8-J8-M8 -> 0 | Q8: ='25-GEN-G-07'!CE28 -> 0 | R8: ='25-GEN-G-07'!CF28 -> 0
A9: VTC04 | B9: Insulation-Material / Vật tư bảo ôn
A10: 1 | B10: ='25-GEN-G-07'!AA31 -> 0 | C10: ='25-GEN-G-07'!AB31 -> 0 | D10: ='25-GEN-G-07'!AE31 -> 0 | E10: ='25-GEN-G-07'!AF31 -> 0 | F10: =E10 -> 0 | G10: ='25-GEN-G-07'!AI31 -> 0 | H10: ='25-GEN-G-07'!AJ31 -> 0 | I10: ='25-GEN-G-07'!AY31 -> 0 | J10: ='25-GEN-G-07'!AZ31 -> 0 | K10: ='25-GEN-G-07'!BC31 -> 0 | L10: ='25-GEN-G-07'!BW31 -> 0 | M10: ='25-GEN-G-07'!BX31 -> 0 | N10: ='25-GEN-G-07'!CA31 -> 0 | O10: =B10-I10-L10 -> 0 | P10: =C10-J10-M10 -> 0 | Q10: ='25-GEN-G-07'!CE31 -> 0 | R10: ='25-GEN-G-07'!CF31 -> 0
A11: VPK | B11: Bolt-Material / Vật tư bulong, phụ kiện
A12: 1 | B12: ='25-GEN-G-07'!AA33 -> 3981 | C12: ='25-GEN-G-07'!AB33 -> 0 | D12: ='25-GEN-G-07'!AE33 -> 0 | E12: ='25-GEN-G-07'!AF33 -> 0 | F12: =E12 -> 0 | G12: ='25-GEN-G-07'!AI33 -> 3981 | H12: ='25-GEN-G-07'!AJ33 -> 0 | I12: ='25-GEN-G-07'!AY33 -> 3982 | J12: ='25-GEN-G-07'!AZ33 -> 17.5 | K12: ='25-GEN-G-07'!BC33 -> 0 | L12: ='25-GEN-G-07'!BW33 -> 0 | M12: ='25-GEN-G-07'!BX33 -> 0 | N12: ='25-GEN-G-07'!CA33 -> 0 | O12: =B12-I12-L12 -> -1 | P12: =C12-J12-M12 -> -17.5 | Q12: ='25-GEN-G-07'!CE33 -> -1 | R12: ='25-GEN-G-07'!CF33 -> -17.5
A13: VTK | B13: Packing Material / Vật tư kiện
A14: 1 | B14: ='25-GEN-G-07'!AA59 | C14: ='25-GEN-G-07'!AB59 -> 0 | D14: ='25-GEN-G-07'!AE59 -> 0 | E14: ='25-GEN-G-07'!AF59 -> 0 | F14: =E14 -> 0 | G14: ='25-GEN-G-07'!AI59 -> 0 | H14: ='25-GEN-G-07'!AJ59 -> 0 | I14: ='25-GEN-G-07'!AY59 -> 0 | J14: ='25-GEN-G-07'!AZ59 -> 0 | K14: ='25-GEN-G-07'!BC59 -> 0 | L14: ='25-GEN-G-07'!BW59 -> 0 | M14: ='25-GEN-G-07'!BX59 -> 0 | N14: ='25-GEN-G-07'!CA59 -> 0 | O14: =B14-I14-L14 -> #VALUE! | P14: =C14-J14-M14 -> 0 | Q14: ='25-GEN-G-07'!CE59 -> 0 | R14: ='25-GEN-G-07'!CF59 -> 0
A17: STT/ No. | B17: Dự án/ Hạng mục/ Project/ Items | C17: Thiết kế, Dự toán/ Design, Estimation | F17: Mua sắm/ Ordered, Puchased (Đến hiện tại/ Up to now) | K17: Tổng Giá trị mua thêm/ Total Cost (VND)
F18: Hàng mua thêm | H18: Hàng tồn
C19: Khối lượng/ Weight (Kg) | D19: Số lượng/ Q'ty (M/M2//PSC) | E19: Tổng Giá trị/ Total Cost (VND) | F19: Khối lượng/ Weight (Kg) | G19: Số lượng/ Q'ty (M/M2//PSC) | H19: Khối lượng/ Weight (Kg/N/A) Materials available at the factory | I19: Số lượng/ Q'ty (M/M2/PSC) Materials available at the factory | J19: Tổng Giá trị mua thêm/ Total Cost (VND) | K19: DỰ TOÁN (VNĐ) | L19: GIÁ TRỊ ĐÃ ĐẶT HÀNG THÊM (VNĐ) | M19: Chênh lệch/ Diff. (VND) | N19: Ghi chú/ Remarks
A20: VTC01 | B20: Main-Material / Vật tư chính thép đen | C20: =C4 -> 31090.659 | D20: =B4 -> 931.375 | F20: =J4+M4 -> 31415.1 | G20: =I4+L4 -> 892.25 | H20: =E4 -> 1107.6395 | I20: =D4 -> 40.375 | J20: ='25-GEN-G-07'!AW7+'25-GEN-G-07'!BN7*27000 -> 4.3019969e+08 | K20: 0 | M20: =K20-J20-L20 -> -4.3019969e+08 | N20: =IF(M20<=0,"VƯỢT DỰ TOÁN","ĐẢM BẢO") -> VƯỢT DỰ TOÁN
A21: VTC02 | B21: Main-Material / Vật tư chính thép trắng | C21: =C6 -> 0 | D21: =B6 -> 0 | F21: =J6+M6 -> 0 | G21: =I6+L6 -> 0 | H21: =E6 -> 0 | I21: =D6 -> 0 | J21: ='25-GEN-G-07'!AW25+'25-GEN-G-07'!BN25*27000 -> 0 | K21: 0 | M21: =K21-J21-L21 -> 0 | N21: =IF(M21<=0,"VƯỢT DỰ TOÁN","ĐẢM BẢO") -> VƯỢT DỰ TOÁN
A22: VTC03 | B22: Gratting-Material / Vật tư gratting | C22: =C8 -> 0 | D22: =B8 -> 0 | F22: =J8+M8 -> 0 | G22: =I8+L8 -> 0 | H22: =E8 -> 0 | I22: =D8 -> 0 | J22: ='25-GEN-G-07'!AW28+'25-GEN-G-07'!BN28*27000 -> 0 | K22: 0 | M22: =K22-J22-L22 -> 0 | N22: =IF(M22<=0,"VƯỢT DỰ TOÁN","ĐẢM BẢO") -> VƯỢT DỰ TOÁN
A23: VTC04 | B23: Insulation-Material / Vật tư bảo ôn | C23: =C10 -> 0 | D23: =B10 -> 0 | F23: =J10+M10 -> 0 | G23: =I10+L10 -> 0 | H23: =E10 -> 0 | I23: =D10 -> 0 | J23: ='25-GEN-G-07'!AW31+'25-GEN-G-07'!BN31*27000 -> 0 | K23: 0 | M23: =K23-J23-L23 -> 0 | N23: =IF(M23<=0,"VƯỢT DỰ TOÁN","ĐẢM BẢO") -> VƯỢT DỰ TOÁN
A24: VPK | B24: Bolt-Material / Vật tư bulong, phụ kiện | C24: =C12 -> 0 | D24: =B12 -> 3981 | F24: =J12+M12 -> 17.5 | G24: =I12+L12 -> 3982 | H24: =E12 -> 0 | I24: =D12 -> 0 | J24: ='25-GEN-G-07'!AW33+'25-GEN-G-07'!BN33*27000 -> 49445437 | K24: 0 | M24: =K24-J24-L24 -> -49445437 | N24: =IF(M24<=0,"VƯỢT DỰ TOÁN","ĐẢM BẢO") -> VƯỢT DỰ TOÁN
A25: VTK | B25: Packing Material / Vật tư kiện | C25: =C14 -> 0 | D25: =B14 | F25: =J14+M14 -> 0 | G25: =I14+L14 -> 0 | H25: =E14 -> 0 | I25: =D14 -> 0 | J25: ='25-GEN-G-07'!AW59+'25-GEN-G-07'!BN59*27000 -> 0 | K25: 0 | M25: =K25-J25-L25 -> 0 | N25: =IF(M25<=0,"VƯỢT DỰ TOÁN","ĐẢM BẢO") -> VƯỢT DỰ TOÁN

Sheet Giải tình Hoàng Hà vit
A1: BID ANALYSIS - GIẢI TRÌNH MUA SẮM/ĐẤU THẦU
A3: Project | B3: PROJECT No/ Dự án: 25-GEN-G-08
A4: Dự án
A5: Subject | B5: Cung cấp vật tư bu lông, phụ kiện
A6: Chủ đề
A8: No. | B8: CONTENT | C8: Phạm vi công việc | H8: Dự toán | K8: Đã mua | L8: Đơn vị cung cấp chào giá (vnđ) | O8: Lựa chọn | P8: Ghi chú
A9: Item | B9: Description/ Chi tiết | C9: Profile/ Vật tư | D9: Grade/ Mác vật liệu | E9: Số lượng Mua | F9: Số lượng PR | G9: Đơn vị | H9: Khối lượng/ Số lượng | I9: Đơn giá (vnd) | J9: Thành tiền (vnd) | K9: Thành tiền (vnd) | L9: HOÀNG HÀ
L10: Phạm vi | M10: Đơn giá (VND) | N10: Thành Tiền (Không có VAT)
A11: Tổng | B11: Bolt-Material / Vật tư bulong, phụ kiện | H11: N/A | I11: N/A | N11: =SUM(N12:N21) -> 6397320 | P11: =J11-K11-N11 -> -6397320
A12: G07-VPK-002 | B12: Bu lông chìm trụ | C12: M6*20 | D12: Inox 304 | E12: 350 | F12: 350 | G12: cái | H12: N/A | I12: N/A | J12: N/A | L12: V | M12: 914 | N12: =M12*F12 -> 319900 | O12: HOÀNG HÀ
A13: G07-VPK-003 | B13: Bu lông chìm trụ | C13: M6*50 | D13: Inox 304 | E13: 380 | F13: 380 | G13: cái | H13: N/A | I13: N/A | J13: N/A | L13: V | M13: 1711 | N13: =M13*F13 -> 650180 | O13: HOÀNG HÀ
A14: G07-VPK-004 | B14: Bu lông chìm trụ | C14: M8*30 | D14: Inox 304 | E14: 120 | F14: 120 | G14: cái | H14: N/A | I14: N/A | J14: N/A | L14: V | M14: 2277 | N14: =M14*F14 -> 273240 | O14: HOÀNG HÀ
A15: G07-VPK-007 | B15: Long đen phẳng | C15: M6 | D15: Inox 304 | E15: 380 | F15: 380 | G15: cái | H15: N/A | I15: N/A | J15: N/A | L15: V | M15: 150 | N15: =M15*F15 -> 57000 | O15: HOÀNG HÀ
A16: G07-VPK-008 | B16: Long đen vênh | C16: M6 | D16: Inox 304 | E16: 730 | F16: 730 | G16: cái | H16: N/A | I16: N/A | J16: N/A | L16: V | M16: 150 | N16: =M16*F16 -> 109500 | O16: HOÀNG HÀ
A17: G07-VPK-009 | B17: Long đen phẳng | C17: M8 | D17: Inox 304 | E17: 120 | F17: 120 | G17: cái | H17: N/A | I17: N/A | J17: N/A | L17: V | M17: 300 | N17: =M17*F17 -> 36000 | O17: HOÀNG HÀ
A18: G07-VPK-010 | B18: Long đen vênh | C18: M8 | D18: Inox 304 | E18: 120 | F18: 120 | G18: cái | H18: N/A | I18: N/A | J18: N/A | L18: V | M18: 300 | N18: =M18*F18 -> 36000 | O18: HOÀNG HÀ
A19: G07-VPK-013 | B19: Bulông nở | C19: Bulong nở M16x150-HDG | D19: mạ kẽm nhúng nóng | E19: 176 | F19: 176 | G19: cái | H19: N/A | I19: N/A | J19: N/A | L19: V | M19: 22500 | N19: 3960000 | O19: HOÀNG HÀ
A20: G07-VPK-014 | B20: Bolt | C20: Bolt M16x100-8.8-DIN933-HDG | D20: mạ kẽm nhúng nóng | E20: 65 | F20: 65 | G20: cái | H20: N/A | I20: N/A | J20: N/A | L20: V | M20: 14700 | N20: 955500 | O20: HOÀNG HÀ
A21: G07-VPK-015 | B21: Nut | C21: Nut M16-8.0-DIN934-HDG | D21: mạ kẽm nhúng nóng | E21: 130 | F21: 130 | G21: cái | H21: N/A | I21: N/A | J21: N/A | L21: V | M21: 0 | N21: 0 | O21: HOÀNG HÀ
B22: Xếp hạng | M22: 1
A23: Ghi chú: Tiếp tục công tác mua sắm để đảm báo tiến độ
A24: NGƯỜI ĐỀ NGHỊ/ RECOMMENDATION BY: | C24: NGƯỜI KIỂM TRA/ DEPARTMENT HEAD CHECK BY: | G24: APPROVED BY: PHÊ DUYỆT
G25: Nguyễn Quang Vinh | K25: Hoàng Ngọc Bằng | O25: Đoàn Văn Toàn

Sheet Ngọc Hiếu 26-1
A1: BID ANALYSIS - GIẢI TRÌNH MUA SẮM/ĐẤU THẦU
A3: Project | B3: PROJECT No/ Dự án: 25-GEN-G-07
A4: Dự án
A5: Subject | B5: Cung cấp vật tư chính thép đen ngọc hiếu 26-1-20226
A6: Chủ đề
A8: No. | B8: CONTENT | C8: Phạm vi công việc | H8: Dự toán | K8: Đã mua | L8: Đơn vị cung cấp chào giá phần còn lại (VNĐ) | O8: Đơn vị cung cấp chào giá phần còn lại (VNĐ) | R8: Đơn vị cung cấp chào giá phần còn lại (VNĐ) | U8: Ghi chú
A9: Item | B9: Description/ Chi tiết | C9: Profile/ Vật tư | D9: Grade/ Mác vật liệu | E9: Grade/ Mác vật liệu mua | F9: Số lượng Mua (M) | G9: Số lượng PR (M) | H9: Khối lượng/ Số lượng | I9: Đơn giá (vnd) | J9: Thành tiền (vnd) | K9: Thành tiền (vnd) | L9: NGỌC HIẾU | O9: Hùng Nguyên | R9: APEC
L10: Phạm vi | M10: Đơn giá trước VAT (VNĐ/KG) | N10: Thành Tiền | O10: Phạm vi | P10: Đơn giá trước VAT (VNĐ/KG) | Q10: Thành Tiền | R10: Phạm vi | S10: Đơn giá trước VAT (VNĐ/KG) | T10: Thành Tiền
A11: Tổng | B11: Main-Material / Vật tư chính thép đen | H11: N/A | I11: N/A | K11: ='Tổng hợp'!J20-N11 -> 4.2305787e+08 | N11: =N12 -> 7141816 | U11: =J11-K11-N11 -> -4.3019969e+08
A12: G07-VTC01-008 | B12: PL2X1200X2500 | C12: Thép tấm 2*1250*2500 | D12: Q235A/SS400 | E12: SS400 | F12: =10*1.25*2.5 -> 31.25 | G12: 30 | H12: N/A | I12: N/A | J12: N/A | K12: N/A | L12: V | M12: 14545.45 | N12: 7141816 | O12: X | P12: #N/A | Q12: #N/A | R12: X | S12: #N/A | T12: =VLOOKUP(D12,'[115]DA 95'!$B$20:$N$31,13,0) -> #N/A | U12: Chọn Ngọc Hiếu
B13: Xếp hạng | M13: 1 | P13: 2 | S13: 3
A14: Ghi chú: Tiếp tục công tác mua sắm để đảm báo tiến độ
A15: NGƯỜI ĐỀ NGHỊ/ RECOMMENDATION BY: | F15: NGƯỜI KIỂM TRA/ DEPARTMENT HEAD CHECK BY: | N15: APPROVED BY: PHÊ DUYỆT
N16: Nguyễn Quang Vinh | Q16: Hoàng Ngọc Bằng | T16: Đoàn Văn Toàn

Sheet Hùng nguyên 26-1 (2)
A1: BID ANALYSIS - GIẢI TRÌNH MUA SẮM/ĐẤU THẦU
A3: Project | B3: PROJECT No/ Dự án: 25-GEN-G-07
A4: Dự án
A5: Subject | B5: Cung cấp vật tư chính thép đen
A6: Chủ đề
A8: No. | B8: CONTENT | C8: Phạm vi công việc | H8: Dự toán | K8: Đã mua | L8: Đơn vị cung cấp chào giá phần còn lại (VNĐ) | O8: Đơn vị cung cấp chào giá phần còn lại (VNĐ) | R8: Đơn vị cung cấp chào giá phần còn lại (VNĐ) | U8: Ghi chú
A9: Item | B9: Description/ Chi tiết | C9: Profile/ Vật tư | D9: Grade/ Mác vật liệu | E9: Grade/ Mác vật liệu mua | F9: Số lượng Mua (M) | G9: Số lượng PR (M) | H9: Khối lượng/ Số lượng | I9: Đơn giá (vnd) | J9: Thành tiền (vnd) | K9: Thành tiền (vnd) | L9: NGỌC HIẾU | O9: Hùng Nguyên | R9: APEC
L10: Phạm vi | M10: Đơn giá trước VAT (VNĐ/KG) | N10: Thành Tiền | O10: Phạm vi | P10: Đơn giá trước VAT (VNĐ/KG) | Q10: Thành Tiền | R10: Phạm vi | S10: Đơn giá trước VAT (VNĐ/KG) | T10: Thành Tiền
A11: Tổng | B11: Main-Material / Vật tư chính thép đen | H11: N/A | I11: N/A | K11: ='Tổng hợp'!J20 -> 4.3019969e+08 | Q11: =SUM(Q12:Q12) -> 33989082 | U11: =J11-K11-Q11-N11 -> -4.6418877e+08
A12: G07-VTC01-001 | B12: PL3X1500X6000 | C12: Thép tấm 3x2000x6000 | D12: Q235A/SS400 | E12: SS400 | F12: 108 | G12: 108 | H12: N/A | I12: N/A | J12: N/A | K12: N/A | L12: V | M12: 13909.09 | N12: #N/A | O12: V | P12: 13363.64 | Q12: 33989082 | R12: V | S12: =14850/1.1 -> 13500 | T12: =VLOOKUP(D12,'[115]DA 95'!$B$20:$N$31,13,0) -> #N/A | U12: Chọn Hùng Nguyên
B13: Xếp hạng | M13: 2 | P13: 1 | S13: 3
A14: Ghi chú: Tiếp tục công tác mua sắm để đảm báo tiến độ
A15: NGƯỜI ĐỀ NGHỊ/ RECOMMENDATION BY: | F15: NGƯỜI KIỂM TRA/ DEPARTMENT HEAD CHECK BY: | N15: APPROVED BY: PHÊ DUYỆT
N16: Nguyễn Quang Vinh | Q16: Hoàng Ngọc Bằng | T16: Đoàn Văn Toàn

Sheet Hùng nguyên 27-1
A1: BID ANALYSIS - GIẢI TRÌNH MUA SẮM/ĐẤU THẦU
A3: Project | B3: PROJECT No/ Dự án: 25-GEN-G-07
A4: Dự án
A5: Subject | B5: Cung cấp vật tư chính thép đen
A6: Chủ đề
A8: No. | B8: CONTENT | C8: Phạm vi công việc | H8: Dự toán | K8: Đã mua | L8: Đơn vị cung cấp chào giá phần còn lại (VNĐ) | O8: Đơn vị cung cấp chào giá phần còn lại (VNĐ) | R8: Đơn vị cung cấp chào giá phần còn lại (VNĐ) | U8: Ghi chú
A9: Item | B9: Description/ Chi tiết | C9: Profile/ Vật tư | D9: Grade/ Mác vật liệu | E9: Grade/ Mác vật liệu mua | F9: Số lượng Mua (M) | G9: Số lượng PR (M) | H9: Khối lượng/ Số lượng | I9: Đơn giá (vnd) | J9: Thành tiền (vnd) | K9: Thành tiền (vnd) | L9: NGỌC HIẾU | O9: Hùng Nguyên | R9: APEC
L10: Phạm vi | M10: Đơn giá trước VAT (VNĐ/KG) | N10: Thành Tiền | O10: Phạm vi | P10: Đơn giá trước VAT (VNĐ/KG) | Q10: Thành Tiền | R10: Phạm vi | S10: Đơn giá trước VAT (VNĐ/KG) | T10: Thành Tiền
A11: Tổng | B11: Main-Material / Vật tư chính thép đen | H11: N/A | I11: N/A | K11: ='Tổng hợp'!J20-Q11 -> 3.181745e+08 | Q11: =SUM(Q12:Q14) -> 1.1202519e+08 | U11: =J11-K11-Q11-N11 -> -4.3019969e+08
A12: G07-VTC01-011 | B12: PL14x2000x12000 (2 tờ) PL14x2000x4500 (1 tầm) | C12: Thép tấm 14x2000x12000 SS400 | D12: Q235A/SS400 | E12: SS400 | F12: =2*(24) -> 48 | G12: =2*(24) -> 48 | H12: N/A | I12: N/A | J12: N/A | K12: N/A | L12: X | M12: #N/A | N12: #N/A | O12: V | P12: 13727.27 | Q12: 72414095 | R12: X | S12: #N/A | T12: #N/A | U12: Chọn Hùng Nguyên
A13: G07-VTC01-011 | B13: PL14x2000x12000 (2 tờ) PL14x2000x4500 (1 tầm) | C13: Thép tấm 14x2000x4500 SS400 | D13: Q235A/SS400 | E13: SS400 | F13: 9 | G13: 9 | H13: N/A | I13: N/A | J13: N/A | K13: N/A | L13: V | M13: #N/A | N13: #N/A | O13: V | P13: 13727.27 | Q13: 13577643 | R13: X | S13: #N/A | T13: #N/A | U13: Chọn Hùng Nguyên
A14: G07-VTC01-012 | B14: PL20x2000x6000 | C14: Thép tấm 20x2000x6000 SS400 | D14: Q235A/SS400 | E14: SS400 | F14: 12 | G14: 12 | H14: N/A | I14: N/A | J14: N/A | K14: N/A | L14: V | M14: 13909.09 | N14: #N/A | O14: V | P14: 13818.18 | Q14: 26033451 | R14: X | S14: #N/A | T14: #N/A | U14: Chọn Hùng Nguyên
B15: Xếp hạng | M15: 2 | P15: 1 | S15: 3
A16: Ghi chú: Chưa có dự toán/ Tiếp tục công tác mua sắm để đảm báo tiến độ
A17: NGƯỜI ĐỀ NGHỊ/ RECOMMENDATION BY: | F17: NGƯỜI KIỂM TRA/ DEPARTMENT HEAD CHECK BY: | N17: APPROVED BY: PHÊ DUYỆT
N18: Nguyễn Quang Vinh | Q18: Hoàng Ngọc Bằng | T18: Đoàn Văn Toàn

Sheet BG Gnee 2
B1: GNEE STEEL CO.,LIMITED
B2: FLAT/RM 1512 15/F LUCKY CENTRE NO.165-171 WAN CHAI ROAD WAN CHAI HK
A3: TEL: +86 15286968617 E-mail:alice@gescosteel.com
A4: QUOTATION SHEET
A5: QUOTATION NO.: GNEEYPH20240527-1
A6: DATE: MAY.27TH,2024
A7: TO:IBS
A8: SR NO. | B8: PRODUCT NAME | C8: SPECIFICATION (mm) | F8: UNIT WEIGHT (KG/PCS) | G8: QUANTITY | I8: FOB CHINA
E9: Số lượng (m/m2) | G9: QTY (PCS) | H9: WEIGHT (KG) | I9: UNIT PRICE（USD/KG) | J9: AMOUNT (USD) | K9: lead time
A10: A-8 | B10: HARDOX 450 PLATE | C10: 6*2000*6000 | E10: =G10*2*6 -> 36 | F10: 565.2 | G10: 3 | H10: =G10*F10 -> 1695.6 | I10: 3.16 | J10: =I10*H10 -> 5358.096 | K10: 20days
A11: A-15 | B11: NM400 PLATE | C11: 12*1500*3700 | E11: =G11*1.5*3.7 -> 5.55 | F11: 653.5 | G11: 1 | H11: =G11*F11 -> 653.5 | I11: 1.1 | J11: =I11*H11 -> 718.85 | K11: 20days
A12: A-20 | B12: HARDOX 500 PLATE | C12: 16*2000*6000 | E12: =G12*2*6 -> 12 | F12: 1507.2 | G12: 1 | H12: =G12*F12 -> 1507.2 | I12: 3.07 | J12: =I12*H12 -> 4627.104 | K12: 20days
A13: A-27 | B13: HARDOX 500 PLATE | C13: 22*2000*6000 | E13: =G13*2*6 -> 12 | F13: =22*2*6*7.85 -> 2072.4 | G13: 1 | H13: =G13*F13 -> 2072.4 | I13: 3.16 | J13: =I13*H13 -> 6548.784 | K13: 20days
A14: A-5 | B14: SA240-304 PLATE | C14: 2*1219*2438 | E14: =G14*1.219*2.438 -> 2.971922 | F14: 47.2 | G14: 1 | H14: =G14*F14 -> 47.2 | I14: 3.29 | J14: =I14*H14 -> 155.288
A15: A-64 | B15: SUS 304 ROUND BAR | C15: 40*6000 | E15: =G15*6 -> 12 | F15: 59.8 | G15: 2 | H15: =G15*F15 -> 119.6 | I15: 3.72 | J15: =I15*H15 -> 444.912
A16: A-46 | B16: Q235B PIPE | C16: 102*6*6000 | E16: =G16*6 -> 6 | F16: 85.2 | G16: 1 | H16: =G16*F16 -> 85.2 | I16: 0.91 | J16: =I16*H16 -> 77.532
A17: A-47 | B17: Q235B PIPE | C17: 108*5*6000 | E17: =G17*6 -> 126 | F17: 76.2 | G17: 21 | H17: =G17*F17 -> 1600.2 | I17: 0.91 | J17: =I17*H17 -> 1456.182
A18: A-48 | B18: Q235B PIPE | C18: 121*5*6000 | E18: =G18*6 -> 60 | F18: 85.8 | G18: 10 | H18: =G18*F18 -> 858 | I18: 0.91 | J18: =I18*H18 -> 780.78
A19: A-49 | B19: Q235B PIPE | C19: 140*6*6000 | E19: =G19*6 -> 150 | F19: 119 | G19: 25 | H19: =G19*F19 -> 2975 | I19: 0.91 | J19: =I19*H19 -> 2707.25
A20: A-50 | B20: Q235B PIPE | C20: 168*8*6000 | E20: =G20*6 -> 18 | F20: 189.4 | G20: 3 | H20: =G20*F20 -> 568.2 | I20: 0.91 | J20: =I20*H20 -> 517.062
A21: A-51 | B21: Q235B PIPE | C21: 194*8*6000 | E21: =G21*6 -> 6 | F21: 220.2 | G21: 1 | H21: =G21*F21 -> 220.2 | I21: 0.91 | J21: =I21*H21 -> 200.382
A22: A-52 | B22: Q235B PIPE | C22: 245*10*12000 | E22: =G22*12 -> 12 | F22: 695.5 | G22: 1 | H22: =G22*F22 -> 695.5 | I22: 0.91 | J22: =I22*H22 -> 632.905
A23: A-53 | B23: Q235B PIPE | C23: 32*4*6000 | E23: =G23*6 -> 6 | F23: 16.6 | G23: 1 | H23: =G23*F23 -> 16.6 | I23: 0.91 | J23: =I23*H23 -> 15.106
A24: A-54 | B24: Q235B PIPE | C24: 60*3.5*6000 | E24: =G24*6 -> 6 | F24: 29.3 | G24: 1 | H24: =G24*F24 -> 29.3 | I24: 0.91 | J24: =I24*H24 -> 26.663
A25: A-55 | B25: Q235B PIPE | C25: 60*6*6000 | E25: =G25*6 -> 6 | F25: 47.9 | G25: 1 | H25: =G25*F25 -> 47.9 | I25: 0.91 | J25: =I25*H25 -> 43.589
A26: A-57 | B26: Q235B PIPE | C26: 76*5*6000 | E26: =G26*6 -> 36 | F26: 52.6 | G26: 6 | H26: =G26*F26 -> 315.6 | I26: 0.91 | J26: =I26*H26 -> 287.196
A27: AMOUNT | G27: =SUM(G10:G26) -> 80 | H27: =SUM(H10:H26) -> 13507.2 | J27: =SUM(J10:J26) -> 24597.681
A28: SPECIFICATION:
A29: 1. SURFACE: | C29: SAFETY
A30: 2. PACKAGE: | C30: SEA WORTHY PACKING
A31: 3. QUALITY STANDARD OF MATERIAL: | C31: ACCORDANCE WITH ABOVE SPECIFICATION.
A32: TERMS:
A33: 1. INSPECTION: | C33: MILL QUALITY TEST.(ORIGINAL MTC WILL BE PROVIDED.)
A34: 2. TOLERANCE OF AMOUNT: | C34: QUANTITY AND AMOUNT ARE ALLOWED MORE OR LESS 10%.
A35: 3.TERMS OF PAYMENT: | C35: 100% LC AT SIGHT.
A36: 4. TIME OF DELIVERY: | C36: 20DAYS AFTER ORIGINAL LC
A37: 5. PORT OF LOADING: | C37: ANY PORT,CHINA
A38: 6. PORT OF DESTINATION: | C38: HAIPHONG,VIETNAM
A39: 7. TRANSPORTATION: | C39: CONTAINER
A40: 8. VALID PERIOD OF PRICE: | C40: 5DAYS
...

Sheet Báo giá của GNEE
B1: GNEE STEEL CO.,LIMITED
B2: FLAT/RM 1512 15/F LUCKY CENTRE NO.165-171 WAN CHAI ROAD WAN CHAI HK
A3: TEL: +86 15286968617 E-mail:alice@gescosteel.com
A4: QUOTATION SHEET
A5: QUOTATION NO.: GNEEYPH20240513-1
A6: DATE: MAY.13TH,2024
A7: TO:IBS
A8: SR NO. | B8: PRODUCT NAME | C8: SPECIFICATION (mm) | F8: UNIT WEIGHT (KG/PCS) | G8: QUANTITY | I8: CIF HAIPHONG, VIETNAM
E9: Số lượng (m/m2) | G9: QTY (PCS) | H9: WEIGHT (KG) | I9: UNIT PRICE（USD/KG) | J9: AMOUNT (USD) | M9: lead time
A10: A-8 | B10: HARDOX 450 PLATE | C10: 6*2000*6000 | E10: =G10*2*6 -> 36 | F10: 565.2 | G10: 3 | H10: =G10*F10 -> 1695.6 | I10: 3.21 | J10: =I10*H10 -> 5442.876 | K10: GNEEYPH20240513-1 | L10: kt: 1500X6000-2 tờ; 1500x5400-1 tờ. | M10: 20days
