Workbook
Name \0: #REF!
Name \a: #N/A
Name \a: #N/A
Name \a: #N/A
Name \a: #N/A
Name \a: #N/A
Name \a: #N/A
Name \a: #N/A
Name \a: #N/A
Name \a: #N/A
Name \a: #N/A
Name \a: #N/A
Name \a: #N/A
Name \b: #N/A
Name \c: #N/A
Name \d: #N/A
Name \e: #N/A
Name \f: #N/A
Name \g: #N/A
Name \h: #N/A
Name \h: #N/A
Name \h: #N/A
Name \h: #N/A
Name \h: #N/A
Name \h: #N/A
Name \h: #N/A
Name \h: #N/A
Name \h: #N/A
Name \h: #N/A
Name \h: #N/A
Name \h: #N/A
Name \i: #N/A
Name \i: #N/A
Name \i: #N/A
Name \i: #N/A
Name \i: #N/A
Name \i: #N/A
Name \i: #N/A
Name \i: #N/A
Name \i: #N/A
Name \i: #N/A
Name \i: #N/A
Name \i: #N/A
Name \j: #N/A
Name \k: #N/A
Name \KWS123: #N/A
Name \l: '[1]??-BLDG'!#REF!
Name \m: #N/A
Name \m: #N/A
Name \m: #N/A
Name \m: #N/A
Name \m: #N/A
Name \m: #N/A
Name \m: #N/A
Name \m: #N/A
Name \m: #N/A
Name \m: #N/A
Name \m: #N/A
Name \m: #N/A
Name \n: #N/A

Sheet HN-16-1
A1: BID ANALYSIS - GIẢI TRÌNH MUA SẮM/ĐẤU THẦU
A3: Project | B3: PROJECT No/ Dự án: 25-VPI-I-095
A4: Dự án
A5: Subject | B5: Cung cấp vật tư chính thép đen Hùng Nguyên ngày 16-1-2026
A6: Chủ đề
A8: No. | B8: CONTENT | C8: Phạm vi công việc | H8: Dự toán | K8: Đã mua | L8: Đơn vị cung cấp chào giá phần còn lại (VNĐ) | O8: Đơn vị cung cấp chào giá phần còn lại (VNĐ) | R8: Đơn vị cung cấp chào giá phần còn lại (VNĐ) | U8: Ghi chú
A9: Item | B9: Description/ Chi tiết | C9: Profile/ Vật tư | D9: Grade/ Mác vật liệu | E9: Grade/ Mác vật liệu mua | F9: Số lượng Mua (M) | G9: Số lượng PR (M) | H9: Khối lượng/ Số lượng | I9: Đơn giá (vnd) | J9: Thành tiền (vnd) | K9: Thành tiền (vnd) | L9: NGỌC HIẾU | O9: Hùng Nguyên | R9: APEC
L10: Phạm vi | M10: Đơn giá trước VAT (VNĐ/KG) | N10: Thành Tiền | O10: Phạm vi | P10: Đơn giá trước VAT (VNĐ/KG) | Q10: Thành Tiền | R10: Phạm vi | S10: Đơn giá trước VAT (VNĐ/KG) | T10: Thành Tiền
A11: Tổng | B11: Main-Material / Vật tư chính thép đen | H11: N/A | I11: N/A | J11: ='DT03 (TM)'!G6 -> 5.7151444e+10 | K11: ='Tổng hợp'!J19 -> 4.7616213e+10 | Q11: =SUM(Q12:Q13) -> 47939240 | U11: =J11-K11-Q11-N11 -> 9.4872916e+09
A12: I95-VTC01-008 | B12: =VLOOKUP(A12,'25-VPI-I-095'!L:N,3,0) -> PL12X2000X12000 | C12: Thép tấm 12x2000x12000 SS400 | D12: =VLOOKUP(A12,'25-VPI-I-095'!L:R,4,0) -> SS400 | E12: SS400 | F12: 24 | G12: =VLOOKUP(A12,'25-VPI-I-095'!L:DI,91,0) -> 0 | H12: N/A | I12: N/A | J12: N/A | K12: N/A | L12: X | M12: #N/A | N12: #N/A | O12: V | P12: 13363.64 | Q12: 30212517 | R12: V | S12: =14800/1.1 -> 13454.545 | T12: =VLOOKUP(D12,'[164]DA 95'!$B$20:$N$31,13,0) -> #N/A | U12: Chọn Hùng Nguyên
A13: I95-VTC01-121 | B13: =VLOOKUP(A13,'25-VPI-I-095'!L:N,3,0) -> PL8X1500X4600 | C13: Thép tấm 8x1500x4600 SS400 | D13: =VLOOKUP(A13,'25-VPI-I-095'!L:R,4,0) -> SS400 | E13: SS400 | F13: =3*1.5*4.6 -> 20.7 | G13: =VLOOKUP(A13,'25-VPI-I-095'!L:DI,91,0) -> 0 | H13: N/A | I13: N/A | J13: N/A | K13: N/A | L13: V | M13: =15100/1.1 -> 13727.273 | N13: #N/A | O13: V | P13: 13636.36 | Q13: 17726723 | R13: V | S13: 13727.273 | T13: =VLOOKUP(D13,'[164]DA 95'!$B$20:$N$31,13,0) -> #N/A | U13: Chọn Hùng Nguyên
B14: Xếp hạng | M14: 3 | P14: 1 | S14: 2
A15: Ghi chú: Tiếp tục công tác mua sắm để đảm báo tiến độ
A16: NGƯỜI ĐỀ NGHỊ/ RECOMMENDATION BY: | F16: NGƯỜI KIỂM TRA/ DEPARTMENT HEAD CHECK BY: | N16: APPROVED BY: PHÊ DUYỆT
N17: Nguyễn Quang Vinh | Q17: Hoàng Ngọc Bằng | T17: Đoàn Văn Toàn

Sheet hOÀNG hÀ bổ sung
A1: BID ANALYSIS - GIẢI TRÌNH MUA SẮM/ĐẤU THẦU
A3: Project | B3: PROJECT No/ Dự án: 25-VPI-I-095
A4: Dự án
A5: Subject | B5: Cung cấp vật tư phụ kiện / đóng kiện hoàng hà 26-1-2026 / Tách
A6: Chủ đề
A8: No. | B8: CONTENT | C8: Phạm vi công việc | I8: Dự toán | K8: Đã mua | L8: Đơn vị cung cấp chào giá (vnđ) | O8: Lựa chọn | P8: Ghi chú
A9: Item | B9: Description/ Chi tiết | C9: Profile/ Vật tư | D9: Grade/ Mác vật liệu | E9: Grade/ Mác vật liệu mua | F9: Số lượng Mua | H9: Khối lượng/ Số lượng | I9: Đơn giá (vnd) | J9: Thành tiền (vnd) | K9: Thành tiền (vnd) | L9: HOÀNG HÀ
L10: Phạm vi | M10: Đơn giá (VND) | N10: Thành Tiền (Chưa có VAT)
A11: Tổng | B11: Bolt-Material / Vật tư bulong, phụ kiện | H11: N/A | I11: N/A | J11: ='Tổng hợp'!K23 -> 9.374355e+09 | K11: ='Tổng hợp'!J23+'Tổng hợp'!J22-'Vật tư bạt trần toàn'!M11 -> 21764911718 | N11: =SUM(N12:N13) -> 11840000 | P11: =J11-K11-N11 -> -1.2402397e+10
A12: I95-VPK-096 | B12: =VLOOKUP(A12,'25-VPI-I-095'!L:N,3,0) -> UBOLT_DN40_M10(4N+2W) | C12: Ubolt làm theo bản vẽ | E12: Mạ kẽm | F12: 80 | G12: T4E2P | H12: =VLOOKUP(A12,'25-VPI-I-095'!L:DG,95,0) -> 80 | I12: N/A | J12: N/A | K12: N/A | L12: V | M12: 45000 | N12: =M12*F12 -> 3600000 | O12: HOÀNG HÀ | Q12: =G12-H12 -> #VALUE!
A13: I95-VPK-099 | B13: =VLOOKUP(A13,'25-VPI-I-095'!L:N,3,0) -> LÒ SO SPRING_D3 | C13: Loò xo làm theo bản vẻ | D13: D3 | E13: Inox 304 | F13: 80 | G13: cái | H13: =VLOOKUP(A13,'25-VPI-I-095'!L:DG,95,0) -> 80 | I13: N/A | J13: N/A | K13: N/A | L13: V | M13: 103000 | N13: =M13*F13 -> 8240000 | O13: HOÀNG HÀ | Q13: =G13-H13 -> #VALUE!
B14: Xếp hạng | M14: 1
A15: Ghi chú: PTM tiến hàng mua sắm để đảm bảo tiến độ
A16: NGƯỜI ĐỀ NGHỊ/ RECOMMENDATION BY: | D16: NGƯỜI KIỂM TRA/ DEPARTMENT HEAD CHECK BY: | J16: APPROVED BY: PHÊ DUYỆT
I17: Nguyễn Quang Vinh | L17: Hoàng Ngọc Bằng | O17: Đoàn Văn Toàn

Sheet Kẹp sàn VSAB
A1: BID ANALYSIS - GIẢI TRÌNH MUA SẮM/ĐẤU THẦU
A3: Project | B3: PROJECT No/ Dự án: 25-VPI-I-095
A4: Dự án
A5: Subject | B5: Cung cấp vật tư kẹp sàn grating 26-2-2026
A6: Chủ đề
A8: No. | B8: CONTENT | C8: Phạm vi công việc | G8: Dự toán | J8: Đã mua | K8: Đơn vị cung cấp chào giá (vnđ) | N8: Đơn vị cung cấp chào giá (vnđ) | Q8: Đơn vị cung cấp chào giá (vnđ) | T8: Lựa chọn | U8: Ghi chú
A9: Item | B9: Description/ Chi tiết | C9: Profile/ Vật tư | D9: Grade/ Mác vật liệu | E9: Grade/ Mác vật liệu mua | F9: Số lượng Mua (Bộ) | G9: Khối lượng/ Số lượng | H9: Đơn giá (vnd) | I9: Thành tiền (vnd) | J9: Thành tiền (vnd) | K9: WINWIN HD JOINT STOCK COMPANY | N9: CÔNG TY TNHH CKTEC | Q9: CÔNG TY CỔ PHẦN AMECC GT
K10: Phạm vi | L10: Đơn giá (VND) | M10: Thành Tiền (Chưa có VAT) | N10: Phạm vi | O10: Đơn giá (VND) | P10: Thành Tiền (Chưa có VAT) | Q10: Phạm vi | R10: Đơn giá (VND) | S10: Thành Tiền (Chưa có VAT)
A11: Tổng | B11: Gratting-Material / Vật tư gratting | G11: N/A | H11: N/A | I11: ='[165]Tổng hợp'!K21 -> 6.7325298e+09 | J11: 3.4811383e+09 | M11: =SUM(M12:M15) -> 113400000 | P11: =SUM(P12:P15) -> 104328000 | S11: =SUM(S12:S15) -> 106596000 | U11: =I11-J11-P11 -> 3.1470635e+09
A12: I95-VTC03-001 | B12: GRATING 32X5-KHÔNG RĂNG CƯA-MUA THEO BẢN VẼ | C12: Kẹp sàn | D12: SS400-HDG | E12: SS400-HDG | F12: 4056 | G12: N/A | H12: N/A | I12: N/A | J12: N/A | K12: V | L12: 25000 | M12: =L12*F12 -> 101400000 | N12: V | O12: 23000 | P12: =O12*F12 -> 93288000 | Q12: V | R12: 23500 | S12: =R12*F12 -> 95316000 | T12: CÔNG TY TNHH CKTEC
A13: I95-VTC03-002 | B13: GRATING 44X5-KHÔNG RĂNG CƯA-MUA THEO BẢN VẼ | C13: N/A | D13: SS400-HDG | E13: SS400-HDG | F13: N/A | G13: N/A | H13: N/A | I13: N/A | J13: N/A | K13: N/A | L13: N/A | M13: N/A | N13: N/A | O13: N/A | P13: N/A | Q13: N/A | R13: N/A | S13: N/A | T13: N/A
A14: I95-VTC03-003 | B14: GRATING 32X5-CÓ RĂNG CƯA-MUA THEO BẢN VẼ | C14: Kẹp sàn | D14: SS400-HDG | E14: SS400-HDG | F14: 480 | G14: N/A | H14: N/A | I14: N/A | J14: N/A | K14: V | L14: 25000 | M14: =L14*F14 -> 12000000 | N14: V | O14: 23000 | P14: =O14*F14 -> 11040000 | Q14: V | R14: 23500 | S14: =R14*F14 -> 11280000 | T14: CÔNG TY TNHH CKTEC
A15: I95-VTC03-004 | B15: GRATING 44X5-CÓ RĂNG CƯA-MUA THEO BẢN VẼ | C15: N/A | D15: SS400-HDG | E15: SS400-HDG | F15: N/A | G15: N/A | H15: N/A | I15: N/A | J15: N/A | K15: N/A | L15: N/A | M15: N/A | N15: N/A | O15: N/A | P15: N/A | Q15: N/A | R15: N/A | S15: N/A | T15: N/A
B16: Xếp hạng | L16: 3 | O16: 1 | R16: 2
A17: Ghi chú: PTM tiến hàng mua sắm để đảm bảo tiến độ
A18: NGƯỜI ĐỀ NGHỊ/ RECOMMENDATION BY: | D18: NGƯỜI KIỂM TRA/ DEPARTMENT HEAD CHECK BY: | I18: APPROVED BY: PHÊ DUYỆT
K19: Nguyễn Quang Vinh | O19: Hoàng Ngọc Bằng | S19: Đoàn Văn Toàn

Sheet WINWIN grating
A1: BID ANALYSIS - GIẢI TRÌNH MUA SẮM/ĐẤU THẦU | Z1: WINWIN HD JOINT STOCK COMPANY
Z2: Add: 10/207 Quang Trung Street - Thanh Dong Ward - Hải Phong City Tel: 0981.862.886 / Email: Winwinhd.jsc@gmail.com / Website: Winwinhd.vn | AJ2: CÔNG TY TNHH SX TM CƠ KHÍ KHANG THỊNH
A3: Project | B3: PROJECT No/ Dự án: 25-VPI-I-095 | Z3: BẢNG BÁO GIÁ / QUOTATION | AJ3: Địa chỉ: 558 Xô Viết Nghệ Tĩnh, Phường Thạnh Mỹ Tây, TP Hồ Chí Minh, Việt Nam
A4: Dự án | Z4: Khách hàng: CÔNG TY CỔ PHẦN CÔNG NGHIỆP NẶNG IBS | AJ4: Website: www.cokhikhangthinh.com – Email: info@cokhikhangthinh.com
A5: Subject | B5: Cung cấp vật tư sàn grating 6-2-2026 | Z5: Bảng báo giá số: 29126 - IBSWWHD | AJ5: Hotline: 0902.6446.86 – Zalo: 0902.6446.86 Mr Hưởng
A6: Chủ đề | Z6: Ngày báo giá: 29.01.2026 | AJ6: BẢNG BÁO GIÁ
Z7: Lần sửa đổi / Rev.: 00
A8: No. | B8: CONTENT | C8: Phạm vi công việc | G8: Dự toán | J8: Đã mua | K8: Đơn vị cung cấp chào giá (vnđ) | N8: Đơn vị cung cấp chào giá (vnđ) | Q8: Đơn vị cung cấp chào giá (vnđ) | T8: Lựa chọn | U8: Ghi chú | AK8: Kính gửi | AL8: CÔNG TY CỔ PHẦN CÔNG NGHIỆP NẶNG IBS
A9: Item | B9: Description/ Chi tiết | C9: Profile/ Vật tư | D9: Grade/ Mác vật liệu | E9: Grade/ Mác vật liệu mua | F9: Số lượng Mua (M) | G9: Khối lượng/ Số lượng | H9: Đơn giá (vnd) | I9: Thành tiền (vnd) | J9: Thành tiền (vnd) | K9: WINWIN HD JOINT STOCK COMPANY | N9: CÔNG TY TNHH SX TM CƠ KHÍ KHANG THỊNH | Q9: CÔNG TY CỔ PHẦN AMECC GT | AK9: Người liên hệ | AL9: Mr Đức | AS9: =[166]Sheet1!$I$8 -> Ngày báo giá | AT9: =TODAY() -> 46086
K10: Phạm vi | L10: Đơn giá (VND) | M10: Thành Tiền (Chưa có VAT) | N10: Phạm vi | O10: Đơn giá (VND) | P10: Thành Tiền (Chưa có VAT) | Q10: Phạm vi | R10: Đơn giá (VND) | S10: Thành Tiền (Chưa có VAT) | Z10: Stt | AA10: Mô tả | AB10: Đơn vị | AC10: Số lượng / Quantity | AD10: Số lượng | AE10: Đơn giá (đ/kg/bộ/bậc) | AF10: Tổng giá (Vnđ) | AG10: Ghi chú | AK10: Địa chỉ | AL10: Km 6 Quốc lộ 5, Phường Hùng Vương, Quận Hồng Bàng, Thành phố Hải Phòng, Việt Nam
A11: Tổng | B11: Gratting-Material / Vật tư gratting | G11: N/A | H11: N/A | I11: ='[165]Tổng hợp'!K21 -> 6.7325298e+09 | M11: =SUM(M12:M15) -> 3.4811383e+09 | P11: =SUM(P12:P15) -> 3232898000 | S11: =SUM(S12:S15) -> 3.5335804e+09 | Z11: 1 | AA11: GRATING 32X5-KHÔNG RĂNG CƯA-MẠ KẼM NÓNG | AB11: Kg | AD11: 67640 | AE11: 37000 | AF11: =AE11*AD11 -> 2502680000
A12: I95-VTC03-001 | B12: GRATING 32X5-KHÔNG RĂNG CƯA-MUA THEO BẢN VẼ | C12: GRATING 32X5-KHÔNG RĂNG CƯA-MẠ KẼM NÓNG | D12: SS400-HDG | E12: SS400-HDG | F12: 67640.06 | G12: N/A | H12: N/A | I12: N/A | J12: N/A | K12: V | L12: 37000 | M12: =L12*F12 -> 2502682220 | N12: V | O12: Danh mục/bản vẽ | P12: 2242492000 | Q12: V | R12: 37000 | S12: =R12*F12 -> 2502682220 | U12: - Chưa có giá trị phần kẹp sàn | Z12: 2 | AA12: GRATING 44X5-KHÔNG RĂNG CƯA-MẠ KẼM NÓNG | AB12: Kg | AD12: 11801 | AE12: 37000 | AF12: =AE12*AD12 -> 436637000
A13: I95-VTC03-002 | B13: GRATING 44X5-KHÔNG RĂNG CƯA-MUA THEO BẢN VẼ | C13: GRATING 44X5-KHÔNG RĂNG CƯA-MẠ KẼM NÓNG | D13: SS400-HDG | E13: SS400-HDG | F13: 11800.88 | G13: N/A | H13: N/A | I13: N/A | J13: N/A | K13: V | L13: 37000 | M13: =L13*F13 -> 4.3663256e+08 | N13: V | O13: Danh mục/bản vẽ | P13: 414348000 | Q13: V | R13: 41000 | S13: =R13*F13 -> 4.8383608e+08 | Z13: 3 | AA13: GRATING 32X5-CÓ RĂNG CƯA-MẠ KẼM NÓNG | AB13: Kg | AD13: 11432 | AE13: 38000 | AF13: =AE13*AD13 -> 434416000 | AJ13: KÝ | AK13: SẢN PHẨM | AL13: QUY CÁCH | AM13: KÍCH THƯỚC | AP13: UNIT | AQ13: SỐ LƯỢNG | AR13: ĐƠN GIÁ | AS13: ĐƠN GIÁ | AT13: GHI CHÚ
A14: I95-VTC03-003 | B14: GRATING 32X5-CÓ RĂNG CƯA-MUA THEO BẢN VẼ | C14: GRATING 32X5-CÓ RĂNG CƯA-MẠ KẼM NÓNG | D14: SS400-HDG | E14: SS400-HDG | F14: 11432.44 | G14: N/A | H14: N/A | I14: N/A | J14: N/A | K14: V | L14: 38000 | M14: =L14*F14 -> 434432720 | N14: V | O14: Danh mục/bản vẽ | P14: 474826000 | Q14: V | R14: 38000 | S14: =R14*F14 -> 434432720 | Z14: 4 | AA14: GRATING 44X5-CÓ RĂNG CƯA-MẠ KẼM NÓNG | AB14: Kg | AD14: 2619 | AE14: 41000 | AF14: =AE14*AD14 -> 107379000 | AJ14: HIỆU | AM14: BEARING | AO14: CROSS | AS14: TRƯỚC THUẾ
A15: I95-VTC03-004 | B15: GRATING 44X5-CÓ RĂNG CƯA-MUA THEO BẢN VẼ | C15: GRATING 44X5-CÓ RĂNG CƯA-MẠ KẼM NÓNG | D15: SS400-HDG | E15: SS400-HDG | F15: 2619.2889 | G15: N/A | H15: N/A | I15: N/A | J15: N/A | K15: V | L15: 41000 | M15: =L15*F15 -> 1.0739084e+08 | N15: V | O15: Danh mục/bản vẽ | P15: 101232000 | Q15: V | R15: 43000 | S15: =R15*F15 -> 1.1262942e+08 | Z15: 5 | AA15: Kẹp sàn loại SY | AB15: Bộ | AD15: =4056+480 -> 4536 | AE15: 24000 | AK15: ITEM | AL15: SPEC. | AM15: L | AO15: W | AP15: DVT | AQ15: SL | AR15: PRICE | AS15: EX.VAT | AT15: REMARKS
B16: Xếp hạng | L16: 1 | AA16: Tổng / Total | AF16: =SUM(AF11:AF15) -> 3481112000 | AM16: mm | AO16: mm
A17: Ghi chú: PTM tiến hàng mua sắm để đảm bảo tiến độ | AA17: VAT 10% | AF17: =AF16*10% -> 348111200 | AJ17: I95-VTC03-001-U1 (LA PHẲNG)
A18: NGƯỜI ĐỀ NGHỊ/ RECOMMENDATION BY: | D18: NGƯỜI KIỂM TRA/ DEPARTMENT HEAD CHECK BY: | I18: APPROVED BY: PHÊ DUYỆT | AA18: Tổng cộng | AF18: =AF17+AF16 -> 3829223200 | AJ18: 1 | AK18: V17565-PW-GR1 | AL18: THANH LA : FB 32x5 - BƯỚC 30- THANH XOẮN 6x6 BƯỚC 100 - (MM) | AM18: 1405 | AN18: x | AO18: 1300 | AP18: Tấm | AQ18: 14 | AR18: 2995000 | AS18: 41930000 | AT18: THEO BẢN VẼ
K19: Nguyễn Quang Vinh | O19: Hoàng Ngọc Bằng | S19: Đoàn Văn Toàn | Z19: Ghi chú / Note: | AJ19: 2 | AK19: V17565-PW-GR2 | AL19: THANH LA : FB 32x5 - BƯỚC 30- THANH XOẮN 6x6 BƯỚC 100 - (MM) | AM19: 886 | AN19: x | AO19: 1234 | AP19: Tấm | AQ19: 1 | AR19: 1830000 | AS19: 1830000 | AT19: THEO BẢN VẼ
AJ20: 3 | AK20: V17565-PW-GR3 | AL20: THANH LA : FB 32x5 - BƯỚC 30- THANH XOẮN 6x6 BƯỚC 100 - (MM) | AM20: 1688 | AN20: x | AO20: 1300 | AP20: Tấm | AQ20: 14 | AR20: 3809000 | AS20: 53326000 | AT20: THEO BẢN VẼ
AJ21: 4 | AK21: V17565-PW-GR4 | AL21: THANH LA : FB 32x5 - BƯỚC 30- THANH XOẮN 6x6 BƯỚC 100 - (MM) | AM21: 1329 | AN21: x | AO21: 1118 | AP21: Tấm | AQ21: 1 | AR21: 2449000 | AS21: 2449000 | AT21: THEO BẢN VẼ
AJ22: 5 | AK22: V17565-PW-GR5 | AL22: THANH LA : FB 32x5 - BƯỚC 30- THANH XOẮN 6x6 BƯỚC 100 - (MM) | AM22: 965 | AN22: x | AO22: 1118 | AP22: Tấm | AQ22: 1 | AR22: 1802000 | AS22: 1802000 | AT22: THEO BẢN VẼ
AJ23: 6 | AK23: V17565-PW-GR6 | AL23: THANH LA : FB 32x5 - BƯỚC 30- THANH XOẮN 6x6 BƯỚC 100 - (MM) | AM23: 761 | AN23: x | AO23: 1234 | AP23: Tấm | AQ23: 1 | AR23: 1585000 | AS23: 1585000 | AT23: THEO BẢN VẼ
AJ24: 7 | AK24: V17565-PW-GR7 | AL24: THANH LA : FB 32x5 - BƯỚC 30- THANH XOẮN 6x6 BƯỚC 100 - (MM) | AM24: 1329 | AN24: x | AO24: 1063 | AP24: Tấm | AQ24: 1 | AR24: 2332000 | AS24: 2332000 | AT24: THEO BẢN VẼ
AJ25: 8 | AK25: V17565-PW-GR8 | AL25: THANH LA : FB 32x5 - BƯỚC 30- THANH XOẮN 6x6 BƯỚC 100 - (MM) | AM25: 965 | AN25: x | AO25: 1063 | AP25: Tấm | AQ25: 1 | AR25: 1716000 | AS25: 1716000 | AT25: THEO BẢN VẼ
AJ26: 9 | AK26: V17565-PW-GR9 | AL26: THANH LA : FB 32x5 - BƯỚC 30- THANH XOẮN 6x6 BƯỚC 100 - (MM) | AM26: 927 | AN26: x | AO26: 1197 | AP26: Tấm | AQ26: 1 | AR26: 1854000 | AS26: 1854000 | AT26: THEO BẢN VẼ
AJ27: 10 | AK27: V17565-PW-GR10 | AL27: THANH LA : FB 32x5 - BƯỚC 30- THANH XOẮN 6x6 BƯỚC 100 - (MM) | AM27: 1329 | AN27: x | AO27: 1197 | AP27: Tấm | AQ27: 1 | AR27: 2618000 | AS27: 2618000 | AT27: THEO BẢN VẼ
AJ28: 11 | AK28: V17565-PW-GR53 | AL28: THANH LA : FB 32x5 - BƯỚC 30- THANH XOẮN 6x6 BƯỚC 100 - (MM) | AM28: 1203 | AN28: x | AO28: 1000 | AP28: Tấm | AQ28: 5 | AR28: 1996000 | AS28: 9980000 | AT28: THEO BẢN VẼ
AJ29: 12 | AK29: V17565-PW-GR54 | AL29: THANH LA : FB 32x5 - BƯỚC 30- THANH XOẮN 6x6 BƯỚC 100 - (MM) | AM29: 1203 | AN29: x | AO29: 1000 | AP29: Tấm | AQ29: 3 | AR29: 1996000 | AS29: 5988000 | AT29: THEO BẢN VẼ
AJ30: 13 | AK30: V17565-PW-GR55 | AL30: THANH LA : FB 32x5 - BƯỚC 30- THANH XOẮN 6x6 BƯỚC 100 - (MM) | AM30: 1203 | AN30: x | AO30: 573 | AP30: Tấm | AQ30: 1 | AR30: 1166000 | AS30: 1166000 | AT30: THEO BẢN VẼ
Z31: XÁC NHẬN ĐẶT HÀNG CỦA KHÁCH HÀNG | AE31: CÔNG TY CỔ PHẦN WINWIN HD | AJ31: 14 | AK31: V17565-PW-GR56 | AL31: THANH LA : FB 32x5 - BƯỚC 30- THANH XOẮN 6x6 BƯỚC 100 - (MM) | AM31: 1458 | AN31: x | AO31: 1103 | AP31: Tấm | AQ31: 1 | AR31: 2644000 | AS31: 2644000 | AT31: THEO BẢN VẼ
AJ32: 15 | AK32: V17565-PW-GR57 | AL32: THANH LA : FB 32x5 - BƯỚC 30- THANH XOẮN 6x6 BƯỚC 100 - (MM) | AM32: 1163 | AN32: x | AO32: 1080 | AP32: Tấm | AQ32: 1 | AR32: 2083000 | AS32: 2083000 | AT32: THEO BẢN VẼ
AJ33: 16 | AK33: V17565-PW-GR58 | AL33: THANH LA : FB 32x5 - BƯỚC 30- THANH XOẮN 6x6 BƯỚC 100 - (MM) | AM33: 1163 | AN33: x | AO33: 1080 | AP33: Tấm | AQ33: 1 | AR33: 2083000 | AS33: 2083000 | AT33: THEO BẢN VẼ
AJ34: 17 | AK34: V17565-PW-GR59 | AL34: THANH LA : FB 32x5 - BƯỚC 30- THANH XOẮN 6x6 BƯỚC 100 - (MM) | AM34: 1048 | AN34: x | AO34: 1080 | AP34: Tấm | AQ34: 2 | AR34: 1885000 | AS34: 3770000 | AT34: THEO BẢN VẼ
AJ35: 18 | AK35: V17565-PW-GR60 | AL35: THANH LA : FB 32x5 - BƯỚC 30- THANH XOẮN 6x6 BƯỚC 100 - (MM) | AM35: 1458 | AN35: x | AO35: 1103 | AP35: Tấm | AQ35: 1 | AR35: 2644000 | AS35: 2644000 | AT35: THEO BẢN VẼ
AJ36: 19 | AK36: V17565-PW-GR61 | AL36: THANH LA : FB 32x5 - BƯỚC 30- THANH XOẮN 6x6 BƯỚC 100 - (MM) | AM36: 790 | AN36: x | AO36: 1002 | AP36: Tấm | AQ36: 7 | AR36: 1340000 | AS36: 9380000 | AT36: THEO BẢN VẼ
AJ37: 20 | AK37: V17565-PW-GR62 | AL37: THANH LA : FB 32x5 - BƯỚC 30- THANH XOẮN 6x6 BƯỚC 100 - (MM) | AM37: 714 | AN37: x | AO37: 1002 | AP37: Tấm | AQ37: 7 | AR37: 1218000 | AS37: 8526000 | AT37: THEO BẢN VẼ
AJ38: 21 | AK38: V17565-PW-GR63 | AL38: THANH LA : FB 32x5 - BƯỚC 30- THANH XOẮN 6x6 BƯỚC 100 - (MM) | AM38: 1559 | AN38: x | AO38: 750 | AP38: Tấm | AQ38: 2 | AR38: 1940000 | AS38: 3880000 | AT38: THEO BẢN VẼ
AJ39: 22 | AK39: V17565-PW-GR64 | AL39: THANH LA : FB 32x5 - BƯỚC 30- THANH XOẮN 6x6 BƯỚC 100 - (MM) | AM39: 1254 | AN39: x | AO39: 750 | AP39: Tấm | AQ39: 1 | AR39: 1572000 | AS39: 1572000 | AT39: THEO BẢN VẼ
AJ40: 23 | AK40: V17565-PW-GR65 | AL40: THANH LA : FB 32x5 - BƯỚC 30- THANH XOẮN 6x6 BƯỚC 100 - (MM) | AM40: 1254 | AN40: x | AO40: 750 | AP40: Tấm | AQ40: 1 | AR40: 1572000 | AS40: 1572000 | AT40: THEO BẢN VẼ
...

Sheet XALACO2
A1: BID ANALYSIS - GIẢI TRÌNH MUA SẮM/ĐẤU THẦU
A3: Project | B3: PROJECT No/ Dự án: 25-VPI-I-095
A4: Dự án
A5: Subject | B5: Cung cấp vật tư chính kéo giãn của XALACO
A6: Chủ đề
A8: No. | B8: CONTENT | C8: Phạm vi công việc | I8: Dự toán | L8: Đã mua | M8: Đơn vị cung cấp chào giá phần còn lại (VNĐ) | P8: Ghi chú
A9: Item | B9: Description/ Chi tiết | C9: Profile/ Vật tư | D9: Grade/ Mác vật liệu | E9: Grade/ Mác vật liệu mua | F9: Số lượng Mua (M2) | G9: Số lượng PR (M2) | H9: Số lượng Mua (Tấm) | I9: Khối lượng/ Số lượng | J9: Đơn giá (vnd) | K9: Thành tiền (vnd) | L9: Thành tiền (vnd) | M9: XALACO
M10: Phạm vi | N10: Đơn giá trước VAT (VNĐ/TẤM) | O10: Thành Tiền
A11: Tổng | B11: Main-Material / Vật tư chính thép đen | I11: N/A | J11: N/A | K11: ='DT03 (TM)'!G6 -> 5.7151444e+10 | L11: ='Tổng hợp'!J19 -> 4.7616213e+10 | O11: =SUM(O12:O17) -> 89770000 | P11: =K11-L11-O11 -> 9.4454609e+09
A12: I95-VTC01-102 | B12: =VLOOKUP(A12,'25-VPI-I-095'!L:N,3,0) -> EXPANDED_METAL_3/4"_#16_FLATTENED | C12: Lưới kéo giãn 1.2x1219x1632 | D12: =VLOOKUP(A12,'25-VPI-I-095'!L:R,4,0) -> SS400-MẠ KẼM | E12: SS400 | F12: =H12*1.1219*1.632 -> 73.237632 | G12: =VLOOKUP(A12,'25-VPI-I-095'!L6:DF319,89,0) -> 0 | H12: 40 | I12: N/A | J12: N/A | K12: N/A | L12: N/A | M12: V | N12: 338875 | O12: =N12*H12 -> 13555000 | P12: Chọn XALACO
A13: I95-VTC01-102 | B13: =VLOOKUP(A13,'25-VPI-I-095'!L:N,3,0) -> EXPANDED_METAL_3/4"_#16_FLATTENED | C13: Lưới kéo giãn 1.2x1219x2337 | D13: =VLOOKUP(A13,'25-VPI-I-095'!L:R,4,0) -> SS400-MẠ KẼM | E13: SS400 | F13: =H13*1.1219*2.337 -> 104.87521 | H13: 40 | I13: N/A | J13: N/A | K13: N/A | L13: N/A | M13: V | N13: 485250 | O13: =N13*H13 -> 19410000 | P13: Chọn XALACO
A14: I95-VTC01-102 | B14: =VLOOKUP(A14,'25-VPI-I-095'!L:N,3,0) -> EXPANDED_METAL_3/4"_#16_FLATTENED | C14: Lưới kéo giãn 1.2x1219x2438 | D14: =VLOOKUP(A14,'25-VPI-I-095'!L:R,4,0) -> SS400-MẠ KẼM | E14: SS400 | F14: =H14*1.1219*2.438 -> 246.1673 | H14: 90 | I14: N/A | J14: N/A | K14: N/A | L14: N/A | M14: V | N14: 506250 | O14: =N14*H14 -> 45562500 | P14: Chọn XALACO
A15: I95-VTC01-102 | B15: =VLOOKUP(A15,'25-VPI-I-095'!L:N,3,0) -> EXPANDED_METAL_3/4"_#16_FLATTENED | C15: Lưới kéo giãn 1.2x1219x2750 | D15: =VLOOKUP(A15,'25-VPI-I-095'!L:R,4,0) -> SS400-MẠ KẼM | E15: SS400 | F15: =H15*1.1219*2.75 -> 12.3409 | H15: 4 | I15: N/A | J15: N/A | K15: N/A | L15: N/A | M15: V | N15: 571125 | O15: =N15*H15 -> 2284500 | P15: Chọn XALACO
A16: I95-VTC01-102 | B16: =VLOOKUP(A16,'25-VPI-I-095'!L:N,3,0) -> EXPANDED_METAL_3/4"_#16_FLATTENED | C16: Lưới kéo giãn 1.2x1219x2850 | D16: =VLOOKUP(A16,'25-VPI-I-095'!L:R,4,0) -> SS400-MẠ KẼM | E16: SS400 | F16: =H16*1.1219*2.85 -> 6.39483 | H16: 2 | I16: N/A | J16: N/A | K16: N/A | L16: N/A | M16: V | N16: 591750 | O16: =N16*H16 -> 1183500 | P16: Chọn XALACO
A17: I95-VTC01-102 | B17: =VLOOKUP(A17,'25-VPI-I-095'!L:N,3,0) -> EXPANDED_METAL_3/4"_#16_FLATTENED | C17: Lưới kéo giãn 1.2x1219x3120 | D17: =VLOOKUP(A17,'25-VPI-I-095'!L:R,4,0) -> SS400-MẠ KẼM | E17: SS400 | F17: =H17*1.1219*3.12 -> 42.003936 | H17: 12 | I17: N/A | J17: N/A | K17: N/A | L17: N/A | M17: V | N17: 647875 | O17: =N17*H17 -> 7774500 | P17: Chọn XALACO
B18: Xếp hạng | N18: 1
A19: Ghi chú: Tiếp tục công tác mua sắm để đảm báo tiến độ
A20: NGƯỜI ĐỀ NGHỊ/ RECOMMENDATION BY: | D20: NGƯỜI KIỂM TRA/ DEPARTMENT HEAD CHECK BY: | K20: APPROVED BY: PHÊ DUYỆT
K21: Nguyễn Quang Vinh | M21: Hoàng Ngọc Bằng | O21: Đoàn Văn Toàn

Sheet Đạt phát 095 24-2 
A1: BID ANALYSIS - GIẢI TRÌNH MUA SẮM/ĐẤU THẦU
A3: Project | B3: PROJECT No/ Dự án: 25-VPI-I-095
A4: Dự án
A5: Subject | B5: Cung cấp vật tư chính thép hình tấm đạt phát 24-2-2026
A6: Chủ đề
A8: No. | B8: CONTENT | C8: Phạm vi công việc | G8: Dự toán | J8: Đã mua | K8: Đơn vị cung cấp chào giá phần còn lại (VNĐ) | N8: Đơn vị cung cấp chào giá phần còn lại (VNĐ) | Q8: Đơn vị cung cấp chào giá phần còn lại (VNĐ) | T8: Ghi chú
A9: Item | B9: Description/ Chi tiết | C9: Profile/ Vật tư | D9: Grade/ Mác vật liệu | E9: Số lượng Mua (M) | F9: Số lượng PR (M) | G9: Khối lượng/ Số lượng | H9: Đơn giá (vnd) | I9: Thành tiền (vnd) | J9: Thành tiền (vnd) | K9: NGỌC HIẾU | N9: Hùng Nguyên | Q9: ĐẠT PHÁT
K10: Phạm vi | L10: Đơn giá trước VAT (VNĐ/KG) | M10: Thành Tiền | N10: Phạm vi | O10: Đơn giá trước VAT (VNĐ/KG) | P10: Thành Tiền | Q10: Phạm vi | R10: Đơn giá trước VAT (VNĐ/KG) | S10: Thành Tiền
A11: Tổng | B11: Main-Material / Vật tư chính thép đen | G11: N/A | H11: N/A | I11: ='DT03 (TM)'!G6 -> 5.7151444e+10 | J11: ='Tổng hợp'!J19+'Tổng hợp'!J24+'Ngọc hiếu 095 24-2'!M11 -> 5.1739565e+10 | S11: =SUM(S12:S15) -> 2.4006797e+08 | T11: =I11-J11-P11-M11-S11 -> 5.1718113e+09
A12: I95-VTC01-004 | B12: =VLOOKUP(A12,'25-VPI-I-095'!L:N,3,0) -> PL25x2000x12000 | C12: Thép tấm 25x2000x12000 | D12: Q355B | E12: 48 | F12: =VLOOKUP(A12,'25-VPI-I-095'!L:DF,97,0) -> 48 | G12: N/A | H12: N/A | I12: N/A | J12: N/A | K12: X | L12: #N/A | M12: N//A | N12: X | O12: 14818.18 | P12: N//A | Q12: X | R12: 14636.364 | S12: 1.3787455e+08 | T12: Chọn ĐẠT PHÁT
A13: Tổng | B13: Packing-Material / Vật tư đóng kiện | G13: N/A | H13: N/A | J13: ='Tổng hợp'!J26 -> 0 | T13: =I13-J13-P13-M13 -> 0
A14: I95-VDK-014 | B14: =VLOOKUP(A14,'25-VPI-I-095'!L:N,3,0) -> PL10X2000X12000 | C14: Thép tấm 10x2000x6000 | D14: SS400 | E14: 48 | F14: =VLOOKUP(A14,'25-VPI-I-095'!L:DF,97,0) -> 55.80349 | G14: N/A | H14: N/A | I14: N/A | J14: N/A | K14: X | L14: #N/A | M14: N//A | N14: V | O14: 13363.64 | P14: N//A | Q14: X | R14: 13363.636 | S14: 50354182 | T14: Chọn ĐẠT PHÁT
A15: I95-VDK-010 | B15: =VLOOKUP(A15,'25-VPI-I-095'!L:N,3,0) -> H300X150X6.5X9-12000L | C15: Thép H300x150x6.5x9x12000 | D15: SS400 | E15: =7*12 -> 84 | F15: =VLOOKUP(A15,'25-VPI-I-095'!L:DF,97,0) -> 81.29712 | G15: N/A | H15: N/A | I15: N/A | J15: N/A | K15: V | L15: =19000/1.1 -> 17272.727 | M15: N//A | N15: X | O15: #N/A | P15: N//A | Q15: X | R15: 16818.182 | S15: 51839242 | T15: Chọn ĐẠT PHÁT
B16: Xếp hạng | L16: 1 | O16: 2 | R16: 3
A17: Ghi chú: Tiếp tục công tác mua sắm để đảm báo tiến độ
A18: NGƯỜI ĐỀ NGHỊ/ RECOMMENDATION BY: | D18: NGƯỜI KIỂM TRA/ DEPARTMENT HEAD CHECK BY: | M18: APPROVED BY: PHÊ DUYỆT
M19: Nguyễn Quang Vinh | P19: Hoàng Ngọc Bằng | S19: Đoàn Văn Toàn

Sheet Ngọc hiếu 095 24-2
A1: BID ANALYSIS - GIẢI TRÌNH MUA SẮM/ĐẤU THẦU
A3: Project | B3: PROJECT No/ Dự án: 25-VPI-I-095
A4: Dự án
A5: Subject | B5: Cung cấp vật tư chính thép hình Ngọc Hiếu 24-2-2026
A6: Chủ đề
A8: No. | B8: CONTENT | C8: Phạm vi công việc | G8: Dự toán | J8: Đã mua | K8: Đơn vị cung cấp chào giá phần còn lại (VNĐ) | N8: Đơn vị cung cấp chào giá phần còn lại (VNĐ) | Q8: Đơn vị cung cấp chào giá phần còn lại (VNĐ) | T8: Ghi chú
A9: Item | B9: Description/ Chi tiết | C9: Profile/ Vật tư | D9: Grade/ Mác vật liệu | E9: Số lượng Mua (M) | F9: Số lượng PR (M) | G9: Khối lượng/ Số lượng | H9: Đơn giá (vnd) | I9: Thành tiền (vnd) | J9: Thành tiền (vnd) | K9: NGỌC HIẾU | N9: Hùng Nguyên | Q9: APEC
K10: Phạm vi | L10: Đơn giá trước VAT (VNĐ/KG) | M10: Thành Tiền | N10: Phạm vi | O10: Đơn giá trước VAT (VNĐ/KG) | P10: Thành Tiền | Q10: Phạm vi | R10: Đơn giá trước VAT (VNĐ/KG) | S10: Thành Tiền
A11: Tổng | B11: Main-Material / Vật tư chính thép đen | G11: N/A | H11: N/A | I11: ='DT03 (TM)'!G6 -> 5.7151444e+10 | J11: ='Tổng hợp'!J19+'Tổng hợp'!J24-M11 -> 4.9967481e+10 | M11: =SUM(M12:M24) -> 886042100 | T11: =I11-J11-P11-M11 -> 6.2979213e+09
A12: I95-VTC01-114 | B12: =VLOOKUP(A12,'25-VPI-I-095'!L:N,3,0) -> L65X65X6-12000L | C12: Thép V65*65*6*12000 | D12: =VLOOKUP(A12,'25-VPI-I-095'!L:R,4,0) -> SS400 | E12: 24 | F12: =VLOOKUP(A12,'25-VPI-I-095'!L:DF,97,0) -> 0 | G12: N/A | H12: N/A | I12: N/A | J12: N/A | K12: V | L12: 14181.82 | M12: 2013818 | N12: X | O12: #N/A | P12: N//A | Q12: X | R12: #N/A | S12: N//A | T12: Chọn Ngọc Hiếu
A13: Tổng | B13: Packing-Material / Vật tư đóng kiện | G13: N/A | H13: N/A | J13: ='Tổng hợp'!J26 -> 0 | T13: =I13-J13-P13-M13 -> 0
A14: I95-VDK-004 | B14: =VLOOKUP(A14,'25-VPI-I-095'!L:N,3,0) -> C100X50X5X7.5-12000L | C14: Thép U100*48*5,3**12000 TQ | D14: =VLOOKUP(A14,'25-VPI-I-095'!L:R,4,0) -> SS400 | E14: 1272 | F14: =VLOOKUP(A14,'25-VPI-I-095'!L:DF,97,0) -> 6.76076 | G14: N/A | H14: N/A | I14: N/A | J14: N/A | K14: V | L14: 14000 | M14: 178080000 | N14: V | O14: 17363.64 | P14: N//A | Q14: X | R14: #N/A | S14: N//A | T14: Chọn Ngọc Hiếu
A15: I95-VDK-005 | B15: =VLOOKUP(A15,'25-VPI-I-095'!L:N,3,0) -> H100X100X6X8-12000L | C15: Thép H100*100*6*8*12000 | D15: =VLOOKUP(A15,'25-VPI-I-095'!L:R,4,0) -> SS400 | E15: 108 | F15: =E15/12 ( 3 cây) | G15: N/A | H15: N/A | I15: N/A | J15: N/A | K15: V | L15: 16909.09 | M15: 30859089 | N15: V | O15: 17500 | P15: N//A | Q15: X | R15: #N/A | S15: N//A | T15: Chọn Ngọc Hiếu
A16: I95-VDK-006 | B16: =VLOOKUP(A16,'25-VPI-I-095'!L:N,3,0) -> H125X125X6.5X9-12000L | C16: Thép H125*125*6,5*9*12000 | D16: =VLOOKUP(A16,'25-VPI-I-095'!L:R,4,0) -> SS400 | E16: 300 | F16: =E16/12 -> 25 | G16: N/A | H16: N/A | I16: N/A | J16: N/A | K16: V | L16: 16909.09 | M16: 119716357 | N16: V | O16: 17500 | P16: N//A | Q16: X | R16: #N/A | S16: N//A | T16: Chọn Ngọc Hiếu
A17: I95-VDK-007 | B17: =VLOOKUP(A17,'25-VPI-I-095'!L:N,3,0) -> H150X150X7X10-12000L | C17: Thép H150*150*7*10*12000 | D17: =VLOOKUP(A17,'25-VPI-I-095'!L:R,4,0) -> SS400 | E17: 96 | F17: =E17/12 -> 8 | G17: N/A | H17: N/A | I17: N/A | J17: N/A | K17: V | L17: 16545.45 | M17: 49404714 | N17: V | O17: 17500 | P17: N//A | Q17: X | R17: #N/A | S17: N//A | T17: Chọn Ngọc Hiếu
A18: I95-VDK-008 | B18: =VLOOKUP(A18,'25-VPI-I-095'!L:N,3,0) -> H150X75X5X7-12000L | C18: Thép I150*75*5*7*12000 | D18: =VLOOKUP(A18,'25-VPI-I-095'!L:R,4,0) -> SS400 | E18: 144 | F18: =E18/12 -> 12 | G18: N/A | H18: N/A | I18: N/A | J18: N/A | K18: V | L18: 17454.55 | M18: 35188373 | N18: X | O18: #N/A | P18: N//A | Q18: X | R18: #N/A | S18: N//A | T18: Chọn Ngọc Hiếu
A19: I95-VDK-009 | B19: =VLOOKUP(A19,'25-VPI-I-095'!L:N,3,0) -> H200X100X5.5X8-12000L | C19: Thép I200*100*5,5*8*12000 | D19: =VLOOKUP(A19,'25-VPI-I-095'!L:R,4,0) -> SS400 | E19: 252 | F19: =E19/12 -> 21 | G19: N/A | H19: N/A | I19: N/A | J19: N/A | K19: V | L19: 17272.73 | M19: 90975469 | N19: V | O19: 17363.64 | P19: N//A | Q19: X | R19: #N/A | S19: N//A | T19: Chọn Ngọc Hiếu
A20: I95-VDK-032 | B20: =VLOOKUP(A20,'25-VPI-I-095'!L:N,3,0) -> C125X65X6X8-12000L | C20: Thép U125*65*6*8*12000 | D20: =VLOOKUP(A20,'25-VPI-I-095'!L:R,4,0) -> SS400 | E20: 60 | F20: =VLOOKUP(A20,'25-VPI-I-095'!L:DF,97,0) -> -4.812 | G20: N/A | H20: N/A | I20: N/A | J20: N/A | K20: V | L20: 17090.91 | M20: 13741092 | N20: X | O20: #N/A | P20: N//A | Q20: X | R20: #N/A | S20: N//A | T20: Chọn Ngọc Hiếu
A21: I95-VDK-033 | B21: =VLOOKUP(A21,'25-VPI-I-095'!L:N,3,0) -> C75X40X5X7-12000L | C21: Thép U75*40*5*7*12000 | D21: =VLOOKUP(A21,'25-VPI-I-095'!L:R,4,0) -> SS400 | E21: 1368 | F21: =VLOOKUP(A21,'25-VPI-I-095'!L:DF,97,0) -> 2.8044 | G21: N/A | H21: N/A | I21: N/A | J21: N/A | K21: V | L21: 17272.73 | M21: 163520935 | N21: X | O21: #N/A | P21: N//A | Q21: X | R21: #N/A | S21: N//A | T21: Chọn Ngọc Hiếu
A22: I95-VDK-034 | B22: =VLOOKUP(A22,'25-VPI-I-095'!L:N,3,0) -> H100X50X5X7-12000L | C22: Thép I100*55*4,5*6000 | D22: =VLOOKUP(A22,'25-VPI-I-095'!L:R,4,0) -> SS400 | E22: =228/2 -> 114 | F22: =E22/6 -> 19 | G22: N/A | H22: N/A | I22: N/A | J22: N/A | K22: V | L22: 15636.36 | M22: 16042905 | N22: V | O22: 15454.55 | P22: N//A | Q22: X | R22: #N/A | S22: N//A | T22: Chọn Ngọc Hiếu
A23: I95-VDK-035 | B23: =VLOOKUP(A23,'25-VPI-I-095'!L:N,3,0) -> H194X150X6X9-12000L | C23: Thép I194*150*6*9*12000 | D23: =VLOOKUP(A23,'25-VPI-I-095'!L:R,4,0) -> SS400 | E23: 288 | F23: =VLOOKUP(A23,'25-VPI-I-095'!L:DF,97,0) -> -1.3584 | G23: N/A | H23: N/A | I23: N/A | J23: N/A | K23: V | L23: 16818.18 | M23: 144821348 | N23: V | O23: 17363.64 | P23: N//A | Q23: X | R23: #N/A | S23: N//A | T23: Chọn Ngọc Hiếu
A24: I95-VDK-036 | B24: =VLOOKUP(A24,'25-VPI-I-095'!L:N,3,0) -> L50X50X6-6000L | C24: Thép V50*50*6*6000 | D24: =VLOOKUP(A24,'25-VPI-I-095'!L:R,4,0) -> SS400 | E24: =1344/2 -> 672 | F24: =VLOOKUP(A24,'25-VPI-I-095'!L:DF,97,0) -> -2.9274 | G24: N/A | H24: N/A | I24: N/A | J24: N/A | K24: V | L24: 14000 | M24: 41678000 | N24: X | O24: 14136.36 | P24: N//A | Q24: X | R24: #N/A | S24: N//A | T24: Chọn Ngọc Hiếu
B25: Xếp hạng | L25: 1 | O25: 2 | R25: 3
A26: Ghi chú: Tiếp tục công tác mua sắm để đảm báo tiến độ
A27: NGƯỜI ĐỀ NGHỊ/ RECOMMENDATION BY: | E27: NGƯỜI KIỂM TRA/ DEPARTMENT HEAD CHECK BY: | M27: APPROVED BY: PHÊ DUYỆT
M28: Nguyễn Quang Vinh | P28: Hoàng Ngọc Bằng | S28: Đoàn Văn Toàn

Sheet Đại phát 31-1
A1: BID ANALYSIS - GIẢI TRÌNH MUA SẮM/ĐẤU THẦU
A3: Project | B3: PROJECT No/ Dự án: 25-VPI-I-095
A4: Dự án
A5: Subject | B5: Cung cấp vật tư chính thép đen ĐẠT PHÁT 31-1-2026
A6: Chủ đề
A8: No. | B8: CONTENT | C8: Phạm vi công việc | H8: Dự toán | K8: Đã mua | L8: Đơn vị cung cấp chào giá phần còn lại (VNĐ) | O8: Đơn vị cung cấp chào giá phần còn lại (VNĐ) | R8: Ghi chú
A9: Item | B9: Description/ Chi tiết | C9: Profile/ Vật tư | D9: Grade/ Mác vật liệu | E9: Grade/ Mác vật liệu mua | F9: Số lượng Mua (M) | G9: Số lượng PR (M) | H9: Khối lượng/ Số lượng | I9: Đơn giá (vnd) | J9: Thành tiền (vnd) | K9: Thành tiền (vnd) | L9: CÔNG TY TNHH SX và TM KIM KHÍ ĐẠT PHÁT | O9: Hùng Nguyên/ APEC
L10: Phạm vi | M10: Đơn giá trước VAT (VNĐ/KG) | N10: Thành Tiền | O10: Phạm vi | P10: Đơn giá trước VAT (VNĐ/KG) | Q10: Thành Tiền
A11: Tổng | B11: Main-Material / Vật tư chính thép đen | H11: N/A | I11: N/A | J11: ='DT03 (TM)'!G6 -> 5.7151444e+10 | K11: ='Tổng hợp'!J19+'Tổng hợp'!J24 -> 5.0853523e+10 | N11: =N12 -> 60288000 | R11: =J11-K11-Q11-N11 -> 6.2376333e+09
A12: I95-VTC01-023 | B12: PL20X2000X12000 | C12: Thép tấm Q355B 20x2000x12000 | D12: ASTM A75 GrB | E12: Q355B | F12: 24 | G12: 19.490933 | H12: N/A | I12: N/A | J12: N/A | K12: N/A | L12: V | M12: =16000/1.1 -> 14545.455 | N12: 60288000 | O12: X | P12: N/A | Q12: N/A | R12: Chọn ĐẠT PHÁT
B13: Xếp hạng | M13: 1 | P13: 2
A14: Ghi chú: Tiếp tục công tác mua sắm để đảm báo tiến độ
A15: NGƯỜI ĐỀ NGHỊ/ RECOMMENDATION BY: | D15: NGƯỜI KIỂM TRA/ DEPARTMENT HEAD CHECK BY: | J15: APPROVED BY: PHÊ DUYỆT
J16: Nguyễn Quang Vinh | M16: Hoàng Ngọc Bằng | P16: Đoàn Văn Toàn

Sheet Hùng nguyên 29-1
A1: BID ANALYSIS - GIẢI TRÌNH MUA SẮM/ĐẤU THẦU
A3: Project | B3: PROJECT No/ Dự án: 25-VPI-I-095
A4: Dự án
A5: Subject | B5: Cung cấp vật tư chính thép đen Hùng Nguyên 29-1-2026
A6: Chủ đề
A8: No. | B8: CONTENT | C8: Phạm vi công việc | H8: Dự toán | K8: Đã mua | L8: Đơn vị cung cấp chào giá phần còn lại (VNĐ) | O8: Đơn vị cung cấp chào giá phần còn lại (VNĐ) | R8: Ghi chú
A9: Item | B9: Description/ Chi tiết | C9: Profile/ Vật tư | D9: Grade/ Mác vật liệu | E9: Grade/ Mác vật liệu mua | F9: Số lượng Mua (M) | G9: Số lượng PR (M) | H9: Khối lượng/ Số lượng | I9: Đơn giá (vnd) | J9: Thành tiền (vnd) | K9: Thành tiền (vnd) | L9: NGỌC HIẾU | O9: Hùng Nguyên
L10: Phạm vi | M10: Đơn giá trước VAT (VNĐ/KG) | N10: Thành Tiền | O10: Phạm vi | P10: Đơn giá trước VAT (VNĐ/KG) | Q10: Thành Tiền
A11: Tổng | B11: Main-Material / Vật tư chính thép đen | H11: N/A | I11: N/A | J11: ='DT03 (TM)'!G6 -> 5.7151444e+10 | K11: ='Tổng hợp'!J19+'Tổng hợp'!J24-Q11 -> 5.0689355e+10 | Q11: =SUM(Q12:Q13) -> 1.6416721e+08 | R11: =J11-K11-Q11-N11 -> 6.2979213e+09
A12: I95-VTC01-023 | B12: H200X200X8X12-12000L | C12: H200X200X8X12-12000L | D12: SS400 | E12: SS400 | F12: =7*12 -> 84 | G12: 0 | H12: N/A | I12: N/A | J12: N/A | K12: N/A | L12: X | M12: =19400/1.1 -> 17636.364 | N12: #N/A | O12: V | P12: =19200/1.1 -> 17454.545 | Q12: 73162492 | R12: Chọn Hùng Nguyên
A13: I95-VTC01-084 | B13: H194X150X6X9-12000L | C13: H194X150X6X9-12000L | D13: =VLOOKUP(A13,'25-VPI-I-095'!L:R,4,0) -> SS400 | E13: SS400 | F13: =15*12 -> 180 | G13: 0 | H13: N/A | I13: N/A | J13: N/A | K13: N/A | L13: V | M13: =18600/1.1 -> 16909.091 | N13: #N/A | O13: V | P13: =18600/1.1 -> 16909.091 | Q13: 91004722
B14: Xếp hạng | M14: 2 | P14: 1
A15: Ghi chú: Tiếp tục công tác mua sắm để đảm báo tiến độ
A16: NGƯỜI ĐỀ NGHỊ/ RECOMMENDATION BY: | D16: NGƯỜI KIỂM TRA/ DEPARTMENT HEAD CHECK BY: | J16: APPROVED BY: PHÊ DUYỆT
J17: Nguyễn Quang Vinh | M17: Hoàng Ngọc Bằng | P17: Đoàn Văn Toàn

Sheet Hùng nguyên 26-1
A1: BID ANALYSIS - GIẢI TRÌNH MUA SẮM/ĐẤU THẦU
A3: Project | B3: PROJECT No/ Dự án: 25-VPI-I-095
A4: Dự án
A5: Subject | B5: Cung cấp vật tư chính thép đen Hùng Nguyên 26-1-2026
A6: Chủ đề
A8: No. | B8: CONTENT | C8: Phạm vi công việc | H8: Dự toán | K8: Đã mua | L8: Đơn vị cung cấp chào giá phần còn lại (VNĐ) | O8: Đơn vị cung cấp chào giá phần còn lại (VNĐ) | R8: Đơn vị cung cấp chào giá phần còn lại (VNĐ) | U8: Ghi chú
A9: Item | B9: Description/ Chi tiết | C9: Profile/ Vật tư | D9: Grade/ Mác vật liệu | E9: Grade/ Mác vật liệu mua | F9: Số lượng Mua (M) | G9: Số lượng PR (M) | H9: Khối lượng/ Số lượng | I9: Đơn giá (vnd) | J9: Thành tiền (vnd) | K9: Thành tiền (vnd) | L9: NGỌC HIẾU | O9: Hùng Nguyên | R9: APEC
L10: Phạm vi | M10: Đơn giá trước VAT (VNĐ/KG) | N10: Thành Tiền | O10: Phạm vi | P10: Đơn giá trước VAT (VNĐ/KG) | Q10: Thành Tiền | R10: Phạm vi | S10: Đơn giá trước VAT (VNĐ/KG) | T10: Thành Tiền
A11: Tổng | B11: Main-Material / Vật tư chính thép đen | H11: N/A | I11: N/A | J11: ='DT03 (TM)'!G6 -> 5.7151444e+10 | K11: ='Tổng hợp'!J19+'Tổng hợp'!J24 -> 5.0853523e+10 | Q11: =SUM(Q12:Q13) -> 185676739 | U11: =J11-K11-Q11-N11 -> 6.1122446e+09
A12: I95-VTC01-001 I95-VDK-014 | B12: PL10x2000X12000 | C12: Thép tấm 10x2000x12000 | D12: SS400 | E12: SS400 | F12: 120 | G12: 118 | H12: N/A | I12: N/A | J12: N/A | K12: N/A | L12: X | M12: 13636.36 | N12: #N/A | O12: V | P12: 13318.18 | Q12: 125457256 | R12: X | S12: =VLOOKUP(C12,'[164]DA 95'!$B$20:$N$31,13,0) -> #N/A | T12: =VLOOKUP(D12,'[164]DA 95'!$B$20:$N$31,13,0) -> #N/A | U12: Chọn Hùng Nguyên
A13: I95-VDK-017 | B13: PL6X2000X12000 | C13: Thép tấm 6x2000x12000 | D13: =VLOOKUP(A13,'25-VPI-I-095'!L:R,4,0) -> SS400 | E13: SS400 | F13: 96 | G13: 100.29197 | H13: N/A | I13: N/A | J13: N/A | K13: N/A | L13: V | M13: 13636.36 | N13: #N/A | O13: V | P13: 13318.18 | Q13: 60219483 | R13: V | S13: =15000/1.1 -> 13636.364 | T13: =VLOOKUP(D13,'[164]DA 95'!$B$20:$N$31,13,0) -> #N/A | U13: Chọn Hùng Nguyên
B14: Xếp hạng | M14: 2 | P14: 1 | S14: 3
A15: Ghi chú: Tiếp tục công tác mua sắm để đảm báo tiến độ
A16: NGƯỜI ĐỀ NGHỊ/ RECOMMENDATION BY: | F16: NGƯỜI KIỂM TRA/ DEPARTMENT HEAD CHECK BY: | N16: APPROVED BY: PHÊ DUYỆT
N17: Nguyễn Quang Vinh | Q17: Hoàng Ngọc Bằng | T17: Đoàn Văn Toàn

Sheet Vật tư bạt trần toàn
A1: BID ANALYSIS - GIẢI TRÌNH MUA SẮM/ĐẤU THẦU
A3: Project | B3: PROJECT No/ Dự án: 25-VPI-I-095
A4: Dự án
A5: Subject | B5: Cung cấp vật tư bạt đóng kiện Trần Toàn 26-1-2026
A6: Chủ đề
A8: No. | B8: CONTENT | C8: Phạm vi công việc | G8: Dự toán | J8: Đã mua | K8: Đơn vị cung cấp chào giá (vnđ) | N8: Lựa chọn | O8: Ghi chú
A9: Item | B9: Description/ Chi tiết | C9: Profile/ Vật tư | D9: Grade/ Mác vật liệu | E9: Đơn vị | F9: Số lượng Mua (M2) | G9: Khối lượng/ Số lượng | H9: Đơn giá (vnd) | I9: Thành tiền (vnd) | J9: Thành tiền (vnd) | K9: Trần Toàn
K10: Phạm vi | L10: Đơn giá (VND) | M10: Thành Tiền (Chưa có VAT)
A11: Tổng | B11: Packing-Material / Vật tư đóng kiện | G11: N/A | H11: N/A | M11: =SUM(M12:M104) -> 559330930 | O11: =I11-J11-M11 -> -559330930
A12: I95-VDK-027 | B12: I95-BAT-BC10 HÌNH CHỮ NHẬT12346 X 3761 = 2 Tấm | C12: Bạt I95 - BC10 ( 12346 X 3761 ) x 2 tấm | D12: bạt da 2 lớp chống nước, khuyên cách nhau 500-mua theo bản vẽ | E12: m2 | F12: 92.87 | G12: N/A | H12: N/A | I12: N/A | J12: N/A | K12: V | L12: 50500 | M12: =L12*F12 -> 4689935 | N12: Trần Toàn | O12: Chưa có trong dự toán
A13: I95-VDK-027 | B13: I95-BAT-SC10A HÌNH CHỮ NHẬT26691 X 3761 = 2 Tấm | C13: Bạt I95 - SC10A ( 26691 x 3761 ) x 2 tấm | D13: bạt da 2 lớp chống nước, khuyên cách nhau 500-mua theo bản vẽ | E13: m2 | F13: 200.77 | G13: N/A | H13: N/A | I13: N/A | J13: N/A | K13: V | L13: 50500 | M13: =L13*F13 -> 10138885 | N13: Trần Toàn | O13: Chưa có trong dự toán
A14: I95-VDK-027 | B14: I95-BAT-SC10C HÌNH CHỮ NHẬT26691 X 3761 = 2 Tấm | C14: Bạt I95 - SC10C ( 26691 x 3761 ) x 2 tấm | D14: bạt da 2 lớp chống nước, khuyên cách nhau 500-mua theo bản vẽ | E14: m2 | F14: 200.77 | G14: N/A | H14: N/A | I14: N/A | J14: N/A | K14: V | L14: 50500 | M14: =L14*F14 -> 10138885 | N14: Trần Toàn | O14: Chưa có trong dự toán
A15: I95-VDK-027 | B15: I95-BAT-BC20 HÌNH CHỮ NHẬT13338 X 4994 = 2 Tấm | C15: Bạt I95 - BC20 ( 13338 X 4994 ) x 2 tấm | D15: bạt da 2 lớp chống nước, khuyên cách nhau 500-mua theo bản vẽ | E15: m2 | F15: 133.22 | G15: N/A | H15: N/A | I15: N/A | J15: N/A | K15: V | L15: 50500 | M15: =L15*F15 -> 6727610 | N15: Trần Toàn | O15: Chưa có trong dự toán
A16: I95-VDK-027 | B16: I95-BAT-SC20A HÌNH CHỮ NHẬT30362 X 5038 = 2 Tấm | C16: Bạt I95 - SC20A ( 30362 x 5038 ) x 2 tấm | D16: bạt da 2 lớp chống nước, khuyên cách nhau 500-mua theo bản vẽ | E16: m2 | F16: 305.93 | G16: N/A | H16: N/A | I16: N/A | J16: N/A | K16: V | L16: 50500 | M16: =L16*F16 -> 15449465 | N16: Trần Toàn | O16: Chưa có trong dự toán
A17: I95-VDK-027 | B17: I95-BAT-SC20C HÌNH CHỮ NHẬT30362 X 5038 = 2 Tấm | C17: Bạt I95 - SC20C ( 30362 x 5038 ) x 2 tấm | D17: bạt da 2 lớp chống nước, khuyên cách nhau 500-mua theo bản vẽ | E17: m2 | F17: 305.93 | G17: N/A | H17: N/A | I17: N/A | J17: N/A | K17: V | L17: 50500 | M17: =L17*F17 -> 15449465 | N17: Trần Toàn | O17: Chưa có trong dự toán
A18: I95-VDK-027 | B18: I95-BAT-BC301 HÌNH CHỮ NHẬT12003 X 4072 = 2 Tấm | C18: Bạt I95 - BC301 ( 12003 x 4072 ) x 2 tấm | D18: bạt da 2 lớp chống nước, khuyên cách nhau 500-mua theo bản vẽ | E18: m2 | F18: 97.75 | G18: N/A | H18: N/A | I18: N/A | J18: N/A | K18: V | L18: 50500 | M18: =L18*F18 -> 4936375 | N18: Trần Toàn | O18: Chưa có trong dự toán
A19: I95-VDK-027 | B19: I95-BAT-SC30A1 HÌNH CHỮ NHẬT29384 X 3919 = 2 Tấm | C19: Bạt I95 - SC30A1 ( 29384 x 3919 ) x 2 tấm | D19: bạt da 2 lớp chống nước, khuyên cách nhau 500-mua theo bản vẽ | E19: m2 | F19: 230.31 | G19: N/A | H19: N/A | I19: N/A | J19: N/A | K19: V | L19: 50500 | M19: =L19*F19 -> 11630655 | N19: Trần Toàn | O19: Chưa có trong dự toán
A20: I95-VDK-027 | B20: I95-BAT-SC30C1 HÌNH CHỮ NHẬT29384 X 3919 = 2 Tấm | C20: Bạt I95 - SC30C1 ( 29384 x 3919 ) x 2 tấm | D20: bạt da 2 lớp chống nước, khuyên cách nhau 500-mua theo bản vẽ | E20: m2 | F20: 230.31 | G20: N/A | H20: N/A | I20: N/A | J20: N/A | K20: V | L20: 50500 | M20: =L20*F20 -> 11630655 | N20: Trần Toàn | O20: Chưa có trong dự toán
A21: I95-VDK-027 | B21: I95-BAT-BC401 HÌNH CHỮ NHẬT11902 X 4126 = 2 Tấm | C21: Bạt I95 -BC401 ( 11902 x 4126 ) x 2 tấm | D21: bạt da 2 lớp chống nước, khuyên cách nhau 500-mua theo bản vẽ | E21: m2 | F21: 98.22 | G21: N/A | H21: N/A | I21: N/A | J21: N/A | K21: V | L21: 50500 | M21: =L21*F21 -> 4960110 | N21: Trần Toàn | O21: Chưa có trong dự toán
A22: I95-VDK-027 | B22: I95-BAT-SC40A1 HÌNH CHỮ NHẬT29340 X 3926 = 2 Tấm | C22: Bạt I95 - SC40A1 ( 29340 x 3926 ) x 2 tấm | D22: bạt da 2 lớp chống nước, khuyên cách nhau 500-mua theo bản vẽ | E22: m2 | F22: 230.38 | G22: N/A | H22: N/A | I22: N/A | J22: N/A | K22: V | L22: 50500 | M22: =L22*F22 -> 11634190 | N22: Trần Toàn | O22: Chưa có trong dự toán
A23: I95-VDK-027 | B23: I95-BAT-SC40C1 HÌNH CHỮ NHẬT29340 X 3926 = 2 Tấm | C23: Bạt I95 - SC40C1 ( 29340 x 3926 ) x 2 tấm | D23: bạt da 2 lớp chống nước, khuyên cách nhau 500-mua theo bản vẽ | E23: m2 | F23: 230.38 | G23: N/A | H23: N/A | I23: N/A | J23: N/A | K23: V | L23: 50500 | M23: =L23*F23 -> 11634190 | N23: Trần Toàn | O23: Chưa có trong dự toán
... A104: I95-VDK-027 | B104: I95-BAT-RFR19 HÌNH CHỮ NHẬT4650 X 2602 = 2 Tấm | C104: Bạt I95 - RFR19 ( 4650 x 2602 ) x 2 tấm | D104: bạt da 2 lớp chống nước, khuyên cách nhau 500-mua theo bản vẽ | E104: m2 | F104: 24.2 | G104: N/A | H104: N/A | I104: N/A | J104: N/A | K104: V | L104: 50500 | M104: =L104*F104 -> 1222100 | N104: Trần Toàn | O104: Chưa có trong dự toán
B105: Xếp hạng | L105: 1
A106: Ghi chú: PTM tiến hàng mua sắm để đảm bảo tiến độ
A107: NGƯỜI ĐỀ NGHỊ/ RECOMMENDATION BY: | D107: NGƯỜI KIỂM TRA/ DEPARTMENT HEAD CHECK BY: | I107: APPROVED BY: PHÊ DUYỆT
H108: Nguyễn Quang Vinh | K108: Hoàng Ngọc Bằng | N108: Đoàn Văn Toàn

Sheet hOÀNG hÀ 26-1 
A1: BID ANALYSIS - GIẢI TRÌNH MUA SẮM/ĐẤU THẦU
A3: Project | B3: PROJECT No/ Dự án: 25-VPI-I-095
A4: Dự án
A5: Subject | B5: Cung cấp vật tư phụ kiện / đóng kiện hoàng hà 26-1-2026
A6: Chủ đề
A8: No. | B8: CONTENT | C8: Phạm vi công việc | I8: Dự toán | K8: Đã mua | L8: Đơn vị cung cấp chào giá (vnđ) | O8: Lựa chọn | P8: Ghi chú
A9: Item | B9: Description/ Chi tiết | C9: Profile/ Vật tư | D9: Grade/ Mác vật liệu | E9: Grade/ Mác vật liệu mua | F9: Số lượng Mua | H9: Khối lượng/ Số lượng | I9: Đơn giá (vnd) | J9: Thành tiền (vnd) | K9: Thành tiền (vnd) | L9: HOÀNG HÀ
L10: Phạm vi | M10: Đơn giá (VND) | N10: Thành Tiền (Chưa có VAT)
A11: Tổng | B11: Bolt-Material / Vật tư bulong, phụ kiện | H11: N/A | I11: N/A | J11: ='Tổng hợp'!K23 -> 9.374355e+09 | K11: ='Tổng hợp'!J23+'Tổng hợp'!J22-'Vật tư bạt trần toàn'!M11 -> 21764911718 | N11: =SUM(N12:N16) -> 14650000 | P11: =J11-K11-N11 -> -1.2405207e+10
A12: I95-VPK-028 | B12: =VLOOKUP(A12,'25-VPI-I-095'!L:N,3,0) -> VÍT TỰ KHOAN M5X10 | C12: Vít tự khoan đầu bằng | D12: M4.8*13 | E12: Inox 410 | F12: 7000 | G12: cái | H12: =VLOOKUP(A12,'25-VPI-I-095'!L:DG,95,0) -> 7000 | I12: N/A | J12: N/A | K12: N/A | L12: V | M12: 350 | N12: =M12*F12 -> 2450000 | O12: HOÀNG HÀ | Q12: =G12-H12 -> #VALUE!
A13: I95-VPK-096 | B13: =VLOOKUP(A13,'25-VPI-I-095'!L:N,3,0) -> UBOLT_DN40_M10(4N+2W) | C13: Ubolt làm theo bản vẽ | E13: Mạ kẽm | F13: 80 | G13: T4E2P | H13: =VLOOKUP(A13,'25-VPI-I-095'!L:DG,95,0) -> 80 | I13: N/A | J13: N/A | K13: N/A | L13: V | M13: 45000 | N13: =M13*F13 -> 3600000 | O13: HOÀNG HÀ | Q13: =G13-H13 -> #VALUE!
A14: I95-VPK-097 | B14: =VLOOKUP(A14,'25-VPI-I-095'!L:N,3,0) -> WASHER M16-ISO7089-140HV-HDG | C14: Long đen phẳng | D14: M16 | E14: Mạ kẽm nhúng nóng | F14: 80 | G14: cái | H14: =VLOOKUP(A14,'25-VPI-I-095'!L:DG,95,0) -> 80 | I14: N/A | J14: N/A | K14: N/A | L14: V | M14: 700 | N14: =M14*F14 -> 56000 | O14: HOÀNG HÀ | Q14: =G14-H14 -> #VALUE!
A15: I95-VPK-098 | B15: =VLOOKUP(A15,'25-VPI-I-095'!L:N,3,0) -> NUT M16-ISO4032-HDG | C15: Ecu | D15: M16 | E15: Mạ kẽm nhúng nóng | F15: 80 | G15: cái | H15: =VLOOKUP(A15,'25-VPI-I-095'!L:DG,95,0) -> 80 | I15: N/A | J15: N/A | K15: N/A | L15: V | M15: 3800 | N15: =M15*F15 -> 304000 | O15: HOÀNG HÀ | Q15: =G15-H15 -> #VALUE!
A16: I95-VPK-099 | B16: =VLOOKUP(A16,'25-VPI-I-095'!L:N,3,0) -> LÒ SO SPRING_D3 | C16: Loò xo làm theo bản vẻ | D16: D3 | E16: Inox 304 | F16: 80 | G16: cái | H16: =VLOOKUP(A16,'25-VPI-I-095'!L:DG,95,0) -> 80 | I16: N/A | J16: N/A | K16: N/A | L16: V | M16: 103000 | N16: =M16*F16 -> 8240000 | O16: HOÀNG HÀ | Q16: =G16-H16 -> #VALUE!
A17: Tổng | B17: Packing-Material / Vật tư đóng kiện | J17: ='Tổng hợp'!K19 -> 5.7151444e+10 | K17: ='Tổng hợp'!J19+'Tổng hợp'!J24 -> 5.0853523e+10 | N17: =SUM(N18:N24) -> 72902300 | P17: =J17-K17-N17 -> 6.225019e+09
A18: I95-VDK-019 | B18: =VLOOKUP(A18,'25-VPI-I-095'!L:N,3,0) -> BOLT-M12x40-ISO4017/ISO4032(1B+1N) | C18: Bu lông ren ren suốt | D18: M12*40 | E18: Mạ kẽm 8.8 | F18: 4100 | G18: TE | H18: =VLOOKUP(A18,'25-VPI-I-095'!L:DG,95,0) -> 4100 | I18: N/A | J18: N/A | K18: N/A | L18: V | M18: 2800 | N18: =M18*F18 -> 11480000 | O18: HOÀNG HÀ | Q18: =G18-H18 -> #VALUE!
A19: I95-VDK-020 | B19: =VLOOKUP(A19,'25-VPI-I-095'!L:N,3,0) -> BOLT-M16x50-ISO4017/ISO4032(1B+1N) | C19: Bu lông ren ren suốt | D19: M16*50 | E19: Mạ kẽm 8.8 | F19: 1700 | G19: TE | H19: =VLOOKUP(A19,'25-VPI-I-095'!L:DG,95,0) -> 1700 | I19: N/A | J19: N/A | K19: N/A | L19: V | M19: 6190 | N19: =M19*F19 -> 10523000 | O19: HOÀNG HÀ | Q19: =G19-H19 -> #VALUE!
A20: I95-VDK-021 | B20: =VLOOKUP(A20,'25-VPI-I-095'!L:N,3,0) -> BOLT-M16X60-ISO4017/ISO4032(1B+1N) | C20: Bu lông ren ren suốt | D20: M16*60 | E20: Mạ kẽm 8.8 | F20: 970 | G20: TE | H20: =VLOOKUP(A20,'25-VPI-I-095'!L:DG,95,0) -> 970 | I20: N/A | J20: N/A | K20: N/A | L20: V | M20: 6790 | N20: =M20*F20 -> 6586300 | O20: HOÀNG HÀ | Q20: =G20-H20 -> #VALUE!
A21: I95-VDK-022 | B21: =VLOOKUP(A21,'25-VPI-I-095'!L:N,3,0) -> BOLT-M16X90-ISO4017/ISO4032(1B+1N) | C21: Bu lông ren ren suốt | D21: M16*90 | E21: Mạ kẽm 8.8 | F21: 200 | G21: TE | H21: =VLOOKUP(A21,'25-VPI-I-095'!L:DG,95,0) -> 200 | I21: N/A | J21: N/A | K21: N/A | L21: V | M21: 8690 | N21: =M21*F21 -> 1738000 | O21: HOÀNG HÀ | Q21: =G21-H21 -> #VALUE!
A22: I95-VDK-023 | B22: =VLOOKUP(A22,'25-VPI-I-095'!L:N,3,0) -> dây Polyme belt 32 | C22: Dây chằng hàng | D22: D32 | E22: Vải | F22: 3000 | G22: Met | H22: =VLOOKUP(A22,'25-VPI-I-095'!L:DG,95,0) -> 3000 | I22: N/A | J22: N/A | K22: N/A | L22: V | M22: 4200 | N22: =M22*F22 -> 12600000 | O22: HOÀNG HÀ | Q22: =G22-H22 -> #VALUE!
A23: I95-VDK-025 | B23: =VLOOKUP(A23,'25-VPI-I-095'!L:N,3,0) -> dây cáp vải rộng 50 | C23: dây cáp vải rộng 50 | D23: D50 | E23: Vải | F23: 5000 | G23: Met | H23: =VLOOKUP(A23,'25-VPI-I-095'!L:DG,95,0) -> 5000 | I23: N/A | J23: N/A | K23: N/A | L23: V | M23: 5830 | N23: =M23*F23 -> 29150000 | O23: HOÀNG HÀ | Q23: =G23-H23 -> #VALUE!
A24: I95-VDK-031 | B24: =VLOOKUP(A24,'25-VPI-I-095'!L:N,3,0) -> VÍT TỰ KHOAN M5X20-MẠ KẼM | C24: VÍT TỰ KHOAN M5X20-MẠ KẼM | D24: M5*19 | E24: Mạ kẽm nhúng nóng | F24: 1500 | G24: cái | H24: =VLOOKUP(A24,'25-VPI-I-095'!L:DG,95,0) -> 1500 | I24: N/A | J24: N/A | K24: N/A | L24: V | M24: 550 | N24: =M24*F24 -> 825000 | O24: HOÀNG HÀ | Q24: =G24-H24 -> #VALUE!
B25: Xếp hạng | M25: 1
A26: Ghi chú: PTM tiến hàng mua sắm để đảm bảo tiến độ
A27: NGƯỜI ĐỀ NGHỊ/ RECOMMENDATION BY: | D27: NGƯỜI KIỂM TRA/ DEPARTMENT HEAD CHECK BY: | J27: APPROVED BY: PHÊ DUYỆT
I28: Nguyễn Quang Vinh | L28: Hoàng Ngọc Bằng | O28: Đoàn Văn Toàn

Sheet Kế hoạch thanh toán
A1: STT | B1: SUPPLIER | C1: SALE CONTRACT | D1: Dự án | E1: VALUE (CIF HAI PHONG PORT) Hoặc giá trước Thuế | F1: PAYMENTS | G1: SIGN DATE | H1: L/C | I1: ETD | J1: ETA | K1: DOCUMENT | L1: Kế hoạch thanh toán | M1: Deadline of L/C | N1: Notet
A2: 1 | B2: GLOBAL | C2: IBS-FY260115 | D2: DA 095 | E2: 1020.5 | F2: T/T | G2: 46038 | H2: N/A | I2: 46058 | J2: 46066 | K2: N/A | L2: Tháng 2 | M2: N/A | N2: Tính phương án lưu container
A3: 2 | B3: GLOBAL | C3: IBSHI-FENGYANG/2512-30 | D3: DA 095 | E3: 19507.84 | F3: LC 100% | G3: 46021 | H3: 46035 | I3: 46058 | J3: 46066 | K3: 46068 | L3: Tháng 2 | M3: 46083 | N3: Tính phương án lưu container
A4: 3 | B4: CENTERWAY | C4: CTWSO2025470ZY | D4: DA 095 | E4: 11753.2 | F4: LC 100% | G4: 45999 | H4: 46013 | I4: 46039 | J4: 46047 | K4: 46052 | L4: Tháng 2 | M4: 46069 | N4: Thanh toán trước tết
A5: 4 | B5: GNEE | C5: IBSHI-GNEE/2511-28 | D5: DA 095 | E5: 97932.26 | F5: LC 100% | G5: 45989 | H5: 46004 | I5: 46055 | J5: =I5+12 -> 46067 | K5: 46071 | L5: Tháng 2 | N5: Tính phương án lưu container
A6: 5 | B6: GNEE | C6: IBSHI-GNEE/2512-24 | D6: DA 095 | E6: 21340.3 | F6: DP | G6: 46015 | H6: N/A | I6: 46038 | J6: 46048 | K6: 46055 | L6: Tháng 2 | M6: N/A | N6: Thanh toán trước tết
A7: 6 | B7: JFE | C7: JFEBS-IBS-001 | D7: DA 095 | E7: 47822.4 | F7: LC 100% | G7: 46015 | H7: 46027 | I7: 46111 | J7: =I7+14 -> 46125 | K7: =J7+2 -> 46127 | L7: Tháng 4 | N7: Thanh toán sau tết
A8: 7 | B8: MCL | C8: 25MCL157S | D8: DA 095 | E8: 39892.1 | F8: DP | G8: 46013 | H8: N/A | I8: 46053 | J8: 46065 | K8: =J8+2 -> 46067 | L8: Tháng 2 | M8: N/A | N8: Tính phương án lưu container
B9: Số tiền cần thanh toán trong tháng 2 dự kiến: | F9: =SUM(E10:E154) -> 16129944088
B10: Đơn nhập khẩu quy ra VNĐ (Sum của các mục nhập khẩu phía trên trong tháng 2) | D10: DA 095 | E10: =26300*(SUM(E2:E6)+E8) -> 5035035060
A11: 8 | B11: Ngọc Hiếu đơn 1 | C11: Thép Hình/ Thép tấm | D11: DA 095 | E11: ='Ngọc hiếu 095 26-1'!M11 -> 1898049693 | K11: Hàng đang đi lấy | L11: Tháng 2 | M11: N/A
A12: 9 | B12: Hoàng Hà 1 | C12: Bu lông | D12: DA 095 | E12: ='Vật tư phụ Hoàng hà 2'!Q13 -> 99508400 | K12: Hàng đa giao ngày 20/1 | L12: Tháng 2
A13: 10 | B13: Hoàng Hà 2 | C13: Bu lông | D13: DA 095 | E13: ='hOÀNG hÀ 26-1 '!N11+'hOÀNG hÀ 26-1 '!N17 -> 87552300 | K13: Hàng sẽ giao ngày 6/2 | L13: Tháng 2
A14: 11 | B14: Hoàng Hà 3 | C14: Bu lông | D14: G07 | E14: 23000000 | K14: Hàng sẽ giao hàng ngày 2/2 | L14: Tháng 2
A15: 12 | B15: Trần Toàn | C15: Bạt | D15: DA 095 | E15: ='Vật tư bạt trần toàn'!M11 -> 559330930 | K15: Hàng sẽ giao trong tháng 2 | L15: Tháng 2
A16: 13 | B16: Xalaco 1 | C16: Bông bảo ôn (Phải thanh toán trước tết để xalaco nhập đợt 2) | D16: DA 095 | E16: 1.5589282e+09 | K16: Thanh toán tiền hàng giao đợt 1: 24/01/2026 và 26/01/2026 Đề nghị thanh toán xong trước ngày 07/02/2026 để giao lần 2 | L16: Tháng 2
A17: 14 | B17: Xalaco 2 | C17: Bông bảo ôn lần 2 | D17: DA 095 | E17: 2.7303998e+09 | K17: Dự kiến thanh toán và giao hàng vào tháng 2 , sau khi nhận tiền đợt 1 | L17: Tháng 2
A18: 15 | B18: Xalaco 3 | C18: Lưới | D18: DA 095 | E18: =XALACO2!O11 -> 89770000 | K18: Hàng sẽ giao trước 14/2 | L18: Tháng 2
A19: 16 | B19: Xalaco 4 | C19: Gioăng | D19: DA 078 | E19: 2.6782764e+08 | K19: Hàng đã giao | L19: Tháng 2
A20: 17 | B20: Kiên Dũng | C20: Gioăng | D20: DA 095 | E20: 10152000 | K20: Hàng sẽ giao trước ngày 9/2 | L20: Tháng 2
A21: 18 | B21: SUN COMMERCIAL | C21: Keo | D21: DA 095 | E21: ='Vật tư SUN COMMERCIAL'!K12 -> 9900000 | K21: Thanh toán xong mới có hàng | L21: Tháng 2
A22: 19 | B22: FUJIMOTO đơn 1 | C22: Vit | D22: DA 095 | E22: 7613000 | K22: Hàng sẽ giao ngày 24/2 | L22: Tháng 2
A23: 20 | B23: FUJIMOTO đơn 2 | C23: Vít | D23: DA 095 | E23: 7500000 | K23: Hàng sẽ giao ngày 24/2 | L23: Tháng 2
A24: 21 | B24: Hùng Nguyên trước đó | C24: Thép tấm | D24: All | E24: =1146425831-E25-E26 -> 814734821 | K24: Đa giao hàng từ lâu | L24: Tháng 2
A25: 22 | B25: Hùng Nguyên | C25: Thép tấm | D25: DA 095 | E25: 185676739 | K25: Hàng giao ngày 28/1 | L25: Tháng 2
A26: 23 | B26: Hùng Nguyên2 | C26: Thép tấm | D26: G07 | E26: 146014271 | K26: Hàng đã giao ngày 28/1 | L26: Tháng 2
A27: 24 | B27: Hùng Nguyên3 | C27: Thép hình | D27: DA 095 | E27: 73162492 | K27: Dự kiến lấy hàng 2/2 | L27: Tháng 2
A28: 25 | B28: Hùng Nguyên4 | C28: Thép hình | D28: DA 095 | E28: 93135268 | K28: Ngày 31/1 đi lấy hàng | L28: Tháng 2
A29: 26 | B29: Quang Thịnh Phát 1 | C29: Thép ống | D29: DA 095 | E29: 11745998 | K29: Hàng đã giao ngày 25/1 | L29: Tháng 2
A30: 27 | B30: VSAN | C30: Bu lông | D30: DA 095 | E30: 1150430610 | K30: Hàng đã giao ngày 30/1 | L30: Tháng 2
A31: 28 | B31: VSAN 2 | C31: Bu lông | D31: DA 095 | E31: 44484000 | K31: Hàng sẽ giao trước 14/2 | L31: Tháng 2
A32: 29 | B32: VSAN 3 | C32: Bu lông | D32: DA 095 | E32: 302139706 | K32: Hàng sẽ giao trước 14/2 | L32: Tháng 2
A33: 30 | B33: Hoàng Anh Minh | C33: Gỗ | D33: DA 097/100/90 | E33: 205858000 | K33: Đã giao | L33: Tháng 2
A34: 31 | B34: WINWIN | C34: Tạm ứng sàn 30% | D34: DA 095 | E34: =3589976000*0.2 -> 717995200 | K34: Tạm ứng/ giá có thể thay đổi | L34: Tháng 2

Sheet VSAN 27-1
A1: BID ANALYSIS - GIẢI TRÌNH MUA SẮM/ĐẤU THẦU
A3: Project | B3: PROJECT No/ Dự án: 25-VPI-I-095
A4: Dự án
A5: Subject | B5: Cung cấp vật tư phụ kiện VSAN 27-1-2026
A6: Chủ đề
A8: No. | B8: CONTENT | C8: Phạm vi công việc | I8: Dự toán | K8: Đã mua | L8: Đơn vị cung cấp chào giá (vnđ) | O8: Lựa chọn | P8: Ghi chú
A9: Item | B9: Description/ Chi tiết | C9: Profile/ Vật tư | D9: Grade/ Mác vật liệu | E9: Grade/ Mác vật liệu mua | F9: Số lượng Mua | H9: Khối lượng/ Số lượng | I9: Đơn giá (vnd) | J9: Thành tiền (vnd) | K9: Thành tiền (vnd) | L9: VSAN
L10: Phạm vi | M10: Đơn giá (VND) | N10: Thành Tiền (Chưa có VAT)
A11: Tổng | B11: Bolt-Material / Vật tư bulong, phụ kiện | H11: N/A | I11: N/A | J11: ='Tổng hợp'!K23 -> 9.374355e+09 | K11: ='Tổng hợp'!J23+'Tổng hợp'!J22 -> 22324242648 | N11: =SUM(N12:N25) -> 325180800 | P11: =J11-K11-N11 -> -1.3275068e+10
A12: I95-VPK-104 | B12: =VLOOKUP(A12,'25-VPI-I-095'!L:N,3,0) -> BOLT-1 1/2"x4 1/4"LG-A193-B7-HDG | C12: BOLT-1 1/2"x4 1/4"LG-A193-B7-HDG | D12: A193-B7 | E12: bolt full thread | F12: CÁI | G12: 80 | H12: =VLOOKUP(A12,'25-VPI-I-095'!L:DG,95,0) -> 80 | I12: N/A | J12: N/A | K12: N/A | L12: V | M12: 229600 | N12: 18368000 | O12: VSAN | Q12: =G12-H12 -> 0
A13: I95-VPK-105 | B13: =VLOOKUP(A13,'25-VPI-I-095'!L:N,3,0) -> BOLT-1 1/8"x4 1/2"LG(1B+1N+1W+1DTIW)-A490-GEOMET | C13: BOLT-1 1/8"x4 1/2"LG(1B+1N+1W+1DTIW)-A490-GEOMET | D13: A490/A563/F436/F959 | E13: bolt full thread | F13: BỘ | G13: 424 | H13: =VLOOKUP(A13,'25-VPI-I-095'!L:DG,95,0) -> 424 | I13: N/A | J13: N/A | K13: N/A | L13: V | M13: 239000 | N13: 101336000 | O13: VSAN | Q13: =G13-H13 -> 0
A14: I95-VPK-106 | B14: =VLOOKUP(A14,'25-VPI-I-095'!L:N,3,0) -> BOLT-1 1/8"x4"LG(1B+1N+1W+1DTIW)-A490-GEOMET | C14: BOLT-1 1/8"x4"LG(1B+1N+1W+1DTIW)-A490-GEOMET | D14: A490/A563/F436/F959 | E14: bolt full thread | F14: BỘ | G14: 494 | H14: =VLOOKUP(A14,'25-VPI-I-095'!L:DG,95,0) -> 494 | I14: N/A | J14: N/A | K14: N/A | L14: V | M14: 228000 | N14: 112632000 | O14: VSAN | Q14: =G14-H14 -> 0
A15: I95-VPK-107 | B15: =VLOOKUP(A15,'25-VPI-I-095'!L:N,3,0) -> BOLT-3/4"x2 1/2"LG(1B+1N)-A193B7-HDG | C15: BOLT-3/4"x2 1/2"LG(1B+1N)-A193B7-HDG | D15: A193-B7/A194-7 | E15: bolt full thread | F15: BỘ | G15: 28 | H15: =VLOOKUP(A15,'25-VPI-I-095'!L:DG,95,0) -> 28 | I15: N/A | J15: N/A | K15: N/A | L15: V | M15: 60000 | N15: 1680000 | O15: VSAN | Q15: =G15-H15 -> 0
A16: I95-VPK-108 | B16: =VLOOKUP(A16,'25-VPI-I-095'!L:N,3,0) -> BOLT-3/4"x2 3/4"LG-FULL THREAD-A193B7-HDG | C16: BOLT-3/4"x2 3/4"LG-FULL THREAD-A193B7-HDG | D16: A193-B7/A194-7 | E16: bolt full thread | F16: BỘ | G16: 62 | H16: =VLOOKUP(A16,'25-VPI-I-095'!L:DG,95,0) -> 62 | I16: N/A | J16: N/A | K16: N/A | L16: V | M16: 62400 | N16: 3868800 | O16: VSAN | Q16: =G16-H16 -> 0
A17: I95-VPK-109 | B17: =VLOOKUP(A17,'25-VPI-I-095'!L:N,3,0) -> BOLT-3/4"x3 1/2"LG(1B+1N)-A193B7-HDG | C17: BOLT-3/4"x3 1/2"LG(1B+1N)-A193B7-HDG | D17: A193-B7/A194-7 | E17: bolt full thread | F17: BỘ | G17: 194 | H17: =VLOOKUP(A17,'25-VPI-I-095'!L:DG,95,0) -> 194 | I17: N/A | J17: N/A | K17: N/A | L17: V | M17: 65000 | N17: 12610000 | O17: VSAN | Q17: =G17-H17 -> 0
A18: I95-VPK-110 | B18: =VLOOKUP(A18,'25-VPI-I-095'!L:N,3,0) -> BOLT-5/8"x1 3/4"LG-A193-B7-HDG | C18: BOLT-5/8"x1 3/4"LG-A193-B7-HDG | D18: A193-B7 | E18: bolt full thread | F18: CÁI | G18: 582 | H18: =VLOOKUP(A18,'25-VPI-I-095'!L:DG,95,0) -> 582 | I18: N/A | J18: N/A | K18: N/A | L18: V | M18: 29000 | N18: 16878000 | O18: VSAN | Q18: =G18-H18 -> 0
A19: I95-VPK-111 | B19: =VLOOKUP(A19,'25-VPI-I-095'!L:N,3,0) -> BOLT-5/8"x3"LG(1B+1N)-A193B7-HDG | C19: BOLT-5/8"x3"LG(1B+1N)-A193B7-HDG | D19: A193-B7/A194-7 | E19: bolt full thread | F19: BỘ | G19: 1004 | H19: =VLOOKUP(A19,'25-VPI-I-095'!L:DG,95,0) -> 1004 | I19: N/A | J19: N/A | K19: N/A | L19: V | M19: 39000 | N19: 39156000 | O19: VSAN | Q19: =G19-H19 -> 0
A20: I95-VPK-112 | B20: =VLOOKUP(A20,'25-VPI-I-095'!L:N,3,0) -> BOLT-5/8"x3"LG-A193-B7-HDG | C20: BOLT-5/8"x3"LG-A193-B7-HDG | D20: A193-B7 | E20: bolt full thread | F20: CÁI | G20: 160 | H20: =VLOOKUP(A20,'25-VPI-I-095'!L:DG,95,0) -> 160 | I20: N/A | J20: N/A | K20: N/A | L20: V | M20: 24800 | N20: 3968000 | O20: VSAN | Q20: =G20-H20 -> 0
A21: I95-VPK-113 | B21: =VLOOKUP(A21,'25-VPI-I-095'!L:N,3,0) -> NUT-1 1/2"-A194-2H-HDG | C21: NUT-1 1/2"-A194-2H-HDG | D21: A194-2H | F21: CÁI | G21: 80 | H21: =VLOOKUP(A21,'25-VPI-I-095'!L:DG,95,0) -> 80 | I21: N/A | J21: N/A | K21: N/A | L21: V | M21: 74400 | N21: 5952000 | O21: VSAN | Q21: =G21-H21 -> 0
A22: I95-VPK-114 | B22: =VLOOKUP(A22,'25-VPI-I-095'!L:N,3,0) -> NUT-3/4"-A194GR7-HDG | C22: NUT-3/4"-A194GR7-HDG | D22: A194-7 | F22: CÁI | G22: 124 | H22: =VLOOKUP(A22,'25-VPI-I-095'!L:DG,95,0) -> 124 | I22: N/A | J22: N/A | K22: N/A | L22: V | M22: 16800 | N22: 2083200 | O22: VSAN | Q22: =G22-H22 -> 0
A23: I95-VPK-115 | B23: =VLOOKUP(A23,'25-VPI-I-095'!L:N,3,0) -> NUT-5/8"-A194-2H-HDG | C23: NUT-5/8"-A194-2H-HDG | D23: A194-2H | F23: CÁI | G23: 740 | H23: =VLOOKUP(A23,'25-VPI-I-095'!L:DG,95,0) -> 740 | I23: N/A | J23: N/A | K23: N/A | L23: V | M23: 6800 | N23: 5032000 | O23: VSAN | Q23: =G23-H23 -> 0
A24: I95-VPK-116 | B24: =VLOOKUP(A24,'25-VPI-I-095'!L:N,3,0) -> WASHER-1 1/2"x3"OD-F436-HDG | C24: WASHER-1 1/2"x3"OD-F436-HDG | D24: F436 | F24: CÁI | G24: 80 | H24: =VLOOKUP(A24,'25-VPI-I-095'!L:DG,95,0) -> 80 | I24: N/A | J24: N/A | K24: N/A | L24: V | M24: 16800 | N24: 1344000 | O24: VSAN | Q24: =G24-H24 -> 0
A25: I95-VPK-117 | B25: =VLOOKUP(A25,'25-VPI-I-095'!L:N,3,0) -> WASHER-3/4"-SUS304 | C25: WASHER-3/4"-SUS304 | D25: SUS304 | F25: CÁI | G25: 62 | H25: =VLOOKUP(A25,'25-VPI-I-095'!L:DG,95,0) -> 62 | I25: N/A | J25: N/A | K25: N/A | L25: V | M25: 4400 | N25: 272800 | O25: VSAN | Q25: =G25-H25 -> 0
B26: Xếp hạng | M26: 1
A27: Ghi chú: PTM tiến hàng mua sắm để đảm bảo tiến độ
A28: NGƯỜI ĐỀ NGHỊ/ RECOMMENDATION BY: | D28: NGƯỜI KIỂM TRA/ DEPARTMENT HEAD CHECK BY: | J28: APPROVED BY: PHÊ DUYỆT
I29: Nguyễn Quang Vinh | L29: Hoàng Ngọc Bằng | O29: Đoàn Văn Toàn

Sheet VSAN 26-1
A1: BID ANALYSIS - GIẢI TRÌNH MUA SẮM/ĐẤU THẦU
A3: Project | B3: PROJECT No/ Dự án: 25-VPI-I-095
A4: Dự án
A5: Subject | B5: Cung cấp vật tư phụ kiện VSAN 28-1-2026
A6: Chủ đề
A8: No. | B8: CONTENT | C8: Phạm vi công việc | H8: Dự toán | K8: Đã mua | L8: Đơn vị cung cấp chào giá (vnđ) | O8: Đơn vị cung cấp chào giá (vnđ) | R8: Đơn vị cung cấp chào giá (vnđ) | U8: Lựa chọn | V8: Ghi chú
A9: Item | B9: Description/ Chi tiết | C9: Profile/ Vật tư | D9: Grade/ Mác vật liệu | E9: Grade/ Mác vật liệu mua | F9: Số lượng Mua | H9: Khối lượng/ Số lượng | I9: Đơn giá (vnd) | J9: Thành tiền (vnd) | K9: Thành tiền (vnd) | L9: VSAN | O9: HSC | R9: FUJIMOTO offer
L10: Phạm vi | M10: Đơn giá (VND) | N10: Thành Tiền (Chưa có VAT) | O10: Phạm vi | P10: Đơn giá (USD) Giá CIF | Q10: Thành Tiền (USD | R10: Phạm vi | S10: Đơn giá (VND) | T10: Tiến độ
A11: Tổng | B11: Bolt-Material / Vật tư bulong, phụ kiện | H11: N/A | I11: N/A | J11: ='Tổng hợp'!K23 -> 9.374355e+09 | K11: ='Tổng hợp'!J23+'Tổng hợp'!J22 -> 22324242648 | N11: =SUM(N12:N87) -> 1797978240 | V11: =J11-K11-N11 -> -1.4747866e+10
